[2025-03-12 00:07:56,401] INFO in logger: [LOGIN_SUCCESS] User 1: User logged in successfully
[2025-03-12 00:08:20,632] ERROR in logger: [EXCEPTION] User 1: Unhandled exception: AttributeError
[2025-03-12 00:08:20,636] ERROR in app: Exception on /auth/check-token [GET]
Traceback (most recent call last):
  File "/Users/macbookpro/Documents/projects/WSS/venv/lib/python3.11/site-packages/flask/app.py", line 1463, in wsgi_app
    response = self.full_dispatch_request()
               ^^^^^^^^^^^^^^^^^^^^^^^^^^^^
  File "/Users/macbookpro/Documents/projects/WSS/venv/lib/python3.11/site-packages/flask/app.py", line 872, in full_dispatch_request
    rv = self.handle_user_exception(e)
         ^^^^^^^^^^^^^^^^^^^^^^^^^^^^^
  File "/Users/macbookpro/Documents/projects/WSS/venv/lib/python3.11/site-packages/flask_cors/extension.py", line 176, in wrapped_function
    return cors_after_request(app.make_response(f(*args, **kwargs)))
                                                ^^^^^^^^^^^^^^^^^^
  File "/Users/macbookpro/Documents/projects/WSS/venv/lib/python3.11/site-packages/flask/app.py", line 762, in handle_user_exception
    return self.ensure_sync(handler)(e)  # type: ignore[no-any-return]
           ^^^^^^^^^^^^^^^^^^^^^^^^^^^^
  File "/Users/macbookpro/Documents/projects/WSS/majesty-backend/app/utils/logger.py", line 184, in log_exception
    raise exception
  File "/Users/macbookpro/Documents/projects/WSS/venv/lib/python3.11/site-packages/flask/app.py", line 870, in full_dispatch_request
    rv = self.dispatch_request()
         ^^^^^^^^^^^^^^^^^^^^^^^
  File "/Users/macbookpro/Documents/projects/WSS/venv/lib/python3.11/site-packages/flask/app.py", line 855, in dispatch_request
    return self.ensure_sync(self.view_functions[rule.endpoint])(**view_args)  # type: ignore[no-any-return]
           ^^^^^^^^^^^^^^^^^^^^^^^^^^^^^^^^^^^^^^^^^^^^^^^^^^^^^^^^^^^^^^^^^
  File "/Users/macbookpro/Documents/projects/WSS/venv/lib/python3.11/site-packages/flask_jwt_extended/view_decorators.py", line 170, in decorator
    return current_app.ensure_sync(fn)(*args, **kwargs)
           ^^^^^^^^^^^^^^^^^^^^^^^^^^^^^^^^^^^^^^^^^^^^
  File "/Users/macbookpro/Documents/projects/WSS/majesty-backend/app/routes/auth.py", line 130, in check_token
    expiry_datetime = datetime.utcfromtimestamp(expiry_timestamp)
                      ^^^^^^^^^^^^^^^^^^^^^^^^^
AttributeError: module 'datetime' has no attribute 'utcfromtimestamp'
[2025-03-12 00:08:20,640] ERROR in logger: [EXCEPTION] User 1: Unhandled exception: InternalServerError
[2025-03-12 00:08:31,180] ERROR in logger: [EXCEPTION] User 1: Unhandled exception: AttributeError
[2025-03-12 00:08:31,184] ERROR in app: Exception on /auth/check-token [GET]
Traceback (most recent call last):
  File "/Users/macbookpro/Documents/projects/WSS/venv/lib/python3.11/site-packages/flask/app.py", line 1463, in wsgi_app
    response = self.full_dispatch_request()
               ^^^^^^^^^^^^^^^^^^^^^^^^^^^^
  File "/Users/macbookpro/Documents/projects/WSS/venv/lib/python3.11/site-packages/flask/app.py", line 872, in full_dispatch_request
    rv = self.handle_user_exception(e)
         ^^^^^^^^^^^^^^^^^^^^^^^^^^^^^
  File "/Users/macbookpro/Documents/projects/WSS/venv/lib/python3.11/site-packages/flask_cors/extension.py", line 176, in wrapped_function
    return cors_after_request(app.make_response(f(*args, **kwargs)))
                                                ^^^^^^^^^^^^^^^^^^
  File "/Users/macbookpro/Documents/projects/WSS/venv/lib/python3.11/site-packages/flask/app.py", line 762, in handle_user_exception
    return self.ensure_sync(handler)(e)  # type: ignore[no-any-return]
           ^^^^^^^^^^^^^^^^^^^^^^^^^^^^
  File "/Users/macbookpro/Documents/projects/WSS/majesty-backend/app/utils/logger.py", line 184, in log_exception
    raise exception
  File "/Users/macbookpro/Documents/projects/WSS/venv/lib/python3.11/site-packages/flask/app.py", line 870, in full_dispatch_request
    rv = self.dispatch_request()
         ^^^^^^^^^^^^^^^^^^^^^^^
  File "/Users/macbookpro/Documents/projects/WSS/venv/lib/python3.11/site-packages/flask/app.py", line 855, in dispatch_request
    return self.ensure_sync(self.view_functions[rule.endpoint])(**view_args)  # type: ignore[no-any-return]
           ^^^^^^^^^^^^^^^^^^^^^^^^^^^^^^^^^^^^^^^^^^^^^^^^^^^^^^^^^^^^^^^^^
  File "/Users/macbookpro/Documents/projects/WSS/venv/lib/python3.11/site-packages/flask_jwt_extended/view_decorators.py", line 170, in decorator
    return current_app.ensure_sync(fn)(*args, **kwargs)
           ^^^^^^^^^^^^^^^^^^^^^^^^^^^^^^^^^^^^^^^^^^^^
  File "/Users/macbookpro/Documents/projects/WSS/majesty-backend/app/routes/auth.py", line 130, in check_token
    expiry_datetime = datetime.utcfromtimestamp(expiry_timestamp)
                      ^^^^^^^^^^^^^^^^^^^^^^^^^
AttributeError: module 'datetime' has no attribute 'utcfromtimestamp'
[2025-03-12 00:08:31,186] ERROR in logger: [EXCEPTION] User 1: Unhandled exception: InternalServerError
[2025-03-12 00:11:19,218] ERROR in logger: [EXCEPTION] User 1: Unhandled exception: AttributeError
[2025-03-12 00:11:19,224] ERROR in app: Exception on /auth/check-token [GET]
Traceback (most recent call last):
  File "/Users/macbookpro/Documents/projects/WSS/venv/lib/python3.11/site-packages/flask/app.py", line 1463, in wsgi_app
    response = self.full_dispatch_request()
               ^^^^^^^^^^^^^^^^^^^^^^^^^^^^
  File "/Users/macbookpro/Documents/projects/WSS/venv/lib/python3.11/site-packages/flask/app.py", line 872, in full_dispatch_request
    rv = self.handle_user_exception(e)
         ^^^^^^^^^^^^^^^^^^^^^^^^^^^^^
  File "/Users/macbookpro/Documents/projects/WSS/venv/lib/python3.11/site-packages/flask_cors/extension.py", line 176, in wrapped_function
    return cors_after_request(app.make_response(f(*args, **kwargs)))
                                                ^^^^^^^^^^^^^^^^^^
  File "/Users/macbookpro/Documents/projects/WSS/venv/lib/python3.11/site-packages/flask/app.py", line 762, in handle_user_exception
    return self.ensure_sync(handler)(e)  # type: ignore[no-any-return]
           ^^^^^^^^^^^^^^^^^^^^^^^^^^^^
  File "/Users/macbookpro/Documents/projects/WSS/majesty-backend/app/utils/logger.py", line 184, in log_exception
    raise exception
  File "/Users/macbookpro/Documents/projects/WSS/venv/lib/python3.11/site-packages/flask/app.py", line 870, in full_dispatch_request
    rv = self.dispatch_request()
         ^^^^^^^^^^^^^^^^^^^^^^^
  File "/Users/macbookpro/Documents/projects/WSS/venv/lib/python3.11/site-packages/flask/app.py", line 855, in dispatch_request
    return self.ensure_sync(self.view_functions[rule.endpoint])(**view_args)  # type: ignore[no-any-return]
           ^^^^^^^^^^^^^^^^^^^^^^^^^^^^^^^^^^^^^^^^^^^^^^^^^^^^^^^^^^^^^^^^^
  File "/Users/macbookpro/Documents/projects/WSS/venv/lib/python3.11/site-packages/flask_jwt_extended/view_decorators.py", line 170, in decorator
    return current_app.ensure_sync(fn)(*args, **kwargs)
           ^^^^^^^^^^^^^^^^^^^^^^^^^^^^^^^^^^^^^^^^^^^^
  File "/Users/macbookpro/Documents/projects/WSS/majesty-backend/app/routes/auth.py", line 130, in check_token
    expiry_datetime = datetime.utcfromtimestamp(expiry_timestamp)  # Correct usage
                      ^^^^^^^^^^^^^^^^^^^^^^^^^
AttributeError: module 'datetime' has no attribute 'utcfromtimestamp'
[2025-03-12 00:11:19,226] ERROR in logger: [EXCEPTION] User 1: Unhandled exception: InternalServerError
[2025-03-12 00:11:20,458] ERROR in logger: [EXCEPTION] User 1: Unhandled exception: AttributeError
[2025-03-12 00:11:20,467] ERROR in app: Exception on /auth/check-token [GET]
Traceback (most recent call last):
  File "/Users/macbookpro/Documents/projects/WSS/venv/lib/python3.11/site-packages/flask/app.py", line 1463, in wsgi_app
    response = self.full_dispatch_request()
               ^^^^^^^^^^^^^^^^^^^^^^^^^^^^
  File "/Users/macbookpro/Documents/projects/WSS/venv/lib/python3.11/site-packages/flask/app.py", line 872, in full_dispatch_request
    rv = self.handle_user_exception(e)
         ^^^^^^^^^^^^^^^^^^^^^^^^^^^^^
  File "/Users/macbookpro/Documents/projects/WSS/venv/lib/python3.11/site-packages/flask_cors/extension.py", line 176, in wrapped_function
    return cors_after_request(app.make_response(f(*args, **kwargs)))
                                                ^^^^^^^^^^^^^^^^^^
  File "/Users/macbookpro/Documents/projects/WSS/venv/lib/python3.11/site-packages/flask/app.py", line 762, in handle_user_exception
    return self.ensure_sync(handler)(e)  # type: ignore[no-any-return]
           ^^^^^^^^^^^^^^^^^^^^^^^^^^^^
  File "/Users/macbookpro/Documents/projects/WSS/majesty-backend/app/utils/logger.py", line 184, in log_exception
    raise exception
  File "/Users/macbookpro/Documents/projects/WSS/venv/lib/python3.11/site-packages/flask/app.py", line 870, in full_dispatch_request
    rv = self.dispatch_request()
         ^^^^^^^^^^^^^^^^^^^^^^^
  File "/Users/macbookpro/Documents/projects/WSS/venv/lib/python3.11/site-packages/flask/app.py", line 855, in dispatch_request
    return self.ensure_sync(self.view_functions[rule.endpoint])(**view_args)  # type: ignore[no-any-return]
           ^^^^^^^^^^^^^^^^^^^^^^^^^^^^^^^^^^^^^^^^^^^^^^^^^^^^^^^^^^^^^^^^^
  File "/Users/macbookpro/Documents/projects/WSS/venv/lib/python3.11/site-packages/flask_jwt_extended/view_decorators.py", line 170, in decorator
    return current_app.ensure_sync(fn)(*args, **kwargs)
           ^^^^^^^^^^^^^^^^^^^^^^^^^^^^^^^^^^^^^^^^^^^^
  File "/Users/macbookpro/Documents/projects/WSS/majesty-backend/app/routes/auth.py", line 130, in check_token
    expiry_datetime = datetime.utcfromtimestamp(expiry_timestamp)  # Correct usage
                      ^^^^^^^^^^^^^^^^^^^^^^^^^
AttributeError: module 'datetime' has no attribute 'utcfromtimestamp'
[2025-03-12 00:11:20,469] ERROR in logger: [EXCEPTION] User 1: Unhandled exception: InternalServerError
[2025-03-12 00:11:39,889] INFO in logger: Wine Inventory API Started - Environment: development
[2025-03-12 00:11:45,564] ERROR in logger: [EXCEPTION] User 1: Unhandled exception: AttributeError
[2025-03-12 00:11:45,603] ERROR in app: Exception on /auth/check-token [GET]
Traceback (most recent call last):
  File "/Users/macbookpro/Documents/projects/WSS/venv/lib/python3.11/site-packages/flask/app.py", line 1463, in wsgi_app
    response = self.full_dispatch_request()
               ^^^^^^^^^^^^^^^^^^^^^^^^^^^^
  File "/Users/macbookpro/Documents/projects/WSS/venv/lib/python3.11/site-packages/flask/app.py", line 872, in full_dispatch_request
    rv = self.handle_user_exception(e)
         ^^^^^^^^^^^^^^^^^^^^^^^^^^^^^
  File "/Users/macbookpro/Documents/projects/WSS/venv/lib/python3.11/site-packages/flask_cors/extension.py", line 176, in wrapped_function
    return cors_after_request(app.make_response(f(*args, **kwargs)))
                                                ^^^^^^^^^^^^^^^^^^
  File "/Users/macbookpro/Documents/projects/WSS/venv/lib/python3.11/site-packages/flask/app.py", line 762, in handle_user_exception
    return self.ensure_sync(handler)(e)  # type: ignore[no-any-return]
           ^^^^^^^^^^^^^^^^^^^^^^^^^^^^
  File "/Users/macbookpro/Documents/projects/WSS/majesty-backend/app/utils/logger.py", line 184, in log_exception
    raise exception
  File "/Users/macbookpro/Documents/projects/WSS/venv/lib/python3.11/site-packages/flask/app.py", line 870, in full_dispatch_request
    rv = self.dispatch_request()
         ^^^^^^^^^^^^^^^^^^^^^^^
  File "/Users/macbookpro/Documents/projects/WSS/venv/lib/python3.11/site-packages/flask/app.py", line 855, in dispatch_request
    return self.ensure_sync(self.view_functions[rule.endpoint])(**view_args)  # type: ignore[no-any-return]
           ^^^^^^^^^^^^^^^^^^^^^^^^^^^^^^^^^^^^^^^^^^^^^^^^^^^^^^^^^^^^^^^^^
  File "/Users/macbookpro/Documents/projects/WSS/venv/lib/python3.11/site-packages/flask_jwt_extended/view_decorators.py", line 170, in decorator
    return current_app.ensure_sync(fn)(*args, **kwargs)
           ^^^^^^^^^^^^^^^^^^^^^^^^^^^^^^^^^^^^^^^^^^^^
  File "/Users/macbookpro/Documents/projects/WSS/majesty-backend/app/routes/auth.py", line 130, in check_token
    expiry_datetime = datetime.utcfromtimestamp(expiry_timestamp)  # Correct usage
                      ^^^^^^^^^^^^^^^^^^^^^^^^^
AttributeError: module 'datetime' has no attribute 'utcfromtimestamp'
[2025-03-12 00:11:45,608] ERROR in logger: [EXCEPTION] User 1: Unhandled exception: InternalServerError
[2025-03-12 00:12:09,267] INFO in logger: Wine Inventory API Started - Environment: development
[2025-03-12 00:12:14,471] ERROR in logger: [EXCEPTION] User 1: Unhandled exception: AttributeError
[2025-03-12 00:12:14,499] ERROR in app: Exception on /auth/check-token [GET]
Traceback (most recent call last):
  File "/Users/macbookpro/Documents/projects/WSS/venv/lib/python3.11/site-packages/flask/app.py", line 1463, in wsgi_app
    response = self.full_dispatch_request()
               ^^^^^^^^^^^^^^^^^^^^^^^^^^^^
  File "/Users/macbookpro/Documents/projects/WSS/venv/lib/python3.11/site-packages/flask/app.py", line 872, in full_dispatch_request
    rv = self.handle_user_exception(e)
         ^^^^^^^^^^^^^^^^^^^^^^^^^^^^^
  File "/Users/macbookpro/Documents/projects/WSS/venv/lib/python3.11/site-packages/flask_cors/extension.py", line 176, in wrapped_function
    return cors_after_request(app.make_response(f(*args, **kwargs)))
                                                ^^^^^^^^^^^^^^^^^^
  File "/Users/macbookpro/Documents/projects/WSS/venv/lib/python3.11/site-packages/flask/app.py", line 762, in handle_user_exception
    return self.ensure_sync(handler)(e)  # type: ignore[no-any-return]
           ^^^^^^^^^^^^^^^^^^^^^^^^^^^^
  File "/Users/macbookpro/Documents/projects/WSS/majesty-backend/app/utils/logger.py", line 184, in log_exception
    raise exception
  File "/Users/macbookpro/Documents/projects/WSS/venv/lib/python3.11/site-packages/flask/app.py", line 870, in full_dispatch_request
    rv = self.dispatch_request()
         ^^^^^^^^^^^^^^^^^^^^^^^
  File "/Users/macbookpro/Documents/projects/WSS/venv/lib/python3.11/site-packages/flask/app.py", line 855, in dispatch_request
    return self.ensure_sync(self.view_functions[rule.endpoint])(**view_args)  # type: ignore[no-any-return]
           ^^^^^^^^^^^^^^^^^^^^^^^^^^^^^^^^^^^^^^^^^^^^^^^^^^^^^^^^^^^^^^^^^
  File "/Users/macbookpro/Documents/projects/WSS/venv/lib/python3.11/site-packages/flask_jwt_extended/view_decorators.py", line 170, in decorator
    return current_app.ensure_sync(fn)(*args, **kwargs)
           ^^^^^^^^^^^^^^^^^^^^^^^^^^^^^^^^^^^^^^^^^^^^
  File "/Users/macbookpro/Documents/projects/WSS/majesty-backend/app/routes/auth.py", line 130, in check_token
    expiry_datetime = datetime.utcfromtimestamp(expiry_timestamp)  # Correct usage
                      ^^^^^^^^^^^^^^^^^^^^^^^^^
AttributeError: module 'datetime' has no attribute 'utcfromtimestamp'
[2025-03-12 00:12:14,503] ERROR in logger: [EXCEPTION] User 1: Unhandled exception: InternalServerError
[2025-03-12 00:13:36,946] ERROR in logger: [EXCEPTION] User 1: Unhandled exception: AttributeError
[2025-03-12 00:13:36,951] ERROR in app: Exception on /auth/check-token [GET]
Traceback (most recent call last):
  File "/Users/macbookpro/Documents/projects/WSS/venv/lib/python3.11/site-packages/flask/app.py", line 1463, in wsgi_app
    response = self.full_dispatch_request()
               ^^^^^^^^^^^^^^^^^^^^^^^^^^^^
  File "/Users/macbookpro/Documents/projects/WSS/venv/lib/python3.11/site-packages/flask/app.py", line 872, in full_dispatch_request
    rv = self.handle_user_exception(e)
         ^^^^^^^^^^^^^^^^^^^^^^^^^^^^^
  File "/Users/macbookpro/Documents/projects/WSS/venv/lib/python3.11/site-packages/flask_cors/extension.py", line 176, in wrapped_function
    return cors_after_request(app.make_response(f(*args, **kwargs)))
                                                ^^^^^^^^^^^^^^^^^^
  File "/Users/macbookpro/Documents/projects/WSS/venv/lib/python3.11/site-packages/flask/app.py", line 762, in handle_user_exception
    return self.ensure_sync(handler)(e)  # type: ignore[no-any-return]
           ^^^^^^^^^^^^^^^^^^^^^^^^^^^^
  File "/Users/macbookpro/Documents/projects/WSS/majesty-backend/app/utils/logger.py", line 184, in log_exception
    raise exception
  File "/Users/macbookpro/Documents/projects/WSS/venv/lib/python3.11/site-packages/flask/app.py", line 870, in full_dispatch_request
    rv = self.dispatch_request()
         ^^^^^^^^^^^^^^^^^^^^^^^
  File "/Users/macbookpro/Documents/projects/WSS/venv/lib/python3.11/site-packages/flask/app.py", line 855, in dispatch_request
    return self.ensure_sync(self.view_functions[rule.endpoint])(**view_args)  # type: ignore[no-any-return]
           ^^^^^^^^^^^^^^^^^^^^^^^^^^^^^^^^^^^^^^^^^^^^^^^^^^^^^^^^^^^^^^^^^
  File "/Users/macbookpro/Documents/projects/WSS/venv/lib/python3.11/site-packages/flask_jwt_extended/view_decorators.py", line 170, in decorator
    return current_app.ensure_sync(fn)(*args, **kwargs)
           ^^^^^^^^^^^^^^^^^^^^^^^^^^^^^^^^^^^^^^^^^^^^
  File "/Users/macbookpro/Documents/projects/WSS/majesty-backend/app/routes/auth.py", line 130, in check_token
    expiry_datetime = datetime.utcfromtimestamp(expiry_timestamp)  # Correct usage
                      ^^^^^^^^^^^^^^^^^^^^^^^^^
AttributeError: module 'datetime' has no attribute 'utcfromtimestamp'
[2025-03-12 00:13:36,953] ERROR in logger: [EXCEPTION] User 1: Unhandled exception: InternalServerError
[2025-03-12 00:14:15,562] ERROR in logger: [EXCEPTION] User 1: Unhandled exception: AttributeError
[2025-03-12 00:14:15,569] ERROR in app: Exception on /auth/check-token [GET]
Traceback (most recent call last):
  File "/Users/macbookpro/Documents/projects/WSS/venv/lib/python3.11/site-packages/flask/app.py", line 1463, in wsgi_app
    response = self.full_dispatch_request()
               ^^^^^^^^^^^^^^^^^^^^^^^^^^^^
  File "/Users/macbookpro/Documents/projects/WSS/venv/lib/python3.11/site-packages/flask/app.py", line 872, in full_dispatch_request
    rv = self.handle_user_exception(e)
         ^^^^^^^^^^^^^^^^^^^^^^^^^^^^^
  File "/Users/macbookpro/Documents/projects/WSS/venv/lib/python3.11/site-packages/flask_cors/extension.py", line 176, in wrapped_function
    return cors_after_request(app.make_response(f(*args, **kwargs)))
                                                ^^^^^^^^^^^^^^^^^^
  File "/Users/macbookpro/Documents/projects/WSS/venv/lib/python3.11/site-packages/flask/app.py", line 762, in handle_user_exception
    return self.ensure_sync(handler)(e)  # type: ignore[no-any-return]
           ^^^^^^^^^^^^^^^^^^^^^^^^^^^^
  File "/Users/macbookpro/Documents/projects/WSS/majesty-backend/app/utils/logger.py", line 184, in log_exception
    raise exception
  File "/Users/macbookpro/Documents/projects/WSS/venv/lib/python3.11/site-packages/flask/app.py", line 870, in full_dispatch_request
    rv = self.dispatch_request()
         ^^^^^^^^^^^^^^^^^^^^^^^
  File "/Users/macbookpro/Documents/projects/WSS/venv/lib/python3.11/site-packages/flask/app.py", line 855, in dispatch_request
    return self.ensure_sync(self.view_functions[rule.endpoint])(**view_args)  # type: ignore[no-any-return]
           ^^^^^^^^^^^^^^^^^^^^^^^^^^^^^^^^^^^^^^^^^^^^^^^^^^^^^^^^^^^^^^^^^
  File "/Users/macbookpro/Documents/projects/WSS/venv/lib/python3.11/site-packages/flask_jwt_extended/view_decorators.py", line 170, in decorator
    return current_app.ensure_sync(fn)(*args, **kwargs)
           ^^^^^^^^^^^^^^^^^^^^^^^^^^^^^^^^^^^^^^^^^^^^
  File "/Users/macbookpro/Documents/projects/WSS/majesty-backend/app/routes/auth.py", line 130, in check_token
    expiry_datetime = datetime.utcfromtimestamp(expiry_timestamp)  # Correct usage
                      ^^^^^^^^^^^^^^^^^^^^^^^^^
AttributeError: module 'datetime' has no attribute 'utcfromtimestamp'
[2025-03-12 00:14:15,572] ERROR in logger: [EXCEPTION] User 1: Unhandled exception: InternalServerError
[2025-03-12 00:16:31,344] ERROR in logger: [EXCEPTION] User 1: Unhandled exception: AttributeError
[2025-03-12 00:16:31,348] ERROR in app: Exception on /auth/check-token [GET]
Traceback (most recent call last):
  File "/Users/macbookpro/Documents/projects/WSS/venv/lib/python3.11/site-packages/flask/app.py", line 1463, in wsgi_app
    response = self.full_dispatch_request()
               ^^^^^^^^^^^^^^^^^^^^^^^^^^^^
  File "/Users/macbookpro/Documents/projects/WSS/venv/lib/python3.11/site-packages/flask/app.py", line 872, in full_dispatch_request
    rv = self.handle_user_exception(e)
         ^^^^^^^^^^^^^^^^^^^^^^^^^^^^^
  File "/Users/macbookpro/Documents/projects/WSS/venv/lib/python3.11/site-packages/flask_cors/extension.py", line 176, in wrapped_function
    return cors_after_request(app.make_response(f(*args, **kwargs)))
                                                ^^^^^^^^^^^^^^^^^^
  File "/Users/macbookpro/Documents/projects/WSS/venv/lib/python3.11/site-packages/flask/app.py", line 762, in handle_user_exception
    return self.ensure_sync(handler)(e)  # type: ignore[no-any-return]
           ^^^^^^^^^^^^^^^^^^^^^^^^^^^^
  File "/Users/macbookpro/Documents/projects/WSS/majesty-backend/app/utils/logger.py", line 184, in log_exception
    raise exception
  File "/Users/macbookpro/Documents/projects/WSS/venv/lib/python3.11/site-packages/flask/app.py", line 870, in full_dispatch_request
    rv = self.dispatch_request()
         ^^^^^^^^^^^^^^^^^^^^^^^
  File "/Users/macbookpro/Documents/projects/WSS/venv/lib/python3.11/site-packages/flask/app.py", line 855, in dispatch_request
    return self.ensure_sync(self.view_functions[rule.endpoint])(**view_args)  # type: ignore[no-any-return]
           ^^^^^^^^^^^^^^^^^^^^^^^^^^^^^^^^^^^^^^^^^^^^^^^^^^^^^^^^^^^^^^^^^
  File "/Users/macbookpro/Documents/projects/WSS/venv/lib/python3.11/site-packages/flask_jwt_extended/view_decorators.py", line 170, in decorator
    return current_app.ensure_sync(fn)(*args, **kwargs)
           ^^^^^^^^^^^^^^^^^^^^^^^^^^^^^^^^^^^^^^^^^^^^
  File "/Users/macbookpro/Documents/projects/WSS/majesty-backend/app/routes/auth.py", line 130, in check_token
    expiry_datetime = datetime.utcfromtimestamp(expiry_timestamp)  # Correct usage
                      ^^^^^^^^^^^^^^^^^^^^^^^^^
AttributeError: module 'datetime' has no attribute 'utcfromtimestamp'
[2025-03-12 00:16:31,351] ERROR in logger: [EXCEPTION] User 1: Unhandled exception: InternalServerError
[2025-03-12 00:16:42,815] INFO in logger: Wine Inventory API Started - Environment: development
