[2025-03-08 00:09:44,789] INFO in logger: Wine Inventory API Started - Environment: development
[2025-03-08 00:10:30,046] INFO in logger: [LOGIN_FAILURE] User None: Invalid login attempt
[2025-03-08 00:11:02,074] INFO in logger: [LOGIN_SUCCESS] User 1: User logged in successfully
[2025-03-08 00:11:10,583] INFO in logger: [LOGIN_SUCCESS] User 1: User logged in successfully
[2025-03-08 00:13:20,437] INFO in logger: [LOGIN_FAILURE] User None: Invalid login attempt
[2025-03-08 00:13:47,784] INFO in logger: [LOGIN_FAILURE] User None: Invalid login attempt
[2025-03-08 00:13:49,850] INFO in logger: [LOGIN_FAILURE] User None: Invalid login attempt
[2025-03-08 00:14:06,996] INFO in logger: [LOGIN_SUCCESS] User 1: User logged in successfully
[2025-03-08 00:15:50,394] INFO in logger: [LOGIN_SUCCESS] User 1: User logged in successfully
[2025-03-08 00:16:09,741] INFO in logger: [LOGIN_SUCCESS] User 1: User logged in successfully
[2025-03-08 00:19:06,543] INFO in logger: [LOGIN_SUCCESS] User 1: User logged in successfully
[2025-03-08 00:19:26,024] INFO in logger: [LOGIN_SUCCESS] User 1: User logged in successfully
[2025-03-08 00:23:15,465] INFO in logger: [LOGIN_SUCCESS] User 1: User logged in successfully
[2025-03-08 00:36:18,096] INFO in logger: [LOGIN_FAILURE] User None: Invalid login attempt
[2025-03-08 00:36:32,836] INFO in logger: [LOGIN_SUCCESS] User 1: User logged in successfully
[2025-03-08 00:36:44,050] INFO in logger: [LOGIN_SUCCESS] User 1: User logged in successfully
[2025-03-08 00:37:47,789] INFO in logger: [LOGIN_SUCCESS] User 1: User logged in successfully
[2025-03-08 00:37:50,219] INFO in logger: [LOGIN_SUCCESS] User 1: User logged in successfully
[2025-03-08 00:37:51,281] INFO in logger: [LOGIN_SUCCESS] User 1: User logged in successfully
[2025-03-08 00:37:52,311] INFO in logger: [LOGIN_SUCCESS] User 1: User logged in successfully
[2025-03-08 00:37:53,668] INFO in logger: [LOGIN_SUCCESS] User 1: User logged in successfully
[2025-03-08 00:38:14,988] INFO in logger: [LOGIN_SUCCESS] User 1: User logged in successfully
[2025-03-08 00:39:25,184] INFO in logger: [LOGIN_SUCCESS] User 1: User logged in successfully
[2025-03-08 00:39:37,008] INFO in logger: [LOGIN_SUCCESS] User 1: User logged in successfully
[2025-03-08 00:39:54,451] INFO in logger: [LOGIN_SUCCESS] User 1: User logged in successfully
[2025-03-08 00:40:23,126] INFO in logger: [LOGIN_SUCCESS] User 1: User logged in successfully
[2025-03-08 00:40:24,727] INFO in logger: [LOGIN_SUCCESS] User 1: User logged in successfully
[2025-03-08 00:40:24,897] INFO in logger: [LOGIN_SUCCESS] User 1: User logged in successfully
[2025-03-08 00:40:25,105] INFO in logger: [LOGIN_SUCCESS] User 1: User logged in successfully
[2025-03-08 00:40:25,224] INFO in logger: [LOGIN_SUCCESS] User 1: User logged in successfully
[2025-03-08 00:40:25,379] INFO in logger: [LOGIN_SUCCESS] User 1: User logged in successfully
[2025-03-08 00:40:25,486] INFO in logger: [LOGIN_SUCCESS] User 1: User logged in successfully
[2025-03-08 00:40:25,658] INFO in logger: [LOGIN_SUCCESS] User 1: User logged in successfully
[2025-03-08 00:40:25,831] INFO in logger: [LOGIN_SUCCESS] User 1: User logged in successfully
[2025-03-08 00:40:25,939] INFO in logger: [LOGIN_SUCCESS] User 1: User logged in successfully
[2025-03-08 00:42:13,258] INFO in logger: [LOGIN_SUCCESS] User 1: User logged in successfully
[2025-03-08 00:42:14,694] INFO in logger: [LOGIN_SUCCESS] User 1: User logged in successfully
[2025-03-08 00:42:14,905] INFO in logger: [LOGIN_SUCCESS] User 1: User logged in successfully
[2025-03-08 00:42:15,141] INFO in logger: [LOGIN_SUCCESS] User 1: User logged in successfully
[2025-03-08 00:42:15,311] INFO in logger: [LOGIN_SUCCESS] User 1: User logged in successfully
[2025-03-08 00:42:15,504] INFO in logger: [LOGIN_SUCCESS] User 1: User logged in successfully
[2025-03-08 00:43:16,063] INFO in logger: [LOGIN_SUCCESS] User 1: User logged in successfully
[2025-03-08 00:43:19,574] INFO in logger: [LOGIN_SUCCESS] User 1: User logged in successfully
[2025-03-08 00:45:25,077] INFO in logger: [LOGIN_SUCCESS] User 1: User logged in successfully
[2025-03-08 00:47:33,952] INFO in logger: [LOGIN_SUCCESS] User 1: User logged in successfully
[2025-03-08 00:47:45,607] INFO in logger: [LOGIN_ATTEMPT] User None: Failed login attempt - missing credentials
[2025-03-08 00:48:27,637] INFO in logger: [LOGIN_SUCCESS] User 1: User logged in successfully
[2025-03-08 00:52:54,293] INFO in logger: [LOGIN_SUCCESS] User 1: User logged in successfully
[2025-03-08 00:55:13,691] INFO in logger: [LOGIN_SUCCESS] User 1: User logged in successfully
[2025-03-08 01:04:09,708] ERROR in logger: [EXCEPTION] User None: Unhandled exception: NotFound
[2025-03-08 01:04:09,716] ERROR in app: Exception on /wines [GET]
Traceback (most recent call last):
  File "/Users/macbook/EverythingProgramming/inventory_management_system/majesty-backend/venv/lib/python3.13/site-packages/flask/app.py", line 1463, in wsgi_app
    response = self.full_dispatch_request()
  File "/Users/macbook/EverythingProgramming/inventory_management_system/majesty-backend/venv/lib/python3.13/site-packages/flask/app.py", line 872, in full_dispatch_request
    rv = self.handle_user_exception(e)
  File "/Users/macbook/EverythingProgramming/inventory_management_system/majesty-backend/venv/lib/python3.13/site-packages/flask_cors/extension.py", line 176, in wrapped_function
    return cors_after_request(app.make_response(f(*args, **kwargs)))
                                                ~^^^^^^^^^^^^^^^^^
  File "/Users/macbook/EverythingProgramming/inventory_management_system/majesty-backend/venv/lib/python3.13/site-packages/flask/app.py", line 755, in handle_user_exception
    return self.handle_http_exception(e)
           ~~~~~~~~~~~~~~~~~~~~~~~~~~^^^
  File "/Users/macbook/EverythingProgramming/inventory_management_system/majesty-backend/venv/lib/python3.13/site-packages/flask/app.py", line 730, in handle_http_exception
    return self.ensure_sync(handler)(e)  # type: ignore[no-any-return]
           ~~~~~~~~~~~~~~~~~~~~~~~~~^^^
  File "/Users/macbook/EverythingProgramming/inventory_management_system/majesty-backend/app/utils/logger.py", line 184, in log_exception
    raise exception
  File "/Users/macbook/EverythingProgramming/inventory_management_system/majesty-backend/venv/lib/python3.13/site-packages/flask/app.py", line 870, in full_dispatch_request
    rv = self.dispatch_request()
  File "/Users/macbook/EverythingProgramming/inventory_management_system/majesty-backend/venv/lib/python3.13/site-packages/flask/app.py", line 844, in dispatch_request
    self.raise_routing_exception(req)
    ~~~~~~~~~~~~~~~~~~~~~~~~~~~~^^^^^
  File "/Users/macbook/EverythingProgramming/inventory_management_system/majesty-backend/venv/lib/python3.13/site-packages/flask/app.py", line 453, in raise_routing_exception
    raise request.routing_exception  # type: ignore[misc]
    ^^^^^^^^^^^^^^^^^^^^^^^^^^^^^^^
  File "/Users/macbook/EverythingProgramming/inventory_management_system/majesty-backend/venv/lib/python3.13/site-packages/flask/ctx.py", line 362, in match_request
    result = self.url_adapter.match(return_rule=True)  # type: ignore
  File "/Users/macbook/EverythingProgramming/inventory_management_system/majesty-backend/venv/lib/python3.13/site-packages/werkzeug/routing/map.py", line 629, in match
    raise NotFound() from None
werkzeug.exceptions.NotFound: 404 Not Found: The requested URL was not found on the server. If you entered the URL manually please check your spelling and try again.
[2025-03-08 01:04:09,726] ERROR in logger: [EXCEPTION] User None: Unhandled exception: InternalServerError
[2025-03-08 01:04:34,273] ERROR in logger: [EXCEPTION] User None: Unhandled exception: NotFound
[2025-03-08 01:04:34,279] ERROR in app: Exception on /wine/total_stock [GET]
Traceback (most recent call last):
  File "/Users/macbook/EverythingProgramming/inventory_management_system/majesty-backend/venv/lib/python3.13/site-packages/flask/app.py", line 1463, in wsgi_app
    response = self.full_dispatch_request()
  File "/Users/macbook/EverythingProgramming/inventory_management_system/majesty-backend/venv/lib/python3.13/site-packages/flask/app.py", line 872, in full_dispatch_request
    rv = self.handle_user_exception(e)
  File "/Users/macbook/EverythingProgramming/inventory_management_system/majesty-backend/venv/lib/python3.13/site-packages/flask_cors/extension.py", line 176, in wrapped_function
    return cors_after_request(app.make_response(f(*args, **kwargs)))
                                                ~^^^^^^^^^^^^^^^^^
  File "/Users/macbook/EverythingProgramming/inventory_management_system/majesty-backend/venv/lib/python3.13/site-packages/flask/app.py", line 755, in handle_user_exception
    return self.handle_http_exception(e)
           ~~~~~~~~~~~~~~~~~~~~~~~~~~^^^
  File "/Users/macbook/EverythingProgramming/inventory_management_system/majesty-backend/venv/lib/python3.13/site-packages/flask/app.py", line 730, in handle_http_exception
    return self.ensure_sync(handler)(e)  # type: ignore[no-any-return]
           ~~~~~~~~~~~~~~~~~~~~~~~~~^^^
  File "/Users/macbook/EverythingProgramming/inventory_management_system/majesty-backend/app/utils/logger.py", line 184, in log_exception
    raise exception
  File "/Users/macbook/EverythingProgramming/inventory_management_system/majesty-backend/venv/lib/python3.13/site-packages/flask/app.py", line 870, in full_dispatch_request
    rv = self.dispatch_request()
  File "/Users/macbook/EverythingProgramming/inventory_management_system/majesty-backend/venv/lib/python3.13/site-packages/flask/app.py", line 844, in dispatch_request
    self.raise_routing_exception(req)
    ~~~~~~~~~~~~~~~~~~~~~~~~~~~~^^^^^
  File "/Users/macbook/EverythingProgramming/inventory_management_system/majesty-backend/venv/lib/python3.13/site-packages/flask/app.py", line 453, in raise_routing_exception
    raise request.routing_exception  # type: ignore[misc]
    ^^^^^^^^^^^^^^^^^^^^^^^^^^^^^^^
  File "/Users/macbook/EverythingProgramming/inventory_management_system/majesty-backend/venv/lib/python3.13/site-packages/flask/ctx.py", line 362, in match_request
    result = self.url_adapter.match(return_rule=True)  # type: ignore
  File "/Users/macbook/EverythingProgramming/inventory_management_system/majesty-backend/venv/lib/python3.13/site-packages/werkzeug/routing/map.py", line 629, in match
    raise NotFound() from None
werkzeug.exceptions.NotFound: 404 Not Found: The requested URL was not found on the server. If you entered the URL manually please check your spelling and try again.
[2025-03-08 01:04:34,284] ERROR in logger: [EXCEPTION] User None: Unhandled exception: InternalServerError
[2025-03-08 01:05:17,786] ERROR in logger: [EXCEPTION] User None: Unhandled exception: NotFound
[2025-03-08 01:05:17,793] ERROR in app: Exception on /wine/stock_by_category [GET]
Traceback (most recent call last):
  File "/Users/macbook/EverythingProgramming/inventory_management_system/majesty-backend/venv/lib/python3.13/site-packages/flask/app.py", line 1463, in wsgi_app
    response = self.full_dispatch_request()
  File "/Users/macbook/EverythingProgramming/inventory_management_system/majesty-backend/venv/lib/python3.13/site-packages/flask/app.py", line 872, in full_dispatch_request
    rv = self.handle_user_exception(e)
  File "/Users/macbook/EverythingProgramming/inventory_management_system/majesty-backend/venv/lib/python3.13/site-packages/flask_cors/extension.py", line 176, in wrapped_function
    return cors_after_request(app.make_response(f(*args, **kwargs)))
                                                ~^^^^^^^^^^^^^^^^^
  File "/Users/macbook/EverythingProgramming/inventory_management_system/majesty-backend/venv/lib/python3.13/site-packages/flask/app.py", line 755, in handle_user_exception
    return self.handle_http_exception(e)
           ~~~~~~~~~~~~~~~~~~~~~~~~~~^^^
  File "/Users/macbook/EverythingProgramming/inventory_management_system/majesty-backend/venv/lib/python3.13/site-packages/flask/app.py", line 730, in handle_http_exception
    return self.ensure_sync(handler)(e)  # type: ignore[no-any-return]
           ~~~~~~~~~~~~~~~~~~~~~~~~~^^^
  File "/Users/macbook/EverythingProgramming/inventory_management_system/majesty-backend/app/utils/logger.py", line 184, in log_exception
    raise exception
  File "/Users/macbook/EverythingProgramming/inventory_management_system/majesty-backend/venv/lib/python3.13/site-packages/flask/app.py", line 870, in full_dispatch_request
    rv = self.dispatch_request()
  File "/Users/macbook/EverythingProgramming/inventory_management_system/majesty-backend/venv/lib/python3.13/site-packages/flask/app.py", line 844, in dispatch_request
    self.raise_routing_exception(req)
    ~~~~~~~~~~~~~~~~~~~~~~~~~~~~^^^^^
  File "/Users/macbook/EverythingProgramming/inventory_management_system/majesty-backend/venv/lib/python3.13/site-packages/flask/app.py", line 453, in raise_routing_exception
    raise request.routing_exception  # type: ignore[misc]
    ^^^^^^^^^^^^^^^^^^^^^^^^^^^^^^^
  File "/Users/macbook/EverythingProgramming/inventory_management_system/majesty-backend/venv/lib/python3.13/site-packages/flask/ctx.py", line 362, in match_request
    result = self.url_adapter.match(return_rule=True)  # type: ignore
  File "/Users/macbook/EverythingProgramming/inventory_management_system/majesty-backend/venv/lib/python3.13/site-packages/werkzeug/routing/map.py", line 629, in match
    raise NotFound() from None
werkzeug.exceptions.NotFound: 404 Not Found: The requested URL was not found on the server. If you entered the URL manually please check your spelling and try again.
[2025-03-08 01:05:17,801] ERROR in logger: [EXCEPTION] User None: Unhandled exception: InternalServerError
[2025-03-08 01:05:31,238] ERROR in logger: [EXCEPTION] User None: Unhandled exception: NotFound
[2025-03-08 01:05:31,243] ERROR in app: Exception on /revenue [GET]
Traceback (most recent call last):
  File "/Users/macbook/EverythingProgramming/inventory_management_system/majesty-backend/venv/lib/python3.13/site-packages/flask/app.py", line 1463, in wsgi_app
    response = self.full_dispatch_request()
  File "/Users/macbook/EverythingProgramming/inventory_management_system/majesty-backend/venv/lib/python3.13/site-packages/flask/app.py", line 872, in full_dispatch_request
    rv = self.handle_user_exception(e)
  File "/Users/macbook/EverythingProgramming/inventory_management_system/majesty-backend/venv/lib/python3.13/site-packages/flask_cors/extension.py", line 176, in wrapped_function
    return cors_after_request(app.make_response(f(*args, **kwargs)))
                                                ~^^^^^^^^^^^^^^^^^
  File "/Users/macbook/EverythingProgramming/inventory_management_system/majesty-backend/venv/lib/python3.13/site-packages/flask/app.py", line 755, in handle_user_exception
    return self.handle_http_exception(e)
           ~~~~~~~~~~~~~~~~~~~~~~~~~~^^^
  File "/Users/macbook/EverythingProgramming/inventory_management_system/majesty-backend/venv/lib/python3.13/site-packages/flask/app.py", line 730, in handle_http_exception
    return self.ensure_sync(handler)(e)  # type: ignore[no-any-return]
           ~~~~~~~~~~~~~~~~~~~~~~~~~^^^
  File "/Users/macbook/EverythingProgramming/inventory_management_system/majesty-backend/app/utils/logger.py", line 184, in log_exception
    raise exception
  File "/Users/macbook/EverythingProgramming/inventory_management_system/majesty-backend/venv/lib/python3.13/site-packages/flask/app.py", line 870, in full_dispatch_request
    rv = self.dispatch_request()
  File "/Users/macbook/EverythingProgramming/inventory_management_system/majesty-backend/venv/lib/python3.13/site-packages/flask/app.py", line 844, in dispatch_request
    self.raise_routing_exception(req)
    ~~~~~~~~~~~~~~~~~~~~~~~~~~~~^^^^^
  File "/Users/macbook/EverythingProgramming/inventory_management_system/majesty-backend/venv/lib/python3.13/site-packages/flask/app.py", line 453, in raise_routing_exception
    raise request.routing_exception  # type: ignore[misc]
    ^^^^^^^^^^^^^^^^^^^^^^^^^^^^^^^
  File "/Users/macbook/EverythingProgramming/inventory_management_system/majesty-backend/venv/lib/python3.13/site-packages/flask/ctx.py", line 362, in match_request
    result = self.url_adapter.match(return_rule=True)  # type: ignore
  File "/Users/macbook/EverythingProgramming/inventory_management_system/majesty-backend/venv/lib/python3.13/site-packages/werkzeug/routing/map.py", line 629, in match
    raise NotFound() from None
werkzeug.exceptions.NotFound: 404 Not Found: The requested URL was not found on the server. If you entered the URL manually please check your spelling and try again.
[2025-03-08 01:05:31,248] ERROR in logger: [EXCEPTION] User None: Unhandled exception: InternalServerError
