<<<<<<< HEAD
[2025-03-17 00:11:18,841] INFO in logger: [LOGIN_SUCCESS] User 1: User logged in successfully | Affected: admin
[2025-03-17 00:12:02,463] INFO in logger: [CHECK_TOKEN_VALID] User 1: Token is valid | Affected: Token System
[2025-03-17 00:12:06,594] INFO in logger: [CHECK_TOKEN_VALID] User 1: Token is valid | Affected: Token System
[2025-03-17 00:12:10,770] INFO in logger: [CHECK_TOKEN_VALID] User 1: Token is valid | Affected: Token System
[2025-03-17 00:12:13,585] INFO in logger: [CHECK_TOKEN_VALID] User 1: Token is valid | Affected: Token System
[2025-03-17 00:12:16,272] INFO in logger: [CHECK_TOKEN_VALID] User 1: Token is valid | Affected: Token System
[2025-03-17 00:12:19,447] INFO in logger: [CHECK_TOKEN_VALID] User 1: Token is valid | Affected: Token System
[2025-03-17 00:12:23,145] INFO in logger: [CHECK_TOKEN_VALID] User 1: Token is valid | Affected: Token System
[2025-03-17 00:12:26,233] INFO in logger: [CHECK_TOKEN_VALID] User 1: Token is valid | Affected: Token System
[2025-03-17 00:12:29,696] INFO in logger: [CHECK_TOKEN_VALID] User 1: Token is valid | Affected: Token System
[2025-03-17 00:12:29,935] INFO in logger: [GET_STOCK_BY_CATEGORY] User 1: Stock by category fetched successfully | Affected: Stock by Category
[2025-03-17 00:12:29,939] INFO in logger: [GET_REVENUE] User 1: Revenue calculated: 150.00 | Affected: Revenue
[2025-03-17 00:12:29,941] INFO in logger: [GET_TOTAL_STOCK] User 1: Total stock checked: 147 | Affected: Total Stock
[2025-03-17 00:12:29,964] INFO in logger: [COMPARE_SALES] User 1: Sales compared: -100% | Affected: Sales Comparison
[2025-03-17 00:12:36,231] INFO in logger: [CHECK_TOKEN_VALID] User 1: Token is valid | Affected: Token System
[2025-03-17 00:12:36,391] INFO in logger: [GET_STOCK_BY_CATEGORY] User 1: Stock by category fetched successfully | Affected: Stock by Category
[2025-03-17 00:12:36,394] INFO in logger: [GET_REVENUE] User 1: Revenue calculated: 150.00 | Affected: Revenue
[2025-03-17 00:12:36,400] INFO in logger: [GET_TOTAL_STOCK] User 1: Total stock checked: 147 | Affected: Total Stock
[2025-03-17 00:12:36,412] INFO in logger: [COMPARE_SALES] User 1: Sales compared: -100% | Affected: Sales Comparison
[2025-03-17 00:12:37,668] INFO in logger: [CHECK_TOKEN_VALID] User 1: Token is valid | Affected: Token System
[2025-03-17 00:12:37,785] INFO in logger: [GET_REVENUE] User 1: Revenue calculated: 150.00 | Affected: Revenue
[2025-03-17 00:12:37,790] INFO in logger: [GET_STOCK_BY_CATEGORY] User 1: Stock by category fetched successfully | Affected: Stock by Category
[2025-03-17 00:12:37,794] INFO in logger: [GET_TOTAL_STOCK] User 1: Total stock checked: 147 | Affected: Total Stock
[2025-03-17 00:12:37,856] INFO in logger: [COMPARE_SALES] User 1: Sales compared: -100% | Affected: Sales Comparison
[2025-03-17 00:12:39,363] INFO in logger: [CHECK_TOKEN_VALID] User 1: Token is valid | Affected: Token System
[2025-03-17 00:12:39,466] INFO in logger: [GET_REVENUE] User 1: Revenue calculated: 150.00 | Affected: Revenue
[2025-03-17 00:12:39,512] INFO in logger: [GET_STOCK_BY_CATEGORY] User 1: Stock by category fetched successfully | Affected: Stock by Category
[2025-03-17 00:12:39,517] INFO in logger: [GET_TOTAL_STOCK] User 1: Total stock checked: 147 | Affected: Total Stock
[2025-03-17 00:12:39,522] INFO in logger: [COMPARE_SALES] User 1: Sales compared: -100% | Affected: Sales Comparison
[2025-03-17 00:12:43,639] INFO in logger: [CHECK_TOKEN_VALID] User 1: Token is valid | Affected: Token System
[2025-03-17 00:12:43,843] INFO in logger: [GET_STOCK_BY_CATEGORY] User 1: Stock by category fetched successfully | Affected: Stock by Category
[2025-03-17 00:12:43,845] INFO in logger: [GET_REVENUE] User 1: Revenue calculated: 150.00 | Affected: Revenue
[2025-03-17 00:12:43,846] INFO in logger: [GET_TOTAL_STOCK] User 1: Total stock checked: 147 | Affected: Total Stock
[2025-03-17 00:12:43,857] INFO in logger: [COMPARE_SALES] User 1: Sales compared: -100% | Affected: Sales Comparison
[2025-03-17 00:12:46,594] INFO in logger: [CHECK_TOKEN_VALID] User 1: Token is valid | Affected: Token System
[2025-03-17 00:12:46,783] INFO in logger: [GET_REVENUE] User 1: Revenue calculated: 150.00 | Affected: Revenue
[2025-03-17 00:12:46,786] INFO in logger: [GET_STOCK_BY_CATEGORY] User 1: Stock by category fetched successfully | Affected: Stock by Category
[2025-03-17 00:12:46,787] INFO in logger: [GET_TOTAL_STOCK] User 1: Total stock checked: 147 | Affected: Total Stock
[2025-03-17 00:12:46,800] INFO in logger: [COMPARE_SALES] User 1: Sales compared: -100% | Affected: Sales Comparison
[2025-03-17 00:13:21,544] INFO in logger: [CHECK_TOKEN_VALID] User 1: Token is valid | Affected: Token System
[2025-03-17 00:13:21,710] INFO in logger: [GET_REVENUE] User 1: Revenue calculated: 150.00 | Affected: Revenue
[2025-03-17 00:13:21,718] INFO in logger: [GET_TOTAL_STOCK] User 1: Total stock checked: 147 | Affected: Total Stock
[2025-03-17 00:13:21,722] INFO in logger: [GET_STOCK_BY_CATEGORY] User 1: Stock by category fetched successfully | Affected: Stock by Category
[2025-03-17 00:13:21,729] INFO in logger: [COMPARE_SALES] User 1: Sales compared: -100% | Affected: Sales Comparison
[2025-03-17 00:13:55,013] INFO in logger: [CHECK_TOKEN_VALID] User 1: Token is valid | Affected: Token System
[2025-03-17 00:13:55,117] INFO in logger: [GET_ALL_WINES] User 1: Fetched all wines | Affected: All Wines
[2025-03-17 00:16:05,093] INFO in logger: [CHECK_TOKEN_VALID] User 1: Token is valid | Affected: Token System
[2025-03-17 00:17:45,285] INFO in logger: [CHECK_TOKEN_VALID] User 1: Token is valid | Affected: Token System
[2025-03-17 00:22:18,024] INFO in logger: [CHECK_TOKEN_VALID] User 1: Token is valid | Affected: Token System
[2025-03-17 00:23:20,516] INFO in logger: [GET_ALL_WINES] User 1: Fetched all wines | Affected: All Wines
[2025-03-17 00:23:55,927] ERROR in logger: [EXCEPTION] User None: Unhandled exception: NotFound
[2025-03-17 00:23:55,933] ERROR in app: Exception on /checkout [OPTIONS]
Traceback (most recent call last):
  File "/Users/macbook/EverythingProgramming/inventory_management_system/majesty-backend/backend/lib/python3.13/site-packages/flask/app.py", line 1463, in wsgi_app
    response = self.full_dispatch_request()
  File "/Users/macbook/EverythingProgramming/inventory_management_system/majesty-backend/backend/lib/python3.13/site-packages/flask/app.py", line 872, in full_dispatch_request
    rv = self.handle_user_exception(e)
  File "/Users/macbook/EverythingProgramming/inventory_management_system/majesty-backend/backend/lib/python3.13/site-packages/flask_cors/extension.py", line 176, in wrapped_function
    return cors_after_request(app.make_response(f(*args, **kwargs)))
                                                ~^^^^^^^^^^^^^^^^^
  File "/Users/macbook/EverythingProgramming/inventory_management_system/majesty-backend/backend/lib/python3.13/site-packages/flask/app.py", line 755, in handle_user_exception
    return self.handle_http_exception(e)
           ~~~~~~~~~~~~~~~~~~~~~~~~~~^^^
  File "/Users/macbook/EverythingProgramming/inventory_management_system/majesty-backend/backend/lib/python3.13/site-packages/flask/app.py", line 730, in handle_http_exception
    return self.ensure_sync(handler)(e)  # type: ignore[no-any-return]
           ~~~~~~~~~~~~~~~~~~~~~~~~~^^^
  File "/Users/macbook/EverythingProgramming/inventory_management_system/majesty-backend/app/utils/logger.py", line 194, in log_exception
    raise exception
  File "/Users/macbook/EverythingProgramming/inventory_management_system/majesty-backend/backend/lib/python3.13/site-packages/flask/app.py", line 870, in full_dispatch_request
    rv = self.dispatch_request()
  File "/Users/macbook/EverythingProgramming/inventory_management_system/majesty-backend/backend/lib/python3.13/site-packages/flask/app.py", line 844, in dispatch_request
    self.raise_routing_exception(req)
    ~~~~~~~~~~~~~~~~~~~~~~~~~~~~^^^^^
  File "/Users/macbook/EverythingProgramming/inventory_management_system/majesty-backend/backend/lib/python3.13/site-packages/flask/app.py", line 453, in raise_routing_exception
    raise request.routing_exception  # type: ignore[misc]
    ^^^^^^^^^^^^^^^^^^^^^^^^^^^^^^^
  File "/Users/macbook/EverythingProgramming/inventory_management_system/majesty-backend/backend/lib/python3.13/site-packages/flask/ctx.py", line 362, in match_request
    result = self.url_adapter.match(return_rule=True)  # type: ignore
  File "/Users/macbook/EverythingProgramming/inventory_management_system/majesty-backend/backend/lib/python3.13/site-packages/werkzeug/routing/map.py", line 629, in match
    raise NotFound() from None
werkzeug.exceptions.NotFound: 404 Not Found: The requested URL was not found on the server. If you entered the URL manually please check your spelling and try again.
[2025-03-17 00:23:55,939] ERROR in logger: [EXCEPTION] User None: Unhandled exception: InternalServerError
[2025-03-17 00:24:20,801] INFO in logger: [GET_USERS_SUCCESS] User 1: Admin retrieved user list | Affected: User Management
[2025-03-17 00:27:12,837] INFO in logger: [CHECK_TOKEN_VALID] User 1: Token is valid | Affected: Token System
[2025-03-17 00:27:12,908] INFO in logger: [GET_USERS_SUCCESS] User 1: Admin retrieved user list | Affected: User Management
[2025-03-17 00:27:47,163] INFO in logger: [CHECK_TOKEN_VALID] User 1: Token is valid | Affected: Token System
[2025-03-17 00:27:47,230] INFO in logger: [GET_USERS_SUCCESS] User 1: Admin retrieved user list | Affected: User Management
[2025-03-17 00:28:06,726] ERROR in logger: [EXCEPTION] User None: Unhandled exception: NotFound
[2025-03-17 00:28:06,730] ERROR in app: Exception on /users/4 [OPTIONS]
Traceback (most recent call last):
  File "/Users/macbook/EverythingProgramming/inventory_management_system/majesty-backend/backend/lib/python3.13/site-packages/flask/app.py", line 1463, in wsgi_app
    response = self.full_dispatch_request()
  File "/Users/macbook/EverythingProgramming/inventory_management_system/majesty-backend/backend/lib/python3.13/site-packages/flask/app.py", line 872, in full_dispatch_request
    rv = self.handle_user_exception(e)
  File "/Users/macbook/EverythingProgramming/inventory_management_system/majesty-backend/backend/lib/python3.13/site-packages/flask_cors/extension.py", line 176, in wrapped_function
    return cors_after_request(app.make_response(f(*args, **kwargs)))
                                                ~^^^^^^^^^^^^^^^^^
  File "/Users/macbook/EverythingProgramming/inventory_management_system/majesty-backend/backend/lib/python3.13/site-packages/flask/app.py", line 755, in handle_user_exception
    return self.handle_http_exception(e)
           ~~~~~~~~~~~~~~~~~~~~~~~~~~^^^
  File "/Users/macbook/EverythingProgramming/inventory_management_system/majesty-backend/backend/lib/python3.13/site-packages/flask/app.py", line 730, in handle_http_exception
    return self.ensure_sync(handler)(e)  # type: ignore[no-any-return]
           ~~~~~~~~~~~~~~~~~~~~~~~~~^^^
  File "/Users/macbook/EverythingProgramming/inventory_management_system/majesty-backend/app/utils/logger.py", line 194, in log_exception
    raise exception
  File "/Users/macbook/EverythingProgramming/inventory_management_system/majesty-backend/backend/lib/python3.13/site-packages/flask/app.py", line 870, in full_dispatch_request
    rv = self.dispatch_request()
  File "/Users/macbook/EverythingProgramming/inventory_management_system/majesty-backend/backend/lib/python3.13/site-packages/flask/app.py", line 844, in dispatch_request
    self.raise_routing_exception(req)
    ~~~~~~~~~~~~~~~~~~~~~~~~~~~~^^^^^
  File "/Users/macbook/EverythingProgramming/inventory_management_system/majesty-backend/backend/lib/python3.13/site-packages/flask/app.py", line 453, in raise_routing_exception
    raise request.routing_exception  # type: ignore[misc]
    ^^^^^^^^^^^^^^^^^^^^^^^^^^^^^^^
  File "/Users/macbook/EverythingProgramming/inventory_management_system/majesty-backend/backend/lib/python3.13/site-packages/flask/ctx.py", line 362, in match_request
    result = self.url_adapter.match(return_rule=True)  # type: ignore
  File "/Users/macbook/EverythingProgramming/inventory_management_system/majesty-backend/backend/lib/python3.13/site-packages/werkzeug/routing/map.py", line 629, in match
    raise NotFound() from None
werkzeug.exceptions.NotFound: 404 Not Found: The requested URL was not found on the server. If you entered the URL manually please check your spelling and try again.
[2025-03-17 00:28:06,735] ERROR in logger: [EXCEPTION] User None: Unhandled exception: InternalServerError
[2025-03-17 00:30:24,731] INFO in logger: [CHECK_TOKEN_VALID] User 1: Token is valid | Affected: Token System
[2025-03-17 00:30:24,812] INFO in logger: [GET_USERS_SUCCESS] User 1: Admin retrieved user list | Affected: User Management
[2025-03-17 00:33:40,346] ERROR in logger: [EXCEPTION] User None: Unhandled exception: NotFound
[2025-03-17 00:33:40,350] ERROR in app: Exception on /users/4 [OPTIONS]
Traceback (most recent call last):
  File "/Users/macbook/EverythingProgramming/inventory_management_system/majesty-backend/backend/lib/python3.13/site-packages/flask/app.py", line 1463, in wsgi_app
    response = self.full_dispatch_request()
  File "/Users/macbook/EverythingProgramming/inventory_management_system/majesty-backend/backend/lib/python3.13/site-packages/flask/app.py", line 872, in full_dispatch_request
    rv = self.handle_user_exception(e)
  File "/Users/macbook/EverythingProgramming/inventory_management_system/majesty-backend/backend/lib/python3.13/site-packages/flask_cors/extension.py", line 176, in wrapped_function
    return cors_after_request(app.make_response(f(*args, **kwargs)))
                                                ~^^^^^^^^^^^^^^^^^
  File "/Users/macbook/EverythingProgramming/inventory_management_system/majesty-backend/backend/lib/python3.13/site-packages/flask/app.py", line 755, in handle_user_exception
    return self.handle_http_exception(e)
           ~~~~~~~~~~~~~~~~~~~~~~~~~~^^^
  File "/Users/macbook/EverythingProgramming/inventory_management_system/majesty-backend/backend/lib/python3.13/site-packages/flask/app.py", line 730, in handle_http_exception
    return self.ensure_sync(handler)(e)  # type: ignore[no-any-return]
           ~~~~~~~~~~~~~~~~~~~~~~~~~^^^
  File "/Users/macbook/EverythingProgramming/inventory_management_system/majesty-backend/app/utils/logger.py", line 194, in log_exception
    raise exception
  File "/Users/macbook/EverythingProgramming/inventory_management_system/majesty-backend/backend/lib/python3.13/site-packages/flask/app.py", line 870, in full_dispatch_request
    rv = self.dispatch_request()
  File "/Users/macbook/EverythingProgramming/inventory_management_system/majesty-backend/backend/lib/python3.13/site-packages/flask/app.py", line 844, in dispatch_request
    self.raise_routing_exception(req)
    ~~~~~~~~~~~~~~~~~~~~~~~~~~~~^^^^^
  File "/Users/macbook/EverythingProgramming/inventory_management_system/majesty-backend/backend/lib/python3.13/site-packages/flask/app.py", line 453, in raise_routing_exception
    raise request.routing_exception  # type: ignore[misc]
    ^^^^^^^^^^^^^^^^^^^^^^^^^^^^^^^
  File "/Users/macbook/EverythingProgramming/inventory_management_system/majesty-backend/backend/lib/python3.13/site-packages/flask/ctx.py", line 362, in match_request
    result = self.url_adapter.match(return_rule=True)  # type: ignore
  File "/Users/macbook/EverythingProgramming/inventory_management_system/majesty-backend/backend/lib/python3.13/site-packages/werkzeug/routing/map.py", line 629, in match
    raise NotFound() from None
werkzeug.exceptions.NotFound: 404 Not Found: The requested URL was not found on the server. If you entered the URL manually please check your spelling and try again.
[2025-03-17 00:33:40,354] ERROR in logger: [EXCEPTION] User None: Unhandled exception: InternalServerError
[2025-03-17 00:34:14,995] ERROR in logger: [EXCEPTION] User None: Unhandled exception: NotFound
[2025-03-17 00:34:14,999] ERROR in app: Exception on /users/4 [OPTIONS]
Traceback (most recent call last):
  File "/Users/macbook/EverythingProgramming/inventory_management_system/majesty-backend/backend/lib/python3.13/site-packages/flask/app.py", line 1463, in wsgi_app
    response = self.full_dispatch_request()
  File "/Users/macbook/EverythingProgramming/inventory_management_system/majesty-backend/backend/lib/python3.13/site-packages/flask/app.py", line 872, in full_dispatch_request
    rv = self.handle_user_exception(e)
  File "/Users/macbook/EverythingProgramming/inventory_management_system/majesty-backend/backend/lib/python3.13/site-packages/flask_cors/extension.py", line 176, in wrapped_function
    return cors_after_request(app.make_response(f(*args, **kwargs)))
                                                ~^^^^^^^^^^^^^^^^^
  File "/Users/macbook/EverythingProgramming/inventory_management_system/majesty-backend/backend/lib/python3.13/site-packages/flask/app.py", line 755, in handle_user_exception
    return self.handle_http_exception(e)
           ~~~~~~~~~~~~~~~~~~~~~~~~~~^^^
  File "/Users/macbook/EverythingProgramming/inventory_management_system/majesty-backend/backend/lib/python3.13/site-packages/flask/app.py", line 730, in handle_http_exception
    return self.ensure_sync(handler)(e)  # type: ignore[no-any-return]
           ~~~~~~~~~~~~~~~~~~~~~~~~~^^^
  File "/Users/macbook/EverythingProgramming/inventory_management_system/majesty-backend/app/utils/logger.py", line 194, in log_exception
    raise exception
  File "/Users/macbook/EverythingProgramming/inventory_management_system/majesty-backend/backend/lib/python3.13/site-packages/flask/app.py", line 870, in full_dispatch_request
    rv = self.dispatch_request()
  File "/Users/macbook/EverythingProgramming/inventory_management_system/majesty-backend/backend/lib/python3.13/site-packages/flask/app.py", line 844, in dispatch_request
    self.raise_routing_exception(req)
    ~~~~~~~~~~~~~~~~~~~~~~~~~~~~^^^^^
  File "/Users/macbook/EverythingProgramming/inventory_management_system/majesty-backend/backend/lib/python3.13/site-packages/flask/app.py", line 453, in raise_routing_exception
    raise request.routing_exception  # type: ignore[misc]
    ^^^^^^^^^^^^^^^^^^^^^^^^^^^^^^^
  File "/Users/macbook/EverythingProgramming/inventory_management_system/majesty-backend/backend/lib/python3.13/site-packages/flask/ctx.py", line 362, in match_request
    result = self.url_adapter.match(return_rule=True)  # type: ignore
  File "/Users/macbook/EverythingProgramming/inventory_management_system/majesty-backend/backend/lib/python3.13/site-packages/werkzeug/routing/map.py", line 629, in match
    raise NotFound() from None
werkzeug.exceptions.NotFound: 404 Not Found: The requested URL was not found on the server. If you entered the URL manually please check your spelling and try again.
[2025-03-17 00:34:15,004] ERROR in logger: [EXCEPTION] User None: Unhandled exception: InternalServerError
[2025-03-17 00:34:36,812] ERROR in logger: [EXCEPTION] User None: Unhandled exception: NotFound
[2025-03-17 00:34:36,816] ERROR in app: Exception on /users/4 [OPTIONS]
Traceback (most recent call last):
  File "/Users/macbook/EverythingProgramming/inventory_management_system/majesty-backend/backend/lib/python3.13/site-packages/flask/app.py", line 1463, in wsgi_app
    response = self.full_dispatch_request()
  File "/Users/macbook/EverythingProgramming/inventory_management_system/majesty-backend/backend/lib/python3.13/site-packages/flask/app.py", line 872, in full_dispatch_request
    rv = self.handle_user_exception(e)
  File "/Users/macbook/EverythingProgramming/inventory_management_system/majesty-backend/backend/lib/python3.13/site-packages/flask_cors/extension.py", line 176, in wrapped_function
    return cors_after_request(app.make_response(f(*args, **kwargs)))
                                                ~^^^^^^^^^^^^^^^^^
  File "/Users/macbook/EverythingProgramming/inventory_management_system/majesty-backend/backend/lib/python3.13/site-packages/flask/app.py", line 755, in handle_user_exception
    return self.handle_http_exception(e)
           ~~~~~~~~~~~~~~~~~~~~~~~~~~^^^
  File "/Users/macbook/EverythingProgramming/inventory_management_system/majesty-backend/backend/lib/python3.13/site-packages/flask/app.py", line 730, in handle_http_exception
    return self.ensure_sync(handler)(e)  # type: ignore[no-any-return]
           ~~~~~~~~~~~~~~~~~~~~~~~~~^^^
  File "/Users/macbook/EverythingProgramming/inventory_management_system/majesty-backend/app/utils/logger.py", line 194, in log_exception
    raise exception
  File "/Users/macbook/EverythingProgramming/inventory_management_system/majesty-backend/backend/lib/python3.13/site-packages/flask/app.py", line 870, in full_dispatch_request
    rv = self.dispatch_request()
  File "/Users/macbook/EverythingProgramming/inventory_management_system/majesty-backend/backend/lib/python3.13/site-packages/flask/app.py", line 844, in dispatch_request
    self.raise_routing_exception(req)
    ~~~~~~~~~~~~~~~~~~~~~~~~~~~~^^^^^
  File "/Users/macbook/EverythingProgramming/inventory_management_system/majesty-backend/backend/lib/python3.13/site-packages/flask/app.py", line 453, in raise_routing_exception
    raise request.routing_exception  # type: ignore[misc]
    ^^^^^^^^^^^^^^^^^^^^^^^^^^^^^^^
  File "/Users/macbook/EverythingProgramming/inventory_management_system/majesty-backend/backend/lib/python3.13/site-packages/flask/ctx.py", line 362, in match_request
    result = self.url_adapter.match(return_rule=True)  # type: ignore
  File "/Users/macbook/EverythingProgramming/inventory_management_system/majesty-backend/backend/lib/python3.13/site-packages/werkzeug/routing/map.py", line 629, in match
    raise NotFound() from None
werkzeug.exceptions.NotFound: 404 Not Found: The requested URL was not found on the server. If you entered the URL manually please check your spelling and try again.
[2025-03-17 00:34:36,821] ERROR in logger: [EXCEPTION] User None: Unhandled exception: InternalServerError
[2025-03-17 00:34:38,432] ERROR in logger: [EXCEPTION] User None: Unhandled exception: NotFound
[2025-03-17 00:34:38,435] ERROR in app: Exception on /users/4 [OPTIONS]
Traceback (most recent call last):
  File "/Users/macbook/EverythingProgramming/inventory_management_system/majesty-backend/backend/lib/python3.13/site-packages/flask/app.py", line 1463, in wsgi_app
    response = self.full_dispatch_request()
  File "/Users/macbook/EverythingProgramming/inventory_management_system/majesty-backend/backend/lib/python3.13/site-packages/flask/app.py", line 872, in full_dispatch_request
    rv = self.handle_user_exception(e)
  File "/Users/macbook/EverythingProgramming/inventory_management_system/majesty-backend/backend/lib/python3.13/site-packages/flask_cors/extension.py", line 176, in wrapped_function
    return cors_after_request(app.make_response(f(*args, **kwargs)))
                                                ~^^^^^^^^^^^^^^^^^
  File "/Users/macbook/EverythingProgramming/inventory_management_system/majesty-backend/backend/lib/python3.13/site-packages/flask/app.py", line 755, in handle_user_exception
    return self.handle_http_exception(e)
           ~~~~~~~~~~~~~~~~~~~~~~~~~~^^^
  File "/Users/macbook/EverythingProgramming/inventory_management_system/majesty-backend/backend/lib/python3.13/site-packages/flask/app.py", line 730, in handle_http_exception
    return self.ensure_sync(handler)(e)  # type: ignore[no-any-return]
           ~~~~~~~~~~~~~~~~~~~~~~~~~^^^
  File "/Users/macbook/EverythingProgramming/inventory_management_system/majesty-backend/app/utils/logger.py", line 194, in log_exception
    raise exception
  File "/Users/macbook/EverythingProgramming/inventory_management_system/majesty-backend/backend/lib/python3.13/site-packages/flask/app.py", line 870, in full_dispatch_request
    rv = self.dispatch_request()
  File "/Users/macbook/EverythingProgramming/inventory_management_system/majesty-backend/backend/lib/python3.13/site-packages/flask/app.py", line 844, in dispatch_request
    self.raise_routing_exception(req)
    ~~~~~~~~~~~~~~~~~~~~~~~~~~~~^^^^^
  File "/Users/macbook/EverythingProgramming/inventory_management_system/majesty-backend/backend/lib/python3.13/site-packages/flask/app.py", line 453, in raise_routing_exception
    raise request.routing_exception  # type: ignore[misc]
    ^^^^^^^^^^^^^^^^^^^^^^^^^^^^^^^
  File "/Users/macbook/EverythingProgramming/inventory_management_system/majesty-backend/backend/lib/python3.13/site-packages/flask/ctx.py", line 362, in match_request
    result = self.url_adapter.match(return_rule=True)  # type: ignore
  File "/Users/macbook/EverythingProgramming/inventory_management_system/majesty-backend/backend/lib/python3.13/site-packages/werkzeug/routing/map.py", line 629, in match
    raise NotFound() from None
werkzeug.exceptions.NotFound: 404 Not Found: The requested URL was not found on the server. If you entered the URL manually please check your spelling and try again.
[2025-03-17 00:34:38,439] ERROR in logger: [EXCEPTION] User None: Unhandled exception: InternalServerError
[2025-03-17 00:34:59,852] ERROR in logger: [EXCEPTION] User None: Unhandled exception: NotFound
[2025-03-17 00:34:59,855] ERROR in app: Exception on /users/4 [OPTIONS]
Traceback (most recent call last):
  File "/Users/macbook/EverythingProgramming/inventory_management_system/majesty-backend/backend/lib/python3.13/site-packages/flask/app.py", line 1463, in wsgi_app
    response = self.full_dispatch_request()
  File "/Users/macbook/EverythingProgramming/inventory_management_system/majesty-backend/backend/lib/python3.13/site-packages/flask/app.py", line 872, in full_dispatch_request
    rv = self.handle_user_exception(e)
  File "/Users/macbook/EverythingProgramming/inventory_management_system/majesty-backend/backend/lib/python3.13/site-packages/flask_cors/extension.py", line 176, in wrapped_function
    return cors_after_request(app.make_response(f(*args, **kwargs)))
                                                ~^^^^^^^^^^^^^^^^^
  File "/Users/macbook/EverythingProgramming/inventory_management_system/majesty-backend/backend/lib/python3.13/site-packages/flask/app.py", line 755, in handle_user_exception
    return self.handle_http_exception(e)
           ~~~~~~~~~~~~~~~~~~~~~~~~~~^^^
  File "/Users/macbook/EverythingProgramming/inventory_management_system/majesty-backend/backend/lib/python3.13/site-packages/flask/app.py", line 730, in handle_http_exception
    return self.ensure_sync(handler)(e)  # type: ignore[no-any-return]
           ~~~~~~~~~~~~~~~~~~~~~~~~~^^^
  File "/Users/macbook/EverythingProgramming/inventory_management_system/majesty-backend/app/utils/logger.py", line 194, in log_exception
    raise exception
  File "/Users/macbook/EverythingProgramming/inventory_management_system/majesty-backend/backend/lib/python3.13/site-packages/flask/app.py", line 870, in full_dispatch_request
    rv = self.dispatch_request()
  File "/Users/macbook/EverythingProgramming/inventory_management_system/majesty-backend/backend/lib/python3.13/site-packages/flask/app.py", line 844, in dispatch_request
    self.raise_routing_exception(req)
    ~~~~~~~~~~~~~~~~~~~~~~~~~~~~^^^^^
  File "/Users/macbook/EverythingProgramming/inventory_management_system/majesty-backend/backend/lib/python3.13/site-packages/flask/app.py", line 453, in raise_routing_exception
    raise request.routing_exception  # type: ignore[misc]
    ^^^^^^^^^^^^^^^^^^^^^^^^^^^^^^^
  File "/Users/macbook/EverythingProgramming/inventory_management_system/majesty-backend/backend/lib/python3.13/site-packages/flask/ctx.py", line 362, in match_request
    result = self.url_adapter.match(return_rule=True)  # type: ignore
  File "/Users/macbook/EverythingProgramming/inventory_management_system/majesty-backend/backend/lib/python3.13/site-packages/werkzeug/routing/map.py", line 629, in match
    raise NotFound() from None
werkzeug.exceptions.NotFound: 404 Not Found: The requested URL was not found on the server. If you entered the URL manually please check your spelling and try again.
[2025-03-17 00:34:59,860] ERROR in logger: [EXCEPTION] User None: Unhandled exception: InternalServerError
[2025-03-17 00:35:24,073] ERROR in logger: [EXCEPTION] User None: Unhandled exception: NotFound
[2025-03-17 00:35:24,078] ERROR in app: Exception on /users/4 [OPTIONS]
Traceback (most recent call last):
  File "/Users/macbook/EverythingProgramming/inventory_management_system/majesty-backend/backend/lib/python3.13/site-packages/flask/app.py", line 1463, in wsgi_app
    response = self.full_dispatch_request()
  File "/Users/macbook/EverythingProgramming/inventory_management_system/majesty-backend/backend/lib/python3.13/site-packages/flask/app.py", line 872, in full_dispatch_request
    rv = self.handle_user_exception(e)
  File "/Users/macbook/EverythingProgramming/inventory_management_system/majesty-backend/backend/lib/python3.13/site-packages/flask_cors/extension.py", line 176, in wrapped_function
    return cors_after_request(app.make_response(f(*args, **kwargs)))
                                                ~^^^^^^^^^^^^^^^^^
  File "/Users/macbook/EverythingProgramming/inventory_management_system/majesty-backend/backend/lib/python3.13/site-packages/flask/app.py", line 755, in handle_user_exception
    return self.handle_http_exception(e)
           ~~~~~~~~~~~~~~~~~~~~~~~~~~^^^
  File "/Users/macbook/EverythingProgramming/inventory_management_system/majesty-backend/backend/lib/python3.13/site-packages/flask/app.py", line 730, in handle_http_exception
    return self.ensure_sync(handler)(e)  # type: ignore[no-any-return]
           ~~~~~~~~~~~~~~~~~~~~~~~~~^^^
  File "/Users/macbook/EverythingProgramming/inventory_management_system/majesty-backend/app/utils/logger.py", line 194, in log_exception
    raise exception
  File "/Users/macbook/EverythingProgramming/inventory_management_system/majesty-backend/backend/lib/python3.13/site-packages/flask/app.py", line 870, in full_dispatch_request
    rv = self.dispatch_request()
  File "/Users/macbook/EverythingProgramming/inventory_management_system/majesty-backend/backend/lib/python3.13/site-packages/flask/app.py", line 844, in dispatch_request
    self.raise_routing_exception(req)
    ~~~~~~~~~~~~~~~~~~~~~~~~~~~~^^^^^
  File "/Users/macbook/EverythingProgramming/inventory_management_system/majesty-backend/backend/lib/python3.13/site-packages/flask/app.py", line 453, in raise_routing_exception
    raise request.routing_exception  # type: ignore[misc]
    ^^^^^^^^^^^^^^^^^^^^^^^^^^^^^^^
  File "/Users/macbook/EverythingProgramming/inventory_management_system/majesty-backend/backend/lib/python3.13/site-packages/flask/ctx.py", line 362, in match_request
    result = self.url_adapter.match(return_rule=True)  # type: ignore
  File "/Users/macbook/EverythingProgramming/inventory_management_system/majesty-backend/backend/lib/python3.13/site-packages/werkzeug/routing/map.py", line 629, in match
    raise NotFound() from None
werkzeug.exceptions.NotFound: 404 Not Found: The requested URL was not found on the server. If you entered the URL manually please check your spelling and try again.
[2025-03-17 00:35:24,082] ERROR in logger: [EXCEPTION] User None: Unhandled exception: InternalServerError
[2025-03-17 00:36:54,438] ERROR in logger: [EXCEPTION] User None: Unhandled exception: NotFound
[2025-03-17 00:36:54,441] ERROR in app: Exception on /users/4 [OPTIONS]
Traceback (most recent call last):
  File "/Users/macbook/EverythingProgramming/inventory_management_system/majesty-backend/backend/lib/python3.13/site-packages/flask/app.py", line 1463, in wsgi_app
    response = self.full_dispatch_request()
  File "/Users/macbook/EverythingProgramming/inventory_management_system/majesty-backend/backend/lib/python3.13/site-packages/flask/app.py", line 872, in full_dispatch_request
    rv = self.handle_user_exception(e)
  File "/Users/macbook/EverythingProgramming/inventory_management_system/majesty-backend/backend/lib/python3.13/site-packages/flask_cors/extension.py", line 176, in wrapped_function
    return cors_after_request(app.make_response(f(*args, **kwargs)))
                                                ~^^^^^^^^^^^^^^^^^
  File "/Users/macbook/EverythingProgramming/inventory_management_system/majesty-backend/backend/lib/python3.13/site-packages/flask/app.py", line 755, in handle_user_exception
    return self.handle_http_exception(e)
           ~~~~~~~~~~~~~~~~~~~~~~~~~~^^^
  File "/Users/macbook/EverythingProgramming/inventory_management_system/majesty-backend/backend/lib/python3.13/site-packages/flask/app.py", line 730, in handle_http_exception
    return self.ensure_sync(handler)(e)  # type: ignore[no-any-return]
           ~~~~~~~~~~~~~~~~~~~~~~~~~^^^
  File "/Users/macbook/EverythingProgramming/inventory_management_system/majesty-backend/app/utils/logger.py", line 194, in log_exception
    raise exception
  File "/Users/macbook/EverythingProgramming/inventory_management_system/majesty-backend/backend/lib/python3.13/site-packages/flask/app.py", line 870, in full_dispatch_request
    rv = self.dispatch_request()
  File "/Users/macbook/EverythingProgramming/inventory_management_system/majesty-backend/backend/lib/python3.13/site-packages/flask/app.py", line 844, in dispatch_request
    self.raise_routing_exception(req)
    ~~~~~~~~~~~~~~~~~~~~~~~~~~~~^^^^^
  File "/Users/macbook/EverythingProgramming/inventory_management_system/majesty-backend/backend/lib/python3.13/site-packages/flask/app.py", line 453, in raise_routing_exception
    raise request.routing_exception  # type: ignore[misc]
    ^^^^^^^^^^^^^^^^^^^^^^^^^^^^^^^
  File "/Users/macbook/EverythingProgramming/inventory_management_system/majesty-backend/backend/lib/python3.13/site-packages/flask/ctx.py", line 362, in match_request
    result = self.url_adapter.match(return_rule=True)  # type: ignore
  File "/Users/macbook/EverythingProgramming/inventory_management_system/majesty-backend/backend/lib/python3.13/site-packages/werkzeug/routing/map.py", line 629, in match
    raise NotFound() from None
werkzeug.exceptions.NotFound: 404 Not Found: The requested URL was not found on the server. If you entered the URL manually please check your spelling and try again.
<<<<<<< HEAD
[2025-03-17 00:36:54,447] ERROR in logger: [EXCEPTION] User None: Unhandled exception: InternalServerError
[2025-03-17 01:02:53,684] INFO in logger: [CHECK_TOKEN_VALID] User 1: Token is valid | Affected: Token System
[2025-03-17 01:18:11,574] INFO in logger: [CHECK_TOKEN_VALID] User 1: Token is valid | Affected: Token System
[2025-03-17 01:22:27,225] INFO in logger: [GET_USERS_SUCCESS] User 1: Admin retrieved user list | Affected: User Management
[2025-03-17 01:22:38,488] INFO in logger: [GET_ALL_WINES] User 1: Fetched all wines | Affected: All Wines
[2025-03-17 01:35:01,373] INFO in logger: [GET_ALL_WINES] User 1: Fetched all wines | Affected: All Wines
[2025-03-17 01:35:39,919] INFO in logger: [CHECK_TOKEN_VALID] User 1: Token is valid | Affected: Token System
[2025-03-17 01:35:40,084] INFO in logger: [GET_ALL_WINES] User 1: Fetched all wines | Affected: All Wines
[2025-03-17 01:37:55,853] INFO in logger: [CHECK_TOKEN_VALID] User 1: Token is valid | Affected: Token System
[2025-03-17 01:37:55,925] INFO in logger: [GET_ALL_WINES] User 1: Fetched all wines | Affected: All Wines
[2025-03-17 01:39:07,178] INFO in logger: [GET_REVENUE] User 1: Revenue calculated: 150.00 | Affected: Revenue
[2025-03-17 01:39:07,183] INFO in logger: [GET_STOCK_BY_CATEGORY] User 1: Stock by category fetched successfully | Affected: Stock by Category
[2025-03-17 01:39:07,184] INFO in logger: [GET_TOTAL_STOCK] User 1: Total stock checked: 147 | Affected: Total Stock
[2025-03-17 01:39:07,188] INFO in logger: [COMPARE_SALES] User 1: Sales compared: -100% | Affected: Sales Comparison
=======
[2025-03-16 18:09:48,275] ERROR in logger: [EXCEPTION] User None: Unhandled exception: InternalServerError
[2025-03-16 18:09:49,887] ERROR in logger: [EXCEPTION] User None: Unhandled exception: NotFound
[2025-03-16 18:09:49,894] ERROR in app: Exception on /wine [GET]
Traceback (most recent call last):
  File "/Users/macbook/EverythingProgramming/inventory_management_system/majesty-backend/backend/lib/python3.13/site-packages/flask/app.py", line 1463, in wsgi_app
    response = self.full_dispatch_request()
  File "/Users/macbook/EverythingProgramming/inventory_management_system/majesty-backend/backend/lib/python3.13/site-packages/flask/app.py", line 872, in full_dispatch_request
    rv = self.handle_user_exception(e)
  File "/Users/macbook/EverythingProgramming/inventory_management_system/majesty-backend/backend/lib/python3.13/site-packages/flask_cors/extension.py", line 176, in wrapped_function
    return cors_after_request(app.make_response(f(*args, **kwargs)))
                                                ~^^^^^^^^^^^^^^^^^
  File "/Users/macbook/EverythingProgramming/inventory_management_system/majesty-backend/backend/lib/python3.13/site-packages/flask/app.py", line 755, in handle_user_exception
    return self.handle_http_exception(e)
           ~~~~~~~~~~~~~~~~~~~~~~~~~~^^^
  File "/Users/macbook/EverythingProgramming/inventory_management_system/majesty-backend/backend/lib/python3.13/site-packages/flask/app.py", line 730, in handle_http_exception
    return self.ensure_sync(handler)(e)  # type: ignore[no-any-return]
           ~~~~~~~~~~~~~~~~~~~~~~~~~^^^
  File "/Users/macbook/EverythingProgramming/inventory_management_system/majesty-backend/app/utils/logger.py", line 194, in log_exception
    raise exception
  File "/Users/macbook/EverythingProgramming/inventory_management_system/majesty-backend/backend/lib/python3.13/site-packages/flask/app.py", line 870, in full_dispatch_request
    rv = self.dispatch_request()
  File "/Users/macbook/EverythingProgramming/inventory_management_system/majesty-backend/backend/lib/python3.13/site-packages/flask/app.py", line 844, in dispatch_request
    self.raise_routing_exception(req)
    ~~~~~~~~~~~~~~~~~~~~~~~~~~~~^^^^^
  File "/Users/macbook/EverythingProgramming/inventory_management_system/majesty-backend/backend/lib/python3.13/site-packages/flask/app.py", line 453, in raise_routing_exception
    raise request.routing_exception  # type: ignore[misc]
    ^^^^^^^^^^^^^^^^^^^^^^^^^^^^^^^
  File "/Users/macbook/EverythingProgramming/inventory_management_system/majesty-backend/backend/lib/python3.13/site-packages/flask/ctx.py", line 362, in match_request
    result = self.url_adapter.match(return_rule=True)  # type: ignore
  File "/Users/macbook/EverythingProgramming/inventory_management_system/majesty-backend/backend/lib/python3.13/site-packages/werkzeug/routing/map.py", line 629, in match
    raise NotFound() from None
werkzeug.exceptions.NotFound: 404 Not Found: The requested URL was not found on the server. If you entered the URL manually please check your spelling and try again.
[2025-03-16 18:09:49,898] ERROR in logger: [EXCEPTION] User None: Unhandled exception: InternalServerError
[2025-03-16 18:09:53,158] ERROR in logger: [EXCEPTION] User None: Unhandled exception: NotFound
[2025-03-16 18:09:53,162] ERROR in app: Exception on /wine/all [GET]
Traceback (most recent call last):
  File "/Users/macbook/EverythingProgramming/inventory_management_system/majesty-backend/backend/lib/python3.13/site-packages/flask/app.py", line 1463, in wsgi_app
    response = self.full_dispatch_request()
  File "/Users/macbook/EverythingProgramming/inventory_management_system/majesty-backend/backend/lib/python3.13/site-packages/flask/app.py", line 872, in full_dispatch_request
    rv = self.handle_user_exception(e)
  File "/Users/macbook/EverythingProgramming/inventory_management_system/majesty-backend/backend/lib/python3.13/site-packages/flask_cors/extension.py", line 176, in wrapped_function
    return cors_after_request(app.make_response(f(*args, **kwargs)))
                                                ~^^^^^^^^^^^^^^^^^
  File "/Users/macbook/EverythingProgramming/inventory_management_system/majesty-backend/backend/lib/python3.13/site-packages/flask/app.py", line 755, in handle_user_exception
    return self.handle_http_exception(e)
           ~~~~~~~~~~~~~~~~~~~~~~~~~~^^^
  File "/Users/macbook/EverythingProgramming/inventory_management_system/majesty-backend/backend/lib/python3.13/site-packages/flask/app.py", line 730, in handle_http_exception
    return self.ensure_sync(handler)(e)  # type: ignore[no-any-return]
           ~~~~~~~~~~~~~~~~~~~~~~~~~^^^
  File "/Users/macbook/EverythingProgramming/inventory_management_system/majesty-backend/app/utils/logger.py", line 194, in log_exception
    raise exception
  File "/Users/macbook/EverythingProgramming/inventory_management_system/majesty-backend/backend/lib/python3.13/site-packages/flask/app.py", line 870, in full_dispatch_request
    rv = self.dispatch_request()
  File "/Users/macbook/EverythingProgramming/inventory_management_system/majesty-backend/backend/lib/python3.13/site-packages/flask/app.py", line 844, in dispatch_request
    self.raise_routing_exception(req)
    ~~~~~~~~~~~~~~~~~~~~~~~~~~~~^^^^^
  File "/Users/macbook/EverythingProgramming/inventory_management_system/majesty-backend/backend/lib/python3.13/site-packages/flask/app.py", line 453, in raise_routing_exception
    raise request.routing_exception  # type: ignore[misc]
    ^^^^^^^^^^^^^^^^^^^^^^^^^^^^^^^
  File "/Users/macbook/EverythingProgramming/inventory_management_system/majesty-backend/backend/lib/python3.13/site-packages/flask/ctx.py", line 362, in match_request
    result = self.url_adapter.match(return_rule=True)  # type: ignore
  File "/Users/macbook/EverythingProgramming/inventory_management_system/majesty-backend/backend/lib/python3.13/site-packages/werkzeug/routing/map.py", line 629, in match
    raise NotFound() from None
werkzeug.exceptions.NotFound: 404 Not Found: The requested URL was not found on the server. If you entered the URL manually please check your spelling and try again.
[2025-03-16 18:09:53,168] ERROR in logger: [EXCEPTION] User None: Unhandled exception: InternalServerError
[2025-03-16 18:11:35,580] INFO in logger: [GET_USERS_SUCCESS] User 1: Admin retrieved user list | Affected: User Management
[2025-03-16 18:11:51,881] ERROR in logger: [EXCEPTION] User None: Unhandled exception: NotFound
[2025-03-16 18:11:51,886] ERROR in app: Exception on /users/4 [OPTIONS]
Traceback (most recent call last):
  File "/Users/macbook/EverythingProgramming/inventory_management_system/majesty-backend/backend/lib/python3.13/site-packages/flask/app.py", line 1463, in wsgi_app
    response = self.full_dispatch_request()
  File "/Users/macbook/EverythingProgramming/inventory_management_system/majesty-backend/backend/lib/python3.13/site-packages/flask/app.py", line 872, in full_dispatch_request
    rv = self.handle_user_exception(e)
  File "/Users/macbook/EverythingProgramming/inventory_management_system/majesty-backend/backend/lib/python3.13/site-packages/flask_cors/extension.py", line 176, in wrapped_function
    return cors_after_request(app.make_response(f(*args, **kwargs)))
                                                ~^^^^^^^^^^^^^^^^^
  File "/Users/macbook/EverythingProgramming/inventory_management_system/majesty-backend/backend/lib/python3.13/site-packages/flask/app.py", line 755, in handle_user_exception
    return self.handle_http_exception(e)
           ~~~~~~~~~~~~~~~~~~~~~~~~~~^^^
  File "/Users/macbook/EverythingProgramming/inventory_management_system/majesty-backend/backend/lib/python3.13/site-packages/flask/app.py", line 730, in handle_http_exception
    return self.ensure_sync(handler)(e)  # type: ignore[no-any-return]
           ~~~~~~~~~~~~~~~~~~~~~~~~~^^^
  File "/Users/macbook/EverythingProgramming/inventory_management_system/majesty-backend/app/utils/logger.py", line 194, in log_exception
    raise exception
  File "/Users/macbook/EverythingProgramming/inventory_management_system/majesty-backend/backend/lib/python3.13/site-packages/flask/app.py", line 870, in full_dispatch_request
    rv = self.dispatch_request()
  File "/Users/macbook/EverythingProgramming/inventory_management_system/majesty-backend/backend/lib/python3.13/site-packages/flask/app.py", line 844, in dispatch_request
    self.raise_routing_exception(req)
    ~~~~~~~~~~~~~~~~~~~~~~~~~~~~^^^^^
  File "/Users/macbook/EverythingProgramming/inventory_management_system/majesty-backend/backend/lib/python3.13/site-packages/flask/app.py", line 453, in raise_routing_exception
    raise request.routing_exception  # type: ignore[misc]
    ^^^^^^^^^^^^^^^^^^^^^^^^^^^^^^^
  File "/Users/macbook/EverythingProgramming/inventory_management_system/majesty-backend/backend/lib/python3.13/site-packages/flask/ctx.py", line 362, in match_request
    result = self.url_adapter.match(return_rule=True)  # type: ignore
  File "/Users/macbook/EverythingProgramming/inventory_management_system/majesty-backend/backend/lib/python3.13/site-packages/werkzeug/routing/map.py", line 629, in match
    raise NotFound() from None
werkzeug.exceptions.NotFound: 404 Not Found: The requested URL was not found on the server. If you entered the URL manually please check your spelling and try again.
[2025-03-16 18:11:51,891] ERROR in logger: [EXCEPTION] User None: Unhandled exception: InternalServerError
[2025-03-16 18:12:07,800] ERROR in logger: [EXCEPTION] User None: Unhandled exception: NotFound
[2025-03-16 18:12:07,803] ERROR in app: Exception on /users/4 [OPTIONS]
Traceback (most recent call last):
  File "/Users/macbook/EverythingProgramming/inventory_management_system/majesty-backend/backend/lib/python3.13/site-packages/flask/app.py", line 1463, in wsgi_app
    response = self.full_dispatch_request()
  File "/Users/macbook/EverythingProgramming/inventory_management_system/majesty-backend/backend/lib/python3.13/site-packages/flask/app.py", line 872, in full_dispatch_request
    rv = self.handle_user_exception(e)
  File "/Users/macbook/EverythingProgramming/inventory_management_system/majesty-backend/backend/lib/python3.13/site-packages/flask_cors/extension.py", line 176, in wrapped_function
    return cors_after_request(app.make_response(f(*args, **kwargs)))
                                                ~^^^^^^^^^^^^^^^^^
  File "/Users/macbook/EverythingProgramming/inventory_management_system/majesty-backend/backend/lib/python3.13/site-packages/flask/app.py", line 755, in handle_user_exception
    return self.handle_http_exception(e)
           ~~~~~~~~~~~~~~~~~~~~~~~~~~^^^
  File "/Users/macbook/EverythingProgramming/inventory_management_system/majesty-backend/backend/lib/python3.13/site-packages/flask/app.py", line 730, in handle_http_exception
    return self.ensure_sync(handler)(e)  # type: ignore[no-any-return]
           ~~~~~~~~~~~~~~~~~~~~~~~~~^^^
  File "/Users/macbook/EverythingProgramming/inventory_management_system/majesty-backend/app/utils/logger.py", line 194, in log_exception
    raise exception
  File "/Users/macbook/EverythingProgramming/inventory_management_system/majesty-backend/backend/lib/python3.13/site-packages/flask/app.py", line 870, in full_dispatch_request
    rv = self.dispatch_request()
  File "/Users/macbook/EverythingProgramming/inventory_management_system/majesty-backend/backend/lib/python3.13/site-packages/flask/app.py", line 844, in dispatch_request
    self.raise_routing_exception(req)
    ~~~~~~~~~~~~~~~~~~~~~~~~~~~~^^^^^
  File "/Users/macbook/EverythingProgramming/inventory_management_system/majesty-backend/backend/lib/python3.13/site-packages/flask/app.py", line 453, in raise_routing_exception
    raise request.routing_exception  # type: ignore[misc]
    ^^^^^^^^^^^^^^^^^^^^^^^^^^^^^^^
  File "/Users/macbook/EverythingProgramming/inventory_management_system/majesty-backend/backend/lib/python3.13/site-packages/flask/ctx.py", line 362, in match_request
    result = self.url_adapter.match(return_rule=True)  # type: ignore
  File "/Users/macbook/EverythingProgramming/inventory_management_system/majesty-backend/backend/lib/python3.13/site-packages/werkzeug/routing/map.py", line 629, in match
    raise NotFound() from None
werkzeug.exceptions.NotFound: 404 Not Found: The requested URL was not found on the server. If you entered the URL manually please check your spelling and try again.
[2025-03-16 18:12:07,808] ERROR in logger: [EXCEPTION] User None: Unhandled exception: InternalServerError
[2025-03-16 18:13:53,318] INFO in logger: [GET_USERS_SUCCESS] User 1: Admin retrieved user list | Affected: User Management
[2025-03-16 18:19:50,962] ERROR in logger: [EXCEPTION] User None: Unhandled exception: NotFound
[2025-03-16 18:19:50,965] ERROR in app: Exception on /wine/all [GET]
Traceback (most recent call last):
  File "/Users/macbook/EverythingProgramming/inventory_management_system/majesty-backend/backend/lib/python3.13/site-packages/flask/app.py", line 1463, in wsgi_app
    response = self.full_dispatch_request()
  File "/Users/macbook/EverythingProgramming/inventory_management_system/majesty-backend/backend/lib/python3.13/site-packages/flask/app.py", line 872, in full_dispatch_request
    rv = self.handle_user_exception(e)
  File "/Users/macbook/EverythingProgramming/inventory_management_system/majesty-backend/backend/lib/python3.13/site-packages/flask_cors/extension.py", line 176, in wrapped_function
    return cors_after_request(app.make_response(f(*args, **kwargs)))
                                                ~^^^^^^^^^^^^^^^^^
  File "/Users/macbook/EverythingProgramming/inventory_management_system/majesty-backend/backend/lib/python3.13/site-packages/flask/app.py", line 755, in handle_user_exception
    return self.handle_http_exception(e)
           ~~~~~~~~~~~~~~~~~~~~~~~~~~^^^
  File "/Users/macbook/EverythingProgramming/inventory_management_system/majesty-backend/backend/lib/python3.13/site-packages/flask/app.py", line 730, in handle_http_exception
    return self.ensure_sync(handler)(e)  # type: ignore[no-any-return]
           ~~~~~~~~~~~~~~~~~~~~~~~~~^^^
  File "/Users/macbook/EverythingProgramming/inventory_management_system/majesty-backend/app/utils/logger.py", line 194, in log_exception
    raise exception
  File "/Users/macbook/EverythingProgramming/inventory_management_system/majesty-backend/backend/lib/python3.13/site-packages/flask/app.py", line 870, in full_dispatch_request
    rv = self.dispatch_request()
  File "/Users/macbook/EverythingProgramming/inventory_management_system/majesty-backend/backend/lib/python3.13/site-packages/flask/app.py", line 844, in dispatch_request
    self.raise_routing_exception(req)
    ~~~~~~~~~~~~~~~~~~~~~~~~~~~~^^^^^
  File "/Users/macbook/EverythingProgramming/inventory_management_system/majesty-backend/backend/lib/python3.13/site-packages/flask/app.py", line 453, in raise_routing_exception
    raise request.routing_exception  # type: ignore[misc]
    ^^^^^^^^^^^^^^^^^^^^^^^^^^^^^^^
  File "/Users/macbook/EverythingProgramming/inventory_management_system/majesty-backend/backend/lib/python3.13/site-packages/flask/ctx.py", line 362, in match_request
    result = self.url_adapter.match(return_rule=True)  # type: ignore
  File "/Users/macbook/EverythingProgramming/inventory_management_system/majesty-backend/backend/lib/python3.13/site-packages/werkzeug/routing/map.py", line 629, in match
    raise NotFound() from None
werkzeug.exceptions.NotFound: 404 Not Found: The requested URL was not found on the server. If you entered the URL manually please check your spelling and try again.
[2025-03-16 18:19:50,970] ERROR in logger: [EXCEPTION] User None: Unhandled exception: InternalServerError
[2025-03-16 18:20:33,419] INFO in logger: Wine Inventory API Started - Environment: development
[2025-03-16 18:20:51,341] INFO in logger: [GET_ALL_WINES] User 1: Fetched all wines successfully | Affected: Wine Inventory
[2025-03-16 18:21:23,452] INFO in logger: [UPDATE_WINE_SUCCESS] User 1: Wine updated: red wine | Affected: red wine
[2025-03-16 18:21:30,615] INFO in logger: [CHECK_TOKEN_VALID] User 1: Token is valid | Affected: Token System
[2025-03-16 18:21:30,714] INFO in logger: [GET_ALL_WINES] User 1: Fetched all wines successfully | Affected: Wine Inventory
[2025-03-16 18:21:31,640] INFO in logger: [GET_STOCK_BY_CATEGORY] User 1: Stock by category fetched successfully | Affected: Stock by Category
[2025-03-16 18:21:31,648] INFO in logger: [GET_TOTAL_STOCK] User 1: Total stock checked: 147 | Affected: Total Stock
[2025-03-16 18:21:31,650] ERROR in logger: [EXCEPTION] User None: Unhandled exception: NotFound
[2025-03-16 18:21:31,652] ERROR in logger: [EXCEPTION] User None: Unhandled exception: NotFound
[2025-03-16 18:21:31,660] ERROR in app: Exception on /wine/compare-sales [OPTIONS]
Traceback (most recent call last):
  File "/Users/macbook/EverythingProgramming/inventory_management_system/majesty-backend/backend/lib/python3.13/site-packages/flask/app.py", line 1463, in wsgi_app
    response = self.full_dispatch_request()
  File "/Users/macbook/EverythingProgramming/inventory_management_system/majesty-backend/backend/lib/python3.13/site-packages/flask/app.py", line 872, in full_dispatch_request
    rv = self.handle_user_exception(e)
  File "/Users/macbook/EverythingProgramming/inventory_management_system/majesty-backend/backend/lib/python3.13/site-packages/flask_cors/extension.py", line 176, in wrapped_function
    return cors_after_request(app.make_response(f(*args, **kwargs)))
                                                ~^^^^^^^^^^^^^^^^^
  File "/Users/macbook/EverythingProgramming/inventory_management_system/majesty-backend/backend/lib/python3.13/site-packages/flask/app.py", line 755, in handle_user_exception
    return self.handle_http_exception(e)
           ~~~~~~~~~~~~~~~~~~~~~~~~~~^^^
  File "/Users/macbook/EverythingProgramming/inventory_management_system/majesty-backend/backend/lib/python3.13/site-packages/flask/app.py", line 730, in handle_http_exception
    return self.ensure_sync(handler)(e)  # type: ignore[no-any-return]
           ~~~~~~~~~~~~~~~~~~~~~~~~~^^^
  File "/Users/macbook/EverythingProgramming/inventory_management_system/majesty-backend/app/utils/logger.py", line 194, in log_exception
    raise exception
  File "/Users/macbook/EverythingProgramming/inventory_management_system/majesty-backend/backend/lib/python3.13/site-packages/flask/app.py", line 870, in full_dispatch_request
    rv = self.dispatch_request()
  File "/Users/macbook/EverythingProgramming/inventory_management_system/majesty-backend/backend/lib/python3.13/site-packages/flask/app.py", line 844, in dispatch_request
    self.raise_routing_exception(req)
    ~~~~~~~~~~~~~~~~~~~~~~~~~~~~^^^^^
  File "/Users/macbook/EverythingProgramming/inventory_management_system/majesty-backend/backend/lib/python3.13/site-packages/flask/app.py", line 453, in raise_routing_exception
    raise request.routing_exception  # type: ignore[misc]
    ^^^^^^^^^^^^^^^^^^^^^^^^^^^^^^^
  File "/Users/macbook/EverythingProgramming/inventory_management_system/majesty-backend/backend/lib/python3.13/site-packages/flask/ctx.py", line 362, in match_request
    result = self.url_adapter.match(return_rule=True)  # type: ignore
  File "/Users/macbook/EverythingProgramming/inventory_management_system/majesty-backend/backend/lib/python3.13/site-packages/werkzeug/routing/map.py", line 629, in match
    raise NotFound() from None
werkzeug.exceptions.NotFound: 404 Not Found: The requested URL was not found on the server. If you entered the URL manually please check your spelling and try again.
[2025-03-16 18:21:31,669] ERROR in app: Exception on /wine/revenue [OPTIONS]
Traceback (most recent call last):
  File "/Users/macbook/EverythingProgramming/inventory_management_system/majesty-backend/backend/lib/python3.13/site-packages/flask/app.py", line 1463, in wsgi_app
    response = self.full_dispatch_request()
  File "/Users/macbook/EverythingProgramming/inventory_management_system/majesty-backend/backend/lib/python3.13/site-packages/flask/app.py", line 872, in full_dispatch_request
    rv = self.handle_user_exception(e)
  File "/Users/macbook/EverythingProgramming/inventory_management_system/majesty-backend/backend/lib/python3.13/site-packages/flask_cors/extension.py", line 176, in wrapped_function
    return cors_after_request(app.make_response(f(*args, **kwargs)))
                                                ~^^^^^^^^^^^^^^^^^
  File "/Users/macbook/EverythingProgramming/inventory_management_system/majesty-backend/backend/lib/python3.13/site-packages/flask/app.py", line 755, in handle_user_exception
    return self.handle_http_exception(e)
           ~~~~~~~~~~~~~~~~~~~~~~~~~~^^^
  File "/Users/macbook/EverythingProgramming/inventory_management_system/majesty-backend/backend/lib/python3.13/site-packages/flask/app.py", line 730, in handle_http_exception
    return self.ensure_sync(handler)(e)  # type: ignore[no-any-return]
           ~~~~~~~~~~~~~~~~~~~~~~~~~^^^
  File "/Users/macbook/EverythingProgramming/inventory_management_system/majesty-backend/app/utils/logger.py", line 194, in log_exception
    raise exception
  File "/Users/macbook/EverythingProgramming/inventory_management_system/majesty-backend/backend/lib/python3.13/site-packages/flask/app.py", line 870, in full_dispatch_request
    rv = self.dispatch_request()
  File "/Users/macbook/EverythingProgramming/inventory_management_system/majesty-backend/backend/lib/python3.13/site-packages/flask/app.py", line 844, in dispatch_request
    self.raise_routing_exception(req)
    ~~~~~~~~~~~~~~~~~~~~~~~~~~~~^^^^^
  File "/Users/macbook/EverythingProgramming/inventory_management_system/majesty-backend/backend/lib/python3.13/site-packages/flask/app.py", line 453, in raise_routing_exception
    raise request.routing_exception  # type: ignore[misc]
    ^^^^^^^^^^^^^^^^^^^^^^^^^^^^^^^
  File "/Users/macbook/EverythingProgramming/inventory_management_system/majesty-backend/backend/lib/python3.13/site-packages/flask/ctx.py", line 362, in match_request
    result = self.url_adapter.match(return_rule=True)  # type: ignore
  File "/Users/macbook/EverythingProgramming/inventory_management_system/majesty-backend/backend/lib/python3.13/site-packages/werkzeug/routing/map.py", line 629, in match
    raise NotFound() from None
werkzeug.exceptions.NotFound: 404 Not Found: The requested URL was not found on the server. If you entered the URL manually please check your spelling and try again.
[2025-03-16 18:21:31,677] ERROR in logger: [EXCEPTION] User None: Unhandled exception: InternalServerError
[2025-03-16 18:21:31,681] ERROR in logger: [EXCEPTION] User None: Unhandled exception: InternalServerError
[2025-03-16 18:22:48,169] ERROR in logger: [EXCEPTION] User 1: Unhandled exception: UnsupportedMediaType
[2025-03-16 18:22:48,175] ERROR in app: Exception on /wine/3 [PUT]
Traceback (most recent call last):
  File "/Users/macbook/EverythingProgramming/inventory_management_system/majesty-backend/backend/lib/python3.13/site-packages/flask/app.py", line 1463, in wsgi_app
    response = self.full_dispatch_request()
  File "/Users/macbook/EverythingProgramming/inventory_management_system/majesty-backend/backend/lib/python3.13/site-packages/flask/app.py", line 872, in full_dispatch_request
    rv = self.handle_user_exception(e)
  File "/Users/macbook/EverythingProgramming/inventory_management_system/majesty-backend/backend/lib/python3.13/site-packages/flask_cors/extension.py", line 176, in wrapped_function
    return cors_after_request(app.make_response(f(*args, **kwargs)))
                                                ~^^^^^^^^^^^^^^^^^
  File "/Users/macbook/EverythingProgramming/inventory_management_system/majesty-backend/backend/lib/python3.13/site-packages/flask/app.py", line 755, in handle_user_exception
    return self.handle_http_exception(e)
           ~~~~~~~~~~~~~~~~~~~~~~~~~~^^^
  File "/Users/macbook/EverythingProgramming/inventory_management_system/majesty-backend/backend/lib/python3.13/site-packages/flask/app.py", line 730, in handle_http_exception
    return self.ensure_sync(handler)(e)  # type: ignore[no-any-return]
           ~~~~~~~~~~~~~~~~~~~~~~~~~^^^
  File "/Users/macbook/EverythingProgramming/inventory_management_system/majesty-backend/app/utils/logger.py", line 194, in log_exception
    raise exception
  File "/Users/macbook/EverythingProgramming/inventory_management_system/majesty-backend/backend/lib/python3.13/site-packages/flask/app.py", line 870, in full_dispatch_request
    rv = self.dispatch_request()
  File "/Users/macbook/EverythingProgramming/inventory_management_system/majesty-backend/backend/lib/python3.13/site-packages/flask/app.py", line 855, in dispatch_request
    return self.ensure_sync(self.view_functions[rule.endpoint])(**view_args)  # type: ignore[no-any-return]
           ~~~~~~~~~~~~~~~~~~~~~~~~~~~~~~~~~~~~~~~~~~~~~~~~~~~~^^^^^^^^^^^^^
  File "/Users/macbook/EverythingProgramming/inventory_management_system/majesty-backend/backend/lib/python3.13/site-packages/flask_jwt_extended/view_decorators.py", line 170, in decorator
    return current_app.ensure_sync(fn)(*args, **kwargs)
           ~~~~~~~~~~~~~~~~~~~~~~~~~~~^^^^^^^^^^^^^^^^^
  File "/Users/macbook/EverythingProgramming/inventory_management_system/majesty-backend/app/routes/wine.py", line 190, in update_wine
    data = request.get_json()
  File "/Users/macbook/EverythingProgramming/inventory_management_system/majesty-backend/backend/lib/python3.13/site-packages/werkzeug/wrappers/request.py", line 604, in get_json
    return self.on_json_loading_failed(None)
           ~~~~~~~~~~~~~~~~~~~~~~~~~~~^^^^^^
  File "/Users/macbook/EverythingProgramming/inventory_management_system/majesty-backend/backend/lib/python3.13/site-packages/flask/wrappers.py", line 131, in on_json_loading_failed
    return super().on_json_loading_failed(e)
           ~~~~~~~~~~~~~~~~~~~~~~~~~~~~~~^^^
  File "/Users/macbook/EverythingProgramming/inventory_management_system/majesty-backend/backend/lib/python3.13/site-packages/werkzeug/wrappers/request.py", line 647, in on_json_loading_failed
    raise UnsupportedMediaType(
    ...<2 lines>...
    )
werkzeug.exceptions.UnsupportedMediaType: 415 Unsupported Media Type: Did not attempt to load JSON data because the request Content-Type was not 'application/json'.
[2025-03-16 18:22:48,186] ERROR in logger: [EXCEPTION] User 1: Unhandled exception: InternalServerError
[2025-03-16 18:23:06,766] INFO in logger: [CHECK_TOKEN_VALID] User 1: Token is valid | Affected: Token System
[2025-03-16 18:23:06,933] INFO in logger: [GET_ALL_WINES] User 1: Fetched all wines successfully | Affected: Wine Inventory
[2025-03-16 18:23:07,705] ERROR in logger: [EXCEPTION] User None: Unhandled exception: NotFound
[2025-03-16 18:23:07,716] ERROR in app: Exception on /wine/revenue [OPTIONS]
Traceback (most recent call last):
  File "/Users/macbook/EverythingProgramming/inventory_management_system/majesty-backend/backend/lib/python3.13/site-packages/flask/app.py", line 1463, in wsgi_app
    response = self.full_dispatch_request()
  File "/Users/macbook/EverythingProgramming/inventory_management_system/majesty-backend/backend/lib/python3.13/site-packages/flask/app.py", line 872, in full_dispatch_request
    rv = self.handle_user_exception(e)
  File "/Users/macbook/EverythingProgramming/inventory_management_system/majesty-backend/backend/lib/python3.13/site-packages/flask_cors/extension.py", line 176, in wrapped_function
    return cors_after_request(app.make_response(f(*args, **kwargs)))
                                                ~^^^^^^^^^^^^^^^^^
  File "/Users/macbook/EverythingProgramming/inventory_management_system/majesty-backend/backend/lib/python3.13/site-packages/flask/app.py", line 755, in handle_user_exception
    return self.handle_http_exception(e)
           ~~~~~~~~~~~~~~~~~~~~~~~~~~^^^
  File "/Users/macbook/EverythingProgramming/inventory_management_system/majesty-backend/backend/lib/python3.13/site-packages/flask/app.py", line 730, in handle_http_exception
    return self.ensure_sync(handler)(e)  # type: ignore[no-any-return]
           ~~~~~~~~~~~~~~~~~~~~~~~~~^^^
  File "/Users/macbook/EverythingProgramming/inventory_management_system/majesty-backend/app/utils/logger.py", line 194, in log_exception
    raise exception
  File "/Users/macbook/EverythingProgramming/inventory_management_system/majesty-backend/backend/lib/python3.13/site-packages/flask/app.py", line 870, in full_dispatch_request
    rv = self.dispatch_request()
  File "/Users/macbook/EverythingProgramming/inventory_management_system/majesty-backend/backend/lib/python3.13/site-packages/flask/app.py", line 844, in dispatch_request
    self.raise_routing_exception(req)
    ~~~~~~~~~~~~~~~~~~~~~~~~~~~~^^^^^
  File "/Users/macbook/EverythingProgramming/inventory_management_system/majesty-backend/backend/lib/python3.13/site-packages/flask/app.py", line 453, in raise_routing_exception
    raise request.routing_exception  # type: ignore[misc]
    ^^^^^^^^^^^^^^^^^^^^^^^^^^^^^^^
  File "/Users/macbook/EverythingProgramming/inventory_management_system/majesty-backend/backend/lib/python3.13/site-packages/flask/ctx.py", line 362, in match_request
    result = self.url_adapter.match(return_rule=True)  # type: ignore
  File "/Users/macbook/EverythingProgramming/inventory_management_system/majesty-backend/backend/lib/python3.13/site-packages/werkzeug/routing/map.py", line 629, in match
    raise NotFound() from None
werkzeug.exceptions.NotFound: 404 Not Found: The requested URL was not found on the server. If you entered the URL manually please check your spelling and try again.
[2025-03-16 18:23:07,721] ERROR in logger: [EXCEPTION] User None: Unhandled exception: NotFound
[2025-03-16 18:23:07,726] INFO in logger: [GET_STOCK_BY_CATEGORY] User 1: Stock by category fetched successfully | Affected: Stock by Category
[2025-03-16 18:23:07,731] INFO in logger: [GET_TOTAL_STOCK] User 1: Total stock checked: 147 | Affected: Total Stock
[2025-03-16 18:23:07,735] ERROR in logger: [EXCEPTION] User None: Unhandled exception: InternalServerError
[2025-03-16 18:23:07,739] ERROR in app: Exception on /wine/compare-sales [OPTIONS]
Traceback (most recent call last):
  File "/Users/macbook/EverythingProgramming/inventory_management_system/majesty-backend/backend/lib/python3.13/site-packages/flask/app.py", line 1463, in wsgi_app
    response = self.full_dispatch_request()
  File "/Users/macbook/EverythingProgramming/inventory_management_system/majesty-backend/backend/lib/python3.13/site-packages/flask/app.py", line 872, in full_dispatch_request
    rv = self.handle_user_exception(e)
  File "/Users/macbook/EverythingProgramming/inventory_management_system/majesty-backend/backend/lib/python3.13/site-packages/flask_cors/extension.py", line 176, in wrapped_function
    return cors_after_request(app.make_response(f(*args, **kwargs)))
                                                ~^^^^^^^^^^^^^^^^^
  File "/Users/macbook/EverythingProgramming/inventory_management_system/majesty-backend/backend/lib/python3.13/site-packages/flask/app.py", line 755, in handle_user_exception
    return self.handle_http_exception(e)
           ~~~~~~~~~~~~~~~~~~~~~~~~~~^^^
  File "/Users/macbook/EverythingProgramming/inventory_management_system/majesty-backend/backend/lib/python3.13/site-packages/flask/app.py", line 730, in handle_http_exception
    return self.ensure_sync(handler)(e)  # type: ignore[no-any-return]
           ~~~~~~~~~~~~~~~~~~~~~~~~~^^^
  File "/Users/macbook/EverythingProgramming/inventory_management_system/majesty-backend/app/utils/logger.py", line 194, in log_exception
    raise exception
  File "/Users/macbook/EverythingProgramming/inventory_management_system/majesty-backend/backend/lib/python3.13/site-packages/flask/app.py", line 870, in full_dispatch_request
    rv = self.dispatch_request()
  File "/Users/macbook/EverythingProgramming/inventory_management_system/majesty-backend/backend/lib/python3.13/site-packages/flask/app.py", line 844, in dispatch_request
    self.raise_routing_exception(req)
    ~~~~~~~~~~~~~~~~~~~~~~~~~~~~^^^^^
  File "/Users/macbook/EverythingProgramming/inventory_management_system/majesty-backend/backend/lib/python3.13/site-packages/flask/app.py", line 453, in raise_routing_exception
    raise request.routing_exception  # type: ignore[misc]
    ^^^^^^^^^^^^^^^^^^^^^^^^^^^^^^^
  File "/Users/macbook/EverythingProgramming/inventory_management_system/majesty-backend/backend/lib/python3.13/site-packages/flask/ctx.py", line 362, in match_request
    result = self.url_adapter.match(return_rule=True)  # type: ignore
  File "/Users/macbook/EverythingProgramming/inventory_management_system/majesty-backend/backend/lib/python3.13/site-packages/werkzeug/routing/map.py", line 629, in match
    raise NotFound() from None
werkzeug.exceptions.NotFound: 404 Not Found: The requested URL was not found on the server. If you entered the URL manually please check your spelling and try again.
[2025-03-16 18:23:07,750] ERROR in logger: [EXCEPTION] User None: Unhandled exception: InternalServerError
[2025-03-16 18:54:08,723] INFO in logger: [CHECK_TOKEN_VALID] User 1: Token is valid | Affected: Token System
[2025-03-16 18:54:09,891] ERROR in logger: [EXCEPTION] User None: Unhandled exception: NotFound
[2025-03-16 18:54:09,904] ERROR in app: Exception on /wine/revenue [OPTIONS]
Traceback (most recent call last):
  File "/Users/macbook/EverythingProgramming/inventory_management_system/majesty-backend/backend/lib/python3.13/site-packages/flask/app.py", line 1463, in wsgi_app
    response = self.full_dispatch_request()
  File "/Users/macbook/EverythingProgramming/inventory_management_system/majesty-backend/backend/lib/python3.13/site-packages/flask/app.py", line 872, in full_dispatch_request
    rv = self.handle_user_exception(e)
  File "/Users/macbook/EverythingProgramming/inventory_management_system/majesty-backend/backend/lib/python3.13/site-packages/flask_cors/extension.py", line 176, in wrapped_function
    return cors_after_request(app.make_response(f(*args, **kwargs)))
                                                ~^^^^^^^^^^^^^^^^^
  File "/Users/macbook/EverythingProgramming/inventory_management_system/majesty-backend/backend/lib/python3.13/site-packages/flask/app.py", line 755, in handle_user_exception
    return self.handle_http_exception(e)
           ~~~~~~~~~~~~~~~~~~~~~~~~~~^^^
  File "/Users/macbook/EverythingProgramming/inventory_management_system/majesty-backend/backend/lib/python3.13/site-packages/flask/app.py", line 730, in handle_http_exception
    return self.ensure_sync(handler)(e)  # type: ignore[no-any-return]
           ~~~~~~~~~~~~~~~~~~~~~~~~~^^^
  File "/Users/macbook/EverythingProgramming/inventory_management_system/majesty-backend/app/utils/logger.py", line 194, in log_exception
    raise exception
  File "/Users/macbook/EverythingProgramming/inventory_management_system/majesty-backend/backend/lib/python3.13/site-packages/flask/app.py", line 870, in full_dispatch_request
    rv = self.dispatch_request()
  File "/Users/macbook/EverythingProgramming/inventory_management_system/majesty-backend/backend/lib/python3.13/site-packages/flask/app.py", line 844, in dispatch_request
    self.raise_routing_exception(req)
    ~~~~~~~~~~~~~~~~~~~~~~~~~~~~^^^^^
  File "/Users/macbook/EverythingProgramming/inventory_management_system/majesty-backend/backend/lib/python3.13/site-packages/flask/app.py", line 453, in raise_routing_exception
    raise request.routing_exception  # type: ignore[misc]
    ^^^^^^^^^^^^^^^^^^^^^^^^^^^^^^^
  File "/Users/macbook/EverythingProgramming/inventory_management_system/majesty-backend/backend/lib/python3.13/site-packages/flask/ctx.py", line 362, in match_request
    result = self.url_adapter.match(return_rule=True)  # type: ignore
  File "/Users/macbook/EverythingProgramming/inventory_management_system/majesty-backend/backend/lib/python3.13/site-packages/werkzeug/routing/map.py", line 629, in match
    raise NotFound() from None
werkzeug.exceptions.NotFound: 404 Not Found: The requested URL was not found on the server. If you entered the URL manually please check your spelling and try again.
[2025-03-16 18:54:09,909] ERROR in logger: [EXCEPTION] User None: Unhandled exception: NotFound
[2025-03-16 18:54:09,915] INFO in logger: [GET_TOTAL_STOCK] User 1: Total stock checked: 147 | Affected: Total Stock
[2025-03-16 18:54:09,915] INFO in logger: [GET_STOCK_BY_CATEGORY] User 1: Stock by category fetched successfully | Affected: Stock by Category
[2025-03-16 18:54:09,928] ERROR in logger: [EXCEPTION] User None: Unhandled exception: InternalServerError
[2025-03-16 18:54:09,944] ERROR in app: Exception on /wine/compare-sales [OPTIONS]
Traceback (most recent call last):
  File "/Users/macbook/EverythingProgramming/inventory_management_system/majesty-backend/backend/lib/python3.13/site-packages/flask/app.py", line 1463, in wsgi_app
    response = self.full_dispatch_request()
  File "/Users/macbook/EverythingProgramming/inventory_management_system/majesty-backend/backend/lib/python3.13/site-packages/flask/app.py", line 872, in full_dispatch_request
    rv = self.handle_user_exception(e)
  File "/Users/macbook/EverythingProgramming/inventory_management_system/majesty-backend/backend/lib/python3.13/site-packages/flask_cors/extension.py", line 176, in wrapped_function
    return cors_after_request(app.make_response(f(*args, **kwargs)))
                                                ~^^^^^^^^^^^^^^^^^
  File "/Users/macbook/EverythingProgramming/inventory_management_system/majesty-backend/backend/lib/python3.13/site-packages/flask/app.py", line 755, in handle_user_exception
    return self.handle_http_exception(e)
           ~~~~~~~~~~~~~~~~~~~~~~~~~~^^^
  File "/Users/macbook/EverythingProgramming/inventory_management_system/majesty-backend/backend/lib/python3.13/site-packages/flask/app.py", line 730, in handle_http_exception
    return self.ensure_sync(handler)(e)  # type: ignore[no-any-return]
           ~~~~~~~~~~~~~~~~~~~~~~~~~^^^
  File "/Users/macbook/EverythingProgramming/inventory_management_system/majesty-backend/app/utils/logger.py", line 194, in log_exception
    raise exception
  File "/Users/macbook/EverythingProgramming/inventory_management_system/majesty-backend/backend/lib/python3.13/site-packages/flask/app.py", line 870, in full_dispatch_request
    rv = self.dispatch_request()
  File "/Users/macbook/EverythingProgramming/inventory_management_system/majesty-backend/backend/lib/python3.13/site-packages/flask/app.py", line 844, in dispatch_request
    self.raise_routing_exception(req)
    ~~~~~~~~~~~~~~~~~~~~~~~~~~~~^^^^^
  File "/Users/macbook/EverythingProgramming/inventory_management_system/majesty-backend/backend/lib/python3.13/site-packages/flask/app.py", line 453, in raise_routing_exception
    raise request.routing_exception  # type: ignore[misc]
    ^^^^^^^^^^^^^^^^^^^^^^^^^^^^^^^
  File "/Users/macbook/EverythingProgramming/inventory_management_system/majesty-backend/backend/lib/python3.13/site-packages/flask/ctx.py", line 362, in match_request
    result = self.url_adapter.match(return_rule=True)  # type: ignore
  File "/Users/macbook/EverythingProgramming/inventory_management_system/majesty-backend/backend/lib/python3.13/site-packages/werkzeug/routing/map.py", line 629, in match
    raise NotFound() from None
werkzeug.exceptions.NotFound: 404 Not Found: The requested URL was not found on the server. If you entered the URL manually please check your spelling and try again.
[2025-03-16 18:54:09,955] ERROR in logger: [EXCEPTION] User None: Unhandled exception: InternalServerError
[2025-03-16 18:54:12,086] INFO in logger: [GET_USERS_SUCCESS] User 1: Admin retrieved user list | Affected: User Management
[2025-03-16 18:54:22,589] ERROR in logger: [EXCEPTION] User None: Unhandled exception: NotFound
[2025-03-16 18:54:22,594] ERROR in app: Exception on /users/4 [OPTIONS]
Traceback (most recent call last):
  File "/Users/macbook/EverythingProgramming/inventory_management_system/majesty-backend/backend/lib/python3.13/site-packages/flask/app.py", line 1463, in wsgi_app
    response = self.full_dispatch_request()
  File "/Users/macbook/EverythingProgramming/inventory_management_system/majesty-backend/backend/lib/python3.13/site-packages/flask/app.py", line 872, in full_dispatch_request
    rv = self.handle_user_exception(e)
  File "/Users/macbook/EverythingProgramming/inventory_management_system/majesty-backend/backend/lib/python3.13/site-packages/flask_cors/extension.py", line 176, in wrapped_function
    return cors_after_request(app.make_response(f(*args, **kwargs)))
                                                ~^^^^^^^^^^^^^^^^^
  File "/Users/macbook/EverythingProgramming/inventory_management_system/majesty-backend/backend/lib/python3.13/site-packages/flask/app.py", line 755, in handle_user_exception
    return self.handle_http_exception(e)
           ~~~~~~~~~~~~~~~~~~~~~~~~~~^^^
  File "/Users/macbook/EverythingProgramming/inventory_management_system/majesty-backend/backend/lib/python3.13/site-packages/flask/app.py", line 730, in handle_http_exception
    return self.ensure_sync(handler)(e)  # type: ignore[no-any-return]
           ~~~~~~~~~~~~~~~~~~~~~~~~~^^^
  File "/Users/macbook/EverythingProgramming/inventory_management_system/majesty-backend/app/utils/logger.py", line 194, in log_exception
    raise exception
  File "/Users/macbook/EverythingProgramming/inventory_management_system/majesty-backend/backend/lib/python3.13/site-packages/flask/app.py", line 870, in full_dispatch_request
    rv = self.dispatch_request()
  File "/Users/macbook/EverythingProgramming/inventory_management_system/majesty-backend/backend/lib/python3.13/site-packages/flask/app.py", line 844, in dispatch_request
    self.raise_routing_exception(req)
    ~~~~~~~~~~~~~~~~~~~~~~~~~~~~^^^^^
  File "/Users/macbook/EverythingProgramming/inventory_management_system/majesty-backend/backend/lib/python3.13/site-packages/flask/app.py", line 453, in raise_routing_exception
    raise request.routing_exception  # type: ignore[misc]
    ^^^^^^^^^^^^^^^^^^^^^^^^^^^^^^^
  File "/Users/macbook/EverythingProgramming/inventory_management_system/majesty-backend/backend/lib/python3.13/site-packages/flask/ctx.py", line 362, in match_request
    result = self.url_adapter.match(return_rule=True)  # type: ignore
  File "/Users/macbook/EverythingProgramming/inventory_management_system/majesty-backend/backend/lib/python3.13/site-packages/werkzeug/routing/map.py", line 629, in match
    raise NotFound() from None
werkzeug.exceptions.NotFound: 404 Not Found: The requested URL was not found on the server. If you entered the URL manually please check your spelling and try again.
[2025-03-16 18:54:22,599] ERROR in logger: [EXCEPTION] User None: Unhandled exception: InternalServerError
[2025-03-16 18:54:56,150] INFO in logger: [GET_ALL_WINES] User 1: Fetched all wines successfully | Affected: Wine Inventory
[2025-03-16 18:55:25,801] ERROR in logger: [EXCEPTION] User None: Unhandled exception: NotFound
[2025-03-16 18:55:25,815] ERROR in logger: [EXCEPTION] User None: Unhandled exception: NotFound
[2025-03-16 18:55:25,816] ERROR in app: Exception on /wine/revenue [OPTIONS]
Traceback (most recent call last):
  File "/Users/macbook/EverythingProgramming/inventory_management_system/majesty-backend/backend/lib/python3.13/site-packages/flask/app.py", line 1463, in wsgi_app
    response = self.full_dispatch_request()
  File "/Users/macbook/EverythingProgramming/inventory_management_system/majesty-backend/backend/lib/python3.13/site-packages/flask/app.py", line 872, in full_dispatch_request
    rv = self.handle_user_exception(e)
  File "/Users/macbook/EverythingProgramming/inventory_management_system/majesty-backend/backend/lib/python3.13/site-packages/flask_cors/extension.py", line 176, in wrapped_function
    return cors_after_request(app.make_response(f(*args, **kwargs)))
                                                ~^^^^^^^^^^^^^^^^^
  File "/Users/macbook/EverythingProgramming/inventory_management_system/majesty-backend/backend/lib/python3.13/site-packages/flask/app.py", line 755, in handle_user_exception
    return self.handle_http_exception(e)
           ~~~~~~~~~~~~~~~~~~~~~~~~~~^^^
  File "/Users/macbook/EverythingProgramming/inventory_management_system/majesty-backend/backend/lib/python3.13/site-packages/flask/app.py", line 730, in handle_http_exception
    return self.ensure_sync(handler)(e)  # type: ignore[no-any-return]
           ~~~~~~~~~~~~~~~~~~~~~~~~~^^^
  File "/Users/macbook/EverythingProgramming/inventory_management_system/majesty-backend/app/utils/logger.py", line 194, in log_exception
    raise exception
  File "/Users/macbook/EverythingProgramming/inventory_management_system/majesty-backend/backend/lib/python3.13/site-packages/flask/app.py", line 870, in full_dispatch_request
    rv = self.dispatch_request()
  File "/Users/macbook/EverythingProgramming/inventory_management_system/majesty-backend/backend/lib/python3.13/site-packages/flask/app.py", line 844, in dispatch_request
    self.raise_routing_exception(req)
    ~~~~~~~~~~~~~~~~~~~~~~~~~~~~^^^^^
  File "/Users/macbook/EverythingProgramming/inventory_management_system/majesty-backend/backend/lib/python3.13/site-packages/flask/app.py", line 453, in raise_routing_exception
    raise request.routing_exception  # type: ignore[misc]
    ^^^^^^^^^^^^^^^^^^^^^^^^^^^^^^^
  File "/Users/macbook/EverythingProgramming/inventory_management_system/majesty-backend/backend/lib/python3.13/site-packages/flask/ctx.py", line 362, in match_request
    result = self.url_adapter.match(return_rule=True)  # type: ignore
  File "/Users/macbook/EverythingProgramming/inventory_management_system/majesty-backend/backend/lib/python3.13/site-packages/werkzeug/routing/map.py", line 629, in match
    raise NotFound() from None
werkzeug.exceptions.NotFound: 404 Not Found: The requested URL was not found on the server. If you entered the URL manually please check your spelling and try again.
[2025-03-16 18:55:25,823] INFO in logger: [GET_TOTAL_STOCK] User 1: Total stock checked: 147 | Affected: Total Stock
[2025-03-16 18:55:25,823] INFO in logger: [GET_STOCK_BY_CATEGORY] User 1: Stock by category fetched successfully | Affected: Stock by Category
[2025-03-16 18:55:25,826] ERROR in app: Exception on /wine/compare-sales [OPTIONS]
Traceback (most recent call last):
  File "/Users/macbook/EverythingProgramming/inventory_management_system/majesty-backend/backend/lib/python3.13/site-packages/flask/app.py", line 1463, in wsgi_app
    response = self.full_dispatch_request()
  File "/Users/macbook/EverythingProgramming/inventory_management_system/majesty-backend/backend/lib/python3.13/site-packages/flask/app.py", line 872, in full_dispatch_request
    rv = self.handle_user_exception(e)
  File "/Users/macbook/EverythingProgramming/inventory_management_system/majesty-backend/backend/lib/python3.13/site-packages/flask_cors/extension.py", line 176, in wrapped_function
    return cors_after_request(app.make_response(f(*args, **kwargs)))
                                                ~^^^^^^^^^^^^^^^^^
  File "/Users/macbook/EverythingProgramming/inventory_management_system/majesty-backend/backend/lib/python3.13/site-packages/flask/app.py", line 755, in handle_user_exception
    return self.handle_http_exception(e)
           ~~~~~~~~~~~~~~~~~~~~~~~~~~^^^
  File "/Users/macbook/EverythingProgramming/inventory_management_system/majesty-backend/backend/lib/python3.13/site-packages/flask/app.py", line 730, in handle_http_exception
    return self.ensure_sync(handler)(e)  # type: ignore[no-any-return]
           ~~~~~~~~~~~~~~~~~~~~~~~~~^^^
  File "/Users/macbook/EverythingProgramming/inventory_management_system/majesty-backend/app/utils/logger.py", line 194, in log_exception
    raise exception
  File "/Users/macbook/EverythingProgramming/inventory_management_system/majesty-backend/backend/lib/python3.13/site-packages/flask/app.py", line 870, in full_dispatch_request
    rv = self.dispatch_request()
  File "/Users/macbook/EverythingProgramming/inventory_management_system/majesty-backend/backend/lib/python3.13/site-packages/flask/app.py", line 844, in dispatch_request
    self.raise_routing_exception(req)
    ~~~~~~~~~~~~~~~~~~~~~~~~~~~~^^^^^
  File "/Users/macbook/EverythingProgramming/inventory_management_system/majesty-backend/backend/lib/python3.13/site-packages/flask/app.py", line 453, in raise_routing_exception
    raise request.routing_exception  # type: ignore[misc]
    ^^^^^^^^^^^^^^^^^^^^^^^^^^^^^^^
  File "/Users/macbook/EverythingProgramming/inventory_management_system/majesty-backend/backend/lib/python3.13/site-packages/flask/ctx.py", line 362, in match_request
    result = self.url_adapter.match(return_rule=True)  # type: ignore
  File "/Users/macbook/EverythingProgramming/inventory_management_system/majesty-backend/backend/lib/python3.13/site-packages/werkzeug/routing/map.py", line 629, in match
    raise NotFound() from None
werkzeug.exceptions.NotFound: 404 Not Found: The requested URL was not found on the server. If you entered the URL manually please check your spelling and try again.
[2025-03-16 18:55:25,833] ERROR in logger: [EXCEPTION] User None: Unhandled exception: InternalServerError
[2025-03-16 18:55:25,837] ERROR in logger: [EXCEPTION] User None: Unhandled exception: InternalServerError
[2025-03-16 18:56:10,305] ERROR in logger: [EXCEPTION] User None: Unhandled exception: NotFound
[2025-03-16 18:56:10,314] ERROR in app: Exception on /wine/compare-sales [OPTIONS]
Traceback (most recent call last):
  File "/Users/macbook/EverythingProgramming/inventory_management_system/majesty-backend/backend/lib/python3.13/site-packages/flask/app.py", line 1463, in wsgi_app
    response = self.full_dispatch_request()
  File "/Users/macbook/EverythingProgramming/inventory_management_system/majesty-backend/backend/lib/python3.13/site-packages/flask/app.py", line 872, in full_dispatch_request
    rv = self.handle_user_exception(e)
  File "/Users/macbook/EverythingProgramming/inventory_management_system/majesty-backend/backend/lib/python3.13/site-packages/flask_cors/extension.py", line 176, in wrapped_function
    return cors_after_request(app.make_response(f(*args, **kwargs)))
                                                ~^^^^^^^^^^^^^^^^^
  File "/Users/macbook/EverythingProgramming/inventory_management_system/majesty-backend/backend/lib/python3.13/site-packages/flask/app.py", line 755, in handle_user_exception
    return self.handle_http_exception(e)
           ~~~~~~~~~~~~~~~~~~~~~~~~~~^^^
  File "/Users/macbook/EverythingProgramming/inventory_management_system/majesty-backend/backend/lib/python3.13/site-packages/flask/app.py", line 730, in handle_http_exception
    return self.ensure_sync(handler)(e)  # type: ignore[no-any-return]
           ~~~~~~~~~~~~~~~~~~~~~~~~~^^^
  File "/Users/macbook/EverythingProgramming/inventory_management_system/majesty-backend/app/utils/logger.py", line 194, in log_exception
    raise exception
  File "/Users/macbook/EverythingProgramming/inventory_management_system/majesty-backend/backend/lib/python3.13/site-packages/flask/app.py", line 870, in full_dispatch_request
    rv = self.dispatch_request()
  File "/Users/macbook/EverythingProgramming/inventory_management_system/majesty-backend/backend/lib/python3.13/site-packages/flask/app.py", line 844, in dispatch_request
    self.raise_routing_exception(req)
    ~~~~~~~~~~~~~~~~~~~~~~~~~~~~^^^^^
  File "/Users/macbook/EverythingProgramming/inventory_management_system/majesty-backend/backend/lib/python3.13/site-packages/flask/app.py", line 453, in raise_routing_exception
    raise request.routing_exception  # type: ignore[misc]
    ^^^^^^^^^^^^^^^^^^^^^^^^^^^^^^^
  File "/Users/macbook/EverythingProgramming/inventory_management_system/majesty-backend/backend/lib/python3.13/site-packages/flask/ctx.py", line 362, in match_request
    result = self.url_adapter.match(return_rule=True)  # type: ignore
  File "/Users/macbook/EverythingProgramming/inventory_management_system/majesty-backend/backend/lib/python3.13/site-packages/werkzeug/routing/map.py", line 629, in match
    raise NotFound() from None
werkzeug.exceptions.NotFound: 404 Not Found: The requested URL was not found on the server. If you entered the URL manually please check your spelling and try again.
[2025-03-16 18:56:10,321] ERROR in logger: [EXCEPTION] User None: Unhandled exception: InternalServerError
[2025-03-16 18:56:14,419] ERROR in logger: [EXCEPTION] User None: Unhandled exception: NotFound
[2025-03-16 18:56:14,422] ERROR in app: Exception on /wine/compare-sales [OPTIONS]
Traceback (most recent call last):
  File "/Users/macbook/EverythingProgramming/inventory_management_system/majesty-backend/backend/lib/python3.13/site-packages/flask/app.py", line 1463, in wsgi_app
    response = self.full_dispatch_request()
  File "/Users/macbook/EverythingProgramming/inventory_management_system/majesty-backend/backend/lib/python3.13/site-packages/flask/app.py", line 872, in full_dispatch_request
    rv = self.handle_user_exception(e)
  File "/Users/macbook/EverythingProgramming/inventory_management_system/majesty-backend/backend/lib/python3.13/site-packages/flask_cors/extension.py", line 176, in wrapped_function
    return cors_after_request(app.make_response(f(*args, **kwargs)))
                                                ~^^^^^^^^^^^^^^^^^
  File "/Users/macbook/EverythingProgramming/inventory_management_system/majesty-backend/backend/lib/python3.13/site-packages/flask/app.py", line 755, in handle_user_exception
    return self.handle_http_exception(e)
           ~~~~~~~~~~~~~~~~~~~~~~~~~~^^^
  File "/Users/macbook/EverythingProgramming/inventory_management_system/majesty-backend/backend/lib/python3.13/site-packages/flask/app.py", line 730, in handle_http_exception
    return self.ensure_sync(handler)(e)  # type: ignore[no-any-return]
           ~~~~~~~~~~~~~~~~~~~~~~~~~^^^
  File "/Users/macbook/EverythingProgramming/inventory_management_system/majesty-backend/app/utils/logger.py", line 194, in log_exception
    raise exception
  File "/Users/macbook/EverythingProgramming/inventory_management_system/majesty-backend/backend/lib/python3.13/site-packages/flask/app.py", line 870, in full_dispatch_request
    rv = self.dispatch_request()
  File "/Users/macbook/EverythingProgramming/inventory_management_system/majesty-backend/backend/lib/python3.13/site-packages/flask/app.py", line 844, in dispatch_request
    self.raise_routing_exception(req)
    ~~~~~~~~~~~~~~~~~~~~~~~~~~~~^^^^^
  File "/Users/macbook/EverythingProgramming/inventory_management_system/majesty-backend/backend/lib/python3.13/site-packages/flask/app.py", line 453, in raise_routing_exception
    raise request.routing_exception  # type: ignore[misc]
    ^^^^^^^^^^^^^^^^^^^^^^^^^^^^^^^
  File "/Users/macbook/EverythingProgramming/inventory_management_system/majesty-backend/backend/lib/python3.13/site-packages/flask/ctx.py", line 362, in match_request
    result = self.url_adapter.match(return_rule=True)  # type: ignore
  File "/Users/macbook/EverythingProgramming/inventory_management_system/majesty-backend/backend/lib/python3.13/site-packages/werkzeug/routing/map.py", line 629, in match
    raise NotFound() from None
werkzeug.exceptions.NotFound: 404 Not Found: The requested URL was not found on the server. If you entered the URL manually please check your spelling and try again.
[2025-03-16 18:56:14,426] ERROR in logger: [EXCEPTION] User None: Unhandled exception: InternalServerError
[2025-03-16 19:03:31,172] INFO in logger: [CHECK_TOKEN_VALID] User 1: Token is valid | Affected: Token System
[2025-03-16 19:03:31,298] ERROR in logger: [EXCEPTION] User None: Unhandled exception: NotFound
[2025-03-16 19:03:31,446] ERROR in logger: [EXCEPTION] User None: Unhandled exception: NotFound
[2025-03-16 19:03:31,451] INFO in logger: [GET_STOCK_BY_CATEGORY] User 1: Stock by category fetched successfully | Affected: Stock by Category
[2025-03-16 19:03:31,456] ERROR in app: Exception on /wine/revenue [OPTIONS]
Traceback (most recent call last):
  File "/Users/macbook/EverythingProgramming/inventory_management_system/majesty-backend/backend/lib/python3.13/site-packages/flask/app.py", line 1463, in wsgi_app
    response = self.full_dispatch_request()
  File "/Users/macbook/EverythingProgramming/inventory_management_system/majesty-backend/backend/lib/python3.13/site-packages/flask/app.py", line 872, in full_dispatch_request
    rv = self.handle_user_exception(e)
  File "/Users/macbook/EverythingProgramming/inventory_management_system/majesty-backend/backend/lib/python3.13/site-packages/flask_cors/extension.py", line 176, in wrapped_function
    return cors_after_request(app.make_response(f(*args, **kwargs)))
                                                ~^^^^^^^^^^^^^^^^^
  File "/Users/macbook/EverythingProgramming/inventory_management_system/majesty-backend/backend/lib/python3.13/site-packages/flask/app.py", line 755, in handle_user_exception
    return self.handle_http_exception(e)
           ~~~~~~~~~~~~~~~~~~~~~~~~~~^^^
  File "/Users/macbook/EverythingProgramming/inventory_management_system/majesty-backend/backend/lib/python3.13/site-packages/flask/app.py", line 730, in handle_http_exception
    return self.ensure_sync(handler)(e)  # type: ignore[no-any-return]
           ~~~~~~~~~~~~~~~~~~~~~~~~~^^^
  File "/Users/macbook/EverythingProgramming/inventory_management_system/majesty-backend/app/utils/logger.py", line 194, in log_exception
    raise exception
  File "/Users/macbook/EverythingProgramming/inventory_management_system/majesty-backend/backend/lib/python3.13/site-packages/flask/app.py", line 870, in full_dispatch_request
    rv = self.dispatch_request()
  File "/Users/macbook/EverythingProgramming/inventory_management_system/majesty-backend/backend/lib/python3.13/site-packages/flask/app.py", line 844, in dispatch_request
    self.raise_routing_exception(req)
    ~~~~~~~~~~~~~~~~~~~~~~~~~~~~^^^^^
  File "/Users/macbook/EverythingProgramming/inventory_management_system/majesty-backend/backend/lib/python3.13/site-packages/flask/app.py", line 453, in raise_routing_exception
    raise request.routing_exception  # type: ignore[misc]
    ^^^^^^^^^^^^^^^^^^^^^^^^^^^^^^^
  File "/Users/macbook/EverythingProgramming/inventory_management_system/majesty-backend/backend/lib/python3.13/site-packages/flask/ctx.py", line 362, in match_request
    result = self.url_adapter.match(return_rule=True)  # type: ignore
  File "/Users/macbook/EverythingProgramming/inventory_management_system/majesty-backend/backend/lib/python3.13/site-packages/werkzeug/routing/map.py", line 629, in match
    raise NotFound() from None
werkzeug.exceptions.NotFound: 404 Not Found: The requested URL was not found on the server. If you entered the URL manually please check your spelling and try again.
[2025-03-16 19:03:31,469] INFO in logger: [GET_TOTAL_STOCK] User 1: Total stock checked: 147 | Affected: Total Stock
[2025-03-16 19:03:31,473] ERROR in logger: [EXCEPTION] User None: Unhandled exception: InternalServerError
[2025-03-16 19:03:31,474] ERROR in app: Exception on /wine/compare-sales [OPTIONS]
Traceback (most recent call last):
  File "/Users/macbook/EverythingProgramming/inventory_management_system/majesty-backend/backend/lib/python3.13/site-packages/flask/app.py", line 1463, in wsgi_app
    response = self.full_dispatch_request()
  File "/Users/macbook/EverythingProgramming/inventory_management_system/majesty-backend/backend/lib/python3.13/site-packages/flask/app.py", line 872, in full_dispatch_request
    rv = self.handle_user_exception(e)
  File "/Users/macbook/EverythingProgramming/inventory_management_system/majesty-backend/backend/lib/python3.13/site-packages/flask_cors/extension.py", line 176, in wrapped_function
    return cors_after_request(app.make_response(f(*args, **kwargs)))
                                                ~^^^^^^^^^^^^^^^^^
  File "/Users/macbook/EverythingProgramming/inventory_management_system/majesty-backend/backend/lib/python3.13/site-packages/flask/app.py", line 755, in handle_user_exception
    return self.handle_http_exception(e)
           ~~~~~~~~~~~~~~~~~~~~~~~~~~^^^
  File "/Users/macbook/EverythingProgramming/inventory_management_system/majesty-backend/backend/lib/python3.13/site-packages/flask/app.py", line 730, in handle_http_exception
    return self.ensure_sync(handler)(e)  # type: ignore[no-any-return]
           ~~~~~~~~~~~~~~~~~~~~~~~~~^^^
  File "/Users/macbook/EverythingProgramming/inventory_management_system/majesty-backend/app/utils/logger.py", line 194, in log_exception
    raise exception
  File "/Users/macbook/EverythingProgramming/inventory_management_system/majesty-backend/backend/lib/python3.13/site-packages/flask/app.py", line 870, in full_dispatch_request
    rv = self.dispatch_request()
  File "/Users/macbook/EverythingProgramming/inventory_management_system/majesty-backend/backend/lib/python3.13/site-packages/flask/app.py", line 844, in dispatch_request
    self.raise_routing_exception(req)
    ~~~~~~~~~~~~~~~~~~~~~~~~~~~~^^^^^
  File "/Users/macbook/EverythingProgramming/inventory_management_system/majesty-backend/backend/lib/python3.13/site-packages/flask/app.py", line 453, in raise_routing_exception
    raise request.routing_exception  # type: ignore[misc]
    ^^^^^^^^^^^^^^^^^^^^^^^^^^^^^^^
  File "/Users/macbook/EverythingProgramming/inventory_management_system/majesty-backend/backend/lib/python3.13/site-packages/flask/ctx.py", line 362, in match_request
    result = self.url_adapter.match(return_rule=True)  # type: ignore
  File "/Users/macbook/EverythingProgramming/inventory_management_system/majesty-backend/backend/lib/python3.13/site-packages/werkzeug/routing/map.py", line 629, in match
    raise NotFound() from None
werkzeug.exceptions.NotFound: 404 Not Found: The requested URL was not found on the server. If you entered the URL manually please check your spelling and try again.
[2025-03-16 19:03:31,488] ERROR in logger: [EXCEPTION] User None: Unhandled exception: InternalServerError
[2025-03-16 19:03:43,260] INFO in logger: [GET_ALL_WINES] User 1: Fetched all wines successfully | Affected: Wine Inventory
[2025-03-16 19:08:10,180] INFO in logger: [GET_USERS_SUCCESS] User 1: Admin retrieved user list | Affected: User Management
[2025-03-16 19:08:19,159] ERROR in logger: [EXCEPTION] User None: Unhandled exception: NotFound
[2025-03-16 19:08:19,162] ERROR in app: Exception on /users/4 [OPTIONS]
Traceback (most recent call last):
  File "/Users/macbook/EverythingProgramming/inventory_management_system/majesty-backend/backend/lib/python3.13/site-packages/flask/app.py", line 1463, in wsgi_app
    response = self.full_dispatch_request()
  File "/Users/macbook/EverythingProgramming/inventory_management_system/majesty-backend/backend/lib/python3.13/site-packages/flask/app.py", line 872, in full_dispatch_request
    rv = self.handle_user_exception(e)
  File "/Users/macbook/EverythingProgramming/inventory_management_system/majesty-backend/backend/lib/python3.13/site-packages/flask_cors/extension.py", line 176, in wrapped_function
    return cors_after_request(app.make_response(f(*args, **kwargs)))
                                                ~^^^^^^^^^^^^^^^^^
  File "/Users/macbook/EverythingProgramming/inventory_management_system/majesty-backend/backend/lib/python3.13/site-packages/flask/app.py", line 755, in handle_user_exception
    return self.handle_http_exception(e)
           ~~~~~~~~~~~~~~~~~~~~~~~~~~^^^
  File "/Users/macbook/EverythingProgramming/inventory_management_system/majesty-backend/backend/lib/python3.13/site-packages/flask/app.py", line 730, in handle_http_exception
    return self.ensure_sync(handler)(e)  # type: ignore[no-any-return]
           ~~~~~~~~~~~~~~~~~~~~~~~~~^^^
  File "/Users/macbook/EverythingProgramming/inventory_management_system/majesty-backend/app/utils/logger.py", line 194, in log_exception
    raise exception
  File "/Users/macbook/EverythingProgramming/inventory_management_system/majesty-backend/backend/lib/python3.13/site-packages/flask/app.py", line 870, in full_dispatch_request
    rv = self.dispatch_request()
  File "/Users/macbook/EverythingProgramming/inventory_management_system/majesty-backend/backend/lib/python3.13/site-packages/flask/app.py", line 844, in dispatch_request
    self.raise_routing_exception(req)
    ~~~~~~~~~~~~~~~~~~~~~~~~~~~~^^^^^
  File "/Users/macbook/EverythingProgramming/inventory_management_system/majesty-backend/backend/lib/python3.13/site-packages/flask/app.py", line 453, in raise_routing_exception
    raise request.routing_exception  # type: ignore[misc]
    ^^^^^^^^^^^^^^^^^^^^^^^^^^^^^^^
  File "/Users/macbook/EverythingProgramming/inventory_management_system/majesty-backend/backend/lib/python3.13/site-packages/flask/ctx.py", line 362, in match_request
    result = self.url_adapter.match(return_rule=True)  # type: ignore
  File "/Users/macbook/EverythingProgramming/inventory_management_system/majesty-backend/backend/lib/python3.13/site-packages/werkzeug/routing/map.py", line 629, in match
    raise NotFound() from None
werkzeug.exceptions.NotFound: 404 Not Found: The requested URL was not found on the server. If you entered the URL manually please check your spelling and try again.
[2025-03-16 19:08:19,168] ERROR in logger: [EXCEPTION] User None: Unhandled exception: InternalServerError
[2025-03-16 22:34:17,386] INFO in logger: Wine Inventory API Started - Environment: development
[2025-03-16 22:35:23,541] INFO in logger: [LOGIN_SUCCESS] User 1: User logged in successfully | Affected: admin
[2025-03-16 22:41:04,112] ERROR in logger: [EXCEPTION] User None: Unhandled exception: NotFound
[2025-03-16 22:41:04,117] ERROR in app: Exception on /users/4 [GET]
=======
[2025-03-17 08:54:22,673] INFO in logger: Wine Inventory API Started - Environment: development
[2025-03-17 08:55:59,522] INFO in logger: [LOGIN_SUCCESS] User 1: User logged in successfully | Affected: admin
[2025-03-17 08:56:26,454] INFO in logger: [GET_INVENTORY_VALUE] User 1: Inventory value fetched | Affected: Inventory Value by Category
[2025-03-17 09:37:18,589] ERROR in logger: [EXCEPTION] User None: Unhandled exception: NotFound
[2025-03-17 09:37:18,608] ERROR in app: Exception on /wine/top_wines [GET]
>>>>>>> 820885401de541d70c94d614081eca1acca6416a
Traceback (most recent call last):
  File "/Users/macbookpro/Documents/projects/WSS/venv/lib/python3.11/site-packages/flask/app.py", line 1463, in wsgi_app
    response = self.full_dispatch_request()
               ^^^^^^^^^^^^^^^^^^^^^^^^^^^^
  File "/Users/macbookpro/Documents/projects/WSS/venv/lib/python3.11/site-packages/flask/app.py", line 872, in full_dispatch_request
    rv = self.handle_user_exception(e)
         ^^^^^^^^^^^^^^^^^^^^^^^^^^^^^
  File "/Users/macbookpro/Documents/projects/WSS/venv/lib/python3.11/site-packages/flask_cors/extension.py", line 176, in wrapped_function
    return cors_after_request(app.make_response(f(*args, **kwargs)))
                                                ^^^^^^^^^^^^^^^^^^
  File "/Users/macbookpro/Documents/projects/WSS/venv/lib/python3.11/site-packages/flask_cors/extension.py", line 176, in wrapped_function
    return cors_after_request(app.make_response(f(*args, **kwargs)))
                                                ^^^^^^^^^^^^^^^^^^
  File "/Users/macbookpro/Documents/projects/WSS/venv/lib/python3.11/site-packages/flask/app.py", line 755, in handle_user_exception
    return self.handle_http_exception(e)
           ^^^^^^^^^^^^^^^^^^^^^^^^^^^^^
  File "/Users/macbookpro/Documents/projects/WSS/venv/lib/python3.11/site-packages/flask/app.py", line 730, in handle_http_exception
    return self.ensure_sync(handler)(e)  # type: ignore[no-any-return]
           ^^^^^^^^^^^^^^^^^^^^^^^^^^^^
  File "/Users/macbookpro/Documents/projects/WSS/majesty-backend/app/utils/logger.py", line 194, in log_exception
    raise exception
  File "/Users/macbookpro/Documents/projects/WSS/venv/lib/python3.11/site-packages/flask/app.py", line 870, in full_dispatch_request
    rv = self.dispatch_request()
         ^^^^^^^^^^^^^^^^^^^^^^^
  File "/Users/macbookpro/Documents/projects/WSS/venv/lib/python3.11/site-packages/flask/app.py", line 844, in dispatch_request
    self.raise_routing_exception(req)
  File "/Users/macbookpro/Documents/projects/WSS/venv/lib/python3.11/site-packages/flask/app.py", line 453, in raise_routing_exception
    raise request.routing_exception  # type: ignore[misc]
    ^^^^^^^^^^^^^^^^^^^^^^^^^^^^^^^
  File "/Users/macbookpro/Documents/projects/WSS/venv/lib/python3.11/site-packages/flask/ctx.py", line 362, in match_request
    result = self.url_adapter.match(return_rule=True)  # type: ignore
             ^^^^^^^^^^^^^^^^^^^^^^^^^^^^^^^^^^^^^^^^
  File "/Users/macbookpro/Documents/projects/WSS/venv/lib/python3.11/site-packages/werkzeug/routing/map.py", line 629, in match
    raise NotFound() from None
werkzeug.exceptions.NotFound: 404 Not Found: The requested URL was not found on the server. If you entered the URL manually please check your spelling and try again.
[2025-03-17 09:37:18,614] ERROR in logger: [EXCEPTION] User None: Unhandled exception: InternalServerError
[2025-03-17 09:38:14,116] INFO in logger: Wine Inventory API Started - Environment: development
[2025-03-17 13:41:09,229] INFO in logger: Wine Inventory API Started - Environment: development
[2025-03-17 14:04:14,714] INFO in logger: [LOGIN_SUCCESS] User 1: User logged in successfully | Affected: admin
[2025-03-17 14:05:55,495] INFO in logger: [LOGOUT] User 1: User logged out | Affected: admin
[2025-03-17 14:38:51,571] INFO in logger: Wine Inventory API Started - Environment: development
[2025-03-17 14:40:02,945] INFO in logger: Wine Inventory API Started - Environment: development
[2025-03-17 14:40:36,799] INFO in logger: Wine Inventory API Started - Environment: development
[2025-03-17 14:40:50,379] INFO in logger: Wine Inventory API Started - Environment: development
[2025-03-17 14:42:54,138] INFO in logger: Wine Inventory API Started - Environment: development
[2025-03-17 14:43:17,798] INFO in logger: Wine Inventory API Started - Environment: development
[2025-03-17 14:43:36,397] INFO in logger: [LOGIN_SUCCESS] User 1: User logged in successfully | Affected: admin
[2025-03-17 14:44:49,021] ERROR in logger: [EXCEPTION] User None: Unhandled exception: ImportError
[2025-03-17 14:44:49,025] ERROR in app: Exception on /logs/logs [GET]
Traceback (most recent call last):
  File "/Users/macbookpro/Documents/projects/WSS/venv/lib/python3.11/site-packages/flask/app.py", line 1463, in wsgi_app
    response = self.full_dispatch_request()
               ^^^^^^^^^^^^^^^^^^^^^^^^^^^^
  File "/Users/macbookpro/Documents/projects/WSS/venv/lib/python3.11/site-packages/flask/app.py", line 872, in full_dispatch_request
    rv = self.handle_user_exception(e)
         ^^^^^^^^^^^^^^^^^^^^^^^^^^^^^
  File "/Users/macbookpro/Documents/projects/WSS/venv/lib/python3.11/site-packages/flask_cors/extension.py", line 176, in wrapped_function
    return cors_after_request(app.make_response(f(*args, **kwargs)))
                                                ^^^^^^^^^^^^^^^^^^
  File "/Users/macbookpro/Documents/projects/WSS/venv/lib/python3.11/site-packages/flask_cors/extension.py", line 176, in wrapped_function
    return cors_after_request(app.make_response(f(*args, **kwargs)))
                                                ^^^^^^^^^^^^^^^^^^
  File "/Users/macbookpro/Documents/projects/WSS/venv/lib/python3.11/site-packages/flask/app.py", line 762, in handle_user_exception
    return self.ensure_sync(handler)(e)  # type: ignore[no-any-return]
           ^^^^^^^^^^^^^^^^^^^^^^^^^^^^
  File "/Users/macbookpro/Documents/projects/WSS/majesty-backend/app/utils/logger.py", line 194, in log_exception
    raise exception
  File "/Users/macbookpro/Documents/projects/WSS/venv/lib/python3.11/site-packages/flask/app.py", line 870, in full_dispatch_request
    rv = self.dispatch_request()
         ^^^^^^^^^^^^^^^^^^^^^^^
  File "/Users/macbookpro/Documents/projects/WSS/venv/lib/python3.11/site-packages/flask/app.py", line 855, in dispatch_request
    return self.ensure_sync(self.view_functions[rule.endpoint])(**view_args)  # type: ignore[no-any-return]
           ^^^^^^^^^^^^^^^^^^^^^^^^^^^^^^^^^^^^^^^^^^^^^^^^^^^^^^^^^^^^^^^^^
  File "/Users/macbookpro/Documents/projects/WSS/majesty-backend/app/utils/decorators.py", line 25, in decorated
    if is_token_blacklisted(token):
       ^^^^^^^^^^^^^^^^^^^^^^^^^^^
  File "/Users/macbookpro/Documents/projects/WSS/majesty-backend/app/utils/decorators.py", line 10, in is_token_blacklisted
    from app.models import BlacklistedToken
ImportError: cannot import name 'BlacklistedToken' from 'app.models' (/Users/macbookpro/Documents/projects/WSS/majesty-backend/app/models/__init__.py)
[2025-03-17 14:44:49,030] ERROR in logger: [EXCEPTION] User None: Unhandled exception: InternalServerError
[2025-03-17 14:45:42,150] INFO in logger: Wine Inventory API Started - Environment: development
[2025-03-17 14:46:15,967] INFO in logger: [LOGIN_SUCCESS] User 1: User logged in successfully | Affected: admin
[2025-03-17 14:46:34,251] ERROR in logger: [EXCEPTION] User None: Unhandled exception: InvalidRequestError
[2025-03-17 14:46:34,253] ERROR in app: Exception on /logs/logs [GET]
Traceback (most recent call last):
  File "/Users/macbookpro/Documents/projects/WSS/venv/lib/python3.11/site-packages/sqlalchemy/sql/base.py", line 2178, in _entity_namespace_key
    return getattr(ns, key)  # type: ignore
           ^^^^^^^^^^^^^^^^
AttributeError: type object 'BlacklistedToken' has no attribute 'token'

The above exception was the direct cause of the following exception:

Traceback (most recent call last):
  File "/Users/macbookpro/Documents/projects/WSS/venv/lib/python3.11/site-packages/flask/app.py", line 1463, in wsgi_app
    response = self.full_dispatch_request()
               ^^^^^^^^^^^^^^^^^^^^^^^^^^^^
  File "/Users/macbookpro/Documents/projects/WSS/venv/lib/python3.11/site-packages/flask/app.py", line 872, in full_dispatch_request
    rv = self.handle_user_exception(e)
         ^^^^^^^^^^^^^^^^^^^^^^^^^^^^^
  File "/Users/macbookpro/Documents/projects/WSS/venv/lib/python3.11/site-packages/flask_cors/extension.py", line 176, in wrapped_function
    return cors_after_request(app.make_response(f(*args, **kwargs)))
                                                ^^^^^^^^^^^^^^^^^^
  File "/Users/macbookpro/Documents/projects/WSS/venv/lib/python3.11/site-packages/flask_cors/extension.py", line 176, in wrapped_function
    return cors_after_request(app.make_response(f(*args, **kwargs)))
                                                ^^^^^^^^^^^^^^^^^^
  File "/Users/macbookpro/Documents/projects/WSS/venv/lib/python3.11/site-packages/flask/app.py", line 762, in handle_user_exception
    return self.ensure_sync(handler)(e)  # type: ignore[no-any-return]
           ^^^^^^^^^^^^^^^^^^^^^^^^^^^^
  File "/Users/macbookpro/Documents/projects/WSS/majesty-backend/app/utils/logger.py", line 194, in log_exception
    raise exception
  File "/Users/macbookpro/Documents/projects/WSS/venv/lib/python3.11/site-packages/flask/app.py", line 870, in full_dispatch_request
    rv = self.dispatch_request()
         ^^^^^^^^^^^^^^^^^^^^^^^
  File "/Users/macbookpro/Documents/projects/WSS/venv/lib/python3.11/site-packages/flask/app.py", line 855, in dispatch_request
    return self.ensure_sync(self.view_functions[rule.endpoint])(**view_args)  # type: ignore[no-any-return]
           ^^^^^^^^^^^^^^^^^^^^^^^^^^^^^^^^^^^^^^^^^^^^^^^^^^^^^^^^^^^^^^^^^
  File "/Users/macbookpro/Documents/projects/WSS/majesty-backend/app/utils/decorators.py", line 25, in decorated
    if is_token_blacklisted(token):
       ^^^^^^^^^^^^^^^^^^^^^^^^^^^
  File "/Users/macbookpro/Documents/projects/WSS/majesty-backend/app/utils/decorators.py", line 12, in is_token_blacklisted
    blacklisted = BlacklistedToken.query.filter_by(token=token).first()
                  ^^^^^^^^^^^^^^^^^^^^^^^^^^^^^^^^^^^^^^^^^^^^^
  File "/Users/macbookpro/Documents/projects/WSS/venv/lib/python3.11/site-packages/sqlalchemy/orm/query.py", line 1986, in filter_by
    clauses = [
              ^
  File "/Users/macbookpro/Documents/projects/WSS/venv/lib/python3.11/site-packages/sqlalchemy/orm/query.py", line 1987, in <listcomp>
    _entity_namespace_key(from_entity, key) == value
    ^^^^^^^^^^^^^^^^^^^^^^^^^^^^^^^^^^^^^^^
  File "/Users/macbookpro/Documents/projects/WSS/venv/lib/python3.11/site-packages/sqlalchemy/sql/base.py", line 2180, in _entity_namespace_key
    raise exc.InvalidRequestError(
sqlalchemy.exc.InvalidRequestError: Entity namespace for "blacklisted_tokens" has no property "token"
[2025-03-17 14:46:34,257] ERROR in logger: [EXCEPTION] User None: Unhandled exception: InternalServerError
[2025-03-17 15:06:17,119] INFO in logger: Wine Inventory API Started - Environment: development
[2025-03-17 15:06:27,364] INFO in logger: [LOGIN_SUCCESS] User 1: User logged in successfully | Affected: admin
[2025-03-17 15:07:03,515] ERROR in logger: [EXCEPTION] User None: Unhandled exception: OperationalError
[2025-03-17 15:07:03,520] ERROR in app: Exception on /logs/logs [GET]
Traceback (most recent call last):
  File "/Users/macbookpro/Documents/projects/WSS/venv/lib/python3.11/site-packages/sqlalchemy/engine/base.py", line 1964, in _exec_single_context
    self.dialect.do_execute(
  File "/Users/macbookpro/Documents/projects/WSS/venv/lib/python3.11/site-packages/sqlalchemy/engine/default.py", line 942, in do_execute
    cursor.execute(statement, parameters)
sqlite3.OperationalError: no such column: blacklisted_tokens.token

The above exception was the direct cause of the following exception:

Traceback (most recent call last):
  File "/Users/macbookpro/Documents/projects/WSS/venv/lib/python3.11/site-packages/flask/app.py", line 1463, in wsgi_app
    response = self.full_dispatch_request()
               ^^^^^^^^^^^^^^^^^^^^^^^^^^^^
  File "/Users/macbookpro/Documents/projects/WSS/venv/lib/python3.11/site-packages/flask/app.py", line 872, in full_dispatch_request
    rv = self.handle_user_exception(e)
         ^^^^^^^^^^^^^^^^^^^^^^^^^^^^^
  File "/Users/macbookpro/Documents/projects/WSS/venv/lib/python3.11/site-packages/flask_cors/extension.py", line 176, in wrapped_function
    return cors_after_request(app.make_response(f(*args, **kwargs)))
                                                ^^^^^^^^^^^^^^^^^^
  File "/Users/macbookpro/Documents/projects/WSS/venv/lib/python3.11/site-packages/flask_cors/extension.py", line 176, in wrapped_function
    return cors_after_request(app.make_response(f(*args, **kwargs)))
                                                ^^^^^^^^^^^^^^^^^^
  File "/Users/macbookpro/Documents/projects/WSS/venv/lib/python3.11/site-packages/flask/app.py", line 762, in handle_user_exception
    return self.ensure_sync(handler)(e)  # type: ignore[no-any-return]
           ^^^^^^^^^^^^^^^^^^^^^^^^^^^^
  File "/Users/macbookpro/Documents/projects/WSS/majesty-backend/app/utils/logger.py", line 194, in log_exception
    raise exception
  File "/Users/macbookpro/Documents/projects/WSS/venv/lib/python3.11/site-packages/flask/app.py", line 870, in full_dispatch_request
    rv = self.dispatch_request()
         ^^^^^^^^^^^^^^^^^^^^^^^
  File "/Users/macbookpro/Documents/projects/WSS/venv/lib/python3.11/site-packages/flask/app.py", line 855, in dispatch_request
    return self.ensure_sync(self.view_functions[rule.endpoint])(**view_args)  # type: ignore[no-any-return]
           ^^^^^^^^^^^^^^^^^^^^^^^^^^^^^^^^^^^^^^^^^^^^^^^^^^^^^^^^^^^^^^^^^
  File "/Users/macbookpro/Documents/projects/WSS/majesty-backend/app/utils/decorators.py", line 25, in decorated
    if is_token_blacklisted(token):
       ^^^^^^^^^^^^^^^^^^^^^^^^^^^
  File "/Users/macbookpro/Documents/projects/WSS/majesty-backend/app/utils/decorators.py", line 12, in is_token_blacklisted
    blacklisted = BlacklistedToken.query.filter_by(token=token).first()
                  ^^^^^^^^^^^^^^^^^^^^^^^^^^^^^^^^^^^^^^^^^^^^^^^^^^^^^
  File "/Users/macbookpro/Documents/projects/WSS/venv/lib/python3.11/site-packages/sqlalchemy/orm/query.py", line 2754, in first
    return self.limit(1)._iter().first()  # type: ignore
           ^^^^^^^^^^^^^^^^^^^^^
  File "/Users/macbookpro/Documents/projects/WSS/venv/lib/python3.11/site-packages/sqlalchemy/orm/query.py", line 2853, in _iter
    result: Union[ScalarResult[_T], Result[_T]] = self.session.execute(
                                                  ^^^^^^^^^^^^^^^^^^^^^
  File "/Users/macbookpro/Documents/projects/WSS/venv/lib/python3.11/site-packages/sqlalchemy/orm/session.py", line 2365, in execute
    return self._execute_internal(
           ^^^^^^^^^^^^^^^^^^^^^^^
  File "/Users/macbookpro/Documents/projects/WSS/venv/lib/python3.11/site-packages/sqlalchemy/orm/session.py", line 2251, in _execute_internal
    result: Result[Any] = compile_state_cls.orm_execute_statement(
                          ^^^^^^^^^^^^^^^^^^^^^^^^^^^^^^^^^^^^^^^^
  File "/Users/macbookpro/Documents/projects/WSS/venv/lib/python3.11/site-packages/sqlalchemy/orm/context.py", line 305, in orm_execute_statement
    result = conn.execute(
             ^^^^^^^^^^^^^
  File "/Users/macbookpro/Documents/projects/WSS/venv/lib/python3.11/site-packages/sqlalchemy/engine/base.py", line 1416, in execute
    return meth(
           ^^^^^
  File "/Users/macbookpro/Documents/projects/WSS/venv/lib/python3.11/site-packages/sqlalchemy/sql/elements.py", line 516, in _execute_on_connection
    return connection._execute_clauseelement(
           ^^^^^^^^^^^^^^^^^^^^^^^^^^^^^^^^^^
  File "/Users/macbookpro/Documents/projects/WSS/venv/lib/python3.11/site-packages/sqlalchemy/engine/base.py", line 1638, in _execute_clauseelement
    ret = self._execute_context(
          ^^^^^^^^^^^^^^^^^^^^^^
  File "/Users/macbookpro/Documents/projects/WSS/venv/lib/python3.11/site-packages/sqlalchemy/engine/base.py", line 1843, in _execute_context
    return self._exec_single_context(
           ^^^^^^^^^^^^^^^^^^^^^^^^^^
  File "/Users/macbookpro/Documents/projects/WSS/venv/lib/python3.11/site-packages/sqlalchemy/engine/base.py", line 1983, in _exec_single_context
    self._handle_dbapi_exception(
  File "/Users/macbookpro/Documents/projects/WSS/venv/lib/python3.11/site-packages/sqlalchemy/engine/base.py", line 2352, in _handle_dbapi_exception
    raise sqlalchemy_exception.with_traceback(exc_info[2]) from e
  File "/Users/macbookpro/Documents/projects/WSS/venv/lib/python3.11/site-packages/sqlalchemy/engine/base.py", line 1964, in _exec_single_context
    self.dialect.do_execute(
  File "/Users/macbookpro/Documents/projects/WSS/venv/lib/python3.11/site-packages/sqlalchemy/engine/default.py", line 942, in do_execute
    cursor.execute(statement, parameters)
sqlalchemy.exc.OperationalError: (sqlite3.OperationalError) no such column: blacklisted_tokens.token
[SQL: SELECT blacklisted_tokens.id AS blacklisted_tokens_id, blacklisted_tokens.token AS blacklisted_tokens_token, blacklisted_tokens.created_at AS blacklisted_tokens_created_at 
FROM blacklisted_tokens 
WHERE blacklisted_tokens.token = ?
 LIMIT ? OFFSET ?]
[parameters: ('Bearer eyJhbGciOiJIUzI1NiIsInR5cCI6IkpXVCJ9.eyJmcmVzaCI6ZmFsc2UsImlhdCI6MTc0MjIyMDM4NywianRpIjoiYWMzNDMwNzctMTUwYS00NjUxLTk1MzQtYTEyYmU2OGYzNzEyIiwid ... (80 characters truncated) ... jk3LTQ3MTAtYjQ3MC0yODZlNGM4YjkzZjAiLCJleHAiOjE3NDIyNzQzODcsInJvbGVzIjpbImFkbWluIl0sImlzX2FkbWluIjp0cnVlfQ.Lst8fRqMKDSatp-feFE86b_iJT7pARikJCfCbmS0OWk', 1, 0)]
(Background on this error at: https://sqlalche.me/e/20/e3q8)
[2025-03-17 15:07:03,525] ERROR in logger: [EXCEPTION] User None: Unhandled exception: InternalServerError
[2025-03-17 15:08:24,151] INFO in logger: Wine Inventory API Started - Environment: development
[2025-03-17 15:08:28,993] INFO in logger: [LOGIN_SUCCESS] User 1: User logged in successfully | Affected: admin
[2025-03-17 15:09:01,250] INFO in logger: [LOGOUT] User 1: User logged out | Affected: admin
[2025-03-17 15:15:29,271] INFO in logger: Wine Inventory API Started - Environment: development
[2025-03-17 15:15:44,566] INFO in logger: [LOGIN_SUCCESS] User 1: User logged in successfully | Affected: admin
[2025-03-17 15:15:59,549] ERROR in logger: [EXCEPTION] User None: Unhandled exception: AttributeError
[2025-03-17 15:15:59,559] ERROR in app: Exception on /logs/logs [GET]
Traceback (most recent call last):
  File "/Users/macbookpro/Documents/projects/WSS/venv/lib/python3.11/site-packages/flask/app.py", line 1463, in wsgi_app
    response = self.full_dispatch_request()
               ^^^^^^^^^^^^^^^^^^^^^^^^^^^^
  File "/Users/macbookpro/Documents/projects/WSS/venv/lib/python3.11/site-packages/flask/app.py", line 872, in full_dispatch_request
    rv = self.handle_user_exception(e)
         ^^^^^^^^^^^^^^^^^^^^^^^^^^^^^
  File "/Users/macbookpro/Documents/projects/WSS/venv/lib/python3.11/site-packages/flask_cors/extension.py", line 176, in wrapped_function
    return cors_after_request(app.make_response(f(*args, **kwargs)))
                                                ^^^^^^^^^^^^^^^^^^
  File "/Users/macbookpro/Documents/projects/WSS/venv/lib/python3.11/site-packages/flask_cors/extension.py", line 176, in wrapped_function
    return cors_after_request(app.make_response(f(*args, **kwargs)))
                                                ^^^^^^^^^^^^^^^^^^
  File "/Users/macbookpro/Documents/projects/WSS/venv/lib/python3.11/site-packages/flask/app.py", line 762, in handle_user_exception
    return self.ensure_sync(handler)(e)  # type: ignore[no-any-return]
           ^^^^^^^^^^^^^^^^^^^^^^^^^^^^
  File "/Users/macbookpro/Documents/projects/WSS/majesty-backend/app/utils/logger.py", line 194, in log_exception
    raise exception
  File "/Users/macbookpro/Documents/projects/WSS/venv/lib/python3.11/site-packages/flask/app.py", line 870, in full_dispatch_request
    rv = self.dispatch_request()
         ^^^^^^^^^^^^^^^^^^^^^^^
  File "/Users/macbookpro/Documents/projects/WSS/venv/lib/python3.11/site-packages/flask/app.py", line 855, in dispatch_request
    return self.ensure_sync(self.view_functions[rule.endpoint])(**view_args)  # type: ignore[no-any-return]
           ^^^^^^^^^^^^^^^^^^^^^^^^^^^^^^^^^^^^^^^^^^^^^^^^^^^^^^^^^^^^^^^^^
  File "/Users/macbookpro/Documents/projects/WSS/majesty-backend/app/utils/decorators.py", line 46, in decorated
    if is_token_blacklisted(token):
       ^^^^^^^^^^^^^^^^^^^^^^^^^^^
  File "/Users/macbookpro/Documents/projects/WSS/majesty-backend/app/utils/decorators.py", line 25, in is_token_blacklisted
    jti = extract_jti(token)
          ^^^^^^^^^^^^^^^^^^
  File "/Users/macbookpro/Documents/projects/WSS/majesty-backend/app/utils/decorators.py", line 12, in extract_jti
    decoded_token = jwt.decode(token, DevelopmentConfig.SECRET_KEY, algorithms=["HS256"])
                                      ^^^^^^^^^^^^^^^^^^^^^^^^^^^^
AttributeError: type object 'DevelopmentConfig' has no attribute 'SECRET_KEY'
[2025-03-17 15:15:59,563] ERROR in logger: [EXCEPTION] User None: Unhandled exception: InternalServerError
[2025-03-17 15:19:00,657] INFO in logger: Wine Inventory API Started - Environment: development
[2025-03-17 15:19:08,385] INFO in logger: [LOGIN_SUCCESS] User 1: User logged in successfully | Affected: admin
[2025-03-17 15:19:40,084] INFO in logger: [LOGOUT] User 1: User logged out | Affected: admin
[2025-03-17 15:19:40,124] ERROR in logger: [EXCEPTION] User 1: Unhandled exception: IntegrityError
[2025-03-17 15:19:40,125] ERROR in logger: Failed to save log entry to database: This Session's transaction has been rolled back due to a previous exception during flush. To begin a new transaction with this Session, first issue Session.rollback(). Original exception was: (sqlite3.IntegrityError) UNIQUE constraint failed: blacklisted_tokens.jti
[SQL: INSERT INTO blacklisted_tokens (jti, created_at) VALUES (?, ?)]
[parameters: ('eead7c66-2e49-4352-96eb-380f6d2633eb', '2025-03-17 14:19:40.089492')]
(Background on this error at: https://sqlalche.me/e/20/gkpj) (Background on this error at: https://sqlalche.me/e/20/7s2a)
[2025-03-17 15:19:40,137] ERROR in app: Exception on /auth/logout [POST]
Traceback (most recent call last):
  File "/Users/macbookpro/Documents/projects/WSS/venv/lib/python3.11/site-packages/sqlalchemy/engine/base.py", line 1964, in _exec_single_context
    self.dialect.do_execute(
  File "/Users/macbookpro/Documents/projects/WSS/venv/lib/python3.11/site-packages/sqlalchemy/engine/default.py", line 942, in do_execute
    cursor.execute(statement, parameters)
sqlite3.IntegrityError: UNIQUE constraint failed: blacklisted_tokens.jti

The above exception was the direct cause of the following exception:

Traceback (most recent call last):
  File "/Users/macbookpro/Documents/projects/WSS/venv/lib/python3.11/site-packages/flask/app.py", line 1463, in wsgi_app
    response = self.full_dispatch_request()
               ^^^^^^^^^^^^^^^^^^^^^^^^^^^^
  File "/Users/macbookpro/Documents/projects/WSS/venv/lib/python3.11/site-packages/flask/app.py", line 872, in full_dispatch_request
    rv = self.handle_user_exception(e)
         ^^^^^^^^^^^^^^^^^^^^^^^^^^^^^
  File "/Users/macbookpro/Documents/projects/WSS/venv/lib/python3.11/site-packages/flask_cors/extension.py", line 176, in wrapped_function
    return cors_after_request(app.make_response(f(*args, **kwargs)))
                                                ^^^^^^^^^^^^^^^^^^
  File "/Users/macbookpro/Documents/projects/WSS/venv/lib/python3.11/site-packages/flask_cors/extension.py", line 176, in wrapped_function
    return cors_after_request(app.make_response(f(*args, **kwargs)))
                                                ^^^^^^^^^^^^^^^^^^
  File "/Users/macbookpro/Documents/projects/WSS/venv/lib/python3.11/site-packages/flask/app.py", line 762, in handle_user_exception
    return self.ensure_sync(handler)(e)  # type: ignore[no-any-return]
           ^^^^^^^^^^^^^^^^^^^^^^^^^^^^
  File "/Users/macbookpro/Documents/projects/WSS/majesty-backend/app/utils/logger.py", line 194, in log_exception
    raise exception
  File "/Users/macbookpro/Documents/projects/WSS/venv/lib/python3.11/site-packages/flask/app.py", line 870, in full_dispatch_request
    rv = self.dispatch_request()
         ^^^^^^^^^^^^^^^^^^^^^^^
  File "/Users/macbookpro/Documents/projects/WSS/venv/lib/python3.11/site-packages/flask/app.py", line 855, in dispatch_request
    return self.ensure_sync(self.view_functions[rule.endpoint])(**view_args)  # type: ignore[no-any-return]
           ^^^^^^^^^^^^^^^^^^^^^^^^^^^^^^^^^^^^^^^^^^^^^^^^^^^^^^^^^^^^^^^^^
  File "/Users/macbookpro/Documents/projects/WSS/venv/lib/python3.11/site-packages/flask_jwt_extended/view_decorators.py", line 170, in decorator
    return current_app.ensure_sync(fn)(*args, **kwargs)
           ^^^^^^^^^^^^^^^^^^^^^^^^^^^^^^^^^^^^^^^^^^^^
  File "/Users/macbookpro/Documents/projects/WSS/majesty-backend/app/routes/auth.py", line 159, in logout
    db.session.commit()
  File "/Users/macbookpro/Documents/projects/WSS/venv/lib/python3.11/site-packages/sqlalchemy/orm/scoping.py", line 599, in commit
    return self._proxied.commit()
           ^^^^^^^^^^^^^^^^^^^^^^
  File "/Users/macbookpro/Documents/projects/WSS/venv/lib/python3.11/site-packages/sqlalchemy/orm/session.py", line 2032, in commit
    trans.commit(_to_root=True)
  File "<string>", line 2, in commit
  File "/Users/macbookpro/Documents/projects/WSS/venv/lib/python3.11/site-packages/sqlalchemy/orm/state_changes.py", line 139, in _go
    ret_value = fn(self, *arg, **kw)
                ^^^^^^^^^^^^^^^^^^^^
  File "/Users/macbookpro/Documents/projects/WSS/venv/lib/python3.11/site-packages/sqlalchemy/orm/session.py", line 1313, in commit
    self._prepare_impl()
  File "<string>", line 2, in _prepare_impl
  File "/Users/macbookpro/Documents/projects/WSS/venv/lib/python3.11/site-packages/sqlalchemy/orm/state_changes.py", line 139, in _go
    ret_value = fn(self, *arg, **kw)
                ^^^^^^^^^^^^^^^^^^^^
  File "/Users/macbookpro/Documents/projects/WSS/venv/lib/python3.11/site-packages/sqlalchemy/orm/session.py", line 1288, in _prepare_impl
    self.session.flush()
  File "/Users/macbookpro/Documents/projects/WSS/venv/lib/python3.11/site-packages/sqlalchemy/orm/session.py", line 4353, in flush
    self._flush(objects)
  File "/Users/macbookpro/Documents/projects/WSS/venv/lib/python3.11/site-packages/sqlalchemy/orm/session.py", line 4488, in _flush
    with util.safe_reraise():
  File "/Users/macbookpro/Documents/projects/WSS/venv/lib/python3.11/site-packages/sqlalchemy/util/langhelpers.py", line 146, in __exit__
    raise exc_value.with_traceback(exc_tb)
  File "/Users/macbookpro/Documents/projects/WSS/venv/lib/python3.11/site-packages/sqlalchemy/orm/session.py", line 4449, in _flush
    flush_context.execute()
  File "/Users/macbookpro/Documents/projects/WSS/venv/lib/python3.11/site-packages/sqlalchemy/orm/unitofwork.py", line 466, in execute
    rec.execute(self)
  File "/Users/macbookpro/Documents/projects/WSS/venv/lib/python3.11/site-packages/sqlalchemy/orm/unitofwork.py", line 642, in execute
    util.preloaded.orm_persistence.save_obj(
  File "/Users/macbookpro/Documents/projects/WSS/venv/lib/python3.11/site-packages/sqlalchemy/orm/persistence.py", line 93, in save_obj
    _emit_insert_statements(
  File "/Users/macbookpro/Documents/projects/WSS/venv/lib/python3.11/site-packages/sqlalchemy/orm/persistence.py", line 1233, in _emit_insert_statements
    result = connection.execute(
             ^^^^^^^^^^^^^^^^^^^
  File "/Users/macbookpro/Documents/projects/WSS/venv/lib/python3.11/site-packages/sqlalchemy/engine/base.py", line 1416, in execute
    return meth(
           ^^^^^
  File "/Users/macbookpro/Documents/projects/WSS/venv/lib/python3.11/site-packages/sqlalchemy/sql/elements.py", line 516, in _execute_on_connection
    return connection._execute_clauseelement(
           ^^^^^^^^^^^^^^^^^^^^^^^^^^^^^^^^^^
  File "/Users/macbookpro/Documents/projects/WSS/venv/lib/python3.11/site-packages/sqlalchemy/engine/base.py", line 1638, in _execute_clauseelement
    ret = self._execute_context(
          ^^^^^^^^^^^^^^^^^^^^^^
  File "/Users/macbookpro/Documents/projects/WSS/venv/lib/python3.11/site-packages/sqlalchemy/engine/base.py", line 1843, in _execute_context
    return self._exec_single_context(
           ^^^^^^^^^^^^^^^^^^^^^^^^^^
  File "/Users/macbookpro/Documents/projects/WSS/venv/lib/python3.11/site-packages/sqlalchemy/engine/base.py", line 1983, in _exec_single_context
    self._handle_dbapi_exception(
  File "/Users/macbookpro/Documents/projects/WSS/venv/lib/python3.11/site-packages/sqlalchemy/engine/base.py", line 2352, in _handle_dbapi_exception
    raise sqlalchemy_exception.with_traceback(exc_info[2]) from e
<<<<<<< HEAD
  File "/Users/macbookpro/Documents/projects/WSS/venv/lib/python3.11/site-packages/sqlalchemy/engine/base.py", line 1812, in _execute_context
    context = constructor(
              ^^^^^^^^^^^^
  File "/Users/macbookpro/Documents/projects/WSS/venv/lib/python3.11/site-packages/sqlalchemy/engine/default.py", line 1475, in _init_compiled
    l_param: List[Any] = [
                         ^
  File "/Users/macbookpro/Documents/projects/WSS/venv/lib/python3.11/site-packages/sqlalchemy/engine/default.py", line 1477, in <listcomp>
    flattened_processors[key](compiled_params[key])
  File "/Users/macbookpro/Documents/projects/WSS/venv/lib/python3.11/site-packages/sqlalchemy/sql/sqltypes.py", line 2022, in process
    value = _strict_as_bool(value)
            ^^^^^^^^^^^^^^^^^^^^^^
  File "/Users/macbookpro/Documents/projects/WSS/venv/lib/python3.11/site-packages/sqlalchemy/sql/sqltypes.py", line 1994, in _strict_as_bool
    raise TypeError("Not a boolean value: %r" % (value,))
sqlalchemy.exc.StatementError: (raised as a result of Query-invoked autoflush; consider using a session.no_autoflush block if this flush is occurring prematurely)
(builtins.TypeError) Not a boolean value: 'false'
[SQL: UPDATE users SET username=?, password_hash=?, is_admin=? WHERE users.id = ?]
[parameters: [{'password_hash': 'scrypt:32768:8:1$10VhCLZHx58uCPsy$886f0998a83a7b880ec564e42bfcafb5af72ff10989dcfa664fbf2aecefa5382fe0eb239a7621391ec468a8b74862559874c058fee4dc2673adffe3348546ad2', 'username': 'fourth_user', 'is_admin': 'false', 'users_id': 4}]]
[2025-03-16 22:42:16,371] ERROR in logger: [EXCEPTION] User 1: Unhandled exception: InternalServerError
[2025-03-16 22:44:31,661] ERROR in logger: [EXCEPTION] User 1: Unhandled exception: StatementError
[2025-03-16 22:44:31,664] ERROR in logger: Failed to save log entry to database: This Session's transaction has been rolled back due to a previous exception during flush. To begin a new transaction with this Session, first issue Session.rollback(). Original exception was: (raised as a result of Query-invoked autoflush; consider using a session.no_autoflush block if this flush is occurring prematurely)
(builtins.TypeError) Not a boolean value: 'False'
[SQL: UPDATE users SET username=?, password_hash=?, is_admin=? WHERE users.id = ?]
[parameters: [{'password_hash': 'scrypt:32768:8:1$Yr5panvN5UzQwWl7$e249baac447a5faa8311231bba256956bf76bc52b7d3664e1bea2a98240ccd99d6e7d93abafd993ba452033e958dd54c6239e2d35118a8ae89ce9a33be155c6c', 'username': 'fourth_user', 'is_admin': 'False', 'users_id': 4}]] (Background on this error at: https://sqlalche.me/e/20/7s2a)
[2025-03-16 22:44:31,670] ERROR in app: Exception on /auth/users/4 [PUT]
Traceback (most recent call last):
  File "/Users/macbookpro/Documents/projects/WSS/venv/lib/python3.11/site-packages/sqlalchemy/engine/base.py", line 1812, in _execute_context
    context = constructor(
              ^^^^^^^^^^^^
  File "/Users/macbookpro/Documents/projects/WSS/venv/lib/python3.11/site-packages/sqlalchemy/engine/default.py", line 1475, in _init_compiled
    l_param: List[Any] = [
                         ^
  File "/Users/macbookpro/Documents/projects/WSS/venv/lib/python3.11/site-packages/sqlalchemy/engine/default.py", line 1477, in <listcomp>
    flattened_processors[key](compiled_params[key])
  File "/Users/macbookpro/Documents/projects/WSS/venv/lib/python3.11/site-packages/sqlalchemy/sql/sqltypes.py", line 2022, in process
    value = _strict_as_bool(value)
            ^^^^^^^^^^^^^^^^^^^^^^
  File "/Users/macbookpro/Documents/projects/WSS/venv/lib/python3.11/site-packages/sqlalchemy/sql/sqltypes.py", line 1994, in _strict_as_bool
    raise TypeError("Not a boolean value: %r" % (value,))
TypeError: Not a boolean value: 'False'

The above exception was the direct cause of the following exception:

Traceback (most recent call last):
  File "/Users/macbookpro/Documents/projects/WSS/venv/lib/python3.11/site-packages/flask/app.py", line 1463, in wsgi_app
    response = self.full_dispatch_request()
               ^^^^^^^^^^^^^^^^^^^^^^^^^^^^
  File "/Users/macbookpro/Documents/projects/WSS/venv/lib/python3.11/site-packages/flask/app.py", line 872, in full_dispatch_request
    rv = self.handle_user_exception(e)
         ^^^^^^^^^^^^^^^^^^^^^^^^^^^^^
  File "/Users/macbookpro/Documents/projects/WSS/venv/lib/python3.11/site-packages/flask_cors/extension.py", line 176, in wrapped_function
    return cors_after_request(app.make_response(f(*args, **kwargs)))
                                                ^^^^^^^^^^^^^^^^^^
  File "/Users/macbookpro/Documents/projects/WSS/venv/lib/python3.11/site-packages/flask/app.py", line 762, in handle_user_exception
    return self.ensure_sync(handler)(e)  # type: ignore[no-any-return]
           ^^^^^^^^^^^^^^^^^^^^^^^^^^^^
  File "/Users/macbookpro/Documents/projects/WSS/majesty-backend/app/utils/logger.py", line 194, in log_exception
    raise exception
  File "/Users/macbookpro/Documents/projects/WSS/venv/lib/python3.11/site-packages/flask/app.py", line 870, in full_dispatch_request
    rv = self.dispatch_request()
         ^^^^^^^^^^^^^^^^^^^^^^^
  File "/Users/macbookpro/Documents/projects/WSS/venv/lib/python3.11/site-packages/flask/app.py", line 855, in dispatch_request
    return self.ensure_sync(self.view_functions[rule.endpoint])(**view_args)  # type: ignore[no-any-return]
           ^^^^^^^^^^^^^^^^^^^^^^^^^^^^^^^^^^^^^^^^^^^^^^^^^^^^^^^^^^^^^^^^^
  File "/Users/macbookpro/Documents/projects/WSS/venv/lib/python3.11/site-packages/flask_jwt_extended/view_decorators.py", line 170, in decorator
    return current_app.ensure_sync(fn)(*args, **kwargs)
           ^^^^^^^^^^^^^^^^^^^^^^^^^^^^^^^^^^^^^^^^^^^^
  File "/Users/macbookpro/Documents/projects/WSS/majesty-backend/app/routes/auth.py", line 326, in update_user
    valid_roles = Role.query.filter(Role.name.in_(roles)).all()
                  ^^^^^^^^^^^^^^^^^^^^^^^^^^^^^^^^^^^^^^^^^^^^^
  File "/Users/macbookpro/Documents/projects/WSS/venv/lib/python3.11/site-packages/sqlalchemy/orm/query.py", line 2699, in all
    return self._iter().all()  # type: ignore
           ^^^^^^^^^^^^
  File "/Users/macbookpro/Documents/projects/WSS/venv/lib/python3.11/site-packages/sqlalchemy/orm/query.py", line 2853, in _iter
    result: Union[ScalarResult[_T], Result[_T]] = self.session.execute(
                                                  ^^^^^^^^^^^^^^^^^^^^^
  File "/Users/macbookpro/Documents/projects/WSS/venv/lib/python3.11/site-packages/sqlalchemy/orm/session.py", line 2365, in execute
    return self._execute_internal(
           ^^^^^^^^^^^^^^^^^^^^^^^
  File "/Users/macbookpro/Documents/projects/WSS/venv/lib/python3.11/site-packages/sqlalchemy/orm/session.py", line 2230, in _execute_internal
    ) = compile_state_cls.orm_pre_session_exec(
        ^^^^^^^^^^^^^^^^^^^^^^^^^^^^^^^^^^^^^^^
  File "/Users/macbookpro/Documents/projects/WSS/venv/lib/python3.11/site-packages/sqlalchemy/orm/context.py", line 561, in orm_pre_session_exec
    session._autoflush()
  File "/Users/macbookpro/Documents/projects/WSS/venv/lib/python3.11/site-packages/sqlalchemy/orm/session.py", line 3065, in _autoflush
    raise e.with_traceback(sys.exc_info()[2])
  File "/Users/macbookpro/Documents/projects/WSS/venv/lib/python3.11/site-packages/sqlalchemy/orm/session.py", line 3054, in _autoflush
    self.flush()
  File "/Users/macbookpro/Documents/projects/WSS/venv/lib/python3.11/site-packages/sqlalchemy/orm/session.py", line 4353, in flush
    self._flush(objects)
  File "/Users/macbookpro/Documents/projects/WSS/venv/lib/python3.11/site-packages/sqlalchemy/orm/session.py", line 4488, in _flush
    with util.safe_reraise():
  File "/Users/macbookpro/Documents/projects/WSS/venv/lib/python3.11/site-packages/sqlalchemy/util/langhelpers.py", line 146, in __exit__
    raise exc_value.with_traceback(exc_tb)
  File "/Users/macbookpro/Documents/projects/WSS/venv/lib/python3.11/site-packages/sqlalchemy/orm/session.py", line 4449, in _flush
    flush_context.execute()
  File "/Users/macbookpro/Documents/projects/WSS/venv/lib/python3.11/site-packages/sqlalchemy/orm/unitofwork.py", line 466, in execute
    rec.execute(self)
  File "/Users/macbookpro/Documents/projects/WSS/venv/lib/python3.11/site-packages/sqlalchemy/orm/unitofwork.py", line 642, in execute
    util.preloaded.orm_persistence.save_obj(
  File "/Users/macbookpro/Documents/projects/WSS/venv/lib/python3.11/site-packages/sqlalchemy/orm/persistence.py", line 85, in save_obj
    _emit_update_statements(
  File "/Users/macbookpro/Documents/projects/WSS/venv/lib/python3.11/site-packages/sqlalchemy/orm/persistence.py", line 912, in _emit_update_statements
    c = connection.execute(
        ^^^^^^^^^^^^^^^^^^^
  File "/Users/macbookpro/Documents/projects/WSS/venv/lib/python3.11/site-packages/sqlalchemy/engine/base.py", line 1416, in execute
    return meth(
           ^^^^^
  File "/Users/macbookpro/Documents/projects/WSS/venv/lib/python3.11/site-packages/sqlalchemy/sql/elements.py", line 516, in _execute_on_connection
    return connection._execute_clauseelement(
           ^^^^^^^^^^^^^^^^^^^^^^^^^^^^^^^^^^
  File "/Users/macbookpro/Documents/projects/WSS/venv/lib/python3.11/site-packages/sqlalchemy/engine/base.py", line 1638, in _execute_clauseelement
    ret = self._execute_context(
          ^^^^^^^^^^^^^^^^^^^^^^
  File "/Users/macbookpro/Documents/projects/WSS/venv/lib/python3.11/site-packages/sqlalchemy/engine/base.py", line 1818, in _execute_context
    self._handle_dbapi_exception(
  File "/Users/macbookpro/Documents/projects/WSS/venv/lib/python3.11/site-packages/sqlalchemy/engine/base.py", line 2352, in _handle_dbapi_exception
    raise sqlalchemy_exception.with_traceback(exc_info[2]) from e
  File "/Users/macbookpro/Documents/projects/WSS/venv/lib/python3.11/site-packages/sqlalchemy/engine/base.py", line 1812, in _execute_context
    context = constructor(
              ^^^^^^^^^^^^
  File "/Users/macbookpro/Documents/projects/WSS/venv/lib/python3.11/site-packages/sqlalchemy/engine/default.py", line 1475, in _init_compiled
    l_param: List[Any] = [
                         ^
  File "/Users/macbookpro/Documents/projects/WSS/venv/lib/python3.11/site-packages/sqlalchemy/engine/default.py", line 1477, in <listcomp>
    flattened_processors[key](compiled_params[key])
  File "/Users/macbookpro/Documents/projects/WSS/venv/lib/python3.11/site-packages/sqlalchemy/sql/sqltypes.py", line 2022, in process
    value = _strict_as_bool(value)
            ^^^^^^^^^^^^^^^^^^^^^^
  File "/Users/macbookpro/Documents/projects/WSS/venv/lib/python3.11/site-packages/sqlalchemy/sql/sqltypes.py", line 1994, in _strict_as_bool
    raise TypeError("Not a boolean value: %r" % (value,))
sqlalchemy.exc.StatementError: (raised as a result of Query-invoked autoflush; consider using a session.no_autoflush block if this flush is occurring prematurely)
(builtins.TypeError) Not a boolean value: 'False'
[SQL: UPDATE users SET username=?, password_hash=?, is_admin=? WHERE users.id = ?]
[parameters: [{'password_hash': 'scrypt:32768:8:1$Yr5panvN5UzQwWl7$e249baac447a5faa8311231bba256956bf76bc52b7d3664e1bea2a98240ccd99d6e7d93abafd993ba452033e958dd54c6239e2d35118a8ae89ce9a33be155c6c', 'username': 'fourth_user', 'is_admin': 'False', 'users_id': 4}]]
[2025-03-16 22:44:31,677] ERROR in logger: [EXCEPTION] User 1: Unhandled exception: InternalServerError
[2025-03-16 22:46:19,229] INFO in logger: [UPDATE_USER_SUCCESS] User 1: User updated: 4 | Affected: fourth_user
[2025-03-16 22:48:55,745] INFO in logger: [DELETE_USER_SUCCESS] User 1: Deleted user fourth_user (ID: 4) | Affected: fourth_user
[2025-03-16 22:50:37,441] INFO in logger: [ADD_WINE_SUCCESS] User 1: Added wine: sparkling fruit juice | Affected: sparkling fruit juice
[2025-03-16 22:51:07,896] INFO in logger: [DELETE_WINE_SUCCESS] User 1: Deleted sparkling fruit juice | Affected: sparkling fruit juice
[2025-03-16 23:34:29,939] INFO in logger: Wine Inventory API Started - Environment: development
[2025-03-16 23:34:36,324] INFO in logger: [LOGIN_SUCCESS] User 1: User logged in successfully | Affected: admin
[2025-03-16 23:38:58,892] ERROR in logger: [EXCEPTION] User None: Unhandled exception: MethodNotAllowed
[2025-03-16 23:38:58,902] ERROR in app: Exception on /invoices/checkout [GET]
Traceback (most recent call last):
  File "/Users/macbookpro/Documents/projects/WSS/venv/lib/python3.11/site-packages/flask/app.py", line 1463, in wsgi_app
    response = self.full_dispatch_request()
               ^^^^^^^^^^^^^^^^^^^^^^^^^^^^
  File "/Users/macbookpro/Documents/projects/WSS/venv/lib/python3.11/site-packages/flask/app.py", line 872, in full_dispatch_request
    rv = self.handle_user_exception(e)
         ^^^^^^^^^^^^^^^^^^^^^^^^^^^^^
  File "/Users/macbookpro/Documents/projects/WSS/venv/lib/python3.11/site-packages/flask_cors/extension.py", line 176, in wrapped_function
    return cors_after_request(app.make_response(f(*args, **kwargs)))
                                                ^^^^^^^^^^^^^^^^^^
  File "/Users/macbookpro/Documents/projects/WSS/venv/lib/python3.11/site-packages/flask_cors/extension.py", line 176, in wrapped_function
    return cors_after_request(app.make_response(f(*args, **kwargs)))
                                                ^^^^^^^^^^^^^^^^^^
  File "/Users/macbookpro/Documents/projects/WSS/venv/lib/python3.11/site-packages/flask/app.py", line 755, in handle_user_exception
    return self.handle_http_exception(e)
           ^^^^^^^^^^^^^^^^^^^^^^^^^^^^^
  File "/Users/macbookpro/Documents/projects/WSS/venv/lib/python3.11/site-packages/flask/app.py", line 730, in handle_http_exception
    return self.ensure_sync(handler)(e)  # type: ignore[no-any-return]
           ^^^^^^^^^^^^^^^^^^^^^^^^^^^^
  File "/Users/macbookpro/Documents/projects/WSS/majesty-backend/app/utils/logger.py", line 194, in log_exception
    raise exception
  File "/Users/macbookpro/Documents/projects/WSS/venv/lib/python3.11/site-packages/flask/app.py", line 870, in full_dispatch_request
    rv = self.dispatch_request()
         ^^^^^^^^^^^^^^^^^^^^^^^
  File "/Users/macbookpro/Documents/projects/WSS/venv/lib/python3.11/site-packages/flask/app.py", line 844, in dispatch_request
    self.raise_routing_exception(req)
  File "/Users/macbookpro/Documents/projects/WSS/venv/lib/python3.11/site-packages/flask/app.py", line 453, in raise_routing_exception
    raise request.routing_exception  # type: ignore[misc]
    ^^^^^^^^^^^^^^^^^^^^^^^^^^^^^^^
  File "/Users/macbookpro/Documents/projects/WSS/venv/lib/python3.11/site-packages/flask/ctx.py", line 362, in match_request
    result = self.url_adapter.match(return_rule=True)  # type: ignore
             ^^^^^^^^^^^^^^^^^^^^^^^^^^^^^^^^^^^^^^^^
  File "/Users/macbookpro/Documents/projects/WSS/venv/lib/python3.11/site-packages/werkzeug/routing/map.py", line 624, in match
    raise MethodNotAllowed(valid_methods=list(e.have_match_for)) from None
werkzeug.exceptions.MethodNotAllowed: 405 Method Not Allowed: The method is not allowed for the requested URL.
[2025-03-16 23:38:58,905] ERROR in logger: [EXCEPTION] User None: Unhandled exception: InternalServerError
[2025-03-16 23:39:36,919] ERROR in logger: [CHECKOUT_ERROR] User 1: Wine 1 not found | Affected: Wine ID 1
[2025-03-16 23:39:49,142] INFO in logger: [CHECKOUT_SUCCESS] User 1: Checkout completed for invoice 2 | Affected: Invoice ID 2
[2025-03-16 23:42:04,263] INFO in logger: [GET_TOTAL_STOCK] User 1: Total stock checked: 144 | Affected: Total Stock
[2025-03-16 23:42:39,275] INFO in logger: [GET_STOCK_BY_CATEGORY] User 1: Stock by category fetched successfully | Affected: Stock by Category
[2025-03-16 23:43:52,150] INFO in logger: [GET_REVENUE] User 1: Revenue calculated: 0 | Affected: Revenue
[2025-03-16 23:44:15,831] INFO in logger: [COMPARE_SALES] User 1: Sales compared: 0% | Affected: Sales Comparison
[2025-03-16 23:45:01,169] INFO in logger: [GET_INVENTORY_VALUE] User 1: Inventory value fetched | Affected: Inventory Value by Category
[2025-03-16 23:45:26,083] INFO in logger: [GET_USER_SALES] User 1: Sales fetched for user 1 | Affected: User ID 1
>>>>>>> b2e1201cbe318e60d5c39c3b2aead5eb7735c2c4
[2025-03-17 01:43:19,105] INFO in logger: Wine Inventory API Started - Environment: development
[2025-03-17 01:44:01,415] INFO in logger: Wine Inventory API Started - Environment: development
[2025-03-17 01:45:51,656] INFO in logger: Wine Inventory API Started - Environment: development
[2025-03-17 01:46:24,348] INFO in logger: [CHECK_TOKEN_VALID] User 1: Token is valid | Affected: Token System
[2025-03-17 01:46:24,597] INFO in logger: [GET_STOCK_BY_CATEGORY] User 1: Stock by category fetched successfully | Affected: Stock by Category
[2025-03-17 01:46:24,598] INFO in logger: [GET_TOTAL_STOCK] User 1: Total stock checked: 147 | Affected: Total Stock
[2025-03-17 01:46:24,604] INFO in logger: [GET_REVENUE] User 1: Revenue calculated: 150.00 | Affected: Revenue
[2025-03-17 01:46:24,612] INFO in logger: [COMPARE_SALES] User 1: Sales compared: -100% | Affected: Sales Comparison
[2025-03-17 01:48:16,632] INFO in logger: [CHECK_TOKEN_VALID] User 1: Token is valid | Affected: Token System
[2025-03-17 01:48:16,697] INFO in logger: [GET_ALL_WINES] User 1: Fetched all wines | Affected: All Wines
[2025-03-17 01:48:46,804] INFO in logger: [UPDATE_WINE_SUCCESS] User 1: Updated Red wine | Affected: Red wine
[2025-03-17 01:49:59,053] INFO in logger: [CHECK_TOKEN_VALID] User 1: Token is valid | Affected: Token System
[2025-03-17 01:49:59,141] INFO in logger: [GET_ALL_WINES] User 1: Fetched all wines | Affected: All Wines
[2025-03-17 01:58:14,602] INFO in logger: [CHECK_TOKEN_VALID] User 1: Token is valid | Affected: Token System
[2025-03-17 01:58:14,824] INFO in logger: [GET_ALL_WINES] User 1: Fetched all wines | Affected: All Wines
[2025-03-17 01:59:12,557] INFO in logger: [UPDATE_WINE_SUCCESS] User 1: Updated Sparkling wine | Affected: Sparkling wine
[2025-03-17 02:01:00,542] INFO in logger: [GET_USERS_SUCCESS] User 1: Admin retrieved user list | Affected: User Management
[2025-03-17 02:01:10,979] ERROR in logger: [EXCEPTION] User None: Unhandled exception: NotFound
[2025-03-17 02:01:10,983] ERROR in app: Exception on /users/4 [OPTIONS]
Traceback (most recent call last):
  File "/Users/macbook/EverythingProgramming/inventory_management_system/majesty-backend/backend/lib/python3.13/site-packages/flask/app.py", line 1463, in wsgi_app
    response = self.full_dispatch_request()
  File "/Users/macbook/EverythingProgramming/inventory_management_system/majesty-backend/backend/lib/python3.13/site-packages/flask/app.py", line 872, in full_dispatch_request
    rv = self.handle_user_exception(e)
  File "/Users/macbook/EverythingProgramming/inventory_management_system/majesty-backend/backend/lib/python3.13/site-packages/flask_cors/extension.py", line 176, in wrapped_function
    return cors_after_request(app.make_response(f(*args, **kwargs)))
                                                ~^^^^^^^^^^^^^^^^^
  File "/Users/macbook/EverythingProgramming/inventory_management_system/majesty-backend/backend/lib/python3.13/site-packages/flask_cors/extension.py", line 176, in wrapped_function
    return cors_after_request(app.make_response(f(*args, **kwargs)))
                                                ~^^^^^^^^^^^^^^^^^
  File "/Users/macbook/EverythingProgramming/inventory_management_system/majesty-backend/backend/lib/python3.13/site-packages/flask/app.py", line 755, in handle_user_exception
    return self.handle_http_exception(e)
           ~~~~~~~~~~~~~~~~~~~~~~~~~~^^^
  File "/Users/macbook/EverythingProgramming/inventory_management_system/majesty-backend/backend/lib/python3.13/site-packages/flask/app.py", line 730, in handle_http_exception
    return self.ensure_sync(handler)(e)  # type: ignore[no-any-return]
           ~~~~~~~~~~~~~~~~~~~~~~~~~^^^
  File "/Users/macbook/EverythingProgramming/inventory_management_system/majesty-backend/app/utils/logger.py", line 194, in log_exception
    raise exception
  File "/Users/macbook/EverythingProgramming/inventory_management_system/majesty-backend/backend/lib/python3.13/site-packages/flask/app.py", line 870, in full_dispatch_request
    rv = self.dispatch_request()
  File "/Users/macbook/EverythingProgramming/inventory_management_system/majesty-backend/backend/lib/python3.13/site-packages/flask/app.py", line 844, in dispatch_request
    self.raise_routing_exception(req)
    ~~~~~~~~~~~~~~~~~~~~~~~~~~~~^^^^^
  File "/Users/macbook/EverythingProgramming/inventory_management_system/majesty-backend/backend/lib/python3.13/site-packages/flask/app.py", line 453, in raise_routing_exception
    raise request.routing_exception  # type: ignore[misc]
    ^^^^^^^^^^^^^^^^^^^^^^^^^^^^^^^
  File "/Users/macbook/EverythingProgramming/inventory_management_system/majesty-backend/backend/lib/python3.13/site-packages/flask/ctx.py", line 362, in match_request
    result = self.url_adapter.match(return_rule=True)  # type: ignore
  File "/Users/macbook/EverythingProgramming/inventory_management_system/majesty-backend/backend/lib/python3.13/site-packages/werkzeug/routing/map.py", line 629, in match
    raise NotFound() from None
werkzeug.exceptions.NotFound: 404 Not Found: The requested URL was not found on the server. If you entered the URL manually please check your spelling and try again.
[2025-03-17 02:01:10,990] ERROR in logger: [EXCEPTION] User None: Unhandled exception: InternalServerError
[2025-03-17 02:01:30,290] ERROR in logger: [EXCEPTION] User None: Unhandled exception: NotFound
[2025-03-17 02:01:30,295] ERROR in app: Exception on /users/3 [OPTIONS]
Traceback (most recent call last):
  File "/Users/macbook/EverythingProgramming/inventory_management_system/majesty-backend/backend/lib/python3.13/site-packages/flask/app.py", line 1463, in wsgi_app
    response = self.full_dispatch_request()
  File "/Users/macbook/EverythingProgramming/inventory_management_system/majesty-backend/backend/lib/python3.13/site-packages/flask/app.py", line 872, in full_dispatch_request
    rv = self.handle_user_exception(e)
  File "/Users/macbook/EverythingProgramming/inventory_management_system/majesty-backend/backend/lib/python3.13/site-packages/flask_cors/extension.py", line 176, in wrapped_function
    return cors_after_request(app.make_response(f(*args, **kwargs)))
                                                ~^^^^^^^^^^^^^^^^^
  File "/Users/macbook/EverythingProgramming/inventory_management_system/majesty-backend/backend/lib/python3.13/site-packages/flask_cors/extension.py", line 176, in wrapped_function
    return cors_after_request(app.make_response(f(*args, **kwargs)))
                                                ~^^^^^^^^^^^^^^^^^
  File "/Users/macbook/EverythingProgramming/inventory_management_system/majesty-backend/backend/lib/python3.13/site-packages/flask/app.py", line 755, in handle_user_exception
    return self.handle_http_exception(e)
           ~~~~~~~~~~~~~~~~~~~~~~~~~~^^^
  File "/Users/macbook/EverythingProgramming/inventory_management_system/majesty-backend/backend/lib/python3.13/site-packages/flask/app.py", line 730, in handle_http_exception
    return self.ensure_sync(handler)(e)  # type: ignore[no-any-return]
           ~~~~~~~~~~~~~~~~~~~~~~~~~^^^
  File "/Users/macbook/EverythingProgramming/inventory_management_system/majesty-backend/app/utils/logger.py", line 194, in log_exception
    raise exception
  File "/Users/macbook/EverythingProgramming/inventory_management_system/majesty-backend/backend/lib/python3.13/site-packages/flask/app.py", line 870, in full_dispatch_request
    rv = self.dispatch_request()
  File "/Users/macbook/EverythingProgramming/inventory_management_system/majesty-backend/backend/lib/python3.13/site-packages/flask/app.py", line 844, in dispatch_request
    self.raise_routing_exception(req)
    ~~~~~~~~~~~~~~~~~~~~~~~~~~~~^^^^^
  File "/Users/macbook/EverythingProgramming/inventory_management_system/majesty-backend/backend/lib/python3.13/site-packages/flask/app.py", line 453, in raise_routing_exception
    raise request.routing_exception  # type: ignore[misc]
    ^^^^^^^^^^^^^^^^^^^^^^^^^^^^^^^
  File "/Users/macbook/EverythingProgramming/inventory_management_system/majesty-backend/backend/lib/python3.13/site-packages/flask/ctx.py", line 362, in match_request
    result = self.url_adapter.match(return_rule=True)  # type: ignore
  File "/Users/macbook/EverythingProgramming/inventory_management_system/majesty-backend/backend/lib/python3.13/site-packages/werkzeug/routing/map.py", line 629, in match
    raise NotFound() from None
werkzeug.exceptions.NotFound: 404 Not Found: The requested URL was not found on the server. If you entered the URL manually please check your spelling and try again.
[2025-03-17 02:01:30,299] ERROR in logger: [EXCEPTION] User None: Unhandled exception: InternalServerError
[2025-03-17 02:02:05,056] INFO in logger: [GET_REVENUE] User 1: Revenue calculated: 150.00 | Affected: Revenue
[2025-03-17 02:02:05,061] INFO in logger: [GET_STOCK_BY_CATEGORY] User 1: Stock by category fetched successfully | Affected: Stock by Category
[2025-03-17 02:02:05,068] INFO in logger: [GET_TOTAL_STOCK] User 1: Total stock checked: 147 | Affected: Total Stock
[2025-03-17 02:02:05,070] INFO in logger: [COMPARE_SALES] User 1: Sales compared: -100% | Affected: Sales Comparison
[2025-03-17 02:03:47,517] INFO in logger: [CHECK_TOKEN_VALID] User 1: Token is valid | Affected: Token System
[2025-03-17 02:03:47,693] INFO in logger: [GET_REVENUE] User 1: Revenue calculated: 150.00 | Affected: Revenue
[2025-03-17 02:03:47,713] INFO in logger: [GET_STOCK_BY_CATEGORY] User 1: Stock by category fetched successfully | Affected: Stock by Category
[2025-03-17 02:03:47,716] INFO in logger: [GET_TOTAL_STOCK] User 1: Total stock checked: 147 | Affected: Total Stock
[2025-03-17 02:03:47,721] INFO in logger: [COMPARE_SALES] User 1: Sales compared: -100% | Affected: Sales Comparison
[2025-03-17 02:03:55,844] INFO in logger: [CHECK_TOKEN_VALID] User 1: Token is valid | Affected: Token System
[2025-03-17 02:03:56,075] INFO in logger: [GET_REVENUE] User 1: Revenue calculated: 150.00 | Affected: Revenue
[2025-03-17 02:03:56,086] INFO in logger: [GET_STOCK_BY_CATEGORY] User 1: Stock by category fetched successfully | Affected: Stock by Category
[2025-03-17 02:03:56,094] INFO in logger: [GET_TOTAL_STOCK] User 1: Total stock checked: 147 | Affected: Total Stock
[2025-03-17 02:03:56,101] INFO in logger: [COMPARE_SALES] User 1: Sales compared: -100% | Affected: Sales Comparison
[2025-03-17 02:05:15,730] INFO in logger: [LOGIN_SUCCESS] User 1: User logged in successfully | Affected: admin
[2025-03-17 02:05:39,741] INFO in logger: [GET_REVENUE] User 1: Revenue calculated: 0 | Affected: Revenue
[2025-03-17 02:06:31,837] INFO in logger: [GET_REVENUE] User 1: Revenue calculated: 150.00 | Affected: Revenue
[2025-03-17 02:09:13,480] INFO in logger: [CHECK_TOKEN_VALID] User 1: Token is valid | Affected: Token System
[2025-03-17 02:09:13,671] INFO in logger: [GET_REVENUE] User 1: Revenue calculated: 150.00 | Affected: Revenue
[2025-03-17 02:09:13,673] INFO in logger: [GET_STOCK_BY_CATEGORY] User 1: Stock by category fetched successfully | Affected: Stock by Category
[2025-03-17 02:09:13,676] INFO in logger: [COMPARE_SALES] User 1: Sales compared: -100% | Affected: Sales Comparison
[2025-03-17 02:09:13,676] INFO in logger: [GET_TOTAL_STOCK] User 1: Total stock checked: 147 | Affected: Total Stock
[2025-03-17 02:09:31,833] INFO in logger: [CHECK_TOKEN_VALID] User 1: Token is valid | Affected: Token System
[2025-03-17 02:09:31,997] INFO in logger: [GET_REVENUE] User 1: Revenue calculated: 150.00 | Affected: Revenue
[2025-03-17 02:09:31,998] INFO in logger: [GET_TOTAL_STOCK] User 1: Total stock checked: 147 | Affected: Total Stock
[2025-03-17 02:09:32,004] INFO in logger: [GET_STOCK_BY_CATEGORY] User 1: Stock by category fetched successfully | Affected: Stock by Category
[2025-03-17 02:09:32,025] INFO in logger: [COMPARE_SALES] User 1: Sales compared: -100% | Affected: Sales Comparison
[2025-03-17 02:12:27,416] INFO in logger: [CHECK_TOKEN_VALID] User 1: Token is valid | Affected: Token System
[2025-03-17 02:12:27,637] INFO in logger: [GET_REVENUE] User 1: Revenue calculated: 150.00 | Affected: Revenue
[2025-03-17 02:12:27,657] INFO in logger: [GET_STOCK_BY_CATEGORY] User 1: Stock by category fetched successfully | Affected: Stock by Category
[2025-03-17 02:12:27,663] INFO in logger: [GET_TOTAL_STOCK] User 1: Total stock checked: 147 | Affected: Total Stock
[2025-03-17 02:12:27,711] INFO in logger: [COMPARE_SALES] User 1: Sales compared: -100% | Affected: Sales Comparison
[2025-03-17 02:13:39,931] INFO in logger: [CHECK_TOKEN_VALID] User 1: Token is valid | Affected: Token System
[2025-03-17 02:13:40,194] INFO in logger: [GET_REVENUE] User 1: Revenue calculated: 150.00 | Affected: Revenue
[2025-03-17 02:13:40,196] INFO in logger: [GET_STOCK_BY_CATEGORY] User 1: Stock by category fetched successfully | Affected: Stock by Category
[2025-03-17 02:13:40,199] INFO in logger: [GET_TOTAL_STOCK] User 1: Total stock checked: 147 | Affected: Total Stock
[2025-03-17 02:13:40,215] INFO in logger: [COMPARE_SALES] User 1: Sales compared: -100% | Affected: Sales Comparison
[2025-03-17 02:14:42,555] INFO in logger: [CHECK_TOKEN_VALID] User 1: Token is valid | Affected: Token System
[2025-03-17 02:14:42,838] INFO in logger: [GET_REVENUE] User 1: Revenue calculated: 150.00 | Affected: Revenue
[2025-03-17 02:14:42,841] INFO in logger: [GET_STOCK_BY_CATEGORY] User 1: Stock by category fetched successfully | Affected: Stock by Category
[2025-03-17 02:14:42,843] INFO in logger: [GET_TOTAL_STOCK] User 1: Total stock checked: 147 | Affected: Total Stock
[2025-03-17 02:14:42,856] INFO in logger: [COMPARE_SALES] User 1: Sales compared: -100% | Affected: Sales Comparison
[2025-03-17 02:16:17,623] INFO in logger: [CHECK_TOKEN_VALID] User 1: Token is valid | Affected: Token System
[2025-03-17 02:16:17,889] INFO in logger: [GET_REVENUE] User 1: Revenue calculated: 150.00 | Affected: Revenue
[2025-03-17 02:16:17,896] INFO in logger: [GET_STOCK_BY_CATEGORY] User 1: Stock by category fetched successfully | Affected: Stock by Category
[2025-03-17 02:16:17,904] INFO in logger: [GET_TOTAL_STOCK] User 1: Total stock checked: 147 | Affected: Total Stock
[2025-03-17 02:16:17,919] INFO in logger: [COMPARE_SALES] User 1: Sales compared: -100% | Affected: Sales Comparison
[2025-03-17 02:20:02,591] INFO in logger: [COMPARE_SALES] User 1: Sales compared: 0% | Affected: Sales Comparison
[2025-03-17 02:21:40,032] INFO in logger: [COMPARE_SALES] User 1: Sales compared: -100% | Affected: Sales Comparison
[2025-03-17 02:37:28,491] INFO in logger: [CHECK_TOKEN_VALID] User 1: Token is valid | Affected: Token System
[2025-03-17 02:37:28,859] INFO in logger: [GET_REVENUE] User 1: Revenue calculated: 150.00 | Affected: Revenue
[2025-03-17 02:37:28,866] INFO in logger: [GET_TOTAL_STOCK] User 1: Total stock checked: 147 | Affected: Total Stock
[2025-03-17 02:37:28,872] INFO in logger: [GET_STOCK_BY_CATEGORY] User 1: Stock by category fetched successfully | Affected: Stock by Category
[2025-03-17 02:37:28,877] INFO in logger: [COMPARE_SALES] User 1: Sales compared: -100% | Affected: Sales Comparison
[2025-03-17 02:37:28,908] INFO in logger: [GET_ALL_WINES] User 1: Fetched all wines | Affected: All Wines
[2025-03-17 02:45:08,261] INFO in logger: [GET_USERS_SUCCESS] User 1: Admin retrieved user list | Affected: User Management
[2025-03-17 02:49:56,179] INFO in logger: [CHECK_TOKEN_VALID] User 1: Token is valid | Affected: Token System
[2025-03-17 02:49:56,297] INFO in logger: [GET_REVENUE] User 1: Revenue calculated: 150.00 | Affected: Revenue
[2025-03-17 02:49:56,318] INFO in logger: [GET_STOCK_BY_CATEGORY] User 1: Stock by category fetched successfully | Affected: Stock by Category
[2025-03-17 02:49:56,323] INFO in logger: [GET_TOTAL_STOCK] User 1: Total stock checked: 147 | Affected: Total Stock
[2025-03-17 02:49:56,324] INFO in logger: [COMPARE_SALES] User 1: Sales compared: -100% | Affected: Sales Comparison
[2025-03-17 02:49:56,332] INFO in logger: [GET_ALL_WINES] User 1: Fetched all wines | Affected: All Wines
[2025-03-17 02:49:56,350] INFO in logger: [GET_USERS_SUCCESS] User 1: Admin retrieved user list | Affected: User Management
[2025-03-17 02:50:13,553] INFO in logger: [CHECK_TOKEN_VALID] User 1: Token is valid | Affected: Token System
[2025-03-17 02:50:13,849] INFO in logger: [GET_REVENUE] User 1: Revenue calculated: 150.00 | Affected: Revenue
[2025-03-17 02:50:13,855] INFO in logger: [GET_STOCK_BY_CATEGORY] User 1: Stock by category fetched successfully | Affected: Stock by Category
[2025-03-17 02:50:13,856] INFO in logger: [GET_TOTAL_STOCK] User 1: Total stock checked: 147 | Affected: Total Stock
[2025-03-17 02:50:13,865] INFO in logger: [COMPARE_SALES] User 1: Sales compared: -100% | Affected: Sales Comparison
[2025-03-17 02:50:13,874] INFO in logger: [GET_ALL_WINES] User 1: Fetched all wines | Affected: All Wines
[2025-03-17 02:50:13,889] INFO in logger: [GET_USERS_SUCCESS] User 1: Admin retrieved user list | Affected: User Management
[2025-03-17 02:50:40,369] INFO in logger: [CHECK_TOKEN_VALID] User 1: Token is valid | Affected: Token System
[2025-03-17 02:50:40,553] INFO in logger: [GET_REVENUE] User 1: Revenue calculated: 150.00 | Affected: Revenue
[2025-03-17 02:50:40,570] INFO in logger: [GET_STOCK_BY_CATEGORY] User 1: Stock by category fetched successfully | Affected: Stock by Category
[2025-03-17 02:50:40,576] INFO in logger: [GET_TOTAL_STOCK] User 1: Total stock checked: 147 | Affected: Total Stock
[2025-03-17 02:50:40,584] INFO in logger: [COMPARE_SALES] User 1: Sales compared: -100% | Affected: Sales Comparison
[2025-03-17 02:50:40,593] INFO in logger: [GET_ALL_WINES] User 1: Fetched all wines | Affected: All Wines
[2025-03-17 02:50:40,618] INFO in logger: [GET_USERS_SUCCESS] User 1: Admin retrieved user list | Affected: User Management
[2025-03-17 02:50:50,234] INFO in logger: [CHECK_TOKEN_VALID] User 1: Token is valid | Affected: Token System
[2025-03-17 02:50:50,595] INFO in logger: [GET_REVENUE] User 1: Revenue calculated: 150.00 | Affected: Revenue
[2025-03-17 02:50:50,599] INFO in logger: [GET_STOCK_BY_CATEGORY] User 1: Stock by category fetched successfully | Affected: Stock by Category
[2025-03-17 02:50:50,601] INFO in logger: [GET_TOTAL_STOCK] User 1: Total stock checked: 147 | Affected: Total Stock
[2025-03-17 02:50:50,672] INFO in logger: [COMPARE_SALES] User 1: Sales compared: -100% | Affected: Sales Comparison
[2025-03-17 02:50:50,704] INFO in logger: [GET_ALL_WINES] User 1: Fetched all wines | Affected: All Wines
[2025-03-17 02:50:50,706] INFO in logger: [GET_USERS_SUCCESS] User 1: Admin retrieved user list | Affected: User Management
[2025-03-17 02:54:29,327] INFO in logger: [CHECK_TOKEN_VALID] User 1: Token is valid | Affected: Token System
[2025-03-17 02:54:29,495] INFO in logger: [GET_REVENUE] User 1: Revenue calculated: 150.00 | Affected: Revenue
[2025-03-17 02:54:29,511] INFO in logger: [GET_STOCK_BY_CATEGORY] User 1: Stock by category fetched successfully | Affected: Stock by Category
[2025-03-17 02:54:29,519] INFO in logger: [GET_TOTAL_STOCK] User 1: Total stock checked: 147 | Affected: Total Stock
[2025-03-17 02:54:29,520] INFO in logger: [COMPARE_SALES] User 1: Sales compared: -100% | Affected: Sales Comparison
[2025-03-17 02:54:29,537] INFO in logger: [GET_ALL_WINES] User 1: Fetched all wines | Affected: All Wines
[2025-03-17 02:54:29,557] INFO in logger: [GET_USERS_SUCCESS] User 1: Admin retrieved user list | Affected: User Management
[2025-03-17 02:56:24,968] INFO in logger: [CHECK_TOKEN_VALID] User 1: Token is valid | Affected: Token System
[2025-03-17 02:56:25,181] INFO in logger: [GET_REVENUE] User 1: Revenue calculated: 150.00 | Affected: Revenue
[2025-03-17 02:56:25,185] INFO in logger: [GET_STOCK_BY_CATEGORY] User 1: Stock by category fetched successfully | Affected: Stock by Category
[2025-03-17 02:56:25,191] INFO in logger: [GET_TOTAL_STOCK] User 1: Total stock checked: 147 | Affected: Total Stock
[2025-03-17 02:56:25,198] INFO in logger: [COMPARE_SALES] User 1: Sales compared: -100% | Affected: Sales Comparison
[2025-03-17 02:56:25,213] INFO in logger: [GET_ALL_WINES] User 1: Fetched all wines | Affected: All Wines
[2025-03-17 02:56:25,228] INFO in logger: [GET_USERS_SUCCESS] User 1: Admin retrieved user list | Affected: User Management
[2025-03-17 02:58:57,505] INFO in logger: [GET_USERS_SUCCESS] User 1: Admin retrieved user list | Affected: User Management
[2025-03-17 03:04:11,512] INFO in logger: [CHECK_TOKEN_VALID] User 1: Token is valid | Affected: Token System
[2025-03-17 03:04:15,369] INFO in logger: [GET_REVENUE] User 1: Revenue calculated: 150.00 | Affected: Revenue
[2025-03-17 03:04:15,405] INFO in logger: [GET_TOTAL_STOCK] User 1: Total stock checked: 147 | Affected: Total Stock
[2025-03-17 03:04:15,405] INFO in logger: [GET_STOCK_BY_CATEGORY] User 1: Stock by category fetched successfully | Affected: Stock by Category
[2025-03-17 03:04:15,417] INFO in logger: [COMPARE_SALES] User 1: Sales compared: -100% | Affected: Sales Comparison
[2025-03-17 03:04:15,421] INFO in logger: [GET_ALL_WINES] User 1: Fetched all wines | Affected: All Wines
[2025-03-17 03:04:15,440] INFO in logger: [GET_USERS_SUCCESS] User 1: Admin retrieved user list | Affected: User Management
[2025-03-17 03:09:09,865] ERROR in logger: [EXCEPTION] User 1: Unhandled exception: UnsupportedMediaType
[2025-03-17 03:09:09,871] ERROR in app: Exception on /wine/2 [PUT]
Traceback (most recent call last):
  File "/Users/macbook/EverythingProgramming/inventory_management_system/majesty-backend/backend/lib/python3.13/site-packages/flask/app.py", line 1463, in wsgi_app
    response = self.full_dispatch_request()
  File "/Users/macbook/EverythingProgramming/inventory_management_system/majesty-backend/backend/lib/python3.13/site-packages/flask/app.py", line 872, in full_dispatch_request
    rv = self.handle_user_exception(e)
  File "/Users/macbook/EverythingProgramming/inventory_management_system/majesty-backend/backend/lib/python3.13/site-packages/flask_cors/extension.py", line 176, in wrapped_function
    return cors_after_request(app.make_response(f(*args, **kwargs)))
                                                ~^^^^^^^^^^^^^^^^^
  File "/Users/macbook/EverythingProgramming/inventory_management_system/majesty-backend/backend/lib/python3.13/site-packages/flask_cors/extension.py", line 176, in wrapped_function
    return cors_after_request(app.make_response(f(*args, **kwargs)))
                                                ~^^^^^^^^^^^^^^^^^
  File "/Users/macbook/EverythingProgramming/inventory_management_system/majesty-backend/backend/lib/python3.13/site-packages/flask/app.py", line 755, in handle_user_exception
    return self.handle_http_exception(e)
           ~~~~~~~~~~~~~~~~~~~~~~~~~~^^^
  File "/Users/macbook/EverythingProgramming/inventory_management_system/majesty-backend/backend/lib/python3.13/site-packages/flask/app.py", line 730, in handle_http_exception
    return self.ensure_sync(handler)(e)  # type: ignore[no-any-return]
           ~~~~~~~~~~~~~~~~~~~~~~~~~^^^
  File "/Users/macbook/EverythingProgramming/inventory_management_system/majesty-backend/app/utils/logger.py", line 194, in log_exception
    raise exception
  File "/Users/macbook/EverythingProgramming/inventory_management_system/majesty-backend/backend/lib/python3.13/site-packages/flask/app.py", line 870, in full_dispatch_request
    rv = self.dispatch_request()
  File "/Users/macbook/EverythingProgramming/inventory_management_system/majesty-backend/backend/lib/python3.13/site-packages/flask/app.py", line 855, in dispatch_request
    return self.ensure_sync(self.view_functions[rule.endpoint])(**view_args)  # type: ignore[no-any-return]
           ~~~~~~~~~~~~~~~~~~~~~~~~~~~~~~~~~~~~~~~~~~~~~~~~~~~~^^^^^^^^^^^^^
  File "/Users/macbook/EverythingProgramming/inventory_management_system/majesty-backend/backend/lib/python3.13/site-packages/flask_jwt_extended/view_decorators.py", line 170, in decorator
    return current_app.ensure_sync(fn)(*args, **kwargs)
           ~~~~~~~~~~~~~~~~~~~~~~~~~~~^^^^^^^^^^^^^^^^^
  File "/Users/macbook/EverythingProgramming/inventory_management_system/majesty-backend/app/routes/wine.py", line 405, in update_wine
    data = request.get_json()
  File "/Users/macbook/EverythingProgramming/inventory_management_system/majesty-backend/backend/lib/python3.13/site-packages/werkzeug/wrappers/request.py", line 604, in get_json
    return self.on_json_loading_failed(None)
           ~~~~~~~~~~~~~~~~~~~~~~~~~~~^^^^^^
  File "/Users/macbook/EverythingProgramming/inventory_management_system/majesty-backend/backend/lib/python3.13/site-packages/flask/wrappers.py", line 131, in on_json_loading_failed
    return super().on_json_loading_failed(e)
           ~~~~~~~~~~~~~~~~~~~~~~~~~~~~~~^^^
  File "/Users/macbook/EverythingProgramming/inventory_management_system/majesty-backend/backend/lib/python3.13/site-packages/werkzeug/wrappers/request.py", line 647, in on_json_loading_failed
    raise UnsupportedMediaType(
    ...<2 lines>...
    )
werkzeug.exceptions.UnsupportedMediaType: 415 Unsupported Media Type: Did not attempt to load JSON data because the request Content-Type was not 'application/json'.
[2025-03-17 03:09:09,888] ERROR in logger: [EXCEPTION] User 1: Unhandled exception: InternalServerError
[2025-03-17 03:12:02,166] INFO in logger: [CHECK_TOKEN_VALID] User 1: Token is valid | Affected: Token System
[2025-03-17 03:12:02,550] INFO in logger: [GET_ALL_WINES] User 1: Fetched all wines | Affected: All Wines
[2025-03-17 03:15:00,823] INFO in logger: [DELETE_WINE_SUCCESS] User 1: Deleted Sparkling wine | Affected: Sparkling wine
[2025-03-17 03:15:07,356] INFO in logger: [CHECK_TOKEN_VALID] User 1: Token is valid | Affected: Token System
[2025-03-17 03:15:07,452] INFO in logger: [GET_ALL_WINES] User 1: Fetched all wines | Affected: All Wines
[2025-03-17 03:16:09,281] INFO in logger: [ADD_WINE_SUCCESS] User 1: Added wine: Cloudy Bay Sauvignon Blanc | Affected: Cloudy Bay Sauvignon Blanc
[2025-03-17 03:16:16,936] INFO in logger: [CHECK_TOKEN_VALID] User 1: Token is valid | Affected: Token System
[2025-03-17 03:16:17,009] INFO in logger: [GET_ALL_WINES] User 1: Fetched all wines | Affected: All Wines
[2025-03-17 03:16:38,242] INFO in logger: [UPDATE_WINE_SUCCESS] User 1: Updated Cabernet Sauvignon | Affected: Cabernet Sauvignon
[2025-03-17 03:16:52,204] INFO in logger: [UPDATE_WINE_SUCCESS] User 1: Updated Cloudy Bay Sauvignon Blanc | Affected: Cloudy Bay Sauvignon Blanc
[2025-03-17 03:16:56,691] INFO in logger: [CHECK_TOKEN_VALID] User 1: Token is valid | Affected: Token System
[2025-03-17 03:16:56,780] INFO in logger: [GET_ALL_WINES] User 1: Fetched all wines | Affected: All Wines
[2025-03-17 03:18:13,577] INFO in logger: [UPDATE_WINE_SUCCESS] User 1: Updated Graham’s 20 Year Old Tawny | Affected: Graham’s 20 Year Old Tawny
[2025-03-17 03:18:18,906] INFO in logger: [CHECK_TOKEN_VALID] User 1: Token is valid | Affected: Token System
[2025-03-17 03:18:19,027] INFO in logger: [GET_ALL_WINES] User 1: Fetched all wines | Affected: All Wines
[2025-03-17 03:19:28,531] INFO in logger: [CHECK_TOKEN_VALID] User 1: Token is valid | Affected: Token System
[2025-03-17 03:19:28,701] INFO in logger: [GET_ALL_WINES] User 1: Fetched all wines | Affected: All Wines
[2025-03-17 03:19:37,717] INFO in logger: [CHECK_TOKEN_VALID] User 1: Token is valid | Affected: Token System
[2025-03-17 03:19:37,800] INFO in logger: [GET_ALL_WINES] User 1: Fetched all wines | Affected: All Wines
[2025-03-17 03:19:49,917] INFO in logger: [CHECK_TOKEN_VALID] User 1: Token is valid | Affected: Token System
[2025-03-17 03:19:50,047] INFO in logger: [GET_ALL_WINES] User 1: Fetched all wines | Affected: All Wines
[2025-03-17 03:20:09,127] INFO in logger: [CHECK_TOKEN_VALID] User 1: Token is valid | Affected: Token System
[2025-03-17 03:20:09,241] INFO in logger: [GET_ALL_WINES] User 1: Fetched all wines | Affected: All Wines
[2025-03-17 03:20:44,271] INFO in logger: [GET_REVENUE] User 1: Revenue calculated: 150.00 | Affected: Revenue
[2025-03-17 03:20:44,274] INFO in logger: [GET_STOCK_BY_CATEGORY] User 1: Stock by category fetched successfully | Affected: Stock by Category
[2025-03-17 03:20:44,282] INFO in logger: [GET_TOTAL_STOCK] User 1: Total stock checked: 58 | Affected: Total Stock
[2025-03-17 03:20:44,286] INFO in logger: [COMPARE_SALES] User 1: Sales compared: -100% | Affected: Sales Comparison
[2025-03-17 03:20:44,301] INFO in logger: [GET_USERS_SUCCESS] User 1: Admin retrieved user list | Affected: User Management
[2025-03-17 03:23:10,936] INFO in logger: [CHECK_TOKEN_VALID] User 1: Token is valid | Affected: Token System
[2025-03-17 03:23:33,370] INFO in logger: [CHECK_TOKEN_VALID] User 1: Token is valid | Affected: Token System
[2025-03-17 03:24:11,348] INFO in logger: [CHECK_TOKEN_VALID] User 1: Token is valid | Affected: Token System
[2025-03-17 03:24:34,275] INFO in logger: [GET_ALL_WINES] User 1: Fetched all wines | Affected: All Wines
[2025-03-17 03:25:39,903] INFO in logger: [GET_ALL_WINES] User 1: Fetched all wines | Affected: All Wines
[2025-03-17 03:25:41,402] INFO in logger: [GET_REVENUE] User 1: Revenue calculated: 150.00 | Affected: Revenue
[2025-03-17 03:25:41,413] INFO in logger: [GET_STOCK_BY_CATEGORY] User 1: Stock by category fetched successfully | Affected: Stock by Category
[2025-03-17 03:25:41,433] INFO in logger: [GET_TOTAL_STOCK] User 1: Total stock checked: 58 | Affected: Total Stock
[2025-03-17 03:25:41,434] INFO in logger: [COMPARE_SALES] User 1: Sales compared: -100% | Affected: Sales Comparison
[2025-03-17 03:25:41,446] INFO in logger: [GET_USERS_SUCCESS] User 1: Admin retrieved user list | Affected: User Management
[2025-03-17 08:57:37,734] INFO in logger: Wine Inventory API Started - Environment: development
[2025-03-17 08:58:14,743] INFO in logger: [CHECK_TOKEN_VALID] User 1: Token is valid | Affected: Token System
[2025-03-17 08:58:14,960] INFO in logger: [GET_TOTAL_STOCK] User 1: Total stock checked: 58 | Affected: Total Stock
[2025-03-17 08:58:14,976] INFO in logger: [GET_STOCK_BY_CATEGORY] User 1: Stock by category fetched successfully | Affected: Stock by Category
[2025-03-17 08:58:14,996] INFO in logger: [GET_REVENUE] User 1: Revenue calculated: 150.00 | Affected: Revenue
[2025-03-17 08:58:14,997] INFO in logger: [COMPARE_SALES] User 1: Sales compared: -100% | Affected: Sales Comparison
[2025-03-17 08:58:14,997] INFO in logger: [GET_ALL_WINES] User 1: Fetched all wines | Affected: All Wines
[2025-03-17 08:58:15,083] INFO in logger: [GET_USERS_SUCCESS] User 1: Admin retrieved user list | Affected: User Management
[2025-03-18 13:13:10,379] INFO in logger: Wine Inventory API Started - Environment: development
=======
  File "/Users/macbookpro/Documents/projects/WSS/venv/lib/python3.11/site-packages/sqlalchemy/engine/base.py", line 1964, in _exec_single_context
    self.dialect.do_execute(
  File "/Users/macbookpro/Documents/projects/WSS/venv/lib/python3.11/site-packages/sqlalchemy/engine/default.py", line 942, in do_execute
    cursor.execute(statement, parameters)
sqlalchemy.exc.IntegrityError: (sqlite3.IntegrityError) UNIQUE constraint failed: blacklisted_tokens.jti
[SQL: INSERT INTO blacklisted_tokens (jti, created_at) VALUES (?, ?)]
[parameters: ('eead7c66-2e49-4352-96eb-380f6d2633eb', '2025-03-17 14:19:40.089492')]
(Background on this error at: https://sqlalche.me/e/20/gkpj)
[2025-03-17 15:19:40,144] ERROR in logger: [EXCEPTION] User 1: Unhandled exception: InternalServerError
[2025-03-17 15:19:49,956] INFO in logger: [LOGOUT] User 1: User logged out | Affected: admin
[2025-03-17 15:30:17,991] INFO in logger: Wine Inventory API Started - Environment: development
[2025-03-17 15:30:21,033] INFO in logger: [LOGIN_SUCCESS] User 1: User logged in successfully | Affected: admin
[2025-03-17 15:30:41,057] INFO in logger: [GET_REVENUE] User 1: Revenue calculated: 0 | Affected: Revenue
[2025-03-17 15:30:49,853] INFO in logger: [LOGOUT] User 1: User logged out | Affected: admin
[2025-03-17 15:32:40,224] INFO in logger: Wine Inventory API Started - Environment: development
[2025-03-17 15:32:45,262] INFO in logger: [LOGIN_SUCCESS] User 1: User logged in successfully | Affected: admin
[2025-03-17 15:32:56,646] INFO in logger: [GET_REVENUE] User 1: Revenue calculated: 0 | Affected: Revenue
[2025-03-17 15:33:03,066] INFO in logger: [LOGOUT] User 1: User logged out | Affected: admin
>>>>>>> 820885401de541d70c94d614081eca1acca6416a
