[2025-03-07 15:59:40,949] INFO in logger: Wine Inventory API Started - Environment: development
[2025-03-07 15:59:51,387] INFO in logger: Wine Inventory API Started - Environment: development
[2025-03-07 15:59:59,108] INFO in logger: Wine Inventory API Started - Environment: development
[2025-03-07 16:00:25,111] INFO in logger: Wine Inventory API Started - Environment: development
[2025-03-07 16:00:38,702] INFO in logger: Wine Inventory API Started - Environment: development
[2025-03-07 16:00:43,549] INFO in logger: [LOGIN_SUCCESS] User 1: User logged in successfully
[2025-03-08 00:09:44,789] INFO in logger: Wine Inventory API Started - Environment: development
[2025-03-08 00:10:30,046] INFO in logger: [LOGIN_FAILURE] User None: Invalid login attempt
[2025-03-08 00:11:02,074] INFO in logger: [LOGIN_SUCCESS] User 1: User logged in successfully
[2025-03-08 00:11:10,583] INFO in logger: [LOGIN_SUCCESS] User 1: User logged in successfully
[2025-03-08 00:13:20,437] INFO in logger: [LOGIN_FAILURE] User None: Invalid login attempt
[2025-03-08 00:13:47,784] INFO in logger: [LOGIN_FAILURE] User None: Invalid login attempt
[2025-03-08 00:13:49,850] INFO in logger: [LOGIN_FAILURE] User None: Invalid login attempt
[2025-03-08 00:14:06,996] INFO in logger: [LOGIN_SUCCESS] User 1: User logged in successfully
[2025-03-08 00:15:50,394] INFO in logger: [LOGIN_SUCCESS] User 1: User logged in successfully
[2025-03-08 00:16:09,741] INFO in logger: [LOGIN_SUCCESS] User 1: User logged in successfully
[2025-03-08 00:19:06,543] INFO in logger: [LOGIN_SUCCESS] User 1: User logged in successfully
[2025-03-08 00:19:26,024] INFO in logger: [LOGIN_SUCCESS] User 1: User logged in successfully
[2025-03-08 00:23:15,465] INFO in logger: [LOGIN_SUCCESS] User 1: User logged in successfully
[2025-03-08 00:36:18,096] INFO in logger: [LOGIN_FAILURE] User None: Invalid login attempt
[2025-03-08 00:36:32,836] INFO in logger: [LOGIN_SUCCESS] User 1: User logged in successfully
[2025-03-08 00:36:44,050] INFO in logger: [LOGIN_SUCCESS] User 1: User logged in successfully
[2025-03-08 00:37:47,789] INFO in logger: [LOGIN_SUCCESS] User 1: User logged in successfully
[2025-03-08 00:37:50,219] INFO in logger: [LOGIN_SUCCESS] User 1: User logged in successfully
[2025-03-08 00:37:51,281] INFO in logger: [LOGIN_SUCCESS] User 1: User logged in successfully
[2025-03-08 00:37:52,311] INFO in logger: [LOGIN_SUCCESS] User 1: User logged in successfully
[2025-03-08 00:37:53,668] INFO in logger: [LOGIN_SUCCESS] User 1: User logged in successfully
[2025-03-08 00:38:14,988] INFO in logger: [LOGIN_SUCCESS] User 1: User logged in successfully
[2025-03-08 00:39:25,184] INFO in logger: [LOGIN_SUCCESS] User 1: User logged in successfully
[2025-03-08 00:39:37,008] INFO in logger: [LOGIN_SUCCESS] User 1: User logged in successfully
[2025-03-08 00:39:54,451] INFO in logger: [LOGIN_SUCCESS] User 1: User logged in successfully
[2025-03-08 00:40:23,126] INFO in logger: [LOGIN_SUCCESS] User 1: User logged in successfully
[2025-03-08 00:40:24,727] INFO in logger: [LOGIN_SUCCESS] User 1: User logged in successfully
[2025-03-08 00:40:24,897] INFO in logger: [LOGIN_SUCCESS] User 1: User logged in successfully
[2025-03-08 00:40:25,105] INFO in logger: [LOGIN_SUCCESS] User 1: User logged in successfully
[2025-03-08 00:40:25,224] INFO in logger: [LOGIN_SUCCESS] User 1: User logged in successfully
[2025-03-08 00:40:25,379] INFO in logger: [LOGIN_SUCCESS] User 1: User logged in successfully
[2025-03-08 00:40:25,486] INFO in logger: [LOGIN_SUCCESS] User 1: User logged in successfully
[2025-03-08 00:40:25,658] INFO in logger: [LOGIN_SUCCESS] User 1: User logged in successfully
[2025-03-08 00:40:25,831] INFO in logger: [LOGIN_SUCCESS] User 1: User logged in successfully
[2025-03-08 00:40:25,939] INFO in logger: [LOGIN_SUCCESS] User 1: User logged in successfully
[2025-03-08 00:42:13,258] INFO in logger: [LOGIN_SUCCESS] User 1: User logged in successfully
[2025-03-08 00:42:14,694] INFO in logger: [LOGIN_SUCCESS] User 1: User logged in successfully
[2025-03-08 00:42:14,905] INFO in logger: [LOGIN_SUCCESS] User 1: User logged in successfully
[2025-03-08 00:42:15,141] INFO in logger: [LOGIN_SUCCESS] User 1: User logged in successfully
[2025-03-08 00:42:15,311] INFO in logger: [LOGIN_SUCCESS] User 1: User logged in successfully
[2025-03-08 00:42:15,504] INFO in logger: [LOGIN_SUCCESS] User 1: User logged in successfully
[2025-03-08 00:43:16,063] INFO in logger: [LOGIN_SUCCESS] User 1: User logged in successfully
[2025-03-08 00:43:19,574] INFO in logger: [LOGIN_SUCCESS] User 1: User logged in successfully
[2025-03-08 00:45:25,077] INFO in logger: [LOGIN_SUCCESS] User 1: User logged in successfully
[2025-03-08 00:47:33,952] INFO in logger: [LOGIN_SUCCESS] User 1: User logged in successfully
[2025-03-08 00:47:45,607] INFO in logger: [LOGIN_ATTEMPT] User None: Failed login attempt - missing credentials
[2025-03-08 00:48:27,637] INFO in logger: [LOGIN_SUCCESS] User 1: User logged in successfully
[2025-03-08 00:52:54,293] INFO in logger: [LOGIN_SUCCESS] User 1: User logged in successfully
[2025-03-08 00:55:13,691] INFO in logger: [LOGIN_SUCCESS] User 1: User logged in successfully
[2025-03-08 01:04:09,708] ERROR in logger: [EXCEPTION] User None: Unhandled exception: NotFound
[2025-03-08 01:04:09,716] ERROR in app: Exception on /wines [GET]
Traceback (most recent call last):
  File "/Users/macbook/EverythingProgramming/inventory_management_system/majesty-backend/venv/lib/python3.13/site-packages/flask/app.py", line 1463, in wsgi_app
    response = self.full_dispatch_request()
  File "/Users/macbook/EverythingProgramming/inventory_management_system/majesty-backend/venv/lib/python3.13/site-packages/flask/app.py", line 872, in full_dispatch_request
    rv = self.handle_user_exception(e)
  File "/Users/macbook/EverythingProgramming/inventory_management_system/majesty-backend/venv/lib/python3.13/site-packages/flask_cors/extension.py", line 176, in wrapped_function
    return cors_after_request(app.make_response(f(*args, **kwargs)))
                                                ~^^^^^^^^^^^^^^^^^
  File "/Users/macbook/EverythingProgramming/inventory_management_system/majesty-backend/venv/lib/python3.13/site-packages/flask/app.py", line 755, in handle_user_exception
    return self.handle_http_exception(e)
           ~~~~~~~~~~~~~~~~~~~~~~~~~~^^^
  File "/Users/macbook/EverythingProgramming/inventory_management_system/majesty-backend/venv/lib/python3.13/site-packages/flask/app.py", line 730, in handle_http_exception
    return self.ensure_sync(handler)(e)  # type: ignore[no-any-return]
           ~~~~~~~~~~~~~~~~~~~~~~~~~^^^
  File "/Users/macbook/EverythingProgramming/inventory_management_system/majesty-backend/app/utils/logger.py", line 184, in log_exception
    raise exception
  File "/Users/macbook/EverythingProgramming/inventory_management_system/majesty-backend/venv/lib/python3.13/site-packages/flask/app.py", line 870, in full_dispatch_request
    rv = self.dispatch_request()
  File "/Users/macbook/EverythingProgramming/inventory_management_system/majesty-backend/venv/lib/python3.13/site-packages/flask/app.py", line 844, in dispatch_request
    self.raise_routing_exception(req)
    ~~~~~~~~~~~~~~~~~~~~~~~~~~~~^^^^^
  File "/Users/macbook/EverythingProgramming/inventory_management_system/majesty-backend/venv/lib/python3.13/site-packages/flask/app.py", line 453, in raise_routing_exception
    raise request.routing_exception  # type: ignore[misc]
    ^^^^^^^^^^^^^^^^^^^^^^^^^^^^^^^
  File "/Users/macbook/EverythingProgramming/inventory_management_system/majesty-backend/venv/lib/python3.13/site-packages/flask/ctx.py", line 362, in match_request
    result = self.url_adapter.match(return_rule=True)  # type: ignore
  File "/Users/macbook/EverythingProgramming/inventory_management_system/majesty-backend/venv/lib/python3.13/site-packages/werkzeug/routing/map.py", line 629, in match
    raise NotFound() from None
werkzeug.exceptions.NotFound: 404 Not Found: The requested URL was not found on the server. If you entered the URL manually please check your spelling and try again.
[2025-03-08 01:04:09,726] ERROR in logger: [EXCEPTION] User None: Unhandled exception: InternalServerError
[2025-03-08 01:04:34,273] ERROR in logger: [EXCEPTION] User None: Unhandled exception: NotFound
[2025-03-08 01:04:34,279] ERROR in app: Exception on /wine/total_stock [GET]
Traceback (most recent call last):
  File "/Users/macbook/EverythingProgramming/inventory_management_system/majesty-backend/venv/lib/python3.13/site-packages/flask/app.py", line 1463, in wsgi_app
    response = self.full_dispatch_request()
  File "/Users/macbook/EverythingProgramming/inventory_management_system/majesty-backend/venv/lib/python3.13/site-packages/flask/app.py", line 872, in full_dispatch_request
    rv = self.handle_user_exception(e)
  File "/Users/macbook/EverythingProgramming/inventory_management_system/majesty-backend/venv/lib/python3.13/site-packages/flask_cors/extension.py", line 176, in wrapped_function
    return cors_after_request(app.make_response(f(*args, **kwargs)))
                                                ~^^^^^^^^^^^^^^^^^
  File "/Users/macbook/EverythingProgramming/inventory_management_system/majesty-backend/venv/lib/python3.13/site-packages/flask/app.py", line 755, in handle_user_exception
    return self.handle_http_exception(e)
           ~~~~~~~~~~~~~~~~~~~~~~~~~~^^^
  File "/Users/macbook/EverythingProgramming/inventory_management_system/majesty-backend/venv/lib/python3.13/site-packages/flask/app.py", line 730, in handle_http_exception
    return self.ensure_sync(handler)(e)  # type: ignore[no-any-return]
           ~~~~~~~~~~~~~~~~~~~~~~~~~^^^
  File "/Users/macbook/EverythingProgramming/inventory_management_system/majesty-backend/app/utils/logger.py", line 184, in log_exception
    raise exception
  File "/Users/macbook/EverythingProgramming/inventory_management_system/majesty-backend/venv/lib/python3.13/site-packages/flask/app.py", line 870, in full_dispatch_request
    rv = self.dispatch_request()
  File "/Users/macbook/EverythingProgramming/inventory_management_system/majesty-backend/venv/lib/python3.13/site-packages/flask/app.py", line 844, in dispatch_request
    self.raise_routing_exception(req)
    ~~~~~~~~~~~~~~~~~~~~~~~~~~~~^^^^^
  File "/Users/macbook/EverythingProgramming/inventory_management_system/majesty-backend/venv/lib/python3.13/site-packages/flask/app.py", line 453, in raise_routing_exception
    raise request.routing_exception  # type: ignore[misc]
    ^^^^^^^^^^^^^^^^^^^^^^^^^^^^^^^
  File "/Users/macbook/EverythingProgramming/inventory_management_system/majesty-backend/venv/lib/python3.13/site-packages/flask/ctx.py", line 362, in match_request
    result = self.url_adapter.match(return_rule=True)  # type: ignore
  File "/Users/macbook/EverythingProgramming/inventory_management_system/majesty-backend/venv/lib/python3.13/site-packages/werkzeug/routing/map.py", line 629, in match
    raise NotFound() from None
werkzeug.exceptions.NotFound: 404 Not Found: The requested URL was not found on the server. If you entered the URL manually please check your spelling and try again.
[2025-03-08 01:04:34,284] ERROR in logger: [EXCEPTION] User None: Unhandled exception: InternalServerError
[2025-03-08 01:05:17,786] ERROR in logger: [EXCEPTION] User None: Unhandled exception: NotFound
[2025-03-08 01:05:17,793] ERROR in app: Exception on /wine/stock_by_category [GET]
Traceback (most recent call last):
  File "/Users/macbook/EverythingProgramming/inventory_management_system/majesty-backend/venv/lib/python3.13/site-packages/flask/app.py", line 1463, in wsgi_app
    response = self.full_dispatch_request()
  File "/Users/macbook/EverythingProgramming/inventory_management_system/majesty-backend/venv/lib/python3.13/site-packages/flask/app.py", line 872, in full_dispatch_request
    rv = self.handle_user_exception(e)
  File "/Users/macbook/EverythingProgramming/inventory_management_system/majesty-backend/venv/lib/python3.13/site-packages/flask_cors/extension.py", line 176, in wrapped_function
    return cors_after_request(app.make_response(f(*args, **kwargs)))
                                                ~^^^^^^^^^^^^^^^^^
  File "/Users/macbook/EverythingProgramming/inventory_management_system/majesty-backend/venv/lib/python3.13/site-packages/flask/app.py", line 755, in handle_user_exception
    return self.handle_http_exception(e)
           ~~~~~~~~~~~~~~~~~~~~~~~~~~^^^
  File "/Users/macbook/EverythingProgramming/inventory_management_system/majesty-backend/venv/lib/python3.13/site-packages/flask/app.py", line 730, in handle_http_exception
    return self.ensure_sync(handler)(e)  # type: ignore[no-any-return]
           ~~~~~~~~~~~~~~~~~~~~~~~~~^^^
  File "/Users/macbook/EverythingProgramming/inventory_management_system/majesty-backend/app/utils/logger.py", line 184, in log_exception
    raise exception
  File "/Users/macbook/EverythingProgramming/inventory_management_system/majesty-backend/venv/lib/python3.13/site-packages/flask/app.py", line 870, in full_dispatch_request
    rv = self.dispatch_request()
  File "/Users/macbook/EverythingProgramming/inventory_management_system/majesty-backend/venv/lib/python3.13/site-packages/flask/app.py", line 844, in dispatch_request
    self.raise_routing_exception(req)
    ~~~~~~~~~~~~~~~~~~~~~~~~~~~~^^^^^
  File "/Users/macbook/EverythingProgramming/inventory_management_system/majesty-backend/venv/lib/python3.13/site-packages/flask/app.py", line 453, in raise_routing_exception
    raise request.routing_exception  # type: ignore[misc]
    ^^^^^^^^^^^^^^^^^^^^^^^^^^^^^^^
  File "/Users/macbook/EverythingProgramming/inventory_management_system/majesty-backend/venv/lib/python3.13/site-packages/flask/ctx.py", line 362, in match_request
    result = self.url_adapter.match(return_rule=True)  # type: ignore
  File "/Users/macbook/EverythingProgramming/inventory_management_system/majesty-backend/venv/lib/python3.13/site-packages/werkzeug/routing/map.py", line 629, in match
    raise NotFound() from None
werkzeug.exceptions.NotFound: 404 Not Found: The requested URL was not found on the server. If you entered the URL manually please check your spelling and try again.
[2025-03-08 01:05:17,801] ERROR in logger: [EXCEPTION] User None: Unhandled exception: InternalServerError
[2025-03-08 01:05:31,238] ERROR in logger: [EXCEPTION] User None: Unhandled exception: NotFound
[2025-03-08 01:05:31,243] ERROR in app: Exception on /revenue [GET]
Traceback (most recent call last):
  File "/Users/macbook/EverythingProgramming/inventory_management_system/majesty-backend/venv/lib/python3.13/site-packages/flask/app.py", line 1463, in wsgi_app
    response = self.full_dispatch_request()
  File "/Users/macbook/EverythingProgramming/inventory_management_system/majesty-backend/venv/lib/python3.13/site-packages/flask/app.py", line 872, in full_dispatch_request
    rv = self.handle_user_exception(e)
  File "/Users/macbook/EverythingProgramming/inventory_management_system/majesty-backend/venv/lib/python3.13/site-packages/flask_cors/extension.py", line 176, in wrapped_function
    return cors_after_request(app.make_response(f(*args, **kwargs)))
                                                ~^^^^^^^^^^^^^^^^^
  File "/Users/macbook/EverythingProgramming/inventory_management_system/majesty-backend/venv/lib/python3.13/site-packages/flask/app.py", line 755, in handle_user_exception
    return self.handle_http_exception(e)
           ~~~~~~~~~~~~~~~~~~~~~~~~~~^^^
  File "/Users/macbook/EverythingProgramming/inventory_management_system/majesty-backend/venv/lib/python3.13/site-packages/flask/app.py", line 730, in handle_http_exception
    return self.ensure_sync(handler)(e)  # type: ignore[no-any-return]
           ~~~~~~~~~~~~~~~~~~~~~~~~~^^^
  File "/Users/macbook/EverythingProgramming/inventory_management_system/majesty-backend/app/utils/logger.py", line 184, in log_exception
    raise exception
  File "/Users/macbook/EverythingProgramming/inventory_management_system/majesty-backend/venv/lib/python3.13/site-packages/flask/app.py", line 870, in full_dispatch_request
    rv = self.dispatch_request()
  File "/Users/macbook/EverythingProgramming/inventory_management_system/majesty-backend/venv/lib/python3.13/site-packages/flask/app.py", line 844, in dispatch_request
    self.raise_routing_exception(req)
    ~~~~~~~~~~~~~~~~~~~~~~~~~~~~^^^^^
  File "/Users/macbook/EverythingProgramming/inventory_management_system/majesty-backend/venv/lib/python3.13/site-packages/flask/app.py", line 453, in raise_routing_exception
    raise request.routing_exception  # type: ignore[misc]
    ^^^^^^^^^^^^^^^^^^^^^^^^^^^^^^^
  File "/Users/macbook/EverythingProgramming/inventory_management_system/majesty-backend/venv/lib/python3.13/site-packages/flask/ctx.py", line 362, in match_request
    result = self.url_adapter.match(return_rule=True)  # type: ignore
  File "/Users/macbook/EverythingProgramming/inventory_management_system/majesty-backend/venv/lib/python3.13/site-packages/werkzeug/routing/map.py", line 629, in match
    raise NotFound() from None
werkzeug.exceptions.NotFound: 404 Not Found: The requested URL was not found on the server. If you entered the URL manually please check your spelling and try again.
[2025-03-08 01:05:31,248] ERROR in logger: [EXCEPTION] User None: Unhandled exception: InternalServerError
[2025-03-08 01:33:55,217] INFO in logger: Wine Inventory API Started - Environment: development
[2025-03-08 01:38:12,561] INFO in logger: [LOGIN_SUCCESS] User 1: User logged in successfully
[2025-03-08 01:38:47,885] ERROR in logger: [EXCEPTION] User None: Unhandled exception: NotFound
[2025-03-08 01:38:47,888] ERROR in app: Exception on /wine/stock_by_category [GET]
Traceback (most recent call last):
  File "/Users/macbookpro/Documents/projects/WSS/venv/lib/python3.11/site-packages/flask/app.py", line 1463, in wsgi_app
    response = self.full_dispatch_request()
               ^^^^^^^^^^^^^^^^^^^^^^^^^^^^
  File "/Users/macbookpro/Documents/projects/WSS/venv/lib/python3.11/site-packages/flask/app.py", line 872, in full_dispatch_request
    rv = self.handle_user_exception(e)
         ^^^^^^^^^^^^^^^^^^^^^^^^^^^^^
  File "/Users/macbookpro/Documents/projects/WSS/venv/lib/python3.11/site-packages/flask_cors/extension.py", line 176, in wrapped_function
    return cors_after_request(app.make_response(f(*args, **kwargs)))
                                                ^^^^^^^^^^^^^^^^^^
  File "/Users/macbookpro/Documents/projects/WSS/venv/lib/python3.11/site-packages/flask/app.py", line 755, in handle_user_exception
    return self.handle_http_exception(e)
           ^^^^^^^^^^^^^^^^^^^^^^^^^^^^^
  File "/Users/macbookpro/Documents/projects/WSS/venv/lib/python3.11/site-packages/flask/app.py", line 730, in handle_http_exception
    return self.ensure_sync(handler)(e)  # type: ignore[no-any-return]
           ^^^^^^^^^^^^^^^^^^^^^^^^^^^^
  File "/Users/macbookpro/Documents/projects/WSS/majesty-backend/app/utils/logger.py", line 184, in log_exception
    raise exception
  File "/Users/macbookpro/Documents/projects/WSS/venv/lib/python3.11/site-packages/flask/app.py", line 870, in full_dispatch_request
    rv = self.dispatch_request()
         ^^^^^^^^^^^^^^^^^^^^^^^
  File "/Users/macbookpro/Documents/projects/WSS/venv/lib/python3.11/site-packages/flask/app.py", line 844, in dispatch_request
    self.raise_routing_exception(req)
  File "/Users/macbookpro/Documents/projects/WSS/venv/lib/python3.11/site-packages/flask/app.py", line 453, in raise_routing_exception
    raise request.routing_exception  # type: ignore[misc]
    ^^^^^^^^^^^^^^^^^^^^^^^^^^^^^^^
  File "/Users/macbookpro/Documents/projects/WSS/venv/lib/python3.11/site-packages/flask/ctx.py", line 362, in match_request
    result = self.url_adapter.match(return_rule=True)  # type: ignore
             ^^^^^^^^^^^^^^^^^^^^^^^^^^^^^^^^^^^^^^^^
  File "/Users/macbookpro/Documents/projects/WSS/venv/lib/python3.11/site-packages/werkzeug/routing/map.py", line 629, in match
    raise NotFound() from None
werkzeug.exceptions.NotFound: 404 Not Found: The requested URL was not found on the server. If you entered the URL manually please check your spelling and try again.
[2025-03-08 01:38:47,906] ERROR in logger: [EXCEPTION] User None: Unhandled exception: InternalServerError
[2025-03-08 01:41:55,887] ERROR in logger: [EXCEPTION] User None: Unhandled exception: NotFound
[2025-03-08 01:41:55,891] ERROR in app: Exception on /wine/stock_by_category [GET]
Traceback (most recent call last):
  File "/Users/macbookpro/Documents/projects/WSS/venv/lib/python3.11/site-packages/flask/app.py", line 1463, in wsgi_app
    response = self.full_dispatch_request()
               ^^^^^^^^^^^^^^^^^^^^^^^^^^^^
  File "/Users/macbookpro/Documents/projects/WSS/venv/lib/python3.11/site-packages/flask/app.py", line 872, in full_dispatch_request
    rv = self.handle_user_exception(e)
         ^^^^^^^^^^^^^^^^^^^^^^^^^^^^^
  File "/Users/macbookpro/Documents/projects/WSS/venv/lib/python3.11/site-packages/flask_cors/extension.py", line 176, in wrapped_function
    return cors_after_request(app.make_response(f(*args, **kwargs)))
                                                ^^^^^^^^^^^^^^^^^^
  File "/Users/macbookpro/Documents/projects/WSS/venv/lib/python3.11/site-packages/flask/app.py", line 755, in handle_user_exception
    return self.handle_http_exception(e)
           ^^^^^^^^^^^^^^^^^^^^^^^^^^^^^
  File "/Users/macbookpro/Documents/projects/WSS/venv/lib/python3.11/site-packages/flask/app.py", line 730, in handle_http_exception
    return self.ensure_sync(handler)(e)  # type: ignore[no-any-return]
           ^^^^^^^^^^^^^^^^^^^^^^^^^^^^
  File "/Users/macbookpro/Documents/projects/WSS/majesty-backend/app/utils/logger.py", line 184, in log_exception
    raise exception
  File "/Users/macbookpro/Documents/projects/WSS/venv/lib/python3.11/site-packages/flask/app.py", line 870, in full_dispatch_request
    rv = self.dispatch_request()
         ^^^^^^^^^^^^^^^^^^^^^^^
  File "/Users/macbookpro/Documents/projects/WSS/venv/lib/python3.11/site-packages/flask/app.py", line 844, in dispatch_request
    self.raise_routing_exception(req)
  File "/Users/macbookpro/Documents/projects/WSS/venv/lib/python3.11/site-packages/flask/app.py", line 453, in raise_routing_exception
    raise request.routing_exception  # type: ignore[misc]
    ^^^^^^^^^^^^^^^^^^^^^^^^^^^^^^^
  File "/Users/macbookpro/Documents/projects/WSS/venv/lib/python3.11/site-packages/flask/ctx.py", line 362, in match_request
    result = self.url_adapter.match(return_rule=True)  # type: ignore
             ^^^^^^^^^^^^^^^^^^^^^^^^^^^^^^^^^^^^^^^^
  File "/Users/macbookpro/Documents/projects/WSS/venv/lib/python3.11/site-packages/werkzeug/routing/map.py", line 629, in match
    raise NotFound() from None
werkzeug.exceptions.NotFound: 404 Not Found: The requested URL was not found on the server. If you entered the URL manually please check your spelling and try again.
[2025-03-08 01:41:55,893] ERROR in logger: [EXCEPTION] User None: Unhandled exception: InternalServerError
[2025-03-08 01:42:44,484] INFO in logger: Wine Inventory API Started - Environment: development
[2025-03-08 01:42:51,383] ERROR in logger: [EXCEPTION] User None: Unhandled exception: NotFound
[2025-03-08 01:42:51,409] ERROR in app: Exception on /wine/stock_by_category [GET]
Traceback (most recent call last):
  File "/Users/macbookpro/Documents/projects/WSS/venv/lib/python3.11/site-packages/flask/app.py", line 1463, in wsgi_app
    response = self.full_dispatch_request()
               ^^^^^^^^^^^^^^^^^^^^^^^^^^^^
  File "/Users/macbookpro/Documents/projects/WSS/venv/lib/python3.11/site-packages/flask/app.py", line 872, in full_dispatch_request
    rv = self.handle_user_exception(e)
         ^^^^^^^^^^^^^^^^^^^^^^^^^^^^^
  File "/Users/macbookpro/Documents/projects/WSS/venv/lib/python3.11/site-packages/flask_cors/extension.py", line 176, in wrapped_function
    return cors_after_request(app.make_response(f(*args, **kwargs)))
                                                ^^^^^^^^^^^^^^^^^^
  File "/Users/macbookpro/Documents/projects/WSS/venv/lib/python3.11/site-packages/flask/app.py", line 755, in handle_user_exception
    return self.handle_http_exception(e)
           ^^^^^^^^^^^^^^^^^^^^^^^^^^^^^
  File "/Users/macbookpro/Documents/projects/WSS/venv/lib/python3.11/site-packages/flask/app.py", line 730, in handle_http_exception
    return self.ensure_sync(handler)(e)  # type: ignore[no-any-return]
           ^^^^^^^^^^^^^^^^^^^^^^^^^^^^
  File "/Users/macbookpro/Documents/projects/WSS/majesty-backend/app/utils/logger.py", line 184, in log_exception
    raise exception
  File "/Users/macbookpro/Documents/projects/WSS/venv/lib/python3.11/site-packages/flask/app.py", line 870, in full_dispatch_request
    rv = self.dispatch_request()
         ^^^^^^^^^^^^^^^^^^^^^^^
  File "/Users/macbookpro/Documents/projects/WSS/venv/lib/python3.11/site-packages/flask/app.py", line 844, in dispatch_request
    self.raise_routing_exception(req)
  File "/Users/macbookpro/Documents/projects/WSS/venv/lib/python3.11/site-packages/flask/app.py", line 453, in raise_routing_exception
    raise request.routing_exception  # type: ignore[misc]
    ^^^^^^^^^^^^^^^^^^^^^^^^^^^^^^^
  File "/Users/macbookpro/Documents/projects/WSS/venv/lib/python3.11/site-packages/flask/ctx.py", line 362, in match_request
    result = self.url_adapter.match(return_rule=True)  # type: ignore
             ^^^^^^^^^^^^^^^^^^^^^^^^^^^^^^^^^^^^^^^^
  File "/Users/macbookpro/Documents/projects/WSS/venv/lib/python3.11/site-packages/werkzeug/routing/map.py", line 629, in match
    raise NotFound() from None
werkzeug.exceptions.NotFound: 404 Not Found: The requested URL was not found on the server. If you entered the URL manually please check your spelling and try again.
[2025-03-08 01:42:51,413] ERROR in logger: [EXCEPTION] User None: Unhandled exception: InternalServerError
[2025-03-08 01:43:33,655] INFO in logger: Wine Inventory API Started - Environment: development
[2025-03-08 01:43:46,239] ERROR in logger: [EXCEPTION] User None: Unhandled exception: NotFound
[2025-03-08 01:43:46,271] ERROR in app: Exception on /wine/stock_by_category [GET]
Traceback (most recent call last):
  File "/Users/macbookpro/Documents/projects/WSS/venv/lib/python3.11/site-packages/flask/app.py", line 1463, in wsgi_app
    response = self.full_dispatch_request()
               ^^^^^^^^^^^^^^^^^^^^^^^^^^^^
  File "/Users/macbookpro/Documents/projects/WSS/venv/lib/python3.11/site-packages/flask/app.py", line 872, in full_dispatch_request
    rv = self.handle_user_exception(e)
         ^^^^^^^^^^^^^^^^^^^^^^^^^^^^^
  File "/Users/macbookpro/Documents/projects/WSS/venv/lib/python3.11/site-packages/flask_cors/extension.py", line 176, in wrapped_function
    return cors_after_request(app.make_response(f(*args, **kwargs)))
                                                ^^^^^^^^^^^^^^^^^^
  File "/Users/macbookpro/Documents/projects/WSS/venv/lib/python3.11/site-packages/flask/app.py", line 755, in handle_user_exception
    return self.handle_http_exception(e)
           ^^^^^^^^^^^^^^^^^^^^^^^^^^^^^
  File "/Users/macbookpro/Documents/projects/WSS/venv/lib/python3.11/site-packages/flask/app.py", line 730, in handle_http_exception
    return self.ensure_sync(handler)(e)  # type: ignore[no-any-return]
           ^^^^^^^^^^^^^^^^^^^^^^^^^^^^
  File "/Users/macbookpro/Documents/projects/WSS/majesty-backend/app/utils/logger.py", line 184, in log_exception
    raise exception
  File "/Users/macbookpro/Documents/projects/WSS/venv/lib/python3.11/site-packages/flask/app.py", line 870, in full_dispatch_request
    rv = self.dispatch_request()
         ^^^^^^^^^^^^^^^^^^^^^^^
  File "/Users/macbookpro/Documents/projects/WSS/venv/lib/python3.11/site-packages/flask/app.py", line 844, in dispatch_request
    self.raise_routing_exception(req)
  File "/Users/macbookpro/Documents/projects/WSS/venv/lib/python3.11/site-packages/flask/app.py", line 453, in raise_routing_exception
    raise request.routing_exception  # type: ignore[misc]
    ^^^^^^^^^^^^^^^^^^^^^^^^^^^^^^^
  File "/Users/macbookpro/Documents/projects/WSS/venv/lib/python3.11/site-packages/flask/ctx.py", line 362, in match_request
    result = self.url_adapter.match(return_rule=True)  # type: ignore
             ^^^^^^^^^^^^^^^^^^^^^^^^^^^^^^^^^^^^^^^^
  File "/Users/macbookpro/Documents/projects/WSS/venv/lib/python3.11/site-packages/werkzeug/routing/map.py", line 629, in match
    raise NotFound() from None
werkzeug.exceptions.NotFound: 404 Not Found: The requested URL was not found on the server. If you entered the URL manually please check your spelling and try again.
[2025-03-08 01:43:46,274] ERROR in logger: [EXCEPTION] User None: Unhandled exception: InternalServerError
[2025-03-08 01:43:51,603] INFO in logger: [LOGIN_SUCCESS] User 1: User logged in successfully
[2025-03-08 01:44:09,503] ERROR in logger: [EXCEPTION] User None: Unhandled exception: NotFound
[2025-03-08 01:44:09,508] ERROR in app: Exception on /wine/stock_by_category [GET]
Traceback (most recent call last):
  File "/Users/macbookpro/Documents/projects/WSS/venv/lib/python3.11/site-packages/flask/app.py", line 1463, in wsgi_app
    response = self.full_dispatch_request()
               ^^^^^^^^^^^^^^^^^^^^^^^^^^^^
  File "/Users/macbookpro/Documents/projects/WSS/venv/lib/python3.11/site-packages/flask/app.py", line 872, in full_dispatch_request
    rv = self.handle_user_exception(e)
         ^^^^^^^^^^^^^^^^^^^^^^^^^^^^^
  File "/Users/macbookpro/Documents/projects/WSS/venv/lib/python3.11/site-packages/flask_cors/extension.py", line 176, in wrapped_function
    return cors_after_request(app.make_response(f(*args, **kwargs)))
                                                ^^^^^^^^^^^^^^^^^^
  File "/Users/macbookpro/Documents/projects/WSS/venv/lib/python3.11/site-packages/flask/app.py", line 755, in handle_user_exception
    return self.handle_http_exception(e)
           ^^^^^^^^^^^^^^^^^^^^^^^^^^^^^
  File "/Users/macbookpro/Documents/projects/WSS/venv/lib/python3.11/site-packages/flask/app.py", line 730, in handle_http_exception
    return self.ensure_sync(handler)(e)  # type: ignore[no-any-return]
           ^^^^^^^^^^^^^^^^^^^^^^^^^^^^
  File "/Users/macbookpro/Documents/projects/WSS/majesty-backend/app/utils/logger.py", line 184, in log_exception
    raise exception
  File "/Users/macbookpro/Documents/projects/WSS/venv/lib/python3.11/site-packages/flask/app.py", line 870, in full_dispatch_request
    rv = self.dispatch_request()
         ^^^^^^^^^^^^^^^^^^^^^^^
  File "/Users/macbookpro/Documents/projects/WSS/venv/lib/python3.11/site-packages/flask/app.py", line 844, in dispatch_request
    self.raise_routing_exception(req)
  File "/Users/macbookpro/Documents/projects/WSS/venv/lib/python3.11/site-packages/flask/app.py", line 453, in raise_routing_exception
    raise request.routing_exception  # type: ignore[misc]
    ^^^^^^^^^^^^^^^^^^^^^^^^^^^^^^^
  File "/Users/macbookpro/Documents/projects/WSS/venv/lib/python3.11/site-packages/flask/ctx.py", line 362, in match_request
    result = self.url_adapter.match(return_rule=True)  # type: ignore
             ^^^^^^^^^^^^^^^^^^^^^^^^^^^^^^^^^^^^^^^^
  File "/Users/macbookpro/Documents/projects/WSS/venv/lib/python3.11/site-packages/werkzeug/routing/map.py", line 629, in match
    raise NotFound() from None
werkzeug.exceptions.NotFound: 404 Not Found: The requested URL was not found on the server. If you entered the URL manually please check your spelling and try again.
[2025-03-08 01:44:09,516] ERROR in logger: [EXCEPTION] User None: Unhandled exception: InternalServerError
[2025-03-08 01:44:54,023] ERROR in logger: [EXCEPTION] User None: Unhandled exception: NotFound
[2025-03-08 01:44:54,027] ERROR in app: Exception on /wine/stock-by-category [GET]
Traceback (most recent call last):
  File "/Users/macbookpro/Documents/projects/WSS/venv/lib/python3.11/site-packages/flask/app.py", line 1463, in wsgi_app
    response = self.full_dispatch_request()
               ^^^^^^^^^^^^^^^^^^^^^^^^^^^^
  File "/Users/macbookpro/Documents/projects/WSS/venv/lib/python3.11/site-packages/flask/app.py", line 872, in full_dispatch_request
    rv = self.handle_user_exception(e)
         ^^^^^^^^^^^^^^^^^^^^^^^^^^^^^
  File "/Users/macbookpro/Documents/projects/WSS/venv/lib/python3.11/site-packages/flask_cors/extension.py", line 176, in wrapped_function
    return cors_after_request(app.make_response(f(*args, **kwargs)))
                                                ^^^^^^^^^^^^^^^^^^
  File "/Users/macbookpro/Documents/projects/WSS/venv/lib/python3.11/site-packages/flask/app.py", line 755, in handle_user_exception
    return self.handle_http_exception(e)
           ^^^^^^^^^^^^^^^^^^^^^^^^^^^^^
  File "/Users/macbookpro/Documents/projects/WSS/venv/lib/python3.11/site-packages/flask/app.py", line 730, in handle_http_exception
    return self.ensure_sync(handler)(e)  # type: ignore[no-any-return]
           ^^^^^^^^^^^^^^^^^^^^^^^^^^^^
  File "/Users/macbookpro/Documents/projects/WSS/majesty-backend/app/utils/logger.py", line 184, in log_exception
    raise exception
  File "/Users/macbookpro/Documents/projects/WSS/venv/lib/python3.11/site-packages/flask/app.py", line 870, in full_dispatch_request
    rv = self.dispatch_request()
         ^^^^^^^^^^^^^^^^^^^^^^^
  File "/Users/macbookpro/Documents/projects/WSS/venv/lib/python3.11/site-packages/flask/app.py", line 844, in dispatch_request
    self.raise_routing_exception(req)
  File "/Users/macbookpro/Documents/projects/WSS/venv/lib/python3.11/site-packages/flask/app.py", line 453, in raise_routing_exception
    raise request.routing_exception  # type: ignore[misc]
    ^^^^^^^^^^^^^^^^^^^^^^^^^^^^^^^
  File "/Users/macbookpro/Documents/projects/WSS/venv/lib/python3.11/site-packages/flask/ctx.py", line 362, in match_request
    result = self.url_adapter.match(return_rule=True)  # type: ignore
             ^^^^^^^^^^^^^^^^^^^^^^^^^^^^^^^^^^^^^^^^
  File "/Users/macbookpro/Documents/projects/WSS/venv/lib/python3.11/site-packages/werkzeug/routing/map.py", line 629, in match
    raise NotFound() from None
werkzeug.exceptions.NotFound: 404 Not Found: The requested URL was not found on the server. If you entered the URL manually please check your spelling and try again.
[2025-03-08 01:44:54,030] ERROR in logger: [EXCEPTION] User None: Unhandled exception: InternalServerError
[2025-03-08 01:44:55,505] ERROR in logger: [EXCEPTION] User None: Unhandled exception: NotFound
[2025-03-08 01:44:55,510] ERROR in app: Exception on /wine/stock-by-category [GET]
Traceback (most recent call last):
  File "/Users/macbookpro/Documents/projects/WSS/venv/lib/python3.11/site-packages/flask/app.py", line 1463, in wsgi_app
    response = self.full_dispatch_request()
               ^^^^^^^^^^^^^^^^^^^^^^^^^^^^
  File "/Users/macbookpro/Documents/projects/WSS/venv/lib/python3.11/site-packages/flask/app.py", line 872, in full_dispatch_request
    rv = self.handle_user_exception(e)
         ^^^^^^^^^^^^^^^^^^^^^^^^^^^^^
  File "/Users/macbookpro/Documents/projects/WSS/venv/lib/python3.11/site-packages/flask_cors/extension.py", line 176, in wrapped_function
    return cors_after_request(app.make_response(f(*args, **kwargs)))
                                                ^^^^^^^^^^^^^^^^^^
  File "/Users/macbookpro/Documents/projects/WSS/venv/lib/python3.11/site-packages/flask/app.py", line 755, in handle_user_exception
    return self.handle_http_exception(e)
           ^^^^^^^^^^^^^^^^^^^^^^^^^^^^^
  File "/Users/macbookpro/Documents/projects/WSS/venv/lib/python3.11/site-packages/flask/app.py", line 730, in handle_http_exception
    return self.ensure_sync(handler)(e)  # type: ignore[no-any-return]
           ^^^^^^^^^^^^^^^^^^^^^^^^^^^^
  File "/Users/macbookpro/Documents/projects/WSS/majesty-backend/app/utils/logger.py", line 184, in log_exception
    raise exception
  File "/Users/macbookpro/Documents/projects/WSS/venv/lib/python3.11/site-packages/flask/app.py", line 870, in full_dispatch_request
    rv = self.dispatch_request()
         ^^^^^^^^^^^^^^^^^^^^^^^
  File "/Users/macbookpro/Documents/projects/WSS/venv/lib/python3.11/site-packages/flask/app.py", line 844, in dispatch_request
    self.raise_routing_exception(req)
  File "/Users/macbookpro/Documents/projects/WSS/venv/lib/python3.11/site-packages/flask/app.py", line 453, in raise_routing_exception
    raise request.routing_exception  # type: ignore[misc]
    ^^^^^^^^^^^^^^^^^^^^^^^^^^^^^^^
  File "/Users/macbookpro/Documents/projects/WSS/venv/lib/python3.11/site-packages/flask/ctx.py", line 362, in match_request
    result = self.url_adapter.match(return_rule=True)  # type: ignore
             ^^^^^^^^^^^^^^^^^^^^^^^^^^^^^^^^^^^^^^^^
  File "/Users/macbookpro/Documents/projects/WSS/venv/lib/python3.11/site-packages/werkzeug/routing/map.py", line 629, in match
    raise NotFound() from None
werkzeug.exceptions.NotFound: 404 Not Found: The requested URL was not found on the server. If you entered the URL manually please check your spelling and try again.
[2025-03-08 01:44:55,516] ERROR in logger: [EXCEPTION] User None: Unhandled exception: InternalServerError
[2025-03-08 01:45:24,992] ERROR in logger: [EXCEPTION] User None: Unhandled exception: NotFound
[2025-03-08 01:45:24,998] ERROR in app: Exception on /wine/stock-by-category [GET]
Traceback (most recent call last):
  File "/Users/macbookpro/Documents/projects/WSS/venv/lib/python3.11/site-packages/flask/app.py", line 1463, in wsgi_app
    response = self.full_dispatch_request()
               ^^^^^^^^^^^^^^^^^^^^^^^^^^^^
  File "/Users/macbookpro/Documents/projects/WSS/venv/lib/python3.11/site-packages/flask/app.py", line 872, in full_dispatch_request
    rv = self.handle_user_exception(e)
         ^^^^^^^^^^^^^^^^^^^^^^^^^^^^^
  File "/Users/macbookpro/Documents/projects/WSS/venv/lib/python3.11/site-packages/flask_cors/extension.py", line 176, in wrapped_function
    return cors_after_request(app.make_response(f(*args, **kwargs)))
                                                ^^^^^^^^^^^^^^^^^^
  File "/Users/macbookpro/Documents/projects/WSS/venv/lib/python3.11/site-packages/flask/app.py", line 755, in handle_user_exception
    return self.handle_http_exception(e)
           ^^^^^^^^^^^^^^^^^^^^^^^^^^^^^
  File "/Users/macbookpro/Documents/projects/WSS/venv/lib/python3.11/site-packages/flask/app.py", line 730, in handle_http_exception
    return self.ensure_sync(handler)(e)  # type: ignore[no-any-return]
           ^^^^^^^^^^^^^^^^^^^^^^^^^^^^
  File "/Users/macbookpro/Documents/projects/WSS/majesty-backend/app/utils/logger.py", line 184, in log_exception
    raise exception
  File "/Users/macbookpro/Documents/projects/WSS/venv/lib/python3.11/site-packages/flask/app.py", line 870, in full_dispatch_request
    rv = self.dispatch_request()
         ^^^^^^^^^^^^^^^^^^^^^^^
  File "/Users/macbookpro/Documents/projects/WSS/venv/lib/python3.11/site-packages/flask/app.py", line 844, in dispatch_request
    self.raise_routing_exception(req)
  File "/Users/macbookpro/Documents/projects/WSS/venv/lib/python3.11/site-packages/flask/app.py", line 453, in raise_routing_exception
    raise request.routing_exception  # type: ignore[misc]
    ^^^^^^^^^^^^^^^^^^^^^^^^^^^^^^^
  File "/Users/macbookpro/Documents/projects/WSS/venv/lib/python3.11/site-packages/flask/ctx.py", line 362, in match_request
    result = self.url_adapter.match(return_rule=True)  # type: ignore
             ^^^^^^^^^^^^^^^^^^^^^^^^^^^^^^^^^^^^^^^^
  File "/Users/macbookpro/Documents/projects/WSS/venv/lib/python3.11/site-packages/werkzeug/routing/map.py", line 629, in match
    raise NotFound() from None
werkzeug.exceptions.NotFound: 404 Not Found: The requested URL was not found on the server. If you entered the URL manually please check your spelling and try again.
[2025-03-08 01:45:25,009] ERROR in logger: [EXCEPTION] User None: Unhandled exception: InternalServerError
[2025-03-08 01:46:40,687] INFO in logger: Wine Inventory API Started - Environment: development
[2025-03-08 01:46:45,745] ERROR in logger: [EXCEPTION] User None: Unhandled exception: NotFound
[2025-03-08 01:46:45,781] ERROR in app: Exception on /wine/stock-by-category [GET]
Traceback (most recent call last):
  File "/Users/macbookpro/Documents/projects/WSS/venv/lib/python3.11/site-packages/flask/app.py", line 1463, in wsgi_app
    response = self.full_dispatch_request()
               ^^^^^^^^^^^^^^^^^^^^^^^^^^^^
  File "/Users/macbookpro/Documents/projects/WSS/venv/lib/python3.11/site-packages/flask/app.py", line 872, in full_dispatch_request
    rv = self.handle_user_exception(e)
         ^^^^^^^^^^^^^^^^^^^^^^^^^^^^^
  File "/Users/macbookpro/Documents/projects/WSS/venv/lib/python3.11/site-packages/flask_cors/extension.py", line 176, in wrapped_function
    return cors_after_request(app.make_response(f(*args, **kwargs)))
                                                ^^^^^^^^^^^^^^^^^^
  File "/Users/macbookpro/Documents/projects/WSS/venv/lib/python3.11/site-packages/flask/app.py", line 755, in handle_user_exception
    return self.handle_http_exception(e)
           ^^^^^^^^^^^^^^^^^^^^^^^^^^^^^
  File "/Users/macbookpro/Documents/projects/WSS/venv/lib/python3.11/site-packages/flask/app.py", line 730, in handle_http_exception
    return self.ensure_sync(handler)(e)  # type: ignore[no-any-return]
           ^^^^^^^^^^^^^^^^^^^^^^^^^^^^
  File "/Users/macbookpro/Documents/projects/WSS/majesty-backend/app/utils/logger.py", line 184, in log_exception
    raise exception
  File "/Users/macbookpro/Documents/projects/WSS/venv/lib/python3.11/site-packages/flask/app.py", line 870, in full_dispatch_request
    rv = self.dispatch_request()
         ^^^^^^^^^^^^^^^^^^^^^^^
  File "/Users/macbookpro/Documents/projects/WSS/venv/lib/python3.11/site-packages/flask/app.py", line 844, in dispatch_request
    self.raise_routing_exception(req)
  File "/Users/macbookpro/Documents/projects/WSS/venv/lib/python3.11/site-packages/flask/app.py", line 453, in raise_routing_exception
    raise request.routing_exception  # type: ignore[misc]
    ^^^^^^^^^^^^^^^^^^^^^^^^^^^^^^^
  File "/Users/macbookpro/Documents/projects/WSS/venv/lib/python3.11/site-packages/flask/ctx.py", line 362, in match_request
    result = self.url_adapter.match(return_rule=True)  # type: ignore
             ^^^^^^^^^^^^^^^^^^^^^^^^^^^^^^^^^^^^^^^^
  File "/Users/macbookpro/Documents/projects/WSS/venv/lib/python3.11/site-packages/werkzeug/routing/map.py", line 629, in match
    raise NotFound() from None
werkzeug.exceptions.NotFound: 404 Not Found: The requested URL was not found on the server. If you entered the URL manually please check your spelling and try again.
[2025-03-08 01:46:45,786] ERROR in logger: [EXCEPTION] User None: Unhandled exception: InternalServerError
[2025-03-08 01:46:55,275] INFO in logger: Wine Inventory API Started - Environment: development
[2025-03-08 01:47:03,082] ERROR in logger: [EXCEPTION] User None: Unhandled exception: NotFound
[2025-03-08 01:47:03,119] ERROR in app: Exception on /wine/stock-by-category [GET]
Traceback (most recent call last):
  File "/Users/macbookpro/Documents/projects/WSS/venv/lib/python3.11/site-packages/flask/app.py", line 1463, in wsgi_app
    response = self.full_dispatch_request()
               ^^^^^^^^^^^^^^^^^^^^^^^^^^^^
  File "/Users/macbookpro/Documents/projects/WSS/venv/lib/python3.11/site-packages/flask/app.py", line 872, in full_dispatch_request
    rv = self.handle_user_exception(e)
         ^^^^^^^^^^^^^^^^^^^^^^^^^^^^^
  File "/Users/macbookpro/Documents/projects/WSS/venv/lib/python3.11/site-packages/flask_cors/extension.py", line 176, in wrapped_function
    return cors_after_request(app.make_response(f(*args, **kwargs)))
                                                ^^^^^^^^^^^^^^^^^^
  File "/Users/macbookpro/Documents/projects/WSS/venv/lib/python3.11/site-packages/flask/app.py", line 755, in handle_user_exception
    return self.handle_http_exception(e)
           ^^^^^^^^^^^^^^^^^^^^^^^^^^^^^
  File "/Users/macbookpro/Documents/projects/WSS/venv/lib/python3.11/site-packages/flask/app.py", line 730, in handle_http_exception
    return self.ensure_sync(handler)(e)  # type: ignore[no-any-return]
           ^^^^^^^^^^^^^^^^^^^^^^^^^^^^
  File "/Users/macbookpro/Documents/projects/WSS/majesty-backend/app/utils/logger.py", line 184, in log_exception
    raise exception
  File "/Users/macbookpro/Documents/projects/WSS/venv/lib/python3.11/site-packages/flask/app.py", line 870, in full_dispatch_request
    rv = self.dispatch_request()
         ^^^^^^^^^^^^^^^^^^^^^^^
  File "/Users/macbookpro/Documents/projects/WSS/venv/lib/python3.11/site-packages/flask/app.py", line 844, in dispatch_request
    self.raise_routing_exception(req)
  File "/Users/macbookpro/Documents/projects/WSS/venv/lib/python3.11/site-packages/flask/app.py", line 453, in raise_routing_exception
    raise request.routing_exception  # type: ignore[misc]
    ^^^^^^^^^^^^^^^^^^^^^^^^^^^^^^^
  File "/Users/macbookpro/Documents/projects/WSS/venv/lib/python3.11/site-packages/flask/ctx.py", line 362, in match_request
    result = self.url_adapter.match(return_rule=True)  # type: ignore
             ^^^^^^^^^^^^^^^^^^^^^^^^^^^^^^^^^^^^^^^^
  File "/Users/macbookpro/Documents/projects/WSS/venv/lib/python3.11/site-packages/werkzeug/routing/map.py", line 629, in match
    raise NotFound() from None
werkzeug.exceptions.NotFound: 404 Not Found: The requested URL was not found on the server. If you entered the URL manually please check your spelling and try again.
[2025-03-08 01:47:03,122] ERROR in logger: [EXCEPTION] User None: Unhandled exception: InternalServerError
[2025-03-08 01:47:46,825] INFO in logger: Wine Inventory API Started - Environment: development
[2025-03-08 01:47:51,544] ERROR in logger: [EXCEPTION] User None: Unhandled exception: NotFound
[2025-03-08 01:47:51,571] ERROR in app: Exception on /wine/stock-by-category [GET]
Traceback (most recent call last):
  File "/Users/macbookpro/Documents/projects/WSS/venv/lib/python3.11/site-packages/flask/app.py", line 1463, in wsgi_app
    response = self.full_dispatch_request()
               ^^^^^^^^^^^^^^^^^^^^^^^^^^^^
  File "/Users/macbookpro/Documents/projects/WSS/venv/lib/python3.11/site-packages/flask/app.py", line 872, in full_dispatch_request
    rv = self.handle_user_exception(e)
         ^^^^^^^^^^^^^^^^^^^^^^^^^^^^^
  File "/Users/macbookpro/Documents/projects/WSS/venv/lib/python3.11/site-packages/flask_cors/extension.py", line 176, in wrapped_function
    return cors_after_request(app.make_response(f(*args, **kwargs)))
                                                ^^^^^^^^^^^^^^^^^^
  File "/Users/macbookpro/Documents/projects/WSS/venv/lib/python3.11/site-packages/flask/app.py", line 755, in handle_user_exception
    return self.handle_http_exception(e)
           ^^^^^^^^^^^^^^^^^^^^^^^^^^^^^
  File "/Users/macbookpro/Documents/projects/WSS/venv/lib/python3.11/site-packages/flask/app.py", line 730, in handle_http_exception
    return self.ensure_sync(handler)(e)  # type: ignore[no-any-return]
           ^^^^^^^^^^^^^^^^^^^^^^^^^^^^
  File "/Users/macbookpro/Documents/projects/WSS/majesty-backend/app/utils/logger.py", line 184, in log_exception
    raise exception
  File "/Users/macbookpro/Documents/projects/WSS/venv/lib/python3.11/site-packages/flask/app.py", line 870, in full_dispatch_request
    rv = self.dispatch_request()
         ^^^^^^^^^^^^^^^^^^^^^^^
  File "/Users/macbookpro/Documents/projects/WSS/venv/lib/python3.11/site-packages/flask/app.py", line 844, in dispatch_request
    self.raise_routing_exception(req)
  File "/Users/macbookpro/Documents/projects/WSS/venv/lib/python3.11/site-packages/flask/app.py", line 453, in raise_routing_exception
    raise request.routing_exception  # type: ignore[misc]
    ^^^^^^^^^^^^^^^^^^^^^^^^^^^^^^^
  File "/Users/macbookpro/Documents/projects/WSS/venv/lib/python3.11/site-packages/flask/ctx.py", line 362, in match_request
    result = self.url_adapter.match(return_rule=True)  # type: ignore
             ^^^^^^^^^^^^^^^^^^^^^^^^^^^^^^^^^^^^^^^^
  File "/Users/macbookpro/Documents/projects/WSS/venv/lib/python3.11/site-packages/werkzeug/routing/map.py", line 629, in match
    raise NotFound() from None
werkzeug.exceptions.NotFound: 404 Not Found: The requested URL was not found on the server. If you entered the URL manually please check your spelling and try again.
[2025-03-08 01:47:51,578] ERROR in logger: [EXCEPTION] User None: Unhandled exception: InternalServerError
[2025-03-08 01:47:59,185] INFO in logger: Wine Inventory API Started - Environment: development
[2025-03-08 01:48:03,826] ERROR in logger: [EXCEPTION] User None: Unhandled exception: NotFound
[2025-03-08 01:48:03,857] ERROR in app: Exception on /wine/stock-by-category [GET]
Traceback (most recent call last):
  File "/Users/macbookpro/Documents/projects/WSS/venv/lib/python3.11/site-packages/flask/app.py", line 1463, in wsgi_app
    response = self.full_dispatch_request()
               ^^^^^^^^^^^^^^^^^^^^^^^^^^^^
  File "/Users/macbookpro/Documents/projects/WSS/venv/lib/python3.11/site-packages/flask/app.py", line 872, in full_dispatch_request
    rv = self.handle_user_exception(e)
         ^^^^^^^^^^^^^^^^^^^^^^^^^^^^^
  File "/Users/macbookpro/Documents/projects/WSS/venv/lib/python3.11/site-packages/flask_cors/extension.py", line 176, in wrapped_function
    return cors_after_request(app.make_response(f(*args, **kwargs)))
                                                ^^^^^^^^^^^^^^^^^^
  File "/Users/macbookpro/Documents/projects/WSS/venv/lib/python3.11/site-packages/flask/app.py", line 755, in handle_user_exception
    return self.handle_http_exception(e)
           ^^^^^^^^^^^^^^^^^^^^^^^^^^^^^
  File "/Users/macbookpro/Documents/projects/WSS/venv/lib/python3.11/site-packages/flask/app.py", line 730, in handle_http_exception
    return self.ensure_sync(handler)(e)  # type: ignore[no-any-return]
           ^^^^^^^^^^^^^^^^^^^^^^^^^^^^
  File "/Users/macbookpro/Documents/projects/WSS/majesty-backend/app/utils/logger.py", line 184, in log_exception
    raise exception
  File "/Users/macbookpro/Documents/projects/WSS/venv/lib/python3.11/site-packages/flask/app.py", line 870, in full_dispatch_request
    rv = self.dispatch_request()
         ^^^^^^^^^^^^^^^^^^^^^^^
  File "/Users/macbookpro/Documents/projects/WSS/venv/lib/python3.11/site-packages/flask/app.py", line 844, in dispatch_request
    self.raise_routing_exception(req)
  File "/Users/macbookpro/Documents/projects/WSS/venv/lib/python3.11/site-packages/flask/app.py", line 453, in raise_routing_exception
    raise request.routing_exception  # type: ignore[misc]
    ^^^^^^^^^^^^^^^^^^^^^^^^^^^^^^^
  File "/Users/macbookpro/Documents/projects/WSS/venv/lib/python3.11/site-packages/flask/ctx.py", line 362, in match_request
    result = self.url_adapter.match(return_rule=True)  # type: ignore
             ^^^^^^^^^^^^^^^^^^^^^^^^^^^^^^^^^^^^^^^^
  File "/Users/macbookpro/Documents/projects/WSS/venv/lib/python3.11/site-packages/werkzeug/routing/map.py", line 629, in match
    raise NotFound() from None
werkzeug.exceptions.NotFound: 404 Not Found: The requested URL was not found on the server. If you entered the URL manually please check your spelling and try again.
[2025-03-08 01:48:03,860] ERROR in logger: [EXCEPTION] User None: Unhandled exception: InternalServerError
[2025-03-08 01:50:02,030] INFO in logger: Wine Inventory API Started - Environment: development
[2025-03-08 01:56:34,349] INFO in logger: Wine Inventory API Started - Environment: development
[2025-03-08 02:07:38,587] ERROR in logger: [EXCEPTION] User None: Unhandled exception: NotFound
[2025-03-08 02:07:38,618] ERROR in app: Exception on /wine/test [GET]
Traceback (most recent call last):
  File "/Users/macbookpro/Documents/projects/WSS/venv/lib/python3.11/site-packages/flask/app.py", line 1463, in wsgi_app
    response = self.full_dispatch_request()
               ^^^^^^^^^^^^^^^^^^^^^^^^^^^^
  File "/Users/macbookpro/Documents/projects/WSS/venv/lib/python3.11/site-packages/flask/app.py", line 872, in full_dispatch_request
    rv = self.handle_user_exception(e)
         ^^^^^^^^^^^^^^^^^^^^^^^^^^^^^
  File "/Users/macbookpro/Documents/projects/WSS/venv/lib/python3.11/site-packages/flask_cors/extension.py", line 176, in wrapped_function
    return cors_after_request(app.make_response(f(*args, **kwargs)))
                                                ^^^^^^^^^^^^^^^^^^
  File "/Users/macbookpro/Documents/projects/WSS/venv/lib/python3.11/site-packages/flask/app.py", line 755, in handle_user_exception
    return self.handle_http_exception(e)
           ^^^^^^^^^^^^^^^^^^^^^^^^^^^^^
  File "/Users/macbookpro/Documents/projects/WSS/venv/lib/python3.11/site-packages/flask/app.py", line 730, in handle_http_exception
    return self.ensure_sync(handler)(e)  # type: ignore[no-any-return]
           ^^^^^^^^^^^^^^^^^^^^^^^^^^^^
  File "/Users/macbookpro/Documents/projects/WSS/majesty-backend/app/utils/logger.py", line 184, in log_exception
    raise exception
  File "/Users/macbookpro/Documents/projects/WSS/venv/lib/python3.11/site-packages/flask/app.py", line 870, in full_dispatch_request
    rv = self.dispatch_request()
         ^^^^^^^^^^^^^^^^^^^^^^^
  File "/Users/macbookpro/Documents/projects/WSS/venv/lib/python3.11/site-packages/flask/app.py", line 844, in dispatch_request
    self.raise_routing_exception(req)
  File "/Users/macbookpro/Documents/projects/WSS/venv/lib/python3.11/site-packages/flask/app.py", line 453, in raise_routing_exception
    raise request.routing_exception  # type: ignore[misc]
    ^^^^^^^^^^^^^^^^^^^^^^^^^^^^^^^
  File "/Users/macbookpro/Documents/projects/WSS/venv/lib/python3.11/site-packages/flask/ctx.py", line 362, in match_request
    result = self.url_adapter.match(return_rule=True)  # type: ignore
             ^^^^^^^^^^^^^^^^^^^^^^^^^^^^^^^^^^^^^^^^
  File "/Users/macbookpro/Documents/projects/WSS/venv/lib/python3.11/site-packages/werkzeug/routing/map.py", line 629, in match
    raise NotFound() from None
werkzeug.exceptions.NotFound: 404 Not Found: The requested URL was not found on the server. If you entered the URL manually please check your spelling and try again.
[2025-03-08 02:07:38,623] ERROR in logger: [EXCEPTION] User None: Unhandled exception: InternalServerError
[2025-03-08 02:08:03,542] INFO in logger: Wine Inventory API Started - Environment: development
[2025-03-08 02:13:01,182] INFO in logger: Wine Inventory API Started - Environment: development
[2025-03-08 02:16:32,678] INFO in logger: [LOGIN_SUCCESS] User 1: User logged in successfully
[2025-03-08 02:16:51,419] INFO in logger: [GET_STOCK_BY_CATEGORY] User 1: No stock data found
[2025-03-08 17:21:59,447] INFO in logger: Wine Inventory API Started - Environment: development
[2025-03-08 17:22:07,703] INFO in logger: Wine Inventory API Started - Environment: development
[2025-03-08 20:05:36,892] INFO in logger: Wine Inventory API Started - Environment: development
[2025-03-08 20:05:42,999] INFO in logger: [LOGIN_SUCCESS] User 1: User logged in successfully
[2025-03-08 20:06:24,793] ERROR in logger: [EXCEPTION] User None: Unhandled exception: MethodNotAllowed
[2025-03-08 20:06:24,800] ERROR in app: Exception on /wine/add [GET]
Traceback (most recent call last):
  File "/Users/macbookpro/Documents/projects/WSS/venv/lib/python3.11/site-packages/flask/app.py", line 1463, in wsgi_app
    response = self.full_dispatch_request()
               ^^^^^^^^^^^^^^^^^^^^^^^^^^^^
  File "/Users/macbookpro/Documents/projects/WSS/venv/lib/python3.11/site-packages/flask/app.py", line 872, in full_dispatch_request
    rv = self.handle_user_exception(e)
         ^^^^^^^^^^^^^^^^^^^^^^^^^^^^^
  File "/Users/macbookpro/Documents/projects/WSS/venv/lib/python3.11/site-packages/flask_cors/extension.py", line 176, in wrapped_function
    return cors_after_request(app.make_response(f(*args, **kwargs)))
                                                ^^^^^^^^^^^^^^^^^^
  File "/Users/macbookpro/Documents/projects/WSS/venv/lib/python3.11/site-packages/flask/app.py", line 755, in handle_user_exception
    return self.handle_http_exception(e)
           ^^^^^^^^^^^^^^^^^^^^^^^^^^^^^
  File "/Users/macbookpro/Documents/projects/WSS/venv/lib/python3.11/site-packages/flask/app.py", line 730, in handle_http_exception
    return self.ensure_sync(handler)(e)  # type: ignore[no-any-return]
           ^^^^^^^^^^^^^^^^^^^^^^^^^^^^
  File "/Users/macbookpro/Documents/projects/WSS/majesty-backend/app/utils/logger.py", line 184, in log_exception
    raise exception
  File "/Users/macbookpro/Documents/projects/WSS/venv/lib/python3.11/site-packages/flask/app.py", line 870, in full_dispatch_request
    rv = self.dispatch_request()
         ^^^^^^^^^^^^^^^^^^^^^^^
  File "/Users/macbookpro/Documents/projects/WSS/venv/lib/python3.11/site-packages/flask/app.py", line 844, in dispatch_request
    self.raise_routing_exception(req)
  File "/Users/macbookpro/Documents/projects/WSS/venv/lib/python3.11/site-packages/flask/app.py", line 453, in raise_routing_exception
    raise request.routing_exception  # type: ignore[misc]
    ^^^^^^^^^^^^^^^^^^^^^^^^^^^^^^^
  File "/Users/macbookpro/Documents/projects/WSS/venv/lib/python3.11/site-packages/flask/ctx.py", line 362, in match_request
    result = self.url_adapter.match(return_rule=True)  # type: ignore
             ^^^^^^^^^^^^^^^^^^^^^^^^^^^^^^^^^^^^^^^^
  File "/Users/macbookpro/Documents/projects/WSS/venv/lib/python3.11/site-packages/werkzeug/routing/map.py", line 624, in match
    raise MethodNotAllowed(valid_methods=list(e.have_match_for)) from None
werkzeug.exceptions.MethodNotAllowed: 405 Method Not Allowed: The method is not allowed for the requested URL.
[2025-03-08 20:06:24,804] ERROR in logger: [EXCEPTION] User None: Unhandled exception: InternalServerError
[2025-03-08 20:08:31,064] ERROR in logger: [EXCEPTION] User None: Unhandled exception: MethodNotAllowed
[2025-03-08 20:08:31,075] ERROR in app: Exception on /wine/add [GET]
Traceback (most recent call last):
  File "/Users/macbookpro/Documents/projects/WSS/venv/lib/python3.11/site-packages/flask/app.py", line 1463, in wsgi_app
    response = self.full_dispatch_request()
               ^^^^^^^^^^^^^^^^^^^^^^^^^^^^
  File "/Users/macbookpro/Documents/projects/WSS/venv/lib/python3.11/site-packages/flask/app.py", line 872, in full_dispatch_request
    rv = self.handle_user_exception(e)
         ^^^^^^^^^^^^^^^^^^^^^^^^^^^^^
  File "/Users/macbookpro/Documents/projects/WSS/venv/lib/python3.11/site-packages/flask_cors/extension.py", line 176, in wrapped_function
    return cors_after_request(app.make_response(f(*args, **kwargs)))
                                                ^^^^^^^^^^^^^^^^^^
  File "/Users/macbookpro/Documents/projects/WSS/venv/lib/python3.11/site-packages/flask/app.py", line 755, in handle_user_exception
    return self.handle_http_exception(e)
           ^^^^^^^^^^^^^^^^^^^^^^^^^^^^^
  File "/Users/macbookpro/Documents/projects/WSS/venv/lib/python3.11/site-packages/flask/app.py", line 730, in handle_http_exception
    return self.ensure_sync(handler)(e)  # type: ignore[no-any-return]
           ^^^^^^^^^^^^^^^^^^^^^^^^^^^^
  File "/Users/macbookpro/Documents/projects/WSS/majesty-backend/app/utils/logger.py", line 184, in log_exception
    raise exception
  File "/Users/macbookpro/Documents/projects/WSS/venv/lib/python3.11/site-packages/flask/app.py", line 870, in full_dispatch_request
    rv = self.dispatch_request()
         ^^^^^^^^^^^^^^^^^^^^^^^
  File "/Users/macbookpro/Documents/projects/WSS/venv/lib/python3.11/site-packages/flask/app.py", line 844, in dispatch_request
    self.raise_routing_exception(req)
  File "/Users/macbookpro/Documents/projects/WSS/venv/lib/python3.11/site-packages/flask/app.py", line 453, in raise_routing_exception
    raise request.routing_exception  # type: ignore[misc]
    ^^^^^^^^^^^^^^^^^^^^^^^^^^^^^^^
  File "/Users/macbookpro/Documents/projects/WSS/venv/lib/python3.11/site-packages/flask/ctx.py", line 362, in match_request
    result = self.url_adapter.match(return_rule=True)  # type: ignore
             ^^^^^^^^^^^^^^^^^^^^^^^^^^^^^^^^^^^^^^^^
  File "/Users/macbookpro/Documents/projects/WSS/venv/lib/python3.11/site-packages/werkzeug/routing/map.py", line 624, in match
    raise MethodNotAllowed(valid_methods=list(e.have_match_for)) from None
werkzeug.exceptions.MethodNotAllowed: 405 Method Not Allowed: The method is not allowed for the requested URL.
[2025-03-08 20:08:31,108] ERROR in logger: [EXCEPTION] User None: Unhandled exception: InternalServerError
[2025-03-08 20:10:31,854] INFO in logger: Wine Inventory API Started - Environment: development
[2025-03-08 20:10:37,870] INFO in logger: [ADD_WINE_SUCCESS] User 1: Wine added: 1
[2025-03-11 13:59:56,510] INFO in logger: Wine Inventory API Started - Environment: development
[2025-03-11 14:05:45,812] INFO in logger: [LOGIN_SUCCESS] User 1: User logged in successfully
[2025-03-11 14:09:37,912] INFO in logger: [GET_TOTAL_STOCK] User 1: Total stock checked: 0
[2025-03-11 14:10:37,533] ERROR in logger: [EXCEPTION] User None: Unhandled exception: NotFound
[2025-03-11 14:10:37,536] ERROR in app: Exception on /wine/stock_by_category [GET]
Traceback (most recent call last):
  File "/Users/macbookpro/Documents/projects/WSS/venv/lib/python3.11/site-packages/flask/app.py", line 1463, in wsgi_app
    response = self.full_dispatch_request()
               ^^^^^^^^^^^^^^^^^^^^^^^^^^^^
  File "/Users/macbookpro/Documents/projects/WSS/venv/lib/python3.11/site-packages/flask/app.py", line 872, in full_dispatch_request
    rv = self.handle_user_exception(e)
         ^^^^^^^^^^^^^^^^^^^^^^^^^^^^^
  File "/Users/macbookpro/Documents/projects/WSS/venv/lib/python3.11/site-packages/flask_cors/extension.py", line 176, in wrapped_function
    return cors_after_request(app.make_response(f(*args, **kwargs)))
                                                ^^^^^^^^^^^^^^^^^^
  File "/Users/macbookpro/Documents/projects/WSS/venv/lib/python3.11/site-packages/flask/app.py", line 755, in handle_user_exception
    return self.handle_http_exception(e)
           ^^^^^^^^^^^^^^^^^^^^^^^^^^^^^
  File "/Users/macbookpro/Documents/projects/WSS/venv/lib/python3.11/site-packages/flask/app.py", line 730, in handle_http_exception
    return self.ensure_sync(handler)(e)  # type: ignore[no-any-return]
           ^^^^^^^^^^^^^^^^^^^^^^^^^^^^
  File "/Users/macbookpro/Documents/projects/WSS/majesty-backend/app/utils/logger.py", line 184, in log_exception
    raise exception
  File "/Users/macbookpro/Documents/projects/WSS/venv/lib/python3.11/site-packages/flask/app.py", line 870, in full_dispatch_request
    rv = self.dispatch_request()
         ^^^^^^^^^^^^^^^^^^^^^^^
  File "/Users/macbookpro/Documents/projects/WSS/venv/lib/python3.11/site-packages/flask/app.py", line 844, in dispatch_request
    self.raise_routing_exception(req)
  File "/Users/macbookpro/Documents/projects/WSS/venv/lib/python3.11/site-packages/flask/app.py", line 453, in raise_routing_exception
    raise request.routing_exception  # type: ignore[misc]
    ^^^^^^^^^^^^^^^^^^^^^^^^^^^^^^^
  File "/Users/macbookpro/Documents/projects/WSS/venv/lib/python3.11/site-packages/flask/ctx.py", line 362, in match_request
    result = self.url_adapter.match(return_rule=True)  # type: ignore
             ^^^^^^^^^^^^^^^^^^^^^^^^^^^^^^^^^^^^^^^^
  File "/Users/macbookpro/Documents/projects/WSS/venv/lib/python3.11/site-packages/werkzeug/routing/map.py", line 629, in match
    raise NotFound() from None
werkzeug.exceptions.NotFound: 404 Not Found: The requested URL was not found on the server. If you entered the URL manually please check your spelling and try again.
[2025-03-11 14:10:37,548] ERROR in logger: [EXCEPTION] User None: Unhandled exception: InternalServerError
[2025-03-11 14:11:14,516] ERROR in logger: [EXCEPTION] User None: Unhandled exception: NotFound
[2025-03-11 14:11:14,522] ERROR in app: Exception on /revenue [GET]
Traceback (most recent call last):
  File "/Users/macbookpro/Documents/projects/WSS/venv/lib/python3.11/site-packages/flask/app.py", line 1463, in wsgi_app
    response = self.full_dispatch_request()
               ^^^^^^^^^^^^^^^^^^^^^^^^^^^^
  File "/Users/macbookpro/Documents/projects/WSS/venv/lib/python3.11/site-packages/flask/app.py", line 872, in full_dispatch_request
    rv = self.handle_user_exception(e)
         ^^^^^^^^^^^^^^^^^^^^^^^^^^^^^
  File "/Users/macbookpro/Documents/projects/WSS/venv/lib/python3.11/site-packages/flask_cors/extension.py", line 176, in wrapped_function
    return cors_after_request(app.make_response(f(*args, **kwargs)))
                                                ^^^^^^^^^^^^^^^^^^
  File "/Users/macbookpro/Documents/projects/WSS/venv/lib/python3.11/site-packages/flask/app.py", line 755, in handle_user_exception
    return self.handle_http_exception(e)
           ^^^^^^^^^^^^^^^^^^^^^^^^^^^^^
  File "/Users/macbookpro/Documents/projects/WSS/venv/lib/python3.11/site-packages/flask/app.py", line 730, in handle_http_exception
    return self.ensure_sync(handler)(e)  # type: ignore[no-any-return]
           ^^^^^^^^^^^^^^^^^^^^^^^^^^^^
  File "/Users/macbookpro/Documents/projects/WSS/majesty-backend/app/utils/logger.py", line 184, in log_exception
    raise exception
  File "/Users/macbookpro/Documents/projects/WSS/venv/lib/python3.11/site-packages/flask/app.py", line 870, in full_dispatch_request
    rv = self.dispatch_request()
         ^^^^^^^^^^^^^^^^^^^^^^^
  File "/Users/macbookpro/Documents/projects/WSS/venv/lib/python3.11/site-packages/flask/app.py", line 844, in dispatch_request
    self.raise_routing_exception(req)
  File "/Users/macbookpro/Documents/projects/WSS/venv/lib/python3.11/site-packages/flask/app.py", line 453, in raise_routing_exception
    raise request.routing_exception  # type: ignore[misc]
    ^^^^^^^^^^^^^^^^^^^^^^^^^^^^^^^
  File "/Users/macbookpro/Documents/projects/WSS/venv/lib/python3.11/site-packages/flask/ctx.py", line 362, in match_request
    result = self.url_adapter.match(return_rule=True)  # type: ignore
             ^^^^^^^^^^^^^^^^^^^^^^^^^^^^^^^^^^^^^^^^
  File "/Users/macbookpro/Documents/projects/WSS/venv/lib/python3.11/site-packages/werkzeug/routing/map.py", line 629, in match
    raise NotFound() from None
werkzeug.exceptions.NotFound: 404 Not Found: The requested URL was not found on the server. If you entered the URL manually please check your spelling and try again.
[2025-03-11 14:11:14,549] ERROR in logger: [EXCEPTION] User None: Unhandled exception: InternalServerError
[2025-03-11 14:12:00,371] ERROR in logger: [EXCEPTION] User None: Unhandled exception: NotFound
[2025-03-11 14:12:00,377] ERROR in app: Exception on /revenue [GET]
Traceback (most recent call last):
  File "/Users/macbookpro/Documents/projects/WSS/venv/lib/python3.11/site-packages/flask/app.py", line 1463, in wsgi_app
    response = self.full_dispatch_request()
               ^^^^^^^^^^^^^^^^^^^^^^^^^^^^
  File "/Users/macbookpro/Documents/projects/WSS/venv/lib/python3.11/site-packages/flask/app.py", line 872, in full_dispatch_request
    rv = self.handle_user_exception(e)
         ^^^^^^^^^^^^^^^^^^^^^^^^^^^^^
  File "/Users/macbookpro/Documents/projects/WSS/venv/lib/python3.11/site-packages/flask_cors/extension.py", line 176, in wrapped_function
    return cors_after_request(app.make_response(f(*args, **kwargs)))
                                                ^^^^^^^^^^^^^^^^^^
  File "/Users/macbookpro/Documents/projects/WSS/venv/lib/python3.11/site-packages/flask/app.py", line 755, in handle_user_exception
    return self.handle_http_exception(e)
           ^^^^^^^^^^^^^^^^^^^^^^^^^^^^^
  File "/Users/macbookpro/Documents/projects/WSS/venv/lib/python3.11/site-packages/flask/app.py", line 730, in handle_http_exception
    return self.ensure_sync(handler)(e)  # type: ignore[no-any-return]
           ^^^^^^^^^^^^^^^^^^^^^^^^^^^^
  File "/Users/macbookpro/Documents/projects/WSS/majesty-backend/app/utils/logger.py", line 184, in log_exception
    raise exception
  File "/Users/macbookpro/Documents/projects/WSS/venv/lib/python3.11/site-packages/flask/app.py", line 870, in full_dispatch_request
    rv = self.dispatch_request()
         ^^^^^^^^^^^^^^^^^^^^^^^
  File "/Users/macbookpro/Documents/projects/WSS/venv/lib/python3.11/site-packages/flask/app.py", line 844, in dispatch_request
    self.raise_routing_exception(req)
  File "/Users/macbookpro/Documents/projects/WSS/venv/lib/python3.11/site-packages/flask/app.py", line 453, in raise_routing_exception
    raise request.routing_exception  # type: ignore[misc]
    ^^^^^^^^^^^^^^^^^^^^^^^^^^^^^^^
  File "/Users/macbookpro/Documents/projects/WSS/venv/lib/python3.11/site-packages/flask/ctx.py", line 362, in match_request
    result = self.url_adapter.match(return_rule=True)  # type: ignore
             ^^^^^^^^^^^^^^^^^^^^^^^^^^^^^^^^^^^^^^^^
  File "/Users/macbookpro/Documents/projects/WSS/venv/lib/python3.11/site-packages/werkzeug/routing/map.py", line 629, in match
    raise NotFound() from None
werkzeug.exceptions.NotFound: 404 Not Found: The requested URL was not found on the server. If you entered the URL manually please check your spelling and try again.
[2025-03-11 14:12:00,379] ERROR in logger: [EXCEPTION] User None: Unhandled exception: InternalServerError
[2025-03-11 14:12:23,777] ERROR in logger: [EXCEPTION] User None: Unhandled exception: NotFound
[2025-03-11 14:12:23,780] ERROR in app: Exception on /compare-sales [GET]
Traceback (most recent call last):
  File "/Users/macbookpro/Documents/projects/WSS/venv/lib/python3.11/site-packages/flask/app.py", line 1463, in wsgi_app
    response = self.full_dispatch_request()
               ^^^^^^^^^^^^^^^^^^^^^^^^^^^^
  File "/Users/macbookpro/Documents/projects/WSS/venv/lib/python3.11/site-packages/flask/app.py", line 872, in full_dispatch_request
    rv = self.handle_user_exception(e)
         ^^^^^^^^^^^^^^^^^^^^^^^^^^^^^
  File "/Users/macbookpro/Documents/projects/WSS/venv/lib/python3.11/site-packages/flask_cors/extension.py", line 176, in wrapped_function
    return cors_after_request(app.make_response(f(*args, **kwargs)))
                                                ^^^^^^^^^^^^^^^^^^
  File "/Users/macbookpro/Documents/projects/WSS/venv/lib/python3.11/site-packages/flask/app.py", line 755, in handle_user_exception
    return self.handle_http_exception(e)
           ^^^^^^^^^^^^^^^^^^^^^^^^^^^^^
  File "/Users/macbookpro/Documents/projects/WSS/venv/lib/python3.11/site-packages/flask/app.py", line 730, in handle_http_exception
    return self.ensure_sync(handler)(e)  # type: ignore[no-any-return]
           ^^^^^^^^^^^^^^^^^^^^^^^^^^^^
  File "/Users/macbookpro/Documents/projects/WSS/majesty-backend/app/utils/logger.py", line 184, in log_exception
    raise exception
  File "/Users/macbookpro/Documents/projects/WSS/venv/lib/python3.11/site-packages/flask/app.py", line 870, in full_dispatch_request
    rv = self.dispatch_request()
         ^^^^^^^^^^^^^^^^^^^^^^^
  File "/Users/macbookpro/Documents/projects/WSS/venv/lib/python3.11/site-packages/flask/app.py", line 844, in dispatch_request
    self.raise_routing_exception(req)
  File "/Users/macbookpro/Documents/projects/WSS/venv/lib/python3.11/site-packages/flask/app.py", line 453, in raise_routing_exception
    raise request.routing_exception  # type: ignore[misc]
    ^^^^^^^^^^^^^^^^^^^^^^^^^^^^^^^
  File "/Users/macbookpro/Documents/projects/WSS/venv/lib/python3.11/site-packages/flask/ctx.py", line 362, in match_request
    result = self.url_adapter.match(return_rule=True)  # type: ignore
             ^^^^^^^^^^^^^^^^^^^^^^^^^^^^^^^^^^^^^^^^
  File "/Users/macbookpro/Documents/projects/WSS/venv/lib/python3.11/site-packages/werkzeug/routing/map.py", line 629, in match
    raise NotFound() from None
werkzeug.exceptions.NotFound: 404 Not Found: The requested URL was not found on the server. If you entered the URL manually please check your spelling and try again.
[2025-03-11 14:12:23,800] ERROR in logger: [EXCEPTION] User None: Unhandled exception: InternalServerError
[2025-03-11 14:13:19,585] INFO in logger: [ADD_WINE_SUCCESS] User 1: Wine added: 2
[2025-03-11 14:13:21,525] ERROR in logger: [ADD_WINE_ERROR] User 1: (sqlite3.IntegrityError) UNIQUE constraint failed: wines.name
[SQL: INSERT INTO wines (name, abv, price, category, bottle_size, in_stock, added_by, added_at) VALUES (?, ?, ?, ?, ?, ?, ?, ?)]
[parameters: ('Cabernet Sauvignon', 14.5, 29.99, 'Red', 750, 50, '1', '2025-03-11 13:13:21.524612')]
(Background on this error at: https://sqlalche.me/e/20/gkpj)
[2025-03-11 14:13:32,017] INFO in logger: [GET_TOTAL_STOCK] User 1: Total stock checked: 50
[2025-03-11 14:13:35,182] INFO in logger: [GET_TOTAL_STOCK] User 1: Total stock checked: 50
[2025-03-11 14:13:55,196] INFO in logger: [ADD_WINE_SUCCESS] User 1: Wine added: 3
[2025-03-11 14:14:04,475] INFO in logger: [GET_TOTAL_STOCK] User 1: Total stock checked: 100
[2025-03-11 14:14:56,217] INFO in logger: [GET_INVENTORY_VALUE] User 1: Inventory value fetched successfully
[2025-03-11 14:20:49,864] ERROR in logger: [EXCEPTION] User None: Unhandled exception: NotFound
[2025-03-11 14:20:49,872] ERROR in app: Exception on /wine/stock_by_category [GET]
Traceback (most recent call last):
  File "/Users/macbookpro/Documents/projects/WSS/venv/lib/python3.11/site-packages/flask/app.py", line 1463, in wsgi_app
    response = self.full_dispatch_request()
               ^^^^^^^^^^^^^^^^^^^^^^^^^^^^
  File "/Users/macbookpro/Documents/projects/WSS/venv/lib/python3.11/site-packages/flask/app.py", line 872, in full_dispatch_request
    rv = self.handle_user_exception(e)
         ^^^^^^^^^^^^^^^^^^^^^^^^^^^^^
  File "/Users/macbookpro/Documents/projects/WSS/venv/lib/python3.11/site-packages/flask_cors/extension.py", line 176, in wrapped_function
    return cors_after_request(app.make_response(f(*args, **kwargs)))
                                                ^^^^^^^^^^^^^^^^^^
  File "/Users/macbookpro/Documents/projects/WSS/venv/lib/python3.11/site-packages/flask/app.py", line 755, in handle_user_exception
    return self.handle_http_exception(e)
           ^^^^^^^^^^^^^^^^^^^^^^^^^^^^^
  File "/Users/macbookpro/Documents/projects/WSS/venv/lib/python3.11/site-packages/flask/app.py", line 730, in handle_http_exception
    return self.ensure_sync(handler)(e)  # type: ignore[no-any-return]
           ^^^^^^^^^^^^^^^^^^^^^^^^^^^^
  File "/Users/macbookpro/Documents/projects/WSS/majesty-backend/app/utils/logger.py", line 184, in log_exception
    raise exception
  File "/Users/macbookpro/Documents/projects/WSS/venv/lib/python3.11/site-packages/flask/app.py", line 870, in full_dispatch_request
    rv = self.dispatch_request()
         ^^^^^^^^^^^^^^^^^^^^^^^
  File "/Users/macbookpro/Documents/projects/WSS/venv/lib/python3.11/site-packages/flask/app.py", line 844, in dispatch_request
    self.raise_routing_exception(req)
  File "/Users/macbookpro/Documents/projects/WSS/venv/lib/python3.11/site-packages/flask/app.py", line 453, in raise_routing_exception
    raise request.routing_exception  # type: ignore[misc]
    ^^^^^^^^^^^^^^^^^^^^^^^^^^^^^^^
  File "/Users/macbookpro/Documents/projects/WSS/venv/lib/python3.11/site-packages/flask/ctx.py", line 362, in match_request
    result = self.url_adapter.match(return_rule=True)  # type: ignore
             ^^^^^^^^^^^^^^^^^^^^^^^^^^^^^^^^^^^^^^^^
  File "/Users/macbookpro/Documents/projects/WSS/venv/lib/python3.11/site-packages/werkzeug/routing/map.py", line 629, in match
    raise NotFound() from None
werkzeug.exceptions.NotFound: 404 Not Found: The requested URL was not found on the server. If you entered the URL manually please check your spelling and try again.
[2025-03-11 14:20:49,876] ERROR in logger: [EXCEPTION] User None: Unhandled exception: InternalServerError
[2025-03-11 14:28:22,423] INFO in logger: [LOGIN_SUCCESS] User 1: User logged in successfully
[2025-03-11 14:28:55,692] ERROR in logger: [EXCEPTION] User 1: Unhandled exception: TypeError
[2025-03-11 14:28:55,695] ERROR in app: Exception on /wine/revenue [GET]
Traceback (most recent call last):
  File "/Users/macbookpro/Documents/projects/WSS/venv/lib/python3.11/site-packages/flask/app.py", line 1463, in wsgi_app
    response = self.full_dispatch_request()
               ^^^^^^^^^^^^^^^^^^^^^^^^^^^^
  File "/Users/macbookpro/Documents/projects/WSS/venv/lib/python3.11/site-packages/flask/app.py", line 872, in full_dispatch_request
    rv = self.handle_user_exception(e)
         ^^^^^^^^^^^^^^^^^^^^^^^^^^^^^
  File "/Users/macbookpro/Documents/projects/WSS/venv/lib/python3.11/site-packages/flask_cors/extension.py", line 176, in wrapped_function
    return cors_after_request(app.make_response(f(*args, **kwargs)))
                                                ^^^^^^^^^^^^^^^^^^
  File "/Users/macbookpro/Documents/projects/WSS/venv/lib/python3.11/site-packages/flask/app.py", line 762, in handle_user_exception
    return self.ensure_sync(handler)(e)  # type: ignore[no-any-return]
           ^^^^^^^^^^^^^^^^^^^^^^^^^^^^
  File "/Users/macbookpro/Documents/projects/WSS/majesty-backend/app/utils/logger.py", line 184, in log_exception
    raise exception
  File "/Users/macbookpro/Documents/projects/WSS/venv/lib/python3.11/site-packages/flask/app.py", line 870, in full_dispatch_request
    rv = self.dispatch_request()
         ^^^^^^^^^^^^^^^^^^^^^^^
  File "/Users/macbookpro/Documents/projects/WSS/venv/lib/python3.11/site-packages/flask/app.py", line 855, in dispatch_request
    return self.ensure_sync(self.view_functions[rule.endpoint])(**view_args)  # type: ignore[no-any-return]
           ^^^^^^^^^^^^^^^^^^^^^^^^^^^^^^^^^^^^^^^^^^^^^^^^^^^^^^^^^^^^^^^^^
  File "/Users/macbookpro/Documents/projects/WSS/venv/lib/python3.11/site-packages/flask_jwt_extended/view_decorators.py", line 170, in decorator
    return current_app.ensure_sync(fn)(*args, **kwargs)
           ^^^^^^^^^^^^^^^^^^^^^^^^^^^^^^^^^^^^^^^^^^^^
  File "/Users/macbookpro/Documents/projects/WSS/majesty-backend/app/routes/wine.py", line 63, in get_revenue
    start_date = datetime.strptime(start_date_str, '%Y-%m-%d')
                 ^^^^^^^^^^^^^^^^^^^^^^^^^^^^^^^^^^^^^^^^^^^^^
TypeError: strptime() argument 1 must be str, not None
[2025-03-11 14:28:55,730] ERROR in logger: [EXCEPTION] User 1: Unhandled exception: InternalServerError
[2025-03-11 14:33:16,983] INFO in logger: [GET_INVENTORY_VALUE] User 1: Inventory value fetched successfully
[2025-03-11 14:33:29,733] ERROR in logger: [EXCEPTION] User None: Unhandled exception: NotFound
[2025-03-11 14:33:29,740] ERROR in app: Exception on /revenue [GET]
Traceback (most recent call last):
  File "/Users/macbookpro/Documents/projects/WSS/venv/lib/python3.11/site-packages/flask/app.py", line 1463, in wsgi_app
    response = self.full_dispatch_request()
               ^^^^^^^^^^^^^^^^^^^^^^^^^^^^
  File "/Users/macbookpro/Documents/projects/WSS/venv/lib/python3.11/site-packages/flask/app.py", line 872, in full_dispatch_request
    rv = self.handle_user_exception(e)
         ^^^^^^^^^^^^^^^^^^^^^^^^^^^^^
  File "/Users/macbookpro/Documents/projects/WSS/venv/lib/python3.11/site-packages/flask_cors/extension.py", line 176, in wrapped_function
    return cors_after_request(app.make_response(f(*args, **kwargs)))
                                                ^^^^^^^^^^^^^^^^^^
  File "/Users/macbookpro/Documents/projects/WSS/venv/lib/python3.11/site-packages/flask/app.py", line 755, in handle_user_exception
    return self.handle_http_exception(e)
           ^^^^^^^^^^^^^^^^^^^^^^^^^^^^^
  File "/Users/macbookpro/Documents/projects/WSS/venv/lib/python3.11/site-packages/flask/app.py", line 730, in handle_http_exception
    return self.ensure_sync(handler)(e)  # type: ignore[no-any-return]
           ^^^^^^^^^^^^^^^^^^^^^^^^^^^^
  File "/Users/macbookpro/Documents/projects/WSS/majesty-backend/app/utils/logger.py", line 184, in log_exception
    raise exception
  File "/Users/macbookpro/Documents/projects/WSS/venv/lib/python3.11/site-packages/flask/app.py", line 870, in full_dispatch_request
    rv = self.dispatch_request()
         ^^^^^^^^^^^^^^^^^^^^^^^
  File "/Users/macbookpro/Documents/projects/WSS/venv/lib/python3.11/site-packages/flask/app.py", line 844, in dispatch_request
    self.raise_routing_exception(req)
  File "/Users/macbookpro/Documents/projects/WSS/venv/lib/python3.11/site-packages/flask/app.py", line 453, in raise_routing_exception
    raise request.routing_exception  # type: ignore[misc]
    ^^^^^^^^^^^^^^^^^^^^^^^^^^^^^^^
  File "/Users/macbookpro/Documents/projects/WSS/venv/lib/python3.11/site-packages/flask/ctx.py", line 362, in match_request
    result = self.url_adapter.match(return_rule=True)  # type: ignore
             ^^^^^^^^^^^^^^^^^^^^^^^^^^^^^^^^^^^^^^^^
  File "/Users/macbookpro/Documents/projects/WSS/venv/lib/python3.11/site-packages/werkzeug/routing/map.py", line 629, in match
    raise NotFound() from None
werkzeug.exceptions.NotFound: 404 Not Found: The requested URL was not found on the server. If you entered the URL manually please check your spelling and try again.
[2025-03-11 14:33:29,742] ERROR in logger: [EXCEPTION] User None: Unhandled exception: InternalServerError
[2025-03-11 14:33:48,836] ERROR in logger: [EXCEPTION] User 1: Unhandled exception: TypeError
[2025-03-11 14:33:48,843] ERROR in app: Exception on /wine/revenue [GET]
Traceback (most recent call last):
  File "/Users/macbookpro/Documents/projects/WSS/venv/lib/python3.11/site-packages/flask/app.py", line 1463, in wsgi_app
    response = self.full_dispatch_request()
               ^^^^^^^^^^^^^^^^^^^^^^^^^^^^
  File "/Users/macbookpro/Documents/projects/WSS/venv/lib/python3.11/site-packages/flask/app.py", line 872, in full_dispatch_request
    rv = self.handle_user_exception(e)
         ^^^^^^^^^^^^^^^^^^^^^^^^^^^^^
  File "/Users/macbookpro/Documents/projects/WSS/venv/lib/python3.11/site-packages/flask_cors/extension.py", line 176, in wrapped_function
    return cors_after_request(app.make_response(f(*args, **kwargs)))
                                                ^^^^^^^^^^^^^^^^^^
  File "/Users/macbookpro/Documents/projects/WSS/venv/lib/python3.11/site-packages/flask/app.py", line 762, in handle_user_exception
    return self.ensure_sync(handler)(e)  # type: ignore[no-any-return]
           ^^^^^^^^^^^^^^^^^^^^^^^^^^^^
  File "/Users/macbookpro/Documents/projects/WSS/majesty-backend/app/utils/logger.py", line 184, in log_exception
    raise exception
  File "/Users/macbookpro/Documents/projects/WSS/venv/lib/python3.11/site-packages/flask/app.py", line 870, in full_dispatch_request
    rv = self.dispatch_request()
         ^^^^^^^^^^^^^^^^^^^^^^^
  File "/Users/macbookpro/Documents/projects/WSS/venv/lib/python3.11/site-packages/flask/app.py", line 855, in dispatch_request
    return self.ensure_sync(self.view_functions[rule.endpoint])(**view_args)  # type: ignore[no-any-return]
           ^^^^^^^^^^^^^^^^^^^^^^^^^^^^^^^^^^^^^^^^^^^^^^^^^^^^^^^^^^^^^^^^^
  File "/Users/macbookpro/Documents/projects/WSS/venv/lib/python3.11/site-packages/flask_jwt_extended/view_decorators.py", line 170, in decorator
    return current_app.ensure_sync(fn)(*args, **kwargs)
           ^^^^^^^^^^^^^^^^^^^^^^^^^^^^^^^^^^^^^^^^^^^^
  File "/Users/macbookpro/Documents/projects/WSS/majesty-backend/app/routes/wine.py", line 63, in get_revenue
    start_date = datetime.strptime(start_date_str, '%Y-%m-%d')
                 ^^^^^^^^^^^^^^^^^^^^^^^^^^^^^^^^^^^^^^^^^^^^^
TypeError: strptime() argument 1 must be str, not None
[2025-03-11 14:33:48,844] ERROR in logger: [EXCEPTION] User 1: Unhandled exception: InternalServerError
[2025-03-11 14:36:24,063] ERROR in logger: [EXCEPTION] User None: Unhandled exception: NotFound
[2025-03-11 14:36:24,069] ERROR in app: Exception on /logs [GET]
Traceback (most recent call last):
  File "/Users/macbookpro/Documents/projects/WSS/venv/lib/python3.11/site-packages/flask/app.py", line 1463, in wsgi_app
    response = self.full_dispatch_request()
               ^^^^^^^^^^^^^^^^^^^^^^^^^^^^
  File "/Users/macbookpro/Documents/projects/WSS/venv/lib/python3.11/site-packages/flask/app.py", line 872, in full_dispatch_request
    rv = self.handle_user_exception(e)
         ^^^^^^^^^^^^^^^^^^^^^^^^^^^^^
  File "/Users/macbookpro/Documents/projects/WSS/venv/lib/python3.11/site-packages/flask_cors/extension.py", line 176, in wrapped_function
    return cors_after_request(app.make_response(f(*args, **kwargs)))
                                                ^^^^^^^^^^^^^^^^^^
  File "/Users/macbookpro/Documents/projects/WSS/venv/lib/python3.11/site-packages/flask/app.py", line 755, in handle_user_exception
    return self.handle_http_exception(e)
           ^^^^^^^^^^^^^^^^^^^^^^^^^^^^^
  File "/Users/macbookpro/Documents/projects/WSS/venv/lib/python3.11/site-packages/flask/app.py", line 730, in handle_http_exception
    return self.ensure_sync(handler)(e)  # type: ignore[no-any-return]
           ^^^^^^^^^^^^^^^^^^^^^^^^^^^^
  File "/Users/macbookpro/Documents/projects/WSS/majesty-backend/app/utils/logger.py", line 184, in log_exception
    raise exception
  File "/Users/macbookpro/Documents/projects/WSS/venv/lib/python3.11/site-packages/flask/app.py", line 870, in full_dispatch_request
    rv = self.dispatch_request()
         ^^^^^^^^^^^^^^^^^^^^^^^
  File "/Users/macbookpro/Documents/projects/WSS/venv/lib/python3.11/site-packages/flask/app.py", line 844, in dispatch_request
    self.raise_routing_exception(req)
  File "/Users/macbookpro/Documents/projects/WSS/venv/lib/python3.11/site-packages/flask/app.py", line 453, in raise_routing_exception
    raise request.routing_exception  # type: ignore[misc]
    ^^^^^^^^^^^^^^^^^^^^^^^^^^^^^^^
  File "/Users/macbookpro/Documents/projects/WSS/venv/lib/python3.11/site-packages/flask/ctx.py", line 362, in match_request
    result = self.url_adapter.match(return_rule=True)  # type: ignore
             ^^^^^^^^^^^^^^^^^^^^^^^^^^^^^^^^^^^^^^^^
  File "/Users/macbookpro/Documents/projects/WSS/venv/lib/python3.11/site-packages/werkzeug/routing/map.py", line 629, in match
    raise NotFound() from None
werkzeug.exceptions.NotFound: 404 Not Found: The requested URL was not found on the server. If you entered the URL manually please check your spelling and try again.
[2025-03-11 14:36:24,091] ERROR in logger: [EXCEPTION] User None: Unhandled exception: InternalServerError
[2025-03-11 20:08:09,158] INFO in logger: Wine Inventory API Started - Environment: development
[2025-03-11 20:10:25,864] INFO in logger: [LOGIN_SUCCESS] User 1: User logged in successfully
[2025-03-11 20:12:10,636] INFO in logger: [GET_TOTAL_STOCK] User 1: Total stock checked: 100
[2025-03-11 20:13:57,946] ERROR in logger: [EXCEPTION] User None: Unhandled exception: NotFound
[2025-03-11 20:13:57,952] ERROR in app: Exception on /wine/stock_by_category [GET]
Traceback (most recent call last):
  File "/Users/macbookpro/Documents/projects/WSS/venv/lib/python3.11/site-packages/flask/app.py", line 1463, in wsgi_app
    response = self.full_dispatch_request()
               ^^^^^^^^^^^^^^^^^^^^^^^^^^^^
  File "/Users/macbookpro/Documents/projects/WSS/venv/lib/python3.11/site-packages/flask/app.py", line 872, in full_dispatch_request
    rv = self.handle_user_exception(e)
         ^^^^^^^^^^^^^^^^^^^^^^^^^^^^^
  File "/Users/macbookpro/Documents/projects/WSS/venv/lib/python3.11/site-packages/flask_cors/extension.py", line 176, in wrapped_function
    return cors_after_request(app.make_response(f(*args, **kwargs)))
                                                ^^^^^^^^^^^^^^^^^^
  File "/Users/macbookpro/Documents/projects/WSS/venv/lib/python3.11/site-packages/flask/app.py", line 755, in handle_user_exception
    return self.handle_http_exception(e)
           ^^^^^^^^^^^^^^^^^^^^^^^^^^^^^
  File "/Users/macbookpro/Documents/projects/WSS/venv/lib/python3.11/site-packages/flask/app.py", line 730, in handle_http_exception
    return self.ensure_sync(handler)(e)  # type: ignore[no-any-return]
           ^^^^^^^^^^^^^^^^^^^^^^^^^^^^
  File "/Users/macbookpro/Documents/projects/WSS/majesty-backend/app/utils/logger.py", line 184, in log_exception
    raise exception
  File "/Users/macbookpro/Documents/projects/WSS/venv/lib/python3.11/site-packages/flask/app.py", line 870, in full_dispatch_request
    rv = self.dispatch_request()
         ^^^^^^^^^^^^^^^^^^^^^^^
  File "/Users/macbookpro/Documents/projects/WSS/venv/lib/python3.11/site-packages/flask/app.py", line 844, in dispatch_request
    self.raise_routing_exception(req)
  File "/Users/macbookpro/Documents/projects/WSS/venv/lib/python3.11/site-packages/flask/app.py", line 453, in raise_routing_exception
    raise request.routing_exception  # type: ignore[misc]
    ^^^^^^^^^^^^^^^^^^^^^^^^^^^^^^^
  File "/Users/macbookpro/Documents/projects/WSS/venv/lib/python3.11/site-packages/flask/ctx.py", line 362, in match_request
    result = self.url_adapter.match(return_rule=True)  # type: ignore
             ^^^^^^^^^^^^^^^^^^^^^^^^^^^^^^^^^^^^^^^^
  File "/Users/macbookpro/Documents/projects/WSS/venv/lib/python3.11/site-packages/werkzeug/routing/map.py", line 629, in match
    raise NotFound() from None
werkzeug.exceptions.NotFound: 404 Not Found: The requested URL was not found on the server. If you entered the URL manually please check your spelling and try again.
[2025-03-11 20:13:57,957] ERROR in logger: [EXCEPTION] User None: Unhandled exception: InternalServerError
[2025-03-11 20:17:51,739] INFO in logger: [GET_STOCK_BY_CATEGORY] User 1: Stock by category fetched successfully
[2025-03-11 20:20:07,269] ERROR in logger: [EXCEPTION] User 1: Unhandled exception: TypeError
[2025-03-11 20:20:07,276] ERROR in app: Exception on /wine/revenue [GET]
Traceback (most recent call last):
  File "/Users/macbookpro/Documents/projects/WSS/venv/lib/python3.11/site-packages/flask/app.py", line 1463, in wsgi_app
    response = self.full_dispatch_request()
               ^^^^^^^^^^^^^^^^^^^^^^^^^^^^
  File "/Users/macbookpro/Documents/projects/WSS/venv/lib/python3.11/site-packages/flask/app.py", line 872, in full_dispatch_request
    rv = self.handle_user_exception(e)
         ^^^^^^^^^^^^^^^^^^^^^^^^^^^^^
  File "/Users/macbookpro/Documents/projects/WSS/venv/lib/python3.11/site-packages/flask_cors/extension.py", line 176, in wrapped_function
    return cors_after_request(app.make_response(f(*args, **kwargs)))
                                                ^^^^^^^^^^^^^^^^^^
  File "/Users/macbookpro/Documents/projects/WSS/venv/lib/python3.11/site-packages/flask/app.py", line 762, in handle_user_exception
    return self.ensure_sync(handler)(e)  # type: ignore[no-any-return]
           ^^^^^^^^^^^^^^^^^^^^^^^^^^^^
  File "/Users/macbookpro/Documents/projects/WSS/majesty-backend/app/utils/logger.py", line 184, in log_exception
    raise exception
  File "/Users/macbookpro/Documents/projects/WSS/venv/lib/python3.11/site-packages/flask/app.py", line 870, in full_dispatch_request
    rv = self.dispatch_request()
         ^^^^^^^^^^^^^^^^^^^^^^^
  File "/Users/macbookpro/Documents/projects/WSS/venv/lib/python3.11/site-packages/flask/app.py", line 855, in dispatch_request
    return self.ensure_sync(self.view_functions[rule.endpoint])(**view_args)  # type: ignore[no-any-return]
           ^^^^^^^^^^^^^^^^^^^^^^^^^^^^^^^^^^^^^^^^^^^^^^^^^^^^^^^^^^^^^^^^^
  File "/Users/macbookpro/Documents/projects/WSS/venv/lib/python3.11/site-packages/flask_jwt_extended/view_decorators.py", line 170, in decorator
    return current_app.ensure_sync(fn)(*args, **kwargs)
           ^^^^^^^^^^^^^^^^^^^^^^^^^^^^^^^^^^^^^^^^^^^^
  File "/Users/macbookpro/Documents/projects/WSS/majesty-backend/app/routes/wine.py", line 63, in get_revenue
    try:
         
TypeError: strptime() argument 1 must be str, not None
[2025-03-11 20:20:07,303] ERROR in logger: [EXCEPTION] User 1: Unhandled exception: InternalServerError
[2025-03-11 20:23:55,657] ERROR in logger: [EXCEPTION] User 1: Unhandled exception: TypeError
[2025-03-11 20:23:55,662] ERROR in app: Exception on /wine/revenue [GET]
Traceback (most recent call last):
  File "/Users/macbookpro/Documents/projects/WSS/venv/lib/python3.11/site-packages/flask/app.py", line 1463, in wsgi_app
    response = self.full_dispatch_request()
               ^^^^^^^^^^^^^^^^^^^^^^^^^^^^
  File "/Users/macbookpro/Documents/projects/WSS/venv/lib/python3.11/site-packages/flask/app.py", line 872, in full_dispatch_request
    rv = self.handle_user_exception(e)
         ^^^^^^^^^^^^^^^^^^^^^^^^^^^^^
  File "/Users/macbookpro/Documents/projects/WSS/venv/lib/python3.11/site-packages/flask_cors/extension.py", line 176, in wrapped_function
    return cors_after_request(app.make_response(f(*args, **kwargs)))
                                                ^^^^^^^^^^^^^^^^^^
  File "/Users/macbookpro/Documents/projects/WSS/venv/lib/python3.11/site-packages/flask/app.py", line 762, in handle_user_exception
    return self.ensure_sync(handler)(e)  # type: ignore[no-any-return]
           ^^^^^^^^^^^^^^^^^^^^^^^^^^^^
  File "/Users/macbookpro/Documents/projects/WSS/majesty-backend/app/utils/logger.py", line 184, in log_exception
    raise exception
  File "/Users/macbookpro/Documents/projects/WSS/venv/lib/python3.11/site-packages/flask/app.py", line 870, in full_dispatch_request
    rv = self.dispatch_request()
         ^^^^^^^^^^^^^^^^^^^^^^^
  File "/Users/macbookpro/Documents/projects/WSS/venv/lib/python3.11/site-packages/flask/app.py", line 855, in dispatch_request
    return self.ensure_sync(self.view_functions[rule.endpoint])(**view_args)  # type: ignore[no-any-return]
           ^^^^^^^^^^^^^^^^^^^^^^^^^^^^^^^^^^^^^^^^^^^^^^^^^^^^^^^^^^^^^^^^^
  File "/Users/macbookpro/Documents/projects/WSS/venv/lib/python3.11/site-packages/flask_jwt_extended/view_decorators.py", line 170, in decorator
    return current_app.ensure_sync(fn)(*args, **kwargs)
           ^^^^^^^^^^^^^^^^^^^^^^^^^^^^^^^^^^^^^^^^^^^^
  File "/Users/macbookpro/Documents/projects/WSS/majesty-backend/app/routes/wine.py", line 63, in get_revenue
    # Check if start_date and end_date are provided
                     ^^^^^^^^^^^^^^^^^^^^^^^^^^^^^^^
TypeError: strptime() argument 1 must be str, not None
[2025-03-11 20:23:55,664] ERROR in logger: [EXCEPTION] User 1: Unhandled exception: InternalServerError
[2025-03-11 20:23:59,829] ERROR in logger: [EXCEPTION] User 1: Unhandled exception: TypeError
[2025-03-11 20:23:59,834] ERROR in app: Exception on /wine/revenue [GET]
Traceback (most recent call last):
  File "/Users/macbookpro/Documents/projects/WSS/venv/lib/python3.11/site-packages/flask/app.py", line 1463, in wsgi_app
    response = self.full_dispatch_request()
               ^^^^^^^^^^^^^^^^^^^^^^^^^^^^
  File "/Users/macbookpro/Documents/projects/WSS/venv/lib/python3.11/site-packages/flask/app.py", line 872, in full_dispatch_request
    rv = self.handle_user_exception(e)
         ^^^^^^^^^^^^^^^^^^^^^^^^^^^^^
  File "/Users/macbookpro/Documents/projects/WSS/venv/lib/python3.11/site-packages/flask_cors/extension.py", line 176, in wrapped_function
    return cors_after_request(app.make_response(f(*args, **kwargs)))
                                                ^^^^^^^^^^^^^^^^^^
  File "/Users/macbookpro/Documents/projects/WSS/venv/lib/python3.11/site-packages/flask/app.py", line 762, in handle_user_exception
    return self.ensure_sync(handler)(e)  # type: ignore[no-any-return]
           ^^^^^^^^^^^^^^^^^^^^^^^^^^^^
  File "/Users/macbookpro/Documents/projects/WSS/majesty-backend/app/utils/logger.py", line 184, in log_exception
    raise exception
  File "/Users/macbookpro/Documents/projects/WSS/venv/lib/python3.11/site-packages/flask/app.py", line 870, in full_dispatch_request
    rv = self.dispatch_request()
         ^^^^^^^^^^^^^^^^^^^^^^^
  File "/Users/macbookpro/Documents/projects/WSS/venv/lib/python3.11/site-packages/flask/app.py", line 855, in dispatch_request
    return self.ensure_sync(self.view_functions[rule.endpoint])(**view_args)  # type: ignore[no-any-return]
           ^^^^^^^^^^^^^^^^^^^^^^^^^^^^^^^^^^^^^^^^^^^^^^^^^^^^^^^^^^^^^^^^^
  File "/Users/macbookpro/Documents/projects/WSS/venv/lib/python3.11/site-packages/flask_jwt_extended/view_decorators.py", line 170, in decorator
    return current_app.ensure_sync(fn)(*args, **kwargs)
           ^^^^^^^^^^^^^^^^^^^^^^^^^^^^^^^^^^^^^^^^^^^^
  File "/Users/macbookpro/Documents/projects/WSS/majesty-backend/app/routes/wine.py", line 63, in get_revenue
    # Check if start_date and end_date are provided
                     ^^^^^^^^^^^^^^^^^^^^^^^^^^^^^^^
TypeError: strptime() argument 1 must be str, not None
[2025-03-11 20:23:59,840] ERROR in logger: [EXCEPTION] User 1: Unhandled exception: InternalServerError
[2025-03-11 20:24:02,010] ERROR in logger: [EXCEPTION] User 1: Unhandled exception: TypeError
[2025-03-11 20:24:02,015] ERROR in app: Exception on /wine/revenue [GET]
Traceback (most recent call last):
  File "/Users/macbookpro/Documents/projects/WSS/venv/lib/python3.11/site-packages/flask/app.py", line 1463, in wsgi_app
    response = self.full_dispatch_request()
               ^^^^^^^^^^^^^^^^^^^^^^^^^^^^
  File "/Users/macbookpro/Documents/projects/WSS/venv/lib/python3.11/site-packages/flask/app.py", line 872, in full_dispatch_request
    rv = self.handle_user_exception(e)
         ^^^^^^^^^^^^^^^^^^^^^^^^^^^^^
  File "/Users/macbookpro/Documents/projects/WSS/venv/lib/python3.11/site-packages/flask_cors/extension.py", line 176, in wrapped_function
    return cors_after_request(app.make_response(f(*args, **kwargs)))
                                                ^^^^^^^^^^^^^^^^^^
  File "/Users/macbookpro/Documents/projects/WSS/venv/lib/python3.11/site-packages/flask/app.py", line 762, in handle_user_exception
    return self.ensure_sync(handler)(e)  # type: ignore[no-any-return]
           ^^^^^^^^^^^^^^^^^^^^^^^^^^^^
  File "/Users/macbookpro/Documents/projects/WSS/majesty-backend/app/utils/logger.py", line 184, in log_exception
    raise exception
  File "/Users/macbookpro/Documents/projects/WSS/venv/lib/python3.11/site-packages/flask/app.py", line 870, in full_dispatch_request
    rv = self.dispatch_request()
         ^^^^^^^^^^^^^^^^^^^^^^^
  File "/Users/macbookpro/Documents/projects/WSS/venv/lib/python3.11/site-packages/flask/app.py", line 855, in dispatch_request
    return self.ensure_sync(self.view_functions[rule.endpoint])(**view_args)  # type: ignore[no-any-return]
           ^^^^^^^^^^^^^^^^^^^^^^^^^^^^^^^^^^^^^^^^^^^^^^^^^^^^^^^^^^^^^^^^^
  File "/Users/macbookpro/Documents/projects/WSS/venv/lib/python3.11/site-packages/flask_jwt_extended/view_decorators.py", line 170, in decorator
    return current_app.ensure_sync(fn)(*args, **kwargs)
           ^^^^^^^^^^^^^^^^^^^^^^^^^^^^^^^^^^^^^^^^^^^^
  File "/Users/macbookpro/Documents/projects/WSS/majesty-backend/app/routes/wine.py", line 63, in get_revenue
    # Check if start_date and end_date are provided
                     ^^^^^^^^^^^^^^^^^^^^^^^^^^^^^^^
TypeError: strptime() argument 1 must be str, not None
[2025-03-11 20:24:02,017] ERROR in logger: [EXCEPTION] User 1: Unhandled exception: InternalServerError
[2025-03-11 20:24:09,017] INFO in logger: Wine Inventory API Started - Environment: development
[2025-03-11 20:24:14,320] ERROR in logger: [GET_REVENUE_ERROR] User 1: Missing start_date or end_date
[2025-03-11 20:26:11,080] INFO in logger: [GET_REVENUE] User 1: Revenue calculated: 0
[2025-03-11 20:28:31,160] ERROR in logger: [EXCEPTION] User 1: Unhandled exception: TypeError
[2025-03-11 20:28:31,165] ERROR in app: Exception on /wine/compare-sales [GET]
Traceback (most recent call last):
  File "/Users/macbookpro/Documents/projects/WSS/venv/lib/python3.11/site-packages/flask/app.py", line 1463, in wsgi_app
    response = self.full_dispatch_request()
               ^^^^^^^^^^^^^^^^^^^^^^^^^^^^
  File "/Users/macbookpro/Documents/projects/WSS/venv/lib/python3.11/site-packages/flask/app.py", line 872, in full_dispatch_request
    rv = self.handle_user_exception(e)
         ^^^^^^^^^^^^^^^^^^^^^^^^^^^^^
  File "/Users/macbookpro/Documents/projects/WSS/venv/lib/python3.11/site-packages/flask_cors/extension.py", line 176, in wrapped_function
    return cors_after_request(app.make_response(f(*args, **kwargs)))
                                                ^^^^^^^^^^^^^^^^^^
  File "/Users/macbookpro/Documents/projects/WSS/venv/lib/python3.11/site-packages/flask/app.py", line 762, in handle_user_exception
    return self.ensure_sync(handler)(e)  # type: ignore[no-any-return]
           ^^^^^^^^^^^^^^^^^^^^^^^^^^^^
  File "/Users/macbookpro/Documents/projects/WSS/majesty-backend/app/utils/logger.py", line 184, in log_exception
    raise exception
  File "/Users/macbookpro/Documents/projects/WSS/venv/lib/python3.11/site-packages/flask/app.py", line 870, in full_dispatch_request
    rv = self.dispatch_request()
         ^^^^^^^^^^^^^^^^^^^^^^^
  File "/Users/macbookpro/Documents/projects/WSS/venv/lib/python3.11/site-packages/flask/app.py", line 855, in dispatch_request
    return self.ensure_sync(self.view_functions[rule.endpoint])(**view_args)  # type: ignore[no-any-return]
           ^^^^^^^^^^^^^^^^^^^^^^^^^^^^^^^^^^^^^^^^^^^^^^^^^^^^^^^^^^^^^^^^^
  File "/Users/macbookpro/Documents/projects/WSS/venv/lib/python3.11/site-packages/flask_jwt_extended/view_decorators.py", line 170, in decorator
    return current_app.ensure_sync(fn)(*args, **kwargs)
           ^^^^^^^^^^^^^^^^^^^^^^^^^^^^^^^^^^^^^^^^^^^^
  File "/Users/macbookpro/Documents/projects/WSS/majesty-backend/app/routes/wine.py", line 96, in compare_sales
    period1_start = datetime.strptime(period1_start_str, '%Y-%m-%d')
                    ^^^^^^^^^^^^^^^^^^^^^^^^^^^^^^^^^^^^^^^^^^^^^^^^
TypeError: strptime() argument 1 must be str, not None
[2025-03-11 20:28:31,173] ERROR in logger: [EXCEPTION] User 1: Unhandled exception: InternalServerError
[2025-03-11 20:31:12,640] ERROR in logger: [EXCEPTION] User 1: Unhandled exception: TypeError
[2025-03-11 20:31:12,645] ERROR in app: Exception on /wine/compare-sales [GET]
Traceback (most recent call last):
  File "/Users/macbookpro/Documents/projects/WSS/venv/lib/python3.11/site-packages/flask/app.py", line 1463, in wsgi_app
    response = self.full_dispatch_request()
               ^^^^^^^^^^^^^^^^^^^^^^^^^^^^
  File "/Users/macbookpro/Documents/projects/WSS/venv/lib/python3.11/site-packages/flask/app.py", line 872, in full_dispatch_request
    rv = self.handle_user_exception(e)
         ^^^^^^^^^^^^^^^^^^^^^^^^^^^^^
  File "/Users/macbookpro/Documents/projects/WSS/venv/lib/python3.11/site-packages/flask_cors/extension.py", line 176, in wrapped_function
    return cors_after_request(app.make_response(f(*args, **kwargs)))
                                                ^^^^^^^^^^^^^^^^^^
  File "/Users/macbookpro/Documents/projects/WSS/venv/lib/python3.11/site-packages/flask/app.py", line 762, in handle_user_exception
    return self.ensure_sync(handler)(e)  # type: ignore[no-any-return]
           ^^^^^^^^^^^^^^^^^^^^^^^^^^^^
  File "/Users/macbookpro/Documents/projects/WSS/majesty-backend/app/utils/logger.py", line 184, in log_exception
    raise exception
  File "/Users/macbookpro/Documents/projects/WSS/venv/lib/python3.11/site-packages/flask/app.py", line 870, in full_dispatch_request
    rv = self.dispatch_request()
         ^^^^^^^^^^^^^^^^^^^^^^^
  File "/Users/macbookpro/Documents/projects/WSS/venv/lib/python3.11/site-packages/flask/app.py", line 855, in dispatch_request
    return self.ensure_sync(self.view_functions[rule.endpoint])(**view_args)  # type: ignore[no-any-return]
           ^^^^^^^^^^^^^^^^^^^^^^^^^^^^^^^^^^^^^^^^^^^^^^^^^^^^^^^^^^^^^^^^^
  File "/Users/macbookpro/Documents/projects/WSS/venv/lib/python3.11/site-packages/flask_jwt_extended/view_decorators.py", line 170, in decorator
    return current_app.ensure_sync(fn)(*args, **kwargs)
           ^^^^^^^^^^^^^^^^^^^^^^^^^^^^^^^^^^^^^^^^^^^^
  File "/Users/macbookpro/Documents/projects/WSS/majesty-backend/app/routes/wine.py", line 96, in compare_sales
    # Check if all required parameters are provided
                        ^^^^^^^^^^^^^^^^^^^^^^^^^^^^
TypeError: strptime() argument 1 must be str, not None
[2025-03-11 20:31:12,647] ERROR in logger: [EXCEPTION] User 1: Unhandled exception: InternalServerError
[2025-03-11 20:31:20,645] INFO in logger: Wine Inventory API Started - Environment: development
[2025-03-11 20:31:25,022] ERROR in logger: [COMPARE_SALES_ERROR] User 1: Missing required query parameters
[2025-03-11 20:37:08,671] INFO in logger: [COMPARE_SALES] User 1: Sales compared: 0%
[2025-03-11 20:42:37,347] ERROR in logger: [EXCEPTION] User None: Unhandled exception: NotFound
[2025-03-11 20:42:37,352] ERROR in app: Exception on /wine/<int:1> [DELETE]
Traceback (most recent call last):
  File "/Users/macbookpro/Documents/projects/WSS/venv/lib/python3.11/site-packages/flask/app.py", line 1463, in wsgi_app
    response = self.full_dispatch_request()
               ^^^^^^^^^^^^^^^^^^^^^^^^^^^^
  File "/Users/macbookpro/Documents/projects/WSS/venv/lib/python3.11/site-packages/flask/app.py", line 872, in full_dispatch_request
    rv = self.handle_user_exception(e)
         ^^^^^^^^^^^^^^^^^^^^^^^^^^^^^
  File "/Users/macbookpro/Documents/projects/WSS/venv/lib/python3.11/site-packages/flask_cors/extension.py", line 176, in wrapped_function
    return cors_after_request(app.make_response(f(*args, **kwargs)))
                                                ^^^^^^^^^^^^^^^^^^
  File "/Users/macbookpro/Documents/projects/WSS/venv/lib/python3.11/site-packages/flask/app.py", line 755, in handle_user_exception
    return self.handle_http_exception(e)
           ^^^^^^^^^^^^^^^^^^^^^^^^^^^^^
  File "/Users/macbookpro/Documents/projects/WSS/venv/lib/python3.11/site-packages/flask/app.py", line 730, in handle_http_exception
    return self.ensure_sync(handler)(e)  # type: ignore[no-any-return]
           ^^^^^^^^^^^^^^^^^^^^^^^^^^^^
  File "/Users/macbookpro/Documents/projects/WSS/majesty-backend/app/utils/logger.py", line 184, in log_exception
    raise exception
  File "/Users/macbookpro/Documents/projects/WSS/venv/lib/python3.11/site-packages/flask/app.py", line 870, in full_dispatch_request
    rv = self.dispatch_request()
         ^^^^^^^^^^^^^^^^^^^^^^^
  File "/Users/macbookpro/Documents/projects/WSS/venv/lib/python3.11/site-packages/flask/app.py", line 844, in dispatch_request
    self.raise_routing_exception(req)
  File "/Users/macbookpro/Documents/projects/WSS/venv/lib/python3.11/site-packages/flask/app.py", line 453, in raise_routing_exception
    raise request.routing_exception  # type: ignore[misc]
    ^^^^^^^^^^^^^^^^^^^^^^^^^^^^^^^
  File "/Users/macbookpro/Documents/projects/WSS/venv/lib/python3.11/site-packages/flask/ctx.py", line 362, in match_request
    result = self.url_adapter.match(return_rule=True)  # type: ignore
             ^^^^^^^^^^^^^^^^^^^^^^^^^^^^^^^^^^^^^^^^
  File "/Users/macbookpro/Documents/projects/WSS/venv/lib/python3.11/site-packages/werkzeug/routing/map.py", line 629, in match
    raise NotFound() from None
werkzeug.exceptions.NotFound: 404 Not Found: The requested URL was not found on the server. If you entered the URL manually please check your spelling and try again.
[2025-03-11 20:42:37,355] ERROR in logger: [EXCEPTION] User None: Unhandled exception: InternalServerError
[2025-03-11 20:49:10,833] INFO in logger: [DELETE_WINE_SUCCESS] User 1: Wine deleted: 1
[2025-03-11 20:49:11,680] INFO in logger: [DELETE_WINE_ERROR] User 1: Wine not found: 1
[2025-03-11 20:51:35,659] INFO in logger: [UPDATE_WINE_SUCCESS] User 1: Wine updated: 2
[2025-03-11 20:52:44,694] INFO in logger: [UPDATE_WINE_SUCCESS] User 1: Wine updated: 2
[2025-03-11 20:54:01,122] ERROR in logger: [EXCEPTION] User None: Unhandled exception: MethodNotAllowed
[2025-03-11 20:54:01,126] ERROR in app: Exception on /wine/1 [POST]
Traceback (most recent call last):
  File "/Users/macbookpro/Documents/projects/WSS/venv/lib/python3.11/site-packages/flask/app.py", line 1463, in wsgi_app
    response = self.full_dispatch_request()
               ^^^^^^^^^^^^^^^^^^^^^^^^^^^^
  File "/Users/macbookpro/Documents/projects/WSS/venv/lib/python3.11/site-packages/flask/app.py", line 872, in full_dispatch_request
    rv = self.handle_user_exception(e)
         ^^^^^^^^^^^^^^^^^^^^^^^^^^^^^
  File "/Users/macbookpro/Documents/projects/WSS/venv/lib/python3.11/site-packages/flask_cors/extension.py", line 176, in wrapped_function
    return cors_after_request(app.make_response(f(*args, **kwargs)))
                                                ^^^^^^^^^^^^^^^^^^
  File "/Users/macbookpro/Documents/projects/WSS/venv/lib/python3.11/site-packages/flask/app.py", line 755, in handle_user_exception
    return self.handle_http_exception(e)
           ^^^^^^^^^^^^^^^^^^^^^^^^^^^^^
  File "/Users/macbookpro/Documents/projects/WSS/venv/lib/python3.11/site-packages/flask/app.py", line 730, in handle_http_exception
    return self.ensure_sync(handler)(e)  # type: ignore[no-any-return]
           ^^^^^^^^^^^^^^^^^^^^^^^^^^^^
  File "/Users/macbookpro/Documents/projects/WSS/majesty-backend/app/utils/logger.py", line 184, in log_exception
    raise exception
  File "/Users/macbookpro/Documents/projects/WSS/venv/lib/python3.11/site-packages/flask/app.py", line 870, in full_dispatch_request
    rv = self.dispatch_request()
         ^^^^^^^^^^^^^^^^^^^^^^^
  File "/Users/macbookpro/Documents/projects/WSS/venv/lib/python3.11/site-packages/flask/app.py", line 844, in dispatch_request
    self.raise_routing_exception(req)
  File "/Users/macbookpro/Documents/projects/WSS/venv/lib/python3.11/site-packages/flask/app.py", line 453, in raise_routing_exception
    raise request.routing_exception  # type: ignore[misc]
    ^^^^^^^^^^^^^^^^^^^^^^^^^^^^^^^
  File "/Users/macbookpro/Documents/projects/WSS/venv/lib/python3.11/site-packages/flask/ctx.py", line 362, in match_request
    result = self.url_adapter.match(return_rule=True)  # type: ignore
             ^^^^^^^^^^^^^^^^^^^^^^^^^^^^^^^^^^^^^^^^
  File "/Users/macbookpro/Documents/projects/WSS/venv/lib/python3.11/site-packages/werkzeug/routing/map.py", line 624, in match
    raise MethodNotAllowed(valid_methods=list(e.have_match_for)) from None
werkzeug.exceptions.MethodNotAllowed: 405 Method Not Allowed: The method is not allowed for the requested URL.
[2025-03-11 20:54:01,147] ERROR in logger: [EXCEPTION] User None: Unhandled exception: InternalServerError
[2025-03-11 20:54:10,325] INFO in logger: [ADD_WINE_SUCCESS] User 1: Wine added: 4
[2025-03-11 20:54:51,684] INFO in logger: [UPDATE_WINE_ERROR] User 1: Wine not found: 1
[2025-03-11 20:55:54,692] INFO in logger: [GET_INVENTORY_VALUE] User 1: Inventory value fetched successfully
[2025-03-11 21:38:05,702] INFO in logger: [LOGIN_SUCCESS] User 1: User logged in successfully
[2025-03-11 21:39:28,572] INFO in logger: [GET_STOCK_BY_CATEGORY] User 1: Stock by category fetched successfully
[2025-03-11 21:41:19,335] ERROR in logger: [GET_USER_SALES_ERROR] User 1: 'User' object has no attribute 'get_user_sales'
[2025-03-11 21:45:26,874] INFO in logger: Wine Inventory API Started - Environment: development
[2025-03-11 21:45:32,487] INFO in logger: [GET_USER_SALES] User 1: Sales fetched for user 1: 0
[2025-03-11 21:53:44,967] ERROR in logger: [EXCEPTION] User None: Unhandled exception: NotFound
[2025-03-11 21:53:44,973] ERROR in app: Exception on / [GET]
Traceback (most recent call last):
  File "/Users/macbookpro/Documents/projects/WSS/venv/lib/python3.11/site-packages/flask/app.py", line 1463, in wsgi_app
    response = self.full_dispatch_request()
               ^^^^^^^^^^^^^^^^^^^^^^^^^^^^
  File "/Users/macbookpro/Documents/projects/WSS/venv/lib/python3.11/site-packages/flask/app.py", line 872, in full_dispatch_request
    rv = self.handle_user_exception(e)
         ^^^^^^^^^^^^^^^^^^^^^^^^^^^^^
  File "/Users/macbookpro/Documents/projects/WSS/venv/lib/python3.11/site-packages/flask_cors/extension.py", line 176, in wrapped_function
    return cors_after_request(app.make_response(f(*args, **kwargs)))
                                                ^^^^^^^^^^^^^^^^^^
  File "/Users/macbookpro/Documents/projects/WSS/venv/lib/python3.11/site-packages/flask/app.py", line 755, in handle_user_exception
    return self.handle_http_exception(e)
           ^^^^^^^^^^^^^^^^^^^^^^^^^^^^^
  File "/Users/macbookpro/Documents/projects/WSS/venv/lib/python3.11/site-packages/flask/app.py", line 730, in handle_http_exception
    return self.ensure_sync(handler)(e)  # type: ignore[no-any-return]
           ^^^^^^^^^^^^^^^^^^^^^^^^^^^^
  File "/Users/macbookpro/Documents/projects/WSS/majesty-backend/app/utils/logger.py", line 184, in log_exception
    raise exception
  File "/Users/macbookpro/Documents/projects/WSS/venv/lib/python3.11/site-packages/flask/app.py", line 870, in full_dispatch_request
    rv = self.dispatch_request()
         ^^^^^^^^^^^^^^^^^^^^^^^
  File "/Users/macbookpro/Documents/projects/WSS/venv/lib/python3.11/site-packages/flask/app.py", line 844, in dispatch_request
    self.raise_routing_exception(req)
  File "/Users/macbookpro/Documents/projects/WSS/venv/lib/python3.11/site-packages/flask/app.py", line 453, in raise_routing_exception
    raise request.routing_exception  # type: ignore[misc]
    ^^^^^^^^^^^^^^^^^^^^^^^^^^^^^^^
  File "/Users/macbookpro/Documents/projects/WSS/venv/lib/python3.11/site-packages/flask/ctx.py", line 362, in match_request
    result = self.url_adapter.match(return_rule=True)  # type: ignore
             ^^^^^^^^^^^^^^^^^^^^^^^^^^^^^^^^^^^^^^^^
  File "/Users/macbookpro/Documents/projects/WSS/venv/lib/python3.11/site-packages/werkzeug/routing/map.py", line 629, in match
    raise NotFound() from None
werkzeug.exceptions.NotFound: 404 Not Found: The requested URL was not found on the server. If you entered the URL manually please check your spelling and try again.
[2025-03-11 21:53:44,979] ERROR in logger: [EXCEPTION] User None: Unhandled exception: InternalServerError
[2025-03-11 21:55:13,042] ERROR in logger: [EXCEPTION] User None: Unhandled exception: NotFound
[2025-03-11 21:55:13,047] ERROR in app: Exception on /logs/user/1 [GET]
Traceback (most recent call last):
  File "/Users/macbookpro/Documents/projects/WSS/venv/lib/python3.11/site-packages/flask/app.py", line 1463, in wsgi_app
    response = self.full_dispatch_request()
               ^^^^^^^^^^^^^^^^^^^^^^^^^^^^
  File "/Users/macbookpro/Documents/projects/WSS/venv/lib/python3.11/site-packages/flask/app.py", line 872, in full_dispatch_request
    rv = self.handle_user_exception(e)
         ^^^^^^^^^^^^^^^^^^^^^^^^^^^^^
  File "/Users/macbookpro/Documents/projects/WSS/venv/lib/python3.11/site-packages/flask_cors/extension.py", line 176, in wrapped_function
    return cors_after_request(app.make_response(f(*args, **kwargs)))
                                                ^^^^^^^^^^^^^^^^^^
  File "/Users/macbookpro/Documents/projects/WSS/venv/lib/python3.11/site-packages/flask/app.py", line 755, in handle_user_exception
    return self.handle_http_exception(e)
           ^^^^^^^^^^^^^^^^^^^^^^^^^^^^^
  File "/Users/macbookpro/Documents/projects/WSS/venv/lib/python3.11/site-packages/flask/app.py", line 730, in handle_http_exception
    return self.ensure_sync(handler)(e)  # type: ignore[no-any-return]
           ^^^^^^^^^^^^^^^^^^^^^^^^^^^^
  File "/Users/macbookpro/Documents/projects/WSS/majesty-backend/app/utils/logger.py", line 184, in log_exception
    raise exception
  File "/Users/macbookpro/Documents/projects/WSS/venv/lib/python3.11/site-packages/flask/app.py", line 870, in full_dispatch_request
    rv = self.dispatch_request()
         ^^^^^^^^^^^^^^^^^^^^^^^
  File "/Users/macbookpro/Documents/projects/WSS/venv/lib/python3.11/site-packages/flask/app.py", line 844, in dispatch_request
    self.raise_routing_exception(req)
  File "/Users/macbookpro/Documents/projects/WSS/venv/lib/python3.11/site-packages/flask/app.py", line 453, in raise_routing_exception
    raise request.routing_exception  # type: ignore[misc]
    ^^^^^^^^^^^^^^^^^^^^^^^^^^^^^^^
  File "/Users/macbookpro/Documents/projects/WSS/venv/lib/python3.11/site-packages/flask/ctx.py", line 362, in match_request
    result = self.url_adapter.match(return_rule=True)  # type: ignore
             ^^^^^^^^^^^^^^^^^^^^^^^^^^^^^^^^^^^^^^^^
  File "/Users/macbookpro/Documents/projects/WSS/venv/lib/python3.11/site-packages/werkzeug/routing/map.py", line 629, in match
    raise NotFound() from None
werkzeug.exceptions.NotFound: 404 Not Found: The requested URL was not found on the server. If you entered the URL manually please check your spelling and try again.
[2025-03-11 21:55:13,056] ERROR in logger: [EXCEPTION] User None: Unhandled exception: InternalServerError
[2025-03-11 21:56:17,196] ERROR in logger: [EXCEPTION] User None: Unhandled exception: NotFound
[2025-03-11 21:56:17,202] ERROR in app: Exception on /logs/user/1 [GET]
Traceback (most recent call last):
  File "/Users/macbookpro/Documents/projects/WSS/venv/lib/python3.11/site-packages/flask/app.py", line 1463, in wsgi_app
    response = self.full_dispatch_request()
               ^^^^^^^^^^^^^^^^^^^^^^^^^^^^
  File "/Users/macbookpro/Documents/projects/WSS/venv/lib/python3.11/site-packages/flask/app.py", line 872, in full_dispatch_request
    rv = self.handle_user_exception(e)
         ^^^^^^^^^^^^^^^^^^^^^^^^^^^^^
  File "/Users/macbookpro/Documents/projects/WSS/venv/lib/python3.11/site-packages/flask_cors/extension.py", line 176, in wrapped_function
    return cors_after_request(app.make_response(f(*args, **kwargs)))
                                                ^^^^^^^^^^^^^^^^^^
  File "/Users/macbookpro/Documents/projects/WSS/venv/lib/python3.11/site-packages/flask/app.py", line 755, in handle_user_exception
    return self.handle_http_exception(e)
           ^^^^^^^^^^^^^^^^^^^^^^^^^^^^^
  File "/Users/macbookpro/Documents/projects/WSS/venv/lib/python3.11/site-packages/flask/app.py", line 730, in handle_http_exception
    return self.ensure_sync(handler)(e)  # type: ignore[no-any-return]
           ^^^^^^^^^^^^^^^^^^^^^^^^^^^^
  File "/Users/macbookpro/Documents/projects/WSS/majesty-backend/app/utils/logger.py", line 184, in log_exception
    raise exception
  File "/Users/macbookpro/Documents/projects/WSS/venv/lib/python3.11/site-packages/flask/app.py", line 870, in full_dispatch_request
    rv = self.dispatch_request()
         ^^^^^^^^^^^^^^^^^^^^^^^
  File "/Users/macbookpro/Documents/projects/WSS/venv/lib/python3.11/site-packages/flask/app.py", line 844, in dispatch_request
    self.raise_routing_exception(req)
  File "/Users/macbookpro/Documents/projects/WSS/venv/lib/python3.11/site-packages/flask/app.py", line 453, in raise_routing_exception
    raise request.routing_exception  # type: ignore[misc]
    ^^^^^^^^^^^^^^^^^^^^^^^^^^^^^^^
  File "/Users/macbookpro/Documents/projects/WSS/venv/lib/python3.11/site-packages/flask/ctx.py", line 362, in match_request
    result = self.url_adapter.match(return_rule=True)  # type: ignore
             ^^^^^^^^^^^^^^^^^^^^^^^^^^^^^^^^^^^^^^^^
  File "/Users/macbookpro/Documents/projects/WSS/venv/lib/python3.11/site-packages/werkzeug/routing/map.py", line 629, in match
    raise NotFound() from None
werkzeug.exceptions.NotFound: 404 Not Found: The requested URL was not found on the server. If you entered the URL manually please check your spelling and try again.
[2025-03-11 21:56:17,205] ERROR in logger: [EXCEPTION] User None: Unhandled exception: InternalServerError
[2025-03-11 22:39:21,419] INFO in logger: Wine Inventory API Started - Environment: development
[2025-03-11 22:39:52,496] INFO in logger: Wine Inventory API Started - Environment: development
[2025-03-11 22:42:56,616] INFO in logger: Wine Inventory API Started - Environment: development
[2025-03-11 22:43:00,911] INFO in logger: Wine Inventory API Started - Environment: development
[2025-03-11 22:46:52,728] INFO in logger: Wine Inventory API Started - Environment: development
[2025-03-12 00:07:56,401] INFO in logger: [LOGIN_SUCCESS] User 1: User logged in successfully
[2025-03-12 00:08:20,632] ERROR in logger: [EXCEPTION] User 1: Unhandled exception: AttributeError
[2025-03-12 00:08:20,636] ERROR in app: Exception on /auth/check-token [GET]
Traceback (most recent call last):
  File "/Users/macbookpro/Documents/projects/WSS/venv/lib/python3.11/site-packages/flask/app.py", line 1463, in wsgi_app
    response = self.full_dispatch_request()
               ^^^^^^^^^^^^^^^^^^^^^^^^^^^^
  File "/Users/macbookpro/Documents/projects/WSS/venv/lib/python3.11/site-packages/flask/app.py", line 872, in full_dispatch_request
    rv = self.handle_user_exception(e)
         ^^^^^^^^^^^^^^^^^^^^^^^^^^^^^
  File "/Users/macbookpro/Documents/projects/WSS/venv/lib/python3.11/site-packages/flask_cors/extension.py", line 176, in wrapped_function
    return cors_after_request(app.make_response(f(*args, **kwargs)))
                                                ^^^^^^^^^^^^^^^^^^
  File "/Users/macbookpro/Documents/projects/WSS/venv/lib/python3.11/site-packages/flask/app.py", line 762, in handle_user_exception
    return self.ensure_sync(handler)(e)  # type: ignore[no-any-return]
           ^^^^^^^^^^^^^^^^^^^^^^^^^^^^
  File "/Users/macbookpro/Documents/projects/WSS/majesty-backend/app/utils/logger.py", line 184, in log_exception
    raise exception
  File "/Users/macbookpro/Documents/projects/WSS/venv/lib/python3.11/site-packages/flask/app.py", line 870, in full_dispatch_request
    rv = self.dispatch_request()
         ^^^^^^^^^^^^^^^^^^^^^^^
  File "/Users/macbookpro/Documents/projects/WSS/venv/lib/python3.11/site-packages/flask/app.py", line 855, in dispatch_request
    return self.ensure_sync(self.view_functions[rule.endpoint])(**view_args)  # type: ignore[no-any-return]
           ^^^^^^^^^^^^^^^^^^^^^^^^^^^^^^^^^^^^^^^^^^^^^^^^^^^^^^^^^^^^^^^^^
  File "/Users/macbookpro/Documents/projects/WSS/venv/lib/python3.11/site-packages/flask_jwt_extended/view_decorators.py", line 170, in decorator
    return current_app.ensure_sync(fn)(*args, **kwargs)
           ^^^^^^^^^^^^^^^^^^^^^^^^^^^^^^^^^^^^^^^^^^^^
  File "/Users/macbookpro/Documents/projects/WSS/majesty-backend/app/routes/auth.py", line 130, in check_token
    expiry_datetime = datetime.utcfromtimestamp(expiry_timestamp)
                      ^^^^^^^^^^^^^^^^^^^^^^^^^
AttributeError: module 'datetime' has no attribute 'utcfromtimestamp'
[2025-03-12 00:08:20,640] ERROR in logger: [EXCEPTION] User 1: Unhandled exception: InternalServerError
[2025-03-12 00:08:31,180] ERROR in logger: [EXCEPTION] User 1: Unhandled exception: AttributeError
[2025-03-12 00:08:31,184] ERROR in app: Exception on /auth/check-token [GET]
Traceback (most recent call last):
  File "/Users/macbookpro/Documents/projects/WSS/venv/lib/python3.11/site-packages/flask/app.py", line 1463, in wsgi_app
    response = self.full_dispatch_request()
               ^^^^^^^^^^^^^^^^^^^^^^^^^^^^
  File "/Users/macbookpro/Documents/projects/WSS/venv/lib/python3.11/site-packages/flask/app.py", line 872, in full_dispatch_request
    rv = self.handle_user_exception(e)
         ^^^^^^^^^^^^^^^^^^^^^^^^^^^^^
  File "/Users/macbookpro/Documents/projects/WSS/venv/lib/python3.11/site-packages/flask_cors/extension.py", line 176, in wrapped_function
    return cors_after_request(app.make_response(f(*args, **kwargs)))
                                                ^^^^^^^^^^^^^^^^^^
  File "/Users/macbookpro/Documents/projects/WSS/venv/lib/python3.11/site-packages/flask/app.py", line 762, in handle_user_exception
    return self.ensure_sync(handler)(e)  # type: ignore[no-any-return]
           ^^^^^^^^^^^^^^^^^^^^^^^^^^^^
  File "/Users/macbookpro/Documents/projects/WSS/majesty-backend/app/utils/logger.py", line 184, in log_exception
    raise exception
  File "/Users/macbookpro/Documents/projects/WSS/venv/lib/python3.11/site-packages/flask/app.py", line 870, in full_dispatch_request
    rv = self.dispatch_request()
         ^^^^^^^^^^^^^^^^^^^^^^^
  File "/Users/macbookpro/Documents/projects/WSS/venv/lib/python3.11/site-packages/flask/app.py", line 855, in dispatch_request
    return self.ensure_sync(self.view_functions[rule.endpoint])(**view_args)  # type: ignore[no-any-return]
           ^^^^^^^^^^^^^^^^^^^^^^^^^^^^^^^^^^^^^^^^^^^^^^^^^^^^^^^^^^^^^^^^^
  File "/Users/macbookpro/Documents/projects/WSS/venv/lib/python3.11/site-packages/flask_jwt_extended/view_decorators.py", line 170, in decorator
    return current_app.ensure_sync(fn)(*args, **kwargs)
           ^^^^^^^^^^^^^^^^^^^^^^^^^^^^^^^^^^^^^^^^^^^^
  File "/Users/macbookpro/Documents/projects/WSS/majesty-backend/app/routes/auth.py", line 130, in check_token
    expiry_datetime = datetime.utcfromtimestamp(expiry_timestamp)
                      ^^^^^^^^^^^^^^^^^^^^^^^^^
AttributeError: module 'datetime' has no attribute 'utcfromtimestamp'
[2025-03-12 00:08:31,186] ERROR in logger: [EXCEPTION] User 1: Unhandled exception: InternalServerError
[2025-03-12 00:11:19,218] ERROR in logger: [EXCEPTION] User 1: Unhandled exception: AttributeError
[2025-03-12 00:11:19,224] ERROR in app: Exception on /auth/check-token [GET]
Traceback (most recent call last):
  File "/Users/macbookpro/Documents/projects/WSS/venv/lib/python3.11/site-packages/flask/app.py", line 1463, in wsgi_app
    response = self.full_dispatch_request()
               ^^^^^^^^^^^^^^^^^^^^^^^^^^^^
  File "/Users/macbookpro/Documents/projects/WSS/venv/lib/python3.11/site-packages/flask/app.py", line 872, in full_dispatch_request
    rv = self.handle_user_exception(e)
         ^^^^^^^^^^^^^^^^^^^^^^^^^^^^^
  File "/Users/macbookpro/Documents/projects/WSS/venv/lib/python3.11/site-packages/flask_cors/extension.py", line 176, in wrapped_function
    return cors_after_request(app.make_response(f(*args, **kwargs)))
                                                ^^^^^^^^^^^^^^^^^^
  File "/Users/macbookpro/Documents/projects/WSS/venv/lib/python3.11/site-packages/flask/app.py", line 762, in handle_user_exception
    return self.ensure_sync(handler)(e)  # type: ignore[no-any-return]
           ^^^^^^^^^^^^^^^^^^^^^^^^^^^^
  File "/Users/macbookpro/Documents/projects/WSS/majesty-backend/app/utils/logger.py", line 184, in log_exception
    raise exception
  File "/Users/macbookpro/Documents/projects/WSS/venv/lib/python3.11/site-packages/flask/app.py", line 870, in full_dispatch_request
    rv = self.dispatch_request()
         ^^^^^^^^^^^^^^^^^^^^^^^
  File "/Users/macbookpro/Documents/projects/WSS/venv/lib/python3.11/site-packages/flask/app.py", line 855, in dispatch_request
    return self.ensure_sync(self.view_functions[rule.endpoint])(**view_args)  # type: ignore[no-any-return]
           ^^^^^^^^^^^^^^^^^^^^^^^^^^^^^^^^^^^^^^^^^^^^^^^^^^^^^^^^^^^^^^^^^
  File "/Users/macbookpro/Documents/projects/WSS/venv/lib/python3.11/site-packages/flask_jwt_extended/view_decorators.py", line 170, in decorator
    return current_app.ensure_sync(fn)(*args, **kwargs)
           ^^^^^^^^^^^^^^^^^^^^^^^^^^^^^^^^^^^^^^^^^^^^
  File "/Users/macbookpro/Documents/projects/WSS/majesty-backend/app/routes/auth.py", line 130, in check_token
    expiry_datetime = datetime.utcfromtimestamp(expiry_timestamp)  # Correct usage
                      ^^^^^^^^^^^^^^^^^^^^^^^^^
AttributeError: module 'datetime' has no attribute 'utcfromtimestamp'
[2025-03-12 00:11:19,226] ERROR in logger: [EXCEPTION] User 1: Unhandled exception: InternalServerError
[2025-03-12 00:11:20,458] ERROR in logger: [EXCEPTION] User 1: Unhandled exception: AttributeError
[2025-03-12 00:11:20,467] ERROR in app: Exception on /auth/check-token [GET]
Traceback (most recent call last):
  File "/Users/macbookpro/Documents/projects/WSS/venv/lib/python3.11/site-packages/flask/app.py", line 1463, in wsgi_app
    response = self.full_dispatch_request()
               ^^^^^^^^^^^^^^^^^^^^^^^^^^^^
  File "/Users/macbookpro/Documents/projects/WSS/venv/lib/python3.11/site-packages/flask/app.py", line 872, in full_dispatch_request
    rv = self.handle_user_exception(e)
         ^^^^^^^^^^^^^^^^^^^^^^^^^^^^^
  File "/Users/macbookpro/Documents/projects/WSS/venv/lib/python3.11/site-packages/flask_cors/extension.py", line 176, in wrapped_function
    return cors_after_request(app.make_response(f(*args, **kwargs)))
                                                ^^^^^^^^^^^^^^^^^^
  File "/Users/macbookpro/Documents/projects/WSS/venv/lib/python3.11/site-packages/flask/app.py", line 762, in handle_user_exception
    return self.ensure_sync(handler)(e)  # type: ignore[no-any-return]
           ^^^^^^^^^^^^^^^^^^^^^^^^^^^^
  File "/Users/macbookpro/Documents/projects/WSS/majesty-backend/app/utils/logger.py", line 184, in log_exception
    raise exception
  File "/Users/macbookpro/Documents/projects/WSS/venv/lib/python3.11/site-packages/flask/app.py", line 870, in full_dispatch_request
    rv = self.dispatch_request()
         ^^^^^^^^^^^^^^^^^^^^^^^
  File "/Users/macbookpro/Documents/projects/WSS/venv/lib/python3.11/site-packages/flask/app.py", line 855, in dispatch_request
    return self.ensure_sync(self.view_functions[rule.endpoint])(**view_args)  # type: ignore[no-any-return]
           ^^^^^^^^^^^^^^^^^^^^^^^^^^^^^^^^^^^^^^^^^^^^^^^^^^^^^^^^^^^^^^^^^
  File "/Users/macbookpro/Documents/projects/WSS/venv/lib/python3.11/site-packages/flask_jwt_extended/view_decorators.py", line 170, in decorator
    return current_app.ensure_sync(fn)(*args, **kwargs)
           ^^^^^^^^^^^^^^^^^^^^^^^^^^^^^^^^^^^^^^^^^^^^
  File "/Users/macbookpro/Documents/projects/WSS/majesty-backend/app/routes/auth.py", line 130, in check_token
    expiry_datetime = datetime.utcfromtimestamp(expiry_timestamp)  # Correct usage
                      ^^^^^^^^^^^^^^^^^^^^^^^^^
AttributeError: module 'datetime' has no attribute 'utcfromtimestamp'
[2025-03-12 00:11:20,469] ERROR in logger: [EXCEPTION] User 1: Unhandled exception: InternalServerError
[2025-03-12 00:11:39,889] INFO in logger: Wine Inventory API Started - Environment: development
[2025-03-12 00:11:45,564] ERROR in logger: [EXCEPTION] User 1: Unhandled exception: AttributeError
[2025-03-12 00:11:45,603] ERROR in app: Exception on /auth/check-token [GET]
Traceback (most recent call last):
  File "/Users/macbookpro/Documents/projects/WSS/venv/lib/python3.11/site-packages/flask/app.py", line 1463, in wsgi_app
    response = self.full_dispatch_request()
               ^^^^^^^^^^^^^^^^^^^^^^^^^^^^
  File "/Users/macbookpro/Documents/projects/WSS/venv/lib/python3.11/site-packages/flask/app.py", line 872, in full_dispatch_request
    rv = self.handle_user_exception(e)
         ^^^^^^^^^^^^^^^^^^^^^^^^^^^^^
  File "/Users/macbookpro/Documents/projects/WSS/venv/lib/python3.11/site-packages/flask_cors/extension.py", line 176, in wrapped_function
    return cors_after_request(app.make_response(f(*args, **kwargs)))
                                                ^^^^^^^^^^^^^^^^^^
  File "/Users/macbookpro/Documents/projects/WSS/venv/lib/python3.11/site-packages/flask/app.py", line 762, in handle_user_exception
    return self.ensure_sync(handler)(e)  # type: ignore[no-any-return]
           ^^^^^^^^^^^^^^^^^^^^^^^^^^^^
  File "/Users/macbookpro/Documents/projects/WSS/majesty-backend/app/utils/logger.py", line 184, in log_exception
    raise exception
  File "/Users/macbookpro/Documents/projects/WSS/venv/lib/python3.11/site-packages/flask/app.py", line 870, in full_dispatch_request
    rv = self.dispatch_request()
         ^^^^^^^^^^^^^^^^^^^^^^^
  File "/Users/macbookpro/Documents/projects/WSS/venv/lib/python3.11/site-packages/flask/app.py", line 855, in dispatch_request
    return self.ensure_sync(self.view_functions[rule.endpoint])(**view_args)  # type: ignore[no-any-return]
           ^^^^^^^^^^^^^^^^^^^^^^^^^^^^^^^^^^^^^^^^^^^^^^^^^^^^^^^^^^^^^^^^^
  File "/Users/macbookpro/Documents/projects/WSS/venv/lib/python3.11/site-packages/flask_jwt_extended/view_decorators.py", line 170, in decorator
    return current_app.ensure_sync(fn)(*args, **kwargs)
           ^^^^^^^^^^^^^^^^^^^^^^^^^^^^^^^^^^^^^^^^^^^^
  File "/Users/macbookpro/Documents/projects/WSS/majesty-backend/app/routes/auth.py", line 130, in check_token
    expiry_datetime = datetime.utcfromtimestamp(expiry_timestamp)  # Correct usage
                      ^^^^^^^^^^^^^^^^^^^^^^^^^
AttributeError: module 'datetime' has no attribute 'utcfromtimestamp'
[2025-03-12 00:11:45,608] ERROR in logger: [EXCEPTION] User 1: Unhandled exception: InternalServerError
[2025-03-12 00:12:09,267] INFO in logger: Wine Inventory API Started - Environment: development
[2025-03-12 00:12:14,471] ERROR in logger: [EXCEPTION] User 1: Unhandled exception: AttributeError
[2025-03-12 00:12:14,499] ERROR in app: Exception on /auth/check-token [GET]
Traceback (most recent call last):
  File "/Users/macbookpro/Documents/projects/WSS/venv/lib/python3.11/site-packages/flask/app.py", line 1463, in wsgi_app
    response = self.full_dispatch_request()
               ^^^^^^^^^^^^^^^^^^^^^^^^^^^^
  File "/Users/macbookpro/Documents/projects/WSS/venv/lib/python3.11/site-packages/flask/app.py", line 872, in full_dispatch_request
    rv = self.handle_user_exception(e)
         ^^^^^^^^^^^^^^^^^^^^^^^^^^^^^
  File "/Users/macbookpro/Documents/projects/WSS/venv/lib/python3.11/site-packages/flask_cors/extension.py", line 176, in wrapped_function
    return cors_after_request(app.make_response(f(*args, **kwargs)))
                                                ^^^^^^^^^^^^^^^^^^
  File "/Users/macbookpro/Documents/projects/WSS/venv/lib/python3.11/site-packages/flask/app.py", line 762, in handle_user_exception
    return self.ensure_sync(handler)(e)  # type: ignore[no-any-return]
           ^^^^^^^^^^^^^^^^^^^^^^^^^^^^
  File "/Users/macbookpro/Documents/projects/WSS/majesty-backend/app/utils/logger.py", line 184, in log_exception
    raise exception
  File "/Users/macbookpro/Documents/projects/WSS/venv/lib/python3.11/site-packages/flask/app.py", line 870, in full_dispatch_request
    rv = self.dispatch_request()
         ^^^^^^^^^^^^^^^^^^^^^^^
  File "/Users/macbookpro/Documents/projects/WSS/venv/lib/python3.11/site-packages/flask/app.py", line 855, in dispatch_request
    return self.ensure_sync(self.view_functions[rule.endpoint])(**view_args)  # type: ignore[no-any-return]
           ^^^^^^^^^^^^^^^^^^^^^^^^^^^^^^^^^^^^^^^^^^^^^^^^^^^^^^^^^^^^^^^^^
  File "/Users/macbookpro/Documents/projects/WSS/venv/lib/python3.11/site-packages/flask_jwt_extended/view_decorators.py", line 170, in decorator
    return current_app.ensure_sync(fn)(*args, **kwargs)
           ^^^^^^^^^^^^^^^^^^^^^^^^^^^^^^^^^^^^^^^^^^^^
  File "/Users/macbookpro/Documents/projects/WSS/majesty-backend/app/routes/auth.py", line 130, in check_token
    expiry_datetime = datetime.utcfromtimestamp(expiry_timestamp)  # Correct usage
                      ^^^^^^^^^^^^^^^^^^^^^^^^^
AttributeError: module 'datetime' has no attribute 'utcfromtimestamp'
[2025-03-12 00:12:14,503] ERROR in logger: [EXCEPTION] User 1: Unhandled exception: InternalServerError
[2025-03-12 00:13:36,946] ERROR in logger: [EXCEPTION] User 1: Unhandled exception: AttributeError
[2025-03-12 00:13:36,951] ERROR in app: Exception on /auth/check-token [GET]
Traceback (most recent call last):
  File "/Users/macbookpro/Documents/projects/WSS/venv/lib/python3.11/site-packages/flask/app.py", line 1463, in wsgi_app
    response = self.full_dispatch_request()
               ^^^^^^^^^^^^^^^^^^^^^^^^^^^^
  File "/Users/macbookpro/Documents/projects/WSS/venv/lib/python3.11/site-packages/flask/app.py", line 872, in full_dispatch_request
    rv = self.handle_user_exception(e)
         ^^^^^^^^^^^^^^^^^^^^^^^^^^^^^
  File "/Users/macbookpro/Documents/projects/WSS/venv/lib/python3.11/site-packages/flask_cors/extension.py", line 176, in wrapped_function
    return cors_after_request(app.make_response(f(*args, **kwargs)))
                                                ^^^^^^^^^^^^^^^^^^
  File "/Users/macbookpro/Documents/projects/WSS/venv/lib/python3.11/site-packages/flask/app.py", line 762, in handle_user_exception
    return self.ensure_sync(handler)(e)  # type: ignore[no-any-return]
           ^^^^^^^^^^^^^^^^^^^^^^^^^^^^
  File "/Users/macbookpro/Documents/projects/WSS/majesty-backend/app/utils/logger.py", line 184, in log_exception
    raise exception
  File "/Users/macbookpro/Documents/projects/WSS/venv/lib/python3.11/site-packages/flask/app.py", line 870, in full_dispatch_request
    rv = self.dispatch_request()
         ^^^^^^^^^^^^^^^^^^^^^^^
  File "/Users/macbookpro/Documents/projects/WSS/venv/lib/python3.11/site-packages/flask/app.py", line 855, in dispatch_request
    return self.ensure_sync(self.view_functions[rule.endpoint])(**view_args)  # type: ignore[no-any-return]
           ^^^^^^^^^^^^^^^^^^^^^^^^^^^^^^^^^^^^^^^^^^^^^^^^^^^^^^^^^^^^^^^^^
  File "/Users/macbookpro/Documents/projects/WSS/venv/lib/python3.11/site-packages/flask_jwt_extended/view_decorators.py", line 170, in decorator
    return current_app.ensure_sync(fn)(*args, **kwargs)
           ^^^^^^^^^^^^^^^^^^^^^^^^^^^^^^^^^^^^^^^^^^^^
  File "/Users/macbookpro/Documents/projects/WSS/majesty-backend/app/routes/auth.py", line 130, in check_token
    expiry_datetime = datetime.utcfromtimestamp(expiry_timestamp)  # Correct usage
                      ^^^^^^^^^^^^^^^^^^^^^^^^^
AttributeError: module 'datetime' has no attribute 'utcfromtimestamp'
[2025-03-12 00:13:36,953] ERROR in logger: [EXCEPTION] User 1: Unhandled exception: InternalServerError
[2025-03-12 00:14:15,562] ERROR in logger: [EXCEPTION] User 1: Unhandled exception: AttributeError
[2025-03-12 00:14:15,569] ERROR in app: Exception on /auth/check-token [GET]
Traceback (most recent call last):
  File "/Users/macbookpro/Documents/projects/WSS/venv/lib/python3.11/site-packages/flask/app.py", line 1463, in wsgi_app
    response = self.full_dispatch_request()
               ^^^^^^^^^^^^^^^^^^^^^^^^^^^^
  File "/Users/macbookpro/Documents/projects/WSS/venv/lib/python3.11/site-packages/flask/app.py", line 872, in full_dispatch_request
    rv = self.handle_user_exception(e)
         ^^^^^^^^^^^^^^^^^^^^^^^^^^^^^
  File "/Users/macbookpro/Documents/projects/WSS/venv/lib/python3.11/site-packages/flask_cors/extension.py", line 176, in wrapped_function
    return cors_after_request(app.make_response(f(*args, **kwargs)))
                                                ^^^^^^^^^^^^^^^^^^
  File "/Users/macbookpro/Documents/projects/WSS/venv/lib/python3.11/site-packages/flask/app.py", line 762, in handle_user_exception
    return self.ensure_sync(handler)(e)  # type: ignore[no-any-return]
           ^^^^^^^^^^^^^^^^^^^^^^^^^^^^
  File "/Users/macbookpro/Documents/projects/WSS/majesty-backend/app/utils/logger.py", line 184, in log_exception
    raise exception
  File "/Users/macbookpro/Documents/projects/WSS/venv/lib/python3.11/site-packages/flask/app.py", line 870, in full_dispatch_request
    rv = self.dispatch_request()
         ^^^^^^^^^^^^^^^^^^^^^^^
  File "/Users/macbookpro/Documents/projects/WSS/venv/lib/python3.11/site-packages/flask/app.py", line 855, in dispatch_request
    return self.ensure_sync(self.view_functions[rule.endpoint])(**view_args)  # type: ignore[no-any-return]
           ^^^^^^^^^^^^^^^^^^^^^^^^^^^^^^^^^^^^^^^^^^^^^^^^^^^^^^^^^^^^^^^^^
  File "/Users/macbookpro/Documents/projects/WSS/venv/lib/python3.11/site-packages/flask_jwt_extended/view_decorators.py", line 170, in decorator
    return current_app.ensure_sync(fn)(*args, **kwargs)
           ^^^^^^^^^^^^^^^^^^^^^^^^^^^^^^^^^^^^^^^^^^^^
  File "/Users/macbookpro/Documents/projects/WSS/majesty-backend/app/routes/auth.py", line 130, in check_token
    expiry_datetime = datetime.utcfromtimestamp(expiry_timestamp)  # Correct usage
                      ^^^^^^^^^^^^^^^^^^^^^^^^^
AttributeError: module 'datetime' has no attribute 'utcfromtimestamp'
[2025-03-12 00:14:15,572] ERROR in logger: [EXCEPTION] User 1: Unhandled exception: InternalServerError
[2025-03-12 00:16:31,344] ERROR in logger: [EXCEPTION] User 1: Unhandled exception: AttributeError
[2025-03-12 00:16:31,348] ERROR in app: Exception on /auth/check-token [GET]
Traceback (most recent call last):
  File "/Users/macbookpro/Documents/projects/WSS/venv/lib/python3.11/site-packages/flask/app.py", line 1463, in wsgi_app
    response = self.full_dispatch_request()
               ^^^^^^^^^^^^^^^^^^^^^^^^^^^^
  File "/Users/macbookpro/Documents/projects/WSS/venv/lib/python3.11/site-packages/flask/app.py", line 872, in full_dispatch_request
    rv = self.handle_user_exception(e)
         ^^^^^^^^^^^^^^^^^^^^^^^^^^^^^
  File "/Users/macbookpro/Documents/projects/WSS/venv/lib/python3.11/site-packages/flask_cors/extension.py", line 176, in wrapped_function
    return cors_after_request(app.make_response(f(*args, **kwargs)))
                                                ^^^^^^^^^^^^^^^^^^
  File "/Users/macbookpro/Documents/projects/WSS/venv/lib/python3.11/site-packages/flask/app.py", line 762, in handle_user_exception
    return self.ensure_sync(handler)(e)  # type: ignore[no-any-return]
           ^^^^^^^^^^^^^^^^^^^^^^^^^^^^
  File "/Users/macbookpro/Documents/projects/WSS/majesty-backend/app/utils/logger.py", line 184, in log_exception
    raise exception
  File "/Users/macbookpro/Documents/projects/WSS/venv/lib/python3.11/site-packages/flask/app.py", line 870, in full_dispatch_request
    rv = self.dispatch_request()
         ^^^^^^^^^^^^^^^^^^^^^^^
  File "/Users/macbookpro/Documents/projects/WSS/venv/lib/python3.11/site-packages/flask/app.py", line 855, in dispatch_request
    return self.ensure_sync(self.view_functions[rule.endpoint])(**view_args)  # type: ignore[no-any-return]
           ^^^^^^^^^^^^^^^^^^^^^^^^^^^^^^^^^^^^^^^^^^^^^^^^^^^^^^^^^^^^^^^^^
  File "/Users/macbookpro/Documents/projects/WSS/venv/lib/python3.11/site-packages/flask_jwt_extended/view_decorators.py", line 170, in decorator
    return current_app.ensure_sync(fn)(*args, **kwargs)
           ^^^^^^^^^^^^^^^^^^^^^^^^^^^^^^^^^^^^^^^^^^^^
  File "/Users/macbookpro/Documents/projects/WSS/majesty-backend/app/routes/auth.py", line 130, in check_token
    expiry_datetime = datetime.utcfromtimestamp(expiry_timestamp)  # Correct usage
                      ^^^^^^^^^^^^^^^^^^^^^^^^^
AttributeError: module 'datetime' has no attribute 'utcfromtimestamp'
[2025-03-12 00:16:31,351] ERROR in logger: [EXCEPTION] User 1: Unhandled exception: InternalServerError
[2025-03-12 00:16:42,815] INFO in logger: Wine Inventory API Started - Environment: development
[2025-03-12 04:09:47,373] INFO in logger: Wine Inventory API Started - Environment: development
[2025-03-12 04:16:15,006] INFO in logger: Wine Inventory API Started - Environment: development
[2025-03-12 04:16:25,087] INFO in logger: Wine Inventory API Started - Environment: development
[2025-03-12 04:18:31,256] INFO in logger: Wine Inventory API Started - Environment: development
[2025-03-12 04:19:15,534] INFO in logger: Wine Inventory API Started - Environment: development
[2025-03-14 11:42:34,837] INFO in logger: Wine Inventory API Started - Environment: development
[2025-03-14 11:45:10,106] INFO in logger: [LOGIN_SUCCESS] User 1: User logged in successfully
[2025-03-14 11:49:16,477] INFO in logger: [LOGIN_SUCCESS] User 1: User logged in successfully
[2025-03-14 11:50:25,362] ERROR in logger: [CHECKOUT_ERROR] User 1: Wine 1 not found
[2025-03-14 11:52:20,305] INFO in logger: [CHECKOUT_SUCCESS] User 1: Checkout completed for invoice 1
[2025-03-14 12:10:01,885] INFO in logger: [CREATE_USER_SUCCESS] User 1: Created user: role_user
[2025-03-14 12:11:28,688] INFO in logger: [CREATE_USER_SUCCESS] User 1: Created user: super_user
[2025-03-14 12:15:46,048] INFO in logger: [CREATE_USER_DUPLICATE] User 1: Attempted to create duplicate user: super_user
[2025-03-14 12:15:59,142] INFO in logger: [CREATE_USER_SUCCESS] User 1: Created user: third_user_try
[2025-03-16 11:49:55,753] INFO in logger: Wine Inventory API Started - Environment: development
[2025-03-16 11:53:56,842] INFO in logger: Wine Inventory API Started - Environment: development
